{
  "version": 8,
  "blockIdVersion": 8,
  "anchorX": 0,
  "anchorY": 10,
  "anchorZ": 1,
  "blocks": [
    {
      "x": -22,
      "y": 10,
      "z": -8,
      "name": "Rock_Stone_Cobble"
    },
    {
      "x": -22,
      "y": 11,
      "z": -8,
      "name": "Rock_Stone_Cobble"
    },
    {
      "x": -22,
      "y": 12,
      "z": -8,
      "name": "Rock_Stone_Cobble"
    },
    {
      "x": -22,
      "y": 10,
      "z": -7,
      "name": "Rock_Stone_Cobble"
    },
    {
      "x": -22,
      "y": 11,
      "z": -7,
      "name": "Rock_Stone_Cobble"
    },
    {
      "x": -22,
      "y": 12,
      "z": -7,
      "name": "Rock_Stone_Cobble"
    },
    {
      "x": -22,
      "y": 10,
      "z": -3,
      "name": "Rock_Stone_Cobble"
    },
    {
      "x": -22,
      "y": 11,
      "z": -3,
      "name": "Rock_Stone_Cobble"
    },
    {
      "x": -22,
      "y": 12,
      "z": -3,
      "name": "Rock_Stone_Cobble"
    },
    {
      "x": -21,
      "y": 10,
      "z": -9,
      "name": "Rock_Stone_Cobble"
    },
    {
      "x": -21,
      "y": 11,
      "z": -9,
      "name": "Rock_Stone_Cobble"
    },
    {
      "x": -21,
      "y": 12,
      "z": -9,
      "name": "Rock_Stone_Cobble"
    },
    {
      "x": -21,
      "y": 8,
      "z": -8,
      "name": "Wood_Beech_Trunk",
      "support": 15
    },
    {
      "x": -21,
      "y": 9,
      "z": -8,
      "name": "Wood_Beech_Trunk",
      "support": 15
    },
    {
      "x": -21,
      "y": 10,
      "z": -8,
      "name": "Wood_Beech_Trunk",
      "support": 15
    },
    {
      "x": -21,
      "y": 11,
      "z": -8,
      "name": "Wood_Beech_Trunk",
      "support": 15
    },
    {
      "x": -21,
      "y": 12,
      "z": -8,
      "name": "Wood_Beech_Trunk",
      "support": 15
    },
    {
      "x": -21,
      "y": 13,
      "z": -8,
      "name": "Wood_Beech_Trunk_Full",
      "support": 15
    },
    {
      "x": -21,
      "y": 14,
      "z": -8,
      "name": "Wood_Beech_Branch_Long",
      "support": 15
    },
    {
      "x": -21,
      "y": 15,
      "z": -8,
      "name": "Survival_Trap_Spike_Wood_Large"
    },
    {
      "x": -21,
      "y": 9,
      "z": -7,
      "name": "Wood_Beech_Trunk",
      "support": 15
    },
    {
      "x": -21,
      "y": 10,
      "z": -7,
      "name": "Wood_Beech_Trunk",
      "support": 15
    },
    {
      "x": -21,
      "y": 11,
      "z": -7,
      "name": "Wood_Beech_Trunk",
      "support": 15
    },
    {
      "x": -21,
      "y": 12,
      "z": -7,
      "name": "Wood_Beech_Trunk",
      "support": 15
    },
    {
      "x": -21,
      "y": 13,
      "z": -7,
      "name": "Wood_Beech_Trunk",
      "support": 15
    },
    {
      "x": -21,
      "y": 14,
      "z": -7,
      "name": "Wood_Beech_Trunk_Full",
      "support": 15
    },
    {
      "x": -21,
      "y": 15,
      "z": -7,
      "name": "Wood_Beech_Branch_Long",
      "support": 15
    },
    {
      "x": -21,
      "y": 16,
      "z": -7,
      "name": "Wood_Beech_Branch_Long",
      "support": 15
    },
    {
      "x": -21,
      "y": 17,
      "z": -7,
      "name": "Survival_Trap_Spike_Wood_Large"
    },
    {
      "x": -21,
      "y": 9,
      "z": -6,
      "name": "Wood_Beech_Trunk",
      "support": 15
    },
    {
      "x": -21,
      "y": 10,
      "z": -6,
      "name": "Wood_Beech_Trunk",
      "support": 15
    },
    {
      "x": -21,
      "y": 11,
      "z": -6,
      "name": "Wood_Beech_Trunk",
      "support": 15
    },
    {
      "x": -21,
      "y": 12,
      "z": -6,
      "name": "Wood_Beech_Trunk",
      "support": 15
    },
    {
      "x": -21,
      "y": 13,
      "z": -6,
      "name": "Wood_Beech_Trunk",
      "support": 15
    },
    {
      "x": -21,
      "y": 14,
      "z": -6,
      "name": "Wood_Beech_Trunk",
      "support": 15
    },
    {
      "x": -21,
      "y": 7,
      "z": -5,
      "name": "Wood_Beech_Trunk",
      "support": 15
    },
    {
      "x": -21,
      "y": 8,
      "z": -5,
      "name": "Wood_Beech_Trunk",
      "support": 15
    },
    {
      "x": -21,
      "y": 9,
      "z": -5,
      "name": "Wood_Beech_Trunk",
      "support": 15
    },
    {
      "x": -21,
      "y": 10,
      "z": -5,
      "name": "Wood_Beech_Trunk",
      "support": 15
    },
    {
      "x": -21,
      "y": 11,
      "z": -5,
      "name": "Wood_Beech_Trunk",
      "support": 15
    },
    {
      "x": -21,
      "y": 12,
      "z": -5,
      "name": "Wood_Beech_Trunk",
      "support": 15
    },
    {
      "x": -21,
      "y": 13,
      "z": -5,
      "name": "Wood_Beech_Trunk",
      "support": 15
    },
    {
      "x": -21,
      "y": 7,
      "z": -4,
      "name": "Wood_Beech_Trunk",
      "support": 15
    },
    {
      "x": -21,
      "y": 8,
      "z": -4,
      "name": "Wood_Beech_Trunk",
      "support": 15
    },
    {
      "x": -21,
      "y": 9,
      "z": -4,
      "name": "Wood_Beech_Trunk",
      "support": 15
    },
    {
      "x": -21,
      "y": 10,
      "z": -4,
      "name": "Wood_Beech_Trunk",
      "support": 15
    },
    {
      "x": -21,
      "y": 11,
      "z": -4,
      "name": "Wood_Beech_Trunk",
      "support": 15
    },
    {
      "x": -21,
      "y": 12,
      "z": -4,
      "name": "Wood_Beech_Trunk",
      "support": 15
    },
    {
      "x": -21,
      "y": 8,
      "z": -3,
      "name": "Wood_Beech_Trunk",
      "support": 15
    },
    {
      "x": -21,
      "y": 9,
      "z": -3,
      "name": "Wood_Beech_Trunk",
      "support": 15
    },
    {
      "x": -21,
      "y": 10,
      "z": -3,
      "name": "Wood_Beech_Trunk",
      "support": 15
    },
    {
      "x": -21,
      "y": 11,
      "z": -3,
      "name": "Wood_Beech_Trunk",
      "support": 15
    },
    {
      "x": -21,
      "y": 12,
      "z": -3,
      "name": "Wood_Beech_Trunk",
      "support": 15
    },
    {
      "x": -21,
      "y": 13,
      "z": -3,
      "name": "Wood_Beech_Trunk_Full"
    },
    {
      "x": -21,
      "y": 14,
      "z": -3,
      "name": "Wood_Beech_Branch_Long",
      "support": 15
    },
    {
      "x": -21,
      "y": 15,
      "z": -3,
      "name": "Survival_Trap_Spike_Wood_Large"
    },
    {
      "x": -21,
      "y": 10,
      "z": -2,
      "name": "Rock_Stone_Cobble"
    },
    {
      "x": -21,
      "y": 11,
      "z": -2,
      "name": "Rock_Stone_Cobble"
    },
    {
      "x": -21,
      "y": 12,
      "z": -2,
      "name": "Rock_Stone_Cobble"
    },
    {
      "x": -21,
      "y": 10,
      "z": -1,
      "name": "Rock_Stone_Cobble"
    },
    {
      "x": -21,
      "y": 11,
      "z": -1,
      "name": "Rock_Stone_Cobble"
    },
    {
      "x": -21,
      "y": 12,
      "z": -1,
      "name": "Rock_Stone_Cobble"
    },
    {
      "x": -21,
      "y": 10,
      "z": 0,
      "name": "Soil_Dirt"
    },
    {
      "x": -21,
      "y": 11,
      "z": 0,
      "name": "Empty"
    },
    {
      "x": -21,
      "y": 10,
      "z": 1,
      "name": "Soil_Dirt"
    },
    {
      "x": -21,
      "y": 11,
      "z": 1,
      "name": "Empty"
    },
    {
      "x": -20,
      "y": 10,
      "z": -14,
      "name": "Soil_Pathway"
    },
    {
      "x": -20,
      "y": 11,
      "z": -14,
      "name": "Empty"
    },
    {
      "x": -20,
      "y": 10,
      "z": -13,
      "name": "Soil_Pathway"
    },
    {
      "x": -20,
      "y": 11,
      "z": -13,
      "name": "Empty"
    },
    {
      "x": -20,
      "y": 10,
      "z": -10,
      "name": "Rock_Stone_Cobble"
    },
    {
      "x": -20,
      "y": 11,
      "z": -10,
      "name": "Rock_Stone_Cobble"
    },
    {
      "x": -20,
      "y": 12,
      "z": -10,
      "name": "Rock_Stone_Cobble"
    },
    {
      "x": -20,
      "y": 10,
      "z": -9,
      "name": "Rock_Stone_Cobble"
    },
    {
      "x": -20,
      "y": 11,
      "z": -9,
      "name": "Rock_Stone_Cobble"
    },
    {
      "x": -20,
      "y": 12,
      "z": -9,
      "name": "Rock_Stone_Cobble"
    },
    {
      "x": -20,
      "y": 10,
      "z": -8,
      "name": "Soil_Dirt"
    },
    {
      "x": -20,
      "y": 11,
      "z": -8,
      "name": "Empty"
    },
    {
      "x": -20,
      "y": 10,
      "z": -7,
      "name": "Soil_Dirt"
    },
    {
      "x": -20,
      "y": 11,
      "z": -7,
      "name": "Empty"
    },
    {
      "x": -20,
      "y": 10,
      "z": -6,
      "name": "Soil_Dirt"
    },
    {
      "x": -20,
      "y": 11,
      "z": -6,
      "name": "Empty"
    },
    {
      "x": -20,
      "y": 10,
      "z": -5,
      "name": "Soil_Dirt"
    },
    {
      "x": -20,
      "y": 11,
      "z": -5,
      "name": "Empty"
    },
    {
      "x": -20,
      "y": 10,
      "z": -4,
      "name": "Soil_Dirt"
    },
    {
      "x": -20,
      "y": 11,
      "z": -4,
      "name": "Empty"
    },
    {
      "x": -20,
      "y": 10,
      "z": -3,
      "name": "Soil_Pathway"
    },
    {
      "x": -20,
      "y": 11,
      "z": -3,
      "name": "Empty"
    },
    {
      "x": -20,
      "y": 10,
      "z": -2,
      "name": "Soil_Pathway"
    },
    {
      "x": -20,
      "y": 11,
      "z": -2,
      "name": "Empty"
    },
    {
      "x": -20,
      "y": 10,
      "z": -1,
      "name": "Rock_Stone_Cobble"
    },
    {
      "x": -20,
      "y": 11,
      "z": -1,
      "name": "Rock_Stone_Cobble"
    },
    {
      "x": -20,
      "y": 12,
      "z": -1,
      "name": "Rock_Stone_Cobble"
    },
    {
      "x": -20,
      "y": 10,
      "z": 0,
      "name": "Soil_Dirt"
    },
    {
      "x": -20,
      "y": 11,
      "z": 0,
      "name": "Empty"
    },
    {
      "x": -20,
      "y": 10,
      "z": 1,
      "name": "Soil_Pathway"
    },
    {
      "x": -20,
      "y": 11,
      "z": 1,
      "name": "Empty"
    },
    {
      "x": -20,
      "y": 10,
      "z": 2,
      "name": "Soil_Pathway"
    },
    {
      "x": -20,
      "y": 11,
      "z": 2,
      "name": "Empty"
    },
    {
      "x": -20,
      "y": 10,
      "z": 3,
      "name": "Soil_Pathway"
    },
    {
      "x": -20,
      "y": 11,
      "z": 3,
      "name": "Empty"
    },
    {
      "x": -19,
      "y": 10,
      "z": -15,
      "name": "Soil_Dirt"
    },
    {
      "x": -19,
      "y": 11,
      "z": -15,
      "name": "Empty"
    },
    {
      "x": -19,
      "y": 10,
      "z": -14,
      "name": "Soil_Pathway"
    },
    {
      "x": -19,
      "y": 11,
      "z": -14,
      "name": "Empty"
    },
    {
      "x": -19,
      "y": 10,
      "z": -13,
      "name": "Soil_Pathway"
    },
    {
      "x": -19,
      "y": 11,
      "z": -13,
      "name": "Empty"
    },
    {
      "x": -19,
      "y": 10,
      "z": -10,
      "name": "Soil_Pathway"
    },
    {
      "x": -19,
      "y": 11,
      "z": -10,
      "name": "Empty"
    },
    {
      "x": -19,
      "y": 10,
      "z": -9,
      "name": "Soil_Pathway"
    },
    {
      "x": -19,
      "y": 11,
      "z": -9,
      "name": "Empty"
    },
    {
      "x": -19,
      "y": 10,
      "z": -8,
      "name": "Soil_Dirt"
    },
    {
      "x": -19,
      "y": 11,
      "z": -8,
      "name": "Empty"
    },
    {
      "x": -19,
      "y": 10,
      "z": -7,
      "name": "Soil_Dirt"
    },
    {
      "x": -19,
      "y": 11,
      "z": -7,
      "name": "Empty"
    },
    {
      "x": -19,
      "y": 10,
      "z": -4,
      "name": "Soil_Dirt"
    },
    {
      "x": -19,
      "y": 11,
      "z": -4,
      "name": "Empty"
    },
    {
      "x": -19,
      "y": 10,
      "z": -3,
      "name": "Soil_Pathway"
    },
    {
      "x": -19,
      "y": 11,
      "z": -3,
      "name": "Empty"
    },
    {
      "x": -19,
      "y": 10,
      "z": -2,
      "name": "Soil_Pathway"
    },
    {
      "x": -19,
      "y": 11,
      "z": -2,
      "name": "Empty"
    },
    {
      "x": -19,
      "y": 10,
      "z": -1,
      "name": "Soil_Pathway"
    },
    {
      "x": -19,
      "y": 11,
      "z": -1,
      "name": "Furniture_Village_Crate"
    },
    {
      "x": -19,
      "y": 10,
      "z": 0,
      "name": "Soil_Pathway"
    },
    {
      "x": -19,
      "y": 11,
      "z": 0,
      "name": "Furniture_Tavern_Barrel"
    },
    {
      "x": -19,
      "y": 10,
      "z": 1,
      "name": "Soil_Pathway"
    },
    {
      "x": -19,
      "y": 11,
      "z": 1,
      "name": "Bench_Lumbermill",
      "components": {
        "Components": {
          "processingBench": {
            "Position": {
              "X": 13,
              "Y": 11,
              "Z": 1
            },
            "TierLevel": 1,
            "UpgradeItems": [],
            "Progress": 0.0,
            "FuelTime": 0.0,
            "Active": false,
            "NextExtra": -1
          }
        }
      },
      "filler": 31
    },
    {
      "x": -19,
      "y": 10,
      "z": 2,
      "name": "Soil_Pathway"
    },
    {
      "x": -19,
      "y": 11,
      "z": 2,
      "name": "Empty"
    },
    {
      "x": -19,
      "y": 10,
      "z": 3,
      "name": "Soil_Pathway"
    },
    {
      "x": -19,
      "y": 11,
      "z": 3,
      "name": "Empty"
    },
    {
      "x": -18,
      "y": 10,
      "z": -15,
      "name": "Soil_Dirt"
    },
    {
      "x": -18,
      "y": 11,
      "z": -15,
      "name": "Empty"
    },
    {
      "x": -18,
      "y": 10,
      "z": -14,
      "name": "Soil_Pathway"
    },
    {
      "x": -18,
      "y": 11,
      "z": -14,
      "name": "Empty"
    },
    {
      "x": -18,
      "y": 10,
      "z": -13,
      "name": "Soil_Pathway"
    },
    {
      "x": -18,
      "y": 11,
      "z": -13,
      "name": "Empty"
    },
    {
      "x": -18,
      "y": 10,
      "z": -11,
      "name": "Soil_Pathway"
    },
    {
      "x": -18,
      "y": 11,
      "z": -11,
      "name": "Empty"
    },
    {
      "x": -18,
      "y": 10,
      "z": -10,
      "name": "Soil_Pathway"
    },
    {
      "x": -18,
      "y": 11,
      "z": -10,
      "name": "Empty"
    },
    {
      "x": -18,
      "y": 10,
      "z": -9,
      "name": "Soil_Pathway"
    },
    {
      "x": -18,
      "y": 11,
      "z": -9,
      "name": "Empty"
    },
    {
      "x": -18,
      "y": 10,
      "z": -3,
      "name": "Soil_Dirt"
    },
    {
      "x": -18,
      "y": 11,
      "z": -3,
      "name": "Empty"
    },
    {
      "x": -18,
      "y": 10,
      "z": -2,
      "name": "Soil_Pathway"
    },
    {
      "x": -18,
      "y": 11,
      "z": -2,
      "name": "Empty"
    },
    {
      "x": -18,
      "y": 10,
      "z": -1,
      "name": "Soil_Pathway"
    },
    {
      "x": -18,
      "y": 11,
      "z": -1,
      "name": "Furniture_Village_Crate"
    },
    {
      "x": -18,
      "y": 10,
      "z": 0,
      "name": "Soil_Pathway"
    },
    {
      "x": -18,
      "y": 11,
      "z": 0,
      "name": "Empty"
    },
    {
      "x": -18,
      "y": 10,
      "z": 1,
      "name": "Soil_Pathway"
    },
    {
      "x": -18,
      "y": 11,
      "z": 1,
      "name": "Bench_Lumbermill",
      "components": {
        "Components": {
          "processingBench": {
            "TierLevel": 1,
            "UpgradeItems": [],
            "InputContainer": {
              "Id": "Simple",
              "Capacity": 2,
              "Items": {}
            },
            "FuelContainer": {
              "Id": "Simple",
              "Capacity": 0,
              "Items": {}
            },
            "OutputContainer": {
              "Id": "Simple",
              "Capacity": 1,
              "Items": {}
            },
            "Progress": 0.0,
            "FuelTime": 0.0,
            "Active": true,
            "NextExtra": 0
          }
        }
      }
    },
    {
      "x": -18,
      "y": 10,
      "z": 2,
      "name": "Soil_Pathway"
    },
    {
      "x": -18,
      "y": 11,
      "z": 2,
      "name": "Empty"
    },
    {
      "x": -18,
      "y": 10,
      "z": 3,
      "name": "Soil_Pathway"
    },
    {
      "x": -18,
      "y": 11,
      "z": 3,
      "name": "Empty"
    },
    {
      "x": -18,
      "y": 9,
      "z": 15,
      "name": "Wood_Beech_Trunk",
      "support": 15
    },
    {
      "x": -18,
      "y": 10,
      "z": 15,
      "name": "Wood_Beech_Trunk",
      "support": 15
    },
    {
      "x": -18,
      "y": 11,
      "z": 15,
      "name": "Wood_Beech_Trunk",
      "support": 15
    },
    {
      "x": -18,
      "y": 12,
      "z": 15,
      "name": "Wood_Beech_Trunk",
      "support": 15
    },
    {
      "x": -17,
      "y": 10,
      "z": -12,
      "name": "Soil_Pathway"
    },
    {
      "x": -17,
      "y": 11,
      "z": -12,
      "name": "Empty"
    },
    {
      "x": -17,
      "y": 10,
      "z": -11,
      "name": "Soil_Pathway"
    },
    {
      "x": -17,
      "y": 11,
      "z": -11,
      "name": "Empty"
    },
    {
      "x": -17,
      "y": 10,
      "z": -10,
      "name": "Soil_Pathway"
    },
    {
      "x": -17,
      "y": 11,
      "z": -10,
      "name": "Empty"
    },
    {
      "x": -17,
      "y": 10,
      "z": -9,
      "name": "Soil_Pathway"
    },
    {
      "x": -17,
      "y": 11,
      "z": -9,
      "name": "Empty"
    },
    {
      "x": -17,
      "y": 10,
      "z": -6,
      "name": "Prefab_Spawner_Block",
      "components": {
        "Components": {
          "prefabspawner": {
            "PrefabPath": "Npc.Trork.Resource.Lumber.Forest_Gully.*",
            "FitHeightmap": false,
            "InheritSeed": true,
            "InheritHeightCondition": true
          }
        }
      }
    },
    {
      "x": -17,
      "y": 10,
      "z": -2,
      "name": "Soil_Pathway"
    },
    {
      "x": -17,
      "y": 11,
      "z": -2,
      "name": "Empty"
    },
    {
      "x": -17,
      "y": 10,
      "z": -1,
      "name": "Soil_Pathway"
    },
    {
      "x": -17,
      "y": 11,
      "z": -1,
      "name": "Empty"
    },
    {
      "x": -17,
      "y": 10,
      "z": 0,
      "name": "Soil_Pathway"
    },
    {
      "x": -17,
      "y": 11,
      "z": 0,
      "name": "Empty"
    },
    {
      "x": -17,
      "y": 10,
      "z": 1,
      "name": "Soil_Pathway"
    },
    {
      "x": -17,
      "y": 11,
      "z": 1,
      "name": "Empty"
    },
    {
      "x": -17,
      "y": 10,
      "z": 2,
      "name": "Soil_Pathway"
    },
    {
      "x": -17,
      "y": 11,
      "z": 2,
      "name": "Empty"
    },
    {
      "x": -17,
      "y": 10,
      "z": 3,
      "name": "Soil_Dirt"
    },
    {
      "x": -17,
      "y": 11,
      "z": 3,
      "name": "Empty"
    },
    {
      "x": -17,
      "y": 8,
      "z": 16,
      "name": "Wood_Beech_Trunk",
      "support": 15
    },
    {
      "x": -17,
      "y": 9,
      "z": 16,
      "name": "Wood_Beech_Trunk",
      "support": 15
    },
    {
      "x": -17,
      "y": 10,
      "z": 16,
      "name": "Wood_Beech_Trunk",
      "support": 15
    },
    {
      "x": -17,
      "y": 11,
      "z": 16,
      "name": "Wood_Beech_Trunk",
      "support": 15
    },
    {
      "x": -17,
      "y": 12,
      "z": 16,
      "name": "Wood_Beech_Trunk",
      "support": 15
    },
    {
      "x": -17,
      "y": 13,
      "z": 16,
      "name": "Wood_Beech_Trunk",
      "support": 15
    },
    {
      "x": -17,
      "y": 14,
      "z": 16,
      "name": "Wood_Beech_Trunk_Full"
    },
    {
      "x": -17,
      "y": 15,
      "z": 16,
      "name": "Wood_Beech_Branch_Long",
      "support": 15
    },
    {
      "x": -17,
      "y": 16,
      "z": 16,
      "name": "Wood_Beech_Branch_Long",
      "support": 15
    },
    {
      "x": -17,
      "y": 17,
      "z": 16,
      "name": "Survival_Trap_Spike_Wood_Large"
    },
    {
      "x": -16,
      "y": 10,
      "z": -13,
      "name": "Soil_Dirt"
    },
    {
      "x": -16,
      "y": 11,
      "z": -13,
      "name": "Empty"
    },
    {
      "x": -16,
      "y": 10,
      "z": -12,
      "name": "Soil_Pathway"
    },
    {
      "x": -16,
      "y": 11,
      "z": -12,
      "name": "Empty"
    },
    {
      "x": -16,
      "y": 10,
      "z": -11,
      "name": "Soil_Pathway"
    },
    {
      "x": -16,
      "y": 11,
      "z": -11,
      "name": "Empty"
    },
    {
      "x": -16,
      "y": 10,
      "z": -10,
      "name": "Soil_Pathway"
    },
    {
      "x": -16,
      "y": 11,
      "z": -10,
      "name": "Empty"
    },
    {
      "x": -16,
      "y": 10,
      "z": -9,
      "name": "Soil_Pathway"
    },
    {
      "x": -16,
      "y": 11,
      "z": -9,
      "name": "Empty"
    },
    {
      "x": -16,
      "y": 10,
      "z": -8,
      "name": "Soil_Pathway"
    },
    {
      "x": -16,
      "y": 11,
      "z": -8,
      "name": "Empty"
    },
    {
      "x": -16,
      "y": 10,
      "z": -2,
      "name": "Soil_Pathway"
    },
    {
      "x": -16,
      "y": 11,
      "z": -2,
      "name": "Empty"
    },
    {
      "x": -16,
      "y": 10,
      "z": -1,
      "name": "Soil_Pathway"
    },
    {
      "x": -16,
      "y": 11,
      "z": -1,
      "name": "Empty"
    },
    {
      "x": -16,
      "y": 10,
      "z": 0,
      "name": "Soil_Pathway"
    },
    {
      "x": -16,
      "y": 11,
      "z": 0,
      "name": "Empty"
    },
    {
      "x": -16,
      "y": 10,
      "z": 1,
      "name": "Soil_Pathway"
    },
    {
      "x": -16,
      "y": 11,
      "z": 1,
      "name": "Empty"
    },
    {
      "x": -16,
      "y": 10,
      "z": 2,
      "name": "Soil_Dirt"
    },
    {
      "x": -16,
      "y": 11,
      "z": 2,
      "name": "Empty"
    },
    {
      "x": -16,
      "y": 10,
      "z": 3,
      "name": "Soil_Dirt"
    },
    {
      "x": -16,
      "y": 11,
      "z": 3,
      "name": "Empty"
    },
    {
      "x": -16,
      "y": 10,
      "z": 4,
      "name": "Soil_Dirt"
    },
    {
      "x": -16,
      "y": 11,
      "z": 4,
      "name": "Empty"
    },
    {
      "x": -16,
      "y": 10,
      "z": 5,
      "name": "Soil_Dirt"
    },
    {
      "x": -16,
      "y": 11,
      "z": 5,
      "name": "Empty"
    },
    {
      "x": -16,
      "y": 10,
      "z": 11,
      "name": "Soil_Pathway"
    },
    {
      "x": -16,
      "y": 11,
      "z": 11,
      "name": "Empty"
    },
    {
      "x": -16,
      "y": 10,
      "z": 12,
      "name": "Soil_Pathway"
    },
    {
      "x": -16,
      "y": 11,
      "z": 12,
      "name": "Empty"
    },
    {
      "x": -16,
      "y": 8,
      "z": 17,
      "name": "Wood_Beech_Trunk",
      "support": 15
    },
    {
      "x": -16,
      "y": 9,
      "z": 17,
      "name": "Wood_Beech_Trunk",
      "support": 15
    },
    {
      "x": -16,
      "y": 10,
      "z": 17,
      "name": "Wood_Beech_Trunk",
      "support": 15
    },
    {
      "x": -16,
      "y": 11,
      "z": 17,
      "name": "Wood_Beech_Trunk",
      "support": 15
    },
    {
      "x": -16,
      "y": 12,
      "z": 17,
      "name": "Wood_Beech_Trunk",
      "support": 15
    },
    {
      "x": -16,
      "y": 13,
      "z": 17,
      "name": "Wood_Beech_Trunk",
      "support": 15
    },
    {
      "x": -16,
      "y": 14,
      "z": 17,
      "name": "Wood_Beech_Trunk_Full"
    },
    {
      "x": -16,
      "y": 15,
      "z": 17,
      "name": "Wood_Beech_Branch_Long",
      "support": 15
    },
    {
      "x": -16,
      "y": 16,
      "z": 17,
      "name": "Survival_Trap_Spike_Wood_Large"
    },
    {
      "x": -16,
      "y": 9,
      "z": 18,
      "name": "Wood_Beech_Trunk",
      "support": 15
    },
    {
      "x": -16,
      "y": 10,
      "z": 18,
      "name": "Wood_Beech_Trunk",
      "support": 15
    },
    {
      "x": -16,
      "y": 11,
      "z": 18,
      "name": "Wood_Beech_Trunk",
      "support": 15
    },
    {
      "x": -16,
      "y": 12,
      "z": 18,
      "name": "Wood_Beech_Trunk",
      "support": 15
    },
    {
      "x": -16,
      "y": 13,
      "z": 18,
      "name": "Wood_Beech_Trunk",
      "support": 15
    },
    {
      "x": -16,
      "y": 10,
      "z": 19,
      "name": "Rock_Stone_Cobble"
    },
    {
      "x": -16,
      "y": 11,
      "z": 19,
      "name": "Rock_Stone_Cobble"
    },
    {
      "x": -16,
      "y": 12,
      "z": 19,
      "name": "Rock_Stone_Cobble"
    },
    {
      "x": -15,
      "y": 10,
      "z": -12,
      "name": "Soil_Dirt"
    },
    {
      "x": -15,
      "y": 11,
      "z": -12,
      "name": "Empty"
    },
    {
      "x": -15,
      "y": 10,
      "z": -11,
      "name": "Soil_Dirt"
    },
    {
      "x": -15,
      "y": 11,
      "z": -11,
      "name": "Empty"
    },
    {
      "x": -15,
      "y": 10,
      "z": -10,
      "name": "Soil_Pathway"
    },
    {
      "x": -15,
      "y": 11,
      "z": -10,
      "name": "Empty"
    },
    {
      "x": -15,
      "y": 10,
      "z": -9,
      "name": "Soil_Pathway"
    },
    {
      "x": -15,
      "y": 11,
      "z": -9,
      "name": "Empty"
    },
    {
      "x": -15,
      "y": 10,
      "z": -8,
      "name": "Soil_Pathway"
    },
    {
      "x": -15,
      "y": 11,
      "z": -8,
      "name": "Empty"
    },
    {
      "x": -15,
      "y": 10,
      "z": -7,
      "name": "Soil_Pathway"
    },
    {
      "x": -15,
      "y": 11,
      "z": -7,
      "name": "Empty"
    },
    {
      "x": -15,
      "y": 10,
      "z": -6,
      "name": "Soil_Pathway"
    },
    {
      "x": -15,
      "y": 11,
      "z": -6,
      "name": "Empty"
    },
    {
      "x": -15,
      "y": 10,
      "z": -5,
      "name": "Soil_Pathway"
    },
    {
      "x": -15,
      "y": 11,
      "z": -5,
      "name": "Empty"
    },
    {
      "x": -15,
      "y": 10,
      "z": -4,
      "name": "Soil_Pathway"
    },
    {
      "x": -15,
      "y": 11,
      "z": -4,
      "name": "Empty"
    },
    {
      "x": -15,
      "y": 10,
      "z": -3,
      "name": "Soil_Pathway"
    },
    {
      "x": -15,
      "y": 11,
      "z": -3,
      "name": "Empty"
    },
    {
      "x": -15,
      "y": 10,
      "z": -2,
      "name": "Soil_Pathway"
    },
    {
      "x": -15,
      "y": 11,
      "z": -2,
      "name": "Empty"
    },
    {
      "x": -15,
      "y": 10,
      "z": -1,
      "name": "Soil_Pathway"
    },
    {
      "x": -15,
      "y": 11,
      "z": -1,
      "name": "Empty"
    },
    {
      "x": -15,
      "y": 10,
      "z": 0,
      "name": "Soil_Pathway"
    },
    {
      "x": -15,
      "y": 11,
      "z": 0,
      "name": "Empty"
    },
    {
      "x": -15,
      "y": 10,
      "z": 1,
      "name": "Soil_Pathway"
    },
    {
      "x": -15,
      "y": 11,
      "z": 1,
      "name": "Empty"
    },
    {
      "x": -15,
      "y": 10,
      "z": 2,
      "name": "Soil_Pathway"
    },
    {
      "x": -15,
      "y": 11,
      "z": 2,
      "name": "Empty"
    },
    {
      "x": -15,
      "y": 10,
      "z": 3,
      "name": "Soil_Pathway"
    },
    {
      "x": -15,
      "y": 11,
      "z": 3,
      "name": "Empty"
    },
    {
      "x": -15,
      "y": 10,
      "z": 4,
      "name": "Soil_Dirt"
    },
    {
      "x": -15,
      "y": 11,
      "z": 4,
      "name": "Empty"
    },
    {
      "x": -15,
      "y": 10,
      "z": 5,
      "name": "Soil_Dirt"
    },
    {
      "x": -15,
      "y": 11,
      "z": 5,
      "name": "Empty"
    },
    {
      "x": -15,
      "y": 10,
      "z": 12,
      "name": "Soil_Pathway"
    },
    {
      "x": -15,
      "y": 11,
      "z": 12,
      "name": "Empty"
    },
    {
      "x": -15,
      "y": 10,
      "z": 13,
      "name": "Soil_Pathway"
    },
    {
      "x": -15,
      "y": 11,
      "z": 13,
      "name": "Empty"
    },
    {
      "x": -15,
      "y": 10,
      "z": 14,
      "name": "Soil_Pathway"
    },
    {
      "x": -15,
      "y": 11,
      "z": 14,
      "name": "Empty"
    },
    {
      "x": -15,
      "y": 10,
      "z": 15,
      "name": "Soil_Pathway"
    },
    {
      "x": -15,
      "y": 11,
      "z": 15,
      "name": "Empty"
    },
    {
      "x": -15,
      "y": 9,
      "z": 19,
      "name": "Wood_Beech_Trunk",
      "support": 15
    },
    {
      "x": -15,
      "y": 10,
      "z": 19,
      "name": "Wood_Beech_Trunk",
      "support": 15
    },
    {
      "x": -15,
      "y": 11,
      "z": 19,
      "name": "Wood_Beech_Trunk",
      "support": 15
    },
    {
      "x": -15,
      "y": 12,
      "z": 19,
      "name": "Wood_Beech_Trunk",
      "support": 15
    },
    {
      "x": -15,
      "y": 13,
      "z": 19,
      "name": "Wood_Beech_Trunk_Full"
    },
    {
      "x": -15,
      "y": 14,
      "z": 19,
      "name": "Wood_Beech_Branch_Long",
      "support": 15
    },
    {
      "x": -15,
      "y": 15,
      "z": 19,
      "name": "Survival_Trap_Spike_Wood_Large"
    },
    {
      "x": -15,
      "y": 10,
      "z": 20,
      "name": "Rock_Stone_Cobble"
    },
    {
      "x": -15,
      "y": 11,
      "z": 20,
      "name": "Rock_Stone_Cobble"
    },
    {
      "x": -15,
      "y": 12,
      "z": 20,
      "name": "Rock_Stone_Cobble"
    },
    {
      "x": -15,
      "y": 10,
      "z": 21,
      "name": "Rock_Stone_Cobble"
    },
    {
      "x": -15,
      "y": 11,
      "z": 21,
      "name": "Rock_Stone_Cobble"
    },
    {
      "x": -15,
      "y": 12,
      "z": 21,
      "name": "Rock_Stone_Cobble"
    },
    {
      "x": -14,
      "y": 10,
      "z": -15,
      "name": "Rock_Stone"
    },
    {
      "x": -14,
      "y": 11,
      "z": -15,
      "name": "Rock_Stone"
    },
    {
      "x": -14,
      "y": 10,
      "z": -14,
      "name": "Rock_Stone"
    },
    {
      "x": -14,
      "y": 11,
      "z": -14,
      "name": "Rock_Stone"
    },
    {
      "x": -14,
      "y": 10,
      "z": -11,
      "name": "Soil_Dirt"
    },
    {
      "x": -14,
      "y": 11,
      "z": -11,
      "name": "Empty"
    },
    {
      "x": -14,
      "y": 10,
      "z": -10,
      "name": "Soil_Dirt"
    },
    {
      "x": -14,
      "y": 11,
      "z": -10,
      "name": "Empty"
    },
    {
      "x": -14,
      "y": 10,
      "z": -9,
      "name": "Soil_Pathway"
    },
    {
      "x": -14,
      "y": 11,
      "z": -9,
      "name": "Empty"
    },
    {
      "x": -14,
      "y": 10,
      "z": -8,
      "name": "Soil_Pathway"
    },
    {
      "x": -14,
      "y": 11,
      "z": -8,
      "name": "Empty"
    },
    {
      "x": -14,
      "y": 10,
      "z": -7,
      "name": "Soil_Pathway"
    },
    {
      "x": -14,
      "y": 11,
      "z": -7,
      "name": "Empty"
    },
    {
      "x": -14,
      "y": 10,
      "z": -6,
      "name": "Soil_Pathway"
    },
    {
      "x": -14,
      "y": 11,
      "z": -6,
      "name": "Empty"
    },
    {
      "x": -14,
      "y": 10,
      "z": -5,
      "name": "Soil_Pathway"
    },
    {
      "x": -14,
      "y": 11,
      "z": -5,
      "name": "Empty"
    },
    {
      "x": -14,
      "y": 10,
      "z": -4,
      "name": "Soil_Pathway"
    },
    {
      "x": -14,
      "y": 11,
      "z": -4,
      "name": "Empty"
    },
    {
      "x": -14,
      "y": 10,
      "z": -3,
      "name": "Soil_Pathway"
    },
    {
      "x": -14,
      "y": 11,
      "z": -3,
      "name": "Empty"
    },
    {
      "x": -14,
      "y": 10,
      "z": -2,
      "name": "Soil_Pathway"
    },
    {
      "x": -14,
      "y": 11,
      "z": -2,
      "name": "Empty"
    },
    {
      "x": -14,
      "y": 10,
      "z": -1,
      "name": "Soil_Pathway"
    },
    {
      "x": -14,
      "y": 11,
      "z": -1,
      "name": "Empty"
    },
    {
      "x": -14,
      "y": 10,
      "z": 0,
      "name": "Soil_Pathway"
    },
    {
      "x": -14,
      "y": 11,
      "z": 0,
      "name": "Empty"
    },
    {
      "x": -14,
      "y": 10,
      "z": 1,
      "name": "Soil_Pathway"
    },
    {
      "x": -14,
      "y": 11,
      "z": 1,
      "name": "Empty"
    },
    {
      "x": -14,
      "y": 10,
      "z": 2,
      "name": "Soil_Pathway"
    },
    {
      "x": -14,
      "y": 11,
      "z": 2,
      "name": "Empty"
    },
    {
      "x": -14,
      "y": 10,
      "z": 3,
      "name": "Soil_Pathway"
    },
    {
      "x": -14,
      "y": 11,
      "z": 3,
      "name": "Empty"
    },
    {
      "x": -14,
      "y": 10,
      "z": 4,
      "name": "Soil_Pathway"
    },
    {
      "x": -14,
      "y": 11,
      "z": 4,
      "name": "Empty"
    },
    {
      "x": -14,
      "y": 10,
      "z": 5,
      "name": "Soil_Dirt"
    },
    {
      "x": -14,
      "y": 11,
      "z": 5,
      "name": "Empty"
    },
    {
      "x": -14,
      "y": 10,
      "z": 8,
      "name": "Soil_Pathway"
    },
    {
      "x": -14,
      "y": 11,
      "z": 8,
      "name": "Empty"
    },
    {
      "x": -14,
      "y": 10,
      "z": 9,
      "name": "Soil_Pathway"
    },
    {
      "x": -14,
      "y": 11,
      "z": 9,
      "name": "Empty"
    },
    {
      "x": -14,
      "y": 10,
      "z": 10,
      "name": "Soil_Pathway"
    },
    {
      "x": -14,
      "y": 11,
      "z": 10,
      "name": "Empty"
    },
    {
      "x": -14,
      "y": 11,
      "z": 12,
      "name": "Furniture_Tavern_Barrel"
    },
    {
      "x": -14,
      "y": 10,
      "z": 13,
      "name": "Soil_Pathway"
    },
    {
      "x": -14,
      "y": 11,
      "z": 13,
      "name": "Furniture_Village_Crate"
    },
    {
      "x": -14,
      "y": 10,
      "z": 14,
      "name": "Soil_Pathway"
    },
    {
      "x": -14,
      "y": 11,
      "z": 14,
      "name": "Empty"
    },
    {
      "x": -14,
      "y": 10,
      "z": 15,
      "name": "Soil_Pathway"
    },
    {
      "x": -14,
      "y": 11,
      "z": 15,
      "name": "Empty"
    },
    {
      "x": -14,
      "y": 10,
      "z": 16,
      "name": "Soil_Pathway"
    },
    {
      "x": -14,
      "y": 11,
      "z": 16,
      "name": "Empty"
    },
    {
      "x": -14,
      "y": 10,
      "z": 22,
      "name": "Rock_Stone_Cobble"
    },
    {
      "x": -14,
      "y": 11,
      "z": 22,
      "name": "Rock_Stone_Cobble"
    },
    {
      "x": -14,
      "y": 12,
      "z": 22,
      "name": "Rock_Stone_Cobble"
    },
    {
      "x": -14,
      "y": 10,
      "z": 23,
      "name": "Rock_Stone_Cobble"
    },
    {
      "x": -14,
      "y": 11,
      "z": 23,
      "name": "Rock_Stone_Cobble"
    },
    {
      "x": -14,
      "y": 12,
      "z": 23,
      "name": "Rock_Stone_Cobble"
    },
    {
      "x": -14,
      "y": 10,
      "z": 24,
      "name": "Rock_Stone_Cobble"
    },
    {
      "x": -14,
      "y": 11,
      "z": 24,
      "name": "Rock_Stone_Cobble"
    },
    {
      "x": -14,
      "y": 12,
      "z": 24,
      "name": "Rock_Stone_Cobble"
    },
    {
      "x": -13,
      "y": 9,
      "z": -16,
      "name": "Rock_Stone"
    },
    {
      "x": -13,
      "y": 10,
      "z": -16,
      "name": "Rock_Stone"
    },
    {
      "x": -13,
      "y": 11,
      "z": -16,
      "name": "Rock_Stone"
    },
    {
      "x": -13,
      "y": 12,
      "z": -16,
      "name": "Rock_Stone"
    },
    {
      "x": -13,
      "y": 8,
      "z": -15,
      "name": "Rock_Stone"
    },
    {
      "x": -13,
      "y": 9,
      "z": -15,
      "name": "Rock_Stone"
    },
    {
      "x": -13,
      "y": 10,
      "z": -15,
      "name": "Rock_Stone"
    },
    {
      "x": -13,
      "y": 11,
      "z": -15,
      "name": "Rock_Stone"
    },
    {
      "x": -13,
      "y": 12,
      "z": -15,
      "name": "Rock_Stone"
    },
    {
      "x": -13,
      "y": 10,
      "z": -14,
      "name": "Rock_Stone"
    },
    {
      "x": -13,
      "y": 11,
      "z": -14,
      "name": "Rock_Stone"
    },
    {
      "x": -13,
      "y": 10,
      "z": -10,
      "name": "Soil_Pathway"
    },
    {
      "x": -13,
      "y": 11,
      "z": -10,
      "name": "Empty"
    },
    {
      "x": -13,
      "y": 10,
      "z": -9,
      "name": "Soil_Pathway"
    },
    {
      "x": -13,
      "y": 11,
      "z": -9,
      "name": "Empty"
    },
    {
      "x": -13,
      "y": 10,
      "z": -8,
      "name": "Soil_Pathway"
    },
    {
      "x": -13,
      "y": 11,
      "z": -8,
      "name": "Empty"
    },
    {
      "x": -13,
      "y": 10,
      "z": -7,
      "name": "Soil_Pathway"
    },
    {
      "x": -13,
      "y": 11,
      "z": -7,
      "name": "Empty"
    },
    {
      "x": -13,
      "y": 10,
      "z": -6,
      "name": "Soil_Pathway"
    },
    {
      "x": -13,
      "y": 11,
      "z": -6,
      "name": "Empty"
    },
    {
      "x": -13,
      "y": 10,
      "z": -5,
      "name": "Soil_Pathway"
    },
    {
      "x": -13,
      "y": 11,
      "z": -5,
      "name": "Empty"
    },
    {
      "x": -13,
      "y": 10,
      "z": -4,
      "name": "Soil_Pathway"
    },
    {
      "x": -13,
      "y": 11,
      "z": -4,
      "name": "Empty"
    },
    {
      "x": -13,
      "y": 10,
      "z": -3,
      "name": "Soil_Pathway"
    },
    {
      "x": -13,
      "y": 11,
      "z": -3,
      "name": "Empty"
    },
    {
      "x": -13,
      "y": 10,
      "z": -2,
      "name": "Soil_Pathway"
    },
    {
      "x": -13,
      "y": 11,
      "z": -2,
      "name": "Empty"
    },
    {
      "x": -13,
      "y": 10,
      "z": -1,
      "name": "Soil_Pathway"
    },
    {
      "x": -13,
      "y": 11,
      "z": -1,
      "name": "Empty"
    },
    {
      "x": -13,
      "y": 10,
      "z": 0,
      "name": "Soil_Pathway"
    },
    {
      "x": -13,
      "y": 11,
      "z": 0,
      "name": "Empty"
    },
    {
      "x": -13,
      "y": 10,
      "z": 1,
      "name": "Soil_Pathway"
    },
    {
      "x": -13,
      "y": 11,
      "z": 1,
      "name": "Empty"
    },
    {
      "x": -13,
      "y": 10,
      "z": 2,
      "name": "Soil_Pathway"
    },
    {
      "x": -13,
      "y": 11,
      "z": 2,
      "name": "Empty"
    },
    {
      "x": -13,
      "y": 10,
      "z": 3,
      "name": "Soil_Pathway"
    },
    {
      "x": -13,
      "y": 11,
      "z": 3,
      "name": "Empty"
    },
    {
      "x": -13,
      "y": 10,
      "z": 4,
      "name": "Soil_Pathway"
    },
    {
      "x": -13,
      "y": 11,
      "z": 4,
      "name": "Empty"
    },
    {
      "x": -13,
      "y": 10,
      "z": 5,
      "name": "Soil_Pathway"
    },
    {
      "x": -13,
      "y": 11,
      "z": 5,
      "name": "Empty"
    },
    {
      "x": -13,
      "y": 10,
      "z": 6,
      "name": "Soil_Dirt"
    },
    {
      "x": -13,
      "y": 11,
      "z": 6,
      "name": "Wood_Hardwood_Beam"
    },
    {
      "x": -13,
      "y": 12,
      "z": 6,
      "name": "Furniture_Crude_Torch"
    },
    {
      "x": -13,
      "y": 10,
      "z": 7,
      "name": "Soil_Pathway"
    },
    {
      "x": -13,
      "y": 11,
      "z": 7,
      "name": "Empty"
    },
    {
      "x": -13,
      "y": 10,
      "z": 8,
      "name": "Soil_Pathway"
    },
    {
      "x": -13,
      "y": 11,
      "z": 8,
      "name": "Empty"
    },
    {
      "x": -13,
      "y": 10,
      "z": 9,
      "name": "Soil_Pathway"
    },
    {
      "x": -13,
      "y": 11,
      "z": 9,
      "name": "Empty"
    },
    {
      "x": -13,
      "y": 10,
      "z": 10,
      "name": "Soil_Pathway"
    },
    {
      "x": -13,
      "y": 11,
      "z": 10,
      "name": "Empty"
    },
    {
      "x": -13,
      "y": 11,
      "z": 13,
      "name": "Furniture_Village_Crate"
    },
    {
      "x": -13,
      "y": 12,
      "z": 13,
      "name": "Furniture_Village_Crate"
    },
    {
      "x": -13,
      "y": 10,
      "z": 14,
      "name": "Rock_Stone"
    },
    {
      "x": -13,
      "y": 11,
      "z": 14,
      "name": "Rock_Stone"
    },
    {
      "x": -13,
      "y": 12,
      "z": 14,
      "name": "Rock_Stone"
    },
    {
      "x": -13,
      "y": 10,
      "z": 15,
      "name": "Rock_Stone"
    },
    {
      "x": -13,
      "y": 11,
      "z": 15,
      "name": "Rock_Stone"
    },
    {
      "x": -13,
      "y": 12,
      "z": 15,
      "name": "Rock_Stone"
    },
    {
      "x": -13,
      "y": 13,
      "z": 15,
      "name": "Rock_Stone"
    },
    {
      "x": -13,
      "y": 10,
      "z": 16,
      "name": "Soil_Dirt"
    },
    {
      "x": -13,
      "y": 11,
      "z": 16,
      "name": "Empty"
    },
    {
      "x": -13,
      "y": 10,
      "z": 17,
      "name": "Soil_Dirt"
    },
    {
      "x": -13,
      "y": 11,
      "z": 17,
      "name": "Empty"
    },
    {
      "x": -13,
      "y": 10,
      "z": 18,
      "name": "Soil_Dirt"
    },
    {
      "x": -13,
      "y": 11,
      "z": 18,
      "name": "Empty"
    },
    {
      "x": -13,
      "y": 10,
      "z": 19,
      "name": "Soil_Dirt"
    },
    {
      "x": -13,
      "y": 11,
      "z": 19,
      "name": "Empty"
    },
    {
      "x": -13,
      "y": 10,
      "z": 20,
      "name": "Soil_Dirt"
    },
    {
      "x": -13,
      "y": 11,
      "z": 20,
      "name": "Empty"
    },
    {
      "x": -13,
      "y": 10,
      "z": 21,
      "name": "Soil_Dirt"
    },
    {
      "x": -13,
      "y": 11,
      "z": 21,
      "name": "Empty"
    },
    {
      "x": -13,
      "y": 10,
      "z": 22,
      "name": "Rock_Stone"
    },
    {
      "x": -13,
      "y": 11,
      "z": 22,
      "name": "Rock_Stone"
    },
    {
      "x": -13,
      "y": 12,
      "z": 22,
      "name": "Rock_Stone"
    },
    {
      "x": -13,
      "y": 13,
      "z": 22,
      "name": "Rock_Stone"
    },
    {
      "x": -13,
      "y": 14,
      "z": 22,
      "name": "Rock_Stone"
    },
    {
      "x": -13,
      "y": 10,
      "z": 23,
      "name": "Rock_Stone"
    },
    {
      "x": -13,
      "y": 11,
      "z": 23,
      "name": "Rock_Stone"
    },
    {
      "x": -13,
      "y": 12,
      "z": 23,
      "name": "Rock_Stone"
    },
    {
      "x": -13,
      "y": 13,
      "z": 23,
      "name": "Rock_Stone"
    },
    {
      "x": -13,
      "y": 14,
      "z": 23,
      "name": "Rock_Stone"
    },
    {
      "x": -13,
      "y": 10,
      "z": 24,
      "name": "Rock_Stone_Cobble"
    },
    {
      "x": -13,
      "y": 11,
      "z": 24,
      "name": "Rock_Stone_Cobble"
    },
    {
      "x": -13,
      "y": 12,
      "z": 24,
      "name": "Rock_Stone_Cobble"
    },
    {
      "x": -12,
      "y": 10,
      "z": -17,
      "name": "Rock_Stone"
    },
    {
      "x": -12,
      "y": 11,
      "z": -17,
      "name": "Rock_Stone"
    },
    {
      "x": -12,
      "y": 10,
      "z": -16,
      "name": "Rock_Stone"
    },
    {
      "x": -12,
      "y": 11,
      "z": -16,
      "name": "Rock_Stone"
    },
    {
      "x": -12,
      "y": 12,
      "z": -16,
      "name": "Rock_Stone"
    },
    {
      "x": -12,
      "y": 9,
      "z": -15,
      "name": "Rock_Stone"
    },
    {
      "x": -12,
      "y": 10,
      "z": -15,
      "name": "Rock_Stone"
    },
    {
      "x": -12,
      "y": 11,
      "z": -15,
      "name": "Rock_Stone"
    },
    {
      "x": -12,
      "y": 10,
      "z": -14,
      "name": "Soil_Dirt"
    },
    {
      "x": -12,
      "y": 11,
      "z": -14,
      "name": "Empty"
    },
    {
      "x": -12,
      "y": 10,
      "z": -10,
      "name": "Soil_Pathway"
    },
    {
      "x": -12,
      "y": 11,
      "z": -10,
      "name": "Empty"
    },
    {
      "x": -12,
      "y": 10,
      "z": -9,
      "name": "Soil_Pathway"
    },
    {
      "x": -12,
      "y": 11,
      "z": -9,
      "name": "Wood_Hardwood_Beam"
    },
    {
      "x": -12,
      "y": 12,
      "z": -9,
      "name": "Furniture_Crude_Torch"
    },
    {
      "x": -12,
      "y": 10,
      "z": -8,
      "name": "Soil_Pathway"
    },
    {
      "x": -12,
      "y": 11,
      "z": -8,
      "name": "Empty"
    },
    {
      "x": -12,
      "y": 10,
      "z": -7,
      "name": "Soil_Pathway"
    },
    {
      "x": -12,
      "y": 11,
      "z": -7,
      "name": "Empty"
    },
    {
      "x": -12,
      "y": 10,
      "z": -6,
      "name": "Soil_Pathway"
    },
    {
      "x": -12,
      "y": 11,
      "z": -6,
      "name": "Empty"
    },
    {
      "x": -12,
      "y": 10,
      "z": -5,
      "name": "Soil_Pathway"
    },
    {
      "x": -12,
      "y": 11,
      "z": -5,
      "name": "Empty"
    },
    {
      "x": -12,
      "y": 10,
      "z": -4,
      "name": "Soil_Pathway"
    },
    {
      "x": -12,
      "y": 11,
      "z": -4,
      "name": "Empty"
    },
    {
      "x": -12,
      "y": 10,
      "z": -3,
      "name": "Soil_Pathway"
    },
    {
      "x": -12,
      "y": 11,
      "z": -3,
      "name": "Empty"
    },
    {
      "x": -12,
      "y": 10,
      "z": -2,
      "name": "Soil_Pathway"
    },
    {
      "x": -12,
      "y": 11,
      "z": -2,
      "name": "Empty"
    },
    {
      "x": -12,
      "y": 10,
      "z": -1,
      "name": "Soil_Pathway"
    },
    {
      "x": -12,
      "y": 11,
      "z": -1,
      "name": "Empty"
    },
    {
      "x": -12,
      "y": 10,
      "z": 0,
      "name": "Soil_Pathway"
    },
    {
      "x": -12,
      "y": 11,
      "z": 0,
      "name": "Empty"
    },
    {
      "x": -12,
      "y": 10,
      "z": 1,
      "name": "Soil_Pathway"
    },
    {
      "x": -12,
      "y": 11,
      "z": 1,
      "name": "Empty"
    },
    {
      "x": -12,
      "y": 10,
      "z": 2,
      "name": "Soil_Pathway"
    },
    {
      "x": -12,
      "y": 11,
      "z": 2,
      "name": "Empty"
    },
    {
      "x": -12,
      "y": 10,
      "z": 3,
      "name": "Soil_Pathway"
    },
    {
      "x": -12,
      "y": 11,
      "z": 3,
      "name": "Empty"
    },
    {
      "x": -12,
      "y": 10,
      "z": 4,
      "name": "Soil_Pathway"
    },
    {
      "x": -12,
      "y": 11,
      "z": 4,
      "name": "Empty"
    },
    {
      "x": -12,
      "y": 10,
      "z": 5,
      "name": "Soil_Pathway"
    },
    {
      "x": -12,
      "y": 11,
      "z": 5,
      "name": "Empty"
    },
    {
      "x": -12,
      "y": 10,
      "z": 6,
      "name": "Soil_Pathway"
    },
    {
      "x": -12,
      "y": 11,
      "z": 6,
      "name": "Empty"
    },
    {
      "x": -12,
      "y": 10,
      "z": 7,
      "name": "Soil_Pathway"
    },
    {
      "x": -12,
      "y": 11,
      "z": 7,
      "name": "Empty"
    },
    {
      "x": -12,
      "y": 10,
      "z": 8,
      "name": "Soil_Pathway"
    },
    {
      "x": -12,
      "y": 11,
      "z": 8,
      "name": "Empty"
    },
    {
      "x": -12,
      "y": 10,
      "z": 9,
      "name": "Soil_Pathway"
    },
    {
      "x": -12,
      "y": 11,
      "z": 9,
      "name": "Empty"
    },
    {
      "x": -12,
      "y": 10,
      "z": 10,
      "name": "Soil_Pathway"
    },
    {
      "x": -12,
      "y": 11,
      "z": 10,
      "name": "Empty"
    },
    {
      "x": -12,
      "y": 10,
      "z": 11,
      "name": "Soil_Pathway"
    },
    {
      "x": -12,
      "y": 11,
      "z": 11,
      "name": "Empty"
    },
    {
      "x": -12,
      "y": 10,
      "z": 12,
      "name": "Soil_Pathway"
    },
    {
      "x": -12,
      "y": 11,
      "z": 12,
      "name": "Empty"
    },
    {
      "x": -12,
      "y": 10,
      "z": 13,
      "name": "Soil_Pathway"
    },
    {
      "x": -12,
      "y": 11,
      "z": 13,
      "name": "Empty"
    },
    {
      "x": -12,
      "y": 10,
      "z": 14,
      "name": "Rock_Stone"
    },
    {
      "x": -12,
      "y": 11,
      "z": 14,
      "name": "Rock_Stone"
    },
    {
      "x": -12,
      "y": 12,
      "z": 14,
      "name": "Rock_Stone"
    },
    {
      "x": -12,
      "y": 13,
      "z": 14,
      "name": "Rock_Stone"
    },
    {
      "x": -12,
      "y": 10,
      "z": 15,
      "name": "Rock_Stone"
    },
    {
      "x": -12,
      "y": 11,
      "z": 15,
      "name": "Rock_Stone"
    },
    {
      "x": -12,
      "y": 12,
      "z": 15,
      "name": "Rock_Stone"
    },
    {
      "x": -12,
      "y": 13,
      "z": 15,
      "name": "Rock_Stone"
    },
    {
      "x": -12,
      "y": 10,
      "z": 16,
      "name": "Soil_Dirt"
    },
    {
      "x": -12,
      "y": 11,
      "z": 16,
      "name": "Empty"
    },
    {
      "x": -12,
      "y": 10,
      "z": 17,
      "name": "Soil_Dirt"
    },
    {
      "x": -12,
      "y": 11,
      "z": 17,
      "name": "Empty"
    },
    {
      "x": -12,
      "y": 10,
      "z": 18,
      "name": "Soil_Dirt"
    },
    {
      "x": -12,
      "y": 11,
      "z": 18,
      "name": "Empty"
    },
    {
      "x": -12,
      "y": 10,
      "z": 19,
      "name": "Soil_Dirt"
    },
    {
      "x": -12,
      "y": 11,
      "z": 19,
      "name": "Empty"
    },
    {
      "x": -12,
      "y": 10,
      "z": 20,
      "name": "Soil_Dirt"
    },
    {
      "x": -12,
      "y": 11,
      "z": 20,
      "name": "Empty"
    },
    {
      "x": -12,
      "y": 10,
      "z": 21,
      "name": "Soil_Dirt"
    },
    {
      "x": -12,
      "y": 11,
      "z": 21,
      "name": "Empty"
    },
    {
      "x": -12,
      "y": 10,
      "z": 22,
      "name": "Rock_Stone"
    },
    {
      "x": -12,
      "y": 11,
      "z": 22,
      "name": "Rock_Stone"
    },
    {
      "x": -12,
      "y": 12,
      "z": 22,
      "name": "Rock_Stone"
    },
    {
      "x": -12,
      "y": 13,
      "z": 22,
      "name": "Rock_Stone"
    },
    {
      "x": -12,
      "y": 14,
      "z": 22,
      "name": "Rock_Stone"
    },
    {
      "x": -12,
      "y": 10,
      "z": 23,
      "name": "Rock_Stone"
    },
    {
      "x": -12,
      "y": 11,
      "z": 23,
      "name": "Rock_Stone"
    },
    {
      "x": -12,
      "y": 12,
      "z": 23,
      "name": "Rock_Stone"
    },
    {
      "x": -12,
      "y": 13,
      "z": 23,
      "name": "Rock_Stone"
    },
    {
      "x": -11,
      "y": 9,
      "z": -19,
      "name": "Rock_Stone"
    },
    {
      "x": -11,
      "y": 10,
      "z": -19,
      "name": "Rock_Stone"
    },
    {
      "x": -11,
      "y": 11,
      "z": -19,
      "name": "Rock_Stone"
    },
    {
      "x": -11,
      "y": 8,
      "z": -18,
      "name": "Rock_Stone"
    },
    {
      "x": -11,
      "y": 9,
      "z": -18,
      "name": "Rock_Stone"
    },
    {
      "x": -11,
      "y": 10,
      "z": -18,
      "name": "Rock_Stone"
    },
    {
      "x": -11,
      "y": 11,
      "z": -18,
      "name": "Rock_Stone"
    },
    {
      "x": -11,
      "y": 12,
      "z": -18,
      "name": "Rock_Stone"
    },
    {
      "x": -11,
      "y": 10,
      "z": -17,
      "name": "Rock_Stone"
    },
    {
      "x": -11,
      "y": 11,
      "z": -17,
      "name": "Rock_Stone"
    },
    {
      "x": -11,
      "y": 12,
      "z": -17,
      "name": "Rock_Stone"
    },
    {
      "x": -11,
      "y": 10,
      "z": -16,
      "name": "Rock_Stone_Cobble"
    },
    {
      "x": -11,
      "y": 11,
      "z": -16,
      "name": "Rock_Stone_Cobble"
    },
    {
      "x": -11,
      "y": 12,
      "z": -16,
      "name": "Rock_Stone_Cobble"
    },
    {
      "x": -11,
      "y": 9,
      "z": -15,
      "name": "Wood_Beech_Trunk",
      "support": 15
    },
    {
      "x": -11,
      "y": 10,
      "z": -15,
      "name": "Wood_Beech_Trunk",
      "support": 15
    },
    {
      "x": -11,
      "y": 11,
      "z": -15,
      "name": "Wood_Beech_Trunk",
      "support": 15
    },
    {
      "x": -11,
      "y": 12,
      "z": -15,
      "name": "Wood_Beech_Trunk",
      "support": 15
    },
    {
      "x": -11,
      "y": 13,
      "z": -15,
      "name": "Wood_Beech_Trunk_Full",
      "support": 15
    },
    {
      "x": -11,
      "y": 14,
      "z": -15,
      "name": "Wood_Beech_Branch_Long",
      "support": 15
    },
    {
      "x": -11,
      "y": 15,
      "z": -15,
      "name": "Survival_Trap_Spike_Wood_Large"
    },
    {
      "x": -11,
      "y": 10,
      "z": -14,
      "name": "Soil_Dirt"
    },
    {
      "x": -11,
      "y": 11,
      "z": -14,
      "name": "Empty"
    },
    {
      "x": -11,
      "y": 10,
      "z": -13,
      "name": "Soil_Dirt"
    },
    {
      "x": -11,
      "y": 11,
      "z": -13,
      "name": "Empty"
    },
    {
      "x": -11,
      "y": 10,
      "z": -12,
      "name": "Soil_Dirt"
    },
    {
      "x": -11,
      "y": 11,
      "z": -12,
      "name": "Empty"
    },
    {
      "x": -11,
      "y": 10,
      "z": -11,
      "name": "Soil_Pathway"
    },
    {
      "x": -11,
      "y": 11,
      "z": -11,
      "name": "Empty"
    },
    {
      "x": -11,
      "y": 10,
      "z": -10,
      "name": "Soil_Pathway"
    },
    {
      "x": -11,
      "y": 11,
      "z": -10,
      "name": "Empty"
    },
    {
      "x": -11,
      "y": 10,
      "z": -9,
      "name": "Soil_Pathway"
    },
    {
      "x": -11,
      "y": 11,
      "z": -9,
      "name": "Empty"
    },
    {
      "x": -11,
      "y": 10,
      "z": -8,
      "name": "Soil_Pathway"
    },
    {
      "x": -11,
      "y": 11,
      "z": -8,
      "name": "Empty"
    },
    {
      "x": -11,
      "y": 10,
      "z": -7,
      "name": "Soil_Pathway"
    },
    {
      "x": -11,
      "y": 11,
      "z": -7,
      "name": "Empty"
    },
    {
      "x": -11,
      "y": 10,
      "z": -6,
      "name": "Soil_Pathway"
    },
    {
      "x": -11,
      "y": 11,
      "z": -6,
      "name": "Empty"
    },
    {
      "x": -11,
      "y": 10,
      "z": -5,
      "name": "Soil_Pathway"
    },
    {
      "x": -11,
      "y": 11,
      "z": -5,
      "name": "Empty"
    },
    {
      "x": -11,
      "y": 10,
      "z": -4,
      "name": "Soil_Pathway"
    },
    {
      "x": -11,
      "y": 11,
      "z": -4,
      "name": "Empty"
    },
    {
      "x": -11,
      "y": 10,
      "z": -3,
      "name": "Soil_Pathway"
    },
    {
      "x": -11,
      "y": 11,
      "z": -3,
      "name": "Empty"
    },
    {
      "x": -11,
      "y": 10,
      "z": -2,
      "name": "Soil_Pathway"
    },
    {
      "x": -11,
      "y": 11,
      "z": -2,
      "name": "Empty"
    },
    {
      "x": -11,
      "y": 10,
      "z": -1,
      "name": "Soil_Pathway"
    },
    {
      "x": -11,
      "y": 11,
      "z": -1,
      "name": "Empty"
    },
    {
      "x": -11,
      "y": 10,
      "z": 0,
      "name": "Soil_Pathway"
    },
    {
      "x": -11,
      "y": 11,
      "z": 0,
      "name": "Empty"
    },
    {
      "x": -11,
      "y": 10,
      "z": 1,
      "name": "Soil_Pathway"
    },
    {
      "x": -11,
      "y": 11,
      "z": 1,
      "name": "Empty"
    },
    {
      "x": -11,
      "y": 10,
      "z": 2,
      "name": "Soil_Pathway"
    },
    {
      "x": -11,
      "y": 11,
      "z": 2,
      "name": "Empty"
    },
    {
      "x": -11,
      "y": 10,
      "z": 3,
      "name": "Soil_Pathway"
    },
    {
      "x": -11,
      "y": 11,
      "z": 3,
      "name": "Empty"
    },
    {
      "x": -11,
      "y": 10,
      "z": 4,
      "name": "Soil_Pathway"
    },
    {
      "x": -11,
      "y": 11,
      "z": 4,
      "name": "Empty"
    },
    {
      "x": -11,
      "y": 10,
      "z": 5,
      "name": "Soil_Pathway"
    },
    {
      "x": -11,
      "y": 11,
      "z": 5,
      "name": "Empty"
    },
    {
      "x": -11,
      "y": 10,
      "z": 6,
      "name": "Soil_Pathway"
    },
    {
      "x": -11,
      "y": 11,
      "z": 6,
      "name": "Empty"
    },
    {
      "x": -11,
      "y": 10,
      "z": 7,
      "name": "Soil_Pathway"
    },
    {
      "x": -11,
      "y": 11,
      "z": 7,
      "name": "Empty"
    },
    {
      "x": -11,
      "y": 10,
      "z": 8,
      "name": "Soil_Pathway"
    },
    {
      "x": -11,
      "y": 11,
      "z": 8,
      "name": "Empty"
    },
    {
      "x": -11,
      "y": 10,
      "z": 9,
      "name": "Soil_Pathway"
    },
    {
      "x": -11,
      "y": 11,
      "z": 9,
      "name": "Empty"
    },
    {
      "x": -11,
      "y": 10,
      "z": 10,
      "name": "Soil_Pathway"
    },
    {
      "x": -11,
      "y": 11,
      "z": 10,
      "name": "Empty"
    },
    {
      "x": -11,
      "y": 10,
      "z": 11,
      "name": "Soil_Pathway"
    },
    {
      "x": -11,
      "y": 11,
      "z": 11,
      "name": "Bench_Lumbermill",
      "components": {
        "Components": {
          "processingBench": {
            "TierLevel": 1,
            "UpgradeItems": [],
            "InputContainer": {
              "Id": "Simple",
              "Capacity": 2,
              "Items": {}
            },
            "FuelContainer": {
              "Id": "Simple",
              "Capacity": 0,
              "Items": {}
            },
            "OutputContainer": {
              "Id": "Simple",
              "Capacity": 1,
              "Items": {}
            },
            "Progress": 0.0,
            "FuelTime": 0.0,
            "Active": true,
            "NextExtra": 0
          }
        }
      },
      "rotation": 1
    },
    {
      "x": -11,
      "y": 10,
      "z": 12,
      "name": "Soil_Pathway"
    },
    {
      "x": -11,
      "y": 11,
      "z": 12,
      "name": "Bench_Lumbermill",
      "components": {
        "Components": {
          "processingBench": {
            "Position": {
              "X": 21,
              "Y": 11,
              "Z": 12
            },
            "TierLevel": 1,
            "UpgradeItems": [],
            "Progress": 0.0,
            "FuelTime": 0.0,
            "Active": false,
            "NextExtra": -1
          }
        }
      },
      "filler": 32,
      "rotation": 1
    },
    {
      "x": -11,
      "y": 10,
      "z": 13,
      "name": "Soil_Pathway"
    },
    {
      "x": -11,
      "y": 11,
      "z": 13,
      "name": "Empty"
    },
    {
      "x": -11,
      "y": 10,
      "z": 14,
      "name": "Soil_Pathway"
    },
    {
      "x": -11,
      "y": 11,
      "z": 14,
      "name": "Empty"
    },
    {
      "x": -11,
      "y": 10,
      "z": 15,
      "name": "Soil_Dirt"
    },
    {
      "x": -11,
      "y": 11,
      "z": 15,
      "name": "Empty"
    },
    {
      "x": -11,
      "y": 10,
      "z": 16,
      "name": "Soil_Dirt"
    },
    {
      "x": -11,
      "y": 11,
      "z": 16,
      "name": "Empty"
    },
    {
      "x": -11,
      "y": 10,
      "z": 17,
      "name": "Soil_Dirt"
    },
    {
      "x": -11,
      "y": 11,
      "z": 17,
      "name": "Empty"
    },
    {
      "x": -11,
      "y": 10,
      "z": 18,
      "name": "Soil_Dirt"
    },
    {
      "x": -11,
      "y": 11,
      "z": 18,
      "name": "Empty"
    },
    {
      "x": -11,
      "y": 10,
      "z": 19,
      "name": "Soil_Dirt"
    },
    {
      "x": -11,
      "y": 11,
      "z": 19,
      "name": "Empty"
    },
    {
      "x": -11,
      "y": 10,
      "z": 20,
      "name": "Soil_Dirt"
    },
    {
      "x": -11,
      "y": 11,
      "z": 20,
      "name": "Empty"
    },
    {
      "x": -11,
      "y": 10,
      "z": 21,
      "name": "Soil_Dirt"
    },
    {
      "x": -11,
      "y": 11,
      "z": 21,
      "name": "Empty"
    },
    {
      "x": -11,
      "y": 10,
      "z": 22,
      "name": "Soil_Pathway"
    },
    {
      "x": -11,
      "y": 11,
      "z": 22,
      "name": "Empty"
    },
    {
      "x": -11,
      "y": 10,
      "z": 23,
      "name": "Soil_Pathway"
    },
    {
      "x": -11,
      "y": 11,
      "z": 23,
      "name": "Empty"
    },
    {
      "x": -10,
      "y": 11,
      "z": -20,
      "name": "Rock_Stone"
    },
    {
      "x": -10,
      "y": 7,
      "z": -19,
      "name": "Rock_Stone"
    },
    {
      "x": -10,
      "y": 8,
      "z": -19,
      "name": "Rock_Stone"
    },
    {
      "x": -10,
      "y": 9,
      "z": -19,
      "name": "Rock_Stone"
    },
    {
      "x": -10,
      "y": 10,
      "z": -19,
      "name": "Rock_Stone"
    },
    {
      "x": -10,
      "y": 11,
      "z": -19,
      "name": "Rock_Stone"
    },
    {
      "x": -10,
      "y": 12,
      "z": -19,
      "name": "Rock_Stone"
    },
    {
      "x": -10,
      "y": 6,
      "z": -18,
      "name": "Rock_Stone"
    },
    {
      "x": -10,
      "y": 7,
      "z": -18,
      "name": "Rock_Stone"
    },
    {
      "x": -10,
      "y": 8,
      "z": -18,
      "name": "Rock_Stone"
    },
    {
      "x": -10,
      "y": 9,
      "z": -18,
      "name": "Rock_Stone"
    },
    {
      "x": -10,
      "y": 10,
      "z": -18,
      "name": "Rock_Stone"
    },
    {
      "x": -10,
      "y": 11,
      "z": -18,
      "name": "Rock_Stone"
    },
    {
      "x": -10,
      "y": 12,
      "z": -18,
      "name": "Rock_Stone"
    },
    {
      "x": -10,
      "y": 9,
      "z": -17,
      "name": "Rock_Stone"
    },
    {
      "x": -10,
      "y": 10,
      "z": -17,
      "name": "Rock_Stone"
    },
    {
      "x": -10,
      "y": 11,
      "z": -17,
      "name": "Rock_Stone"
    },
    {
      "x": -10,
      "y": 12,
      "z": -17,
      "name": "Rock_Stone"
    },
    {
      "x": -10,
      "y": 10,
      "z": -16,
      "name": "Rock_Stone"
    },
    {
      "x": -10,
      "y": 11,
      "z": -16,
      "name": "Rock_Stone"
    },
    {
      "x": -10,
      "y": 12,
      "z": -16,
      "name": "Rock_Stone"
    },
    {
      "x": -10,
      "y": 10,
      "z": -15,
      "name": "Rock_Stone_Cobble"
    },
    {
      "x": -10,
      "y": 11,
      "z": -15,
      "name": "Rock_Stone_Cobble"
    },
    {
      "x": -10,
      "y": 12,
      "z": -15,
      "name": "Rock_Stone_Cobble"
    },
    {
      "x": -10,
      "y": 8,
      "z": -14,
      "name": "Wood_Beech_Trunk",
      "support": 15
    },
    {
      "x": -10,
      "y": 9,
      "z": -14,
      "name": "Wood_Beech_Trunk",
      "support": 15
    },
    {
      "x": -10,
      "y": 10,
      "z": -14,
      "name": "Wood_Beech_Trunk",
      "support": 15
    },
    {
      "x": -10,
      "y": 11,
      "z": -14,
      "name": "Wood_Beech_Trunk",
      "support": 15
    },
    {
      "x": -10,
      "y": 12,
      "z": -14,
      "name": "Wood_Beech_Trunk",
      "support": 15
    },
    {
      "x": -10,
      "y": 13,
      "z": -14,
      "name": "Wood_Beech_Trunk",
      "support": 15
    },
    {
      "x": -10,
      "y": 14,
      "z": -14,
      "name": "Wood_Beech_Trunk",
      "support": 15
    },
    {
      "x": -10,
      "y": 10,
      "z": -13,
      "name": "Soil_Dirt"
    },
    {
      "x": -10,
      "y": 11,
      "z": -13,
      "name": "Empty"
    },
    {
      "x": -10,
      "y": 10,
      "z": -12,
      "name": "Soil_Dirt"
    },
    {
      "x": -10,
      "y": 11,
      "z": -12,
      "name": "Empty"
    },
    {
      "x": -10,
      "y": 10,
      "z": -11,
      "name": "Soil_Pathway"
    },
    {
      "x": -10,
      "y": 11,
      "z": -11,
      "name": "Empty"
    },
    {
      "x": -10,
      "y": 10,
      "z": -10,
      "name": "Soil_Pathway"
    },
    {
      "x": -10,
      "y": 11,
      "z": -10,
      "name": "Empty"
    },
    {
      "x": -10,
      "y": 10,
      "z": -9,
      "name": "Soil_Pathway"
    },
    {
      "x": -10,
      "y": 11,
      "z": -9,
      "name": "Empty"
    },
    {
      "x": -10,
      "y": 10,
      "z": -8,
      "name": "Soil_Pathway"
    },
    {
      "x": -10,
      "y": 11,
      "z": -8,
      "name": "Empty"
    },
    {
      "x": -10,
      "y": 10,
      "z": -7,
      "name": "Soil_Pathway"
    },
    {
      "x": -10,
      "y": 11,
      "z": -7,
      "name": "Empty"
    },
    {
      "x": -10,
      "y": 10,
      "z": -6,
      "name": "Soil_Pathway"
    },
    {
      "x": -10,
      "y": 11,
      "z": -6,
      "name": "Empty"
    },
    {
      "x": -10,
      "y": 10,
      "z": -5,
      "name": "Soil_Pathway"
    },
    {
      "x": -10,
      "y": 11,
      "z": -5,
      "name": "Empty"
    },
    {
      "x": -10,
      "y": 10,
      "z": -4,
      "name": "Soil_Pathway"
    },
    {
      "x": -10,
      "y": 11,
      "z": -4,
      "name": "Empty"
    },
    {
      "x": -10,
      "y": 10,
      "z": -3,
      "name": "Soil_Pathway"
    },
    {
      "x": -10,
      "y": 11,
      "z": -3,
      "name": "Empty"
    },
    {
      "x": -10,
      "y": 10,
      "z": -2,
      "name": "Soil_Pathway"
    },
    {
      "x": -10,
      "y": 11,
      "z": -2,
      "name": "Empty"
    },
    {
      "x": -10,
      "y": 10,
      "z": -1,
      "name": "Soil_Pathway"
    },
    {
      "x": -10,
      "y": 11,
      "z": -1,
      "name": "Empty"
    },
    {
      "x": -10,
      "y": 10,
      "z": 0,
      "name": "Soil_Pathway"
    },
    {
      "x": -10,
      "y": 11,
      "z": 0,
      "name": "Empty"
    },
    {
      "x": -10,
      "y": 10,
      "z": 1,
      "name": "Rock_Stone"
    },
    {
      "x": -10,
      "y": 11,
      "z": 1,
      "name": "Rock_Stone"
    },
    {
      "x": -10,
      "y": 10,
      "z": 2,
      "name": "Rock_Stone"
    },
    {
      "x": -10,
      "y": 11,
      "z": 2,
      "name": "Rock_Stone"
    },
    {
      "x": -10,
      "y": 10,
      "z": 3,
      "name": "Rock_Stone"
    },
    {
      "x": -10,
      "y": 11,
      "z": 3,
      "name": "Rock_Stone"
    },
    {
      "x": -10,
      "y": 10,
      "z": 4,
      "name": "Soil_Pathway"
    },
    {
      "x": -10,
      "y": 11,
      "z": 4,
      "name": "Empty"
    },
    {
      "x": -10,
      "y": 10,
      "z": 5,
      "name": "Soil_Pathway"
    },
    {
      "x": -10,
      "y": 11,
      "z": 5,
      "name": "Empty"
    },
    {
      "x": -10,
      "y": 10,
      "z": 6,
      "name": "Soil_Pathway"
    },
    {
      "x": -10,
      "y": 11,
      "z": 6,
      "name": "Empty"
    },
    {
      "x": -10,
      "y": 10,
      "z": 7,
      "name": "Soil_Pathway"
    },
    {
      "x": -10,
      "y": 11,
      "z": 7,
      "name": "Empty"
    },
    {
      "x": -10,
      "y": 10,
      "z": 8,
      "name": "Soil_Pathway"
    },
    {
      "x": -10,
      "y": 11,
      "z": 8,
      "name": "Empty"
    },
    {
      "x": -10,
      "y": 10,
      "z": 9,
      "name": "Soil_Pathway"
    },
    {
      "x": -10,
      "y": 11,
      "z": 9,
      "name": "Empty"
    },
    {
      "x": -10,
      "y": 10,
      "z": 10,
      "name": "Soil_Pathway"
    },
    {
      "x": -10,
      "y": 11,
      "z": 10,
      "name": "Empty"
    },
    {
      "x": -10,
      "y": 10,
      "z": 11,
      "name": "Soil_Pathway"
    },
    {
      "x": -10,
      "y": 11,
      "z": 11,
      "name": "Empty"
    },
    {
      "x": -10,
      "y": 10,
      "z": 12,
      "name": "Soil_Pathway"
    },
    {
      "x": -10,
      "y": 11,
      "z": 12,
      "name": "Empty"
    },
    {
      "x": -10,
      "y": 10,
      "z": 13,
      "name": "Soil_Pathway"
    },
    {
      "x": -10,
      "y": 11,
      "z": 13,
      "name": "Empty"
    },
    {
      "x": -10,
      "y": 10,
      "z": 14,
      "name": "Soil_Dirt"
    },
    {
      "x": -10,
      "y": 11,
      "z": 14,
      "name": "Empty"
    },
    {
      "x": -10,
      "y": 10,
      "z": 15,
      "name": "Soil_Dirt"
    },
    {
      "x": -10,
      "y": 11,
      "z": 15,
      "name": "Empty"
    },
    {
      "x": -10,
      "y": 10,
      "z": 16,
      "name": "Soil_Dirt"
    },
    {
      "x": -10,
      "y": 11,
      "z": 16,
      "name": "Empty"
    },
    {
      "x": -10,
      "y": 10,
      "z": 17,
      "name": "Soil_Dirt"
    },
    {
      "x": -10,
      "y": 11,
      "z": 17,
      "name": "Empty"
    },
    {
      "x": -10,
      "y": 10,
      "z": 18,
      "name": "Soil_Dirt"
    },
    {
      "x": -10,
      "y": 11,
      "z": 18,
      "name": "Empty"
    },
    {
      "x": -10,
      "y": 10,
      "z": 19,
      "name": "Soil_Dirt"
    },
    {
      "x": -10,
      "y": 11,
      "z": 19,
      "name": "Empty"
    },
    {
      "x": -10,
      "y": 10,
      "z": 20,
      "name": "Soil_Dirt"
    },
    {
      "x": -10,
      "y": 11,
      "z": 20,
      "name": "Empty"
    },
    {
      "x": -10,
      "y": 10,
      "z": 21,
      "name": "Soil_Dirt"
    },
    {
      "x": -10,
      "y": 11,
      "z": 21,
      "name": "Empty"
    },
    {
      "x": -10,
      "y": 10,
      "z": 22,
      "name": "Soil_Pathway"
    },
    {
      "x": -10,
      "y": 11,
      "z": 22,
      "name": "Empty"
    },
    {
      "x": -9,
      "y": 10,
      "z": -20,
      "name": "Rock_Stone"
    },
    {
      "x": -9,
      "y": 11,
      "z": -20,
      "name": "Rock_Stone"
    },
    {
      "x": -9,
      "y": 8,
      "z": -19,
      "name": "Rock_Stone"
    },
    {
      "x": -9,
      "y": 9,
      "z": -19,
      "name": "Rock_Stone"
    },
    {
      "x": -9,
      "y": 10,
      "z": -19,
      "name": "Rock_Stone"
    },
    {
      "x": -9,
      "y": 11,
      "z": -19,
      "name": "Rock_Stone"
    },
    {
      "x": -9,
      "y": 12,
      "z": -19,
      "name": "Rock_Stone"
    },
    {
      "x": -9,
      "y": 7,
      "z": -18,
      "name": "Rock_Stone"
    },
    {
      "x": -9,
      "y": 8,
      "z": -18,
      "name": "Rock_Stone"
    },
    {
      "x": -9,
      "y": 9,
      "z": -18,
      "name": "Rock_Stone"
    },
    {
      "x": -9,
      "y": 10,
      "z": -18,
      "name": "Rock_Stone"
    },
    {
      "x": -9,
      "y": 11,
      "z": -18,
      "name": "Rock_Stone"
    },
    {
      "x": -9,
      "y": 12,
      "z": -18,
      "name": "Rock_Stone"
    },
    {
      "x": -9,
      "y": 7,
      "z": -17,
      "name": "Rock_Stone"
    },
    {
      "x": -9,
      "y": 8,
      "z": -17,
      "name": "Rock_Stone"
    },
    {
      "x": -9,
      "y": 9,
      "z": -17,
      "name": "Rock_Stone"
    },
    {
      "x": -9,
      "y": 10,
      "z": -17,
      "name": "Rock_Stone"
    },
    {
      "x": -9,
      "y": 11,
      "z": -17,
      "name": "Rock_Stone"
    },
    {
      "x": -9,
      "y": 12,
      "z": -17,
      "name": "Rock_Stone"
    },
    {
      "x": -9,
      "y": 8,
      "z": -16,
      "name": "Rock_Stone"
    },
    {
      "x": -9,
      "y": 9,
      "z": -16,
      "name": "Rock_Stone"
    },
    {
      "x": -9,
      "y": 10,
      "z": -16,
      "name": "Rock_Stone"
    },
    {
      "x": -9,
      "y": 11,
      "z": -16,
      "name": "Rock_Stone"
    },
    {
      "x": -9,
      "y": 12,
      "z": -16,
      "name": "Rock_Stone"
    },
    {
      "x": -9,
      "y": 7,
      "z": -13,
      "name": "Wood_Beech_Trunk",
      "support": 15
    },
    {
      "x": -9,
      "y": 8,
      "z": -13,
      "name": "Wood_Beech_Trunk",
      "support": 15
    },
    {
      "x": -9,
      "y": 9,
      "z": -13,
      "name": "Wood_Beech_Trunk",
      "support": 15
    },
    {
      "x": -9,
      "y": 10,
      "z": -13,
      "name": "Wood_Beech_Trunk",
      "support": 15
    },
    {
      "x": -9,
      "y": 11,
      "z": -13,
      "name": "Wood_Beech_Trunk",
      "support": 15
    },
    {
      "x": -9,
      "y": 12,
      "z": -13,
      "name": "Wood_Beech_Trunk",
      "support": 15
    },
    {
      "x": -9,
      "y": 13,
      "z": -13,
      "name": "Wood_Beech_Trunk",
      "support": 15
    },
    {
      "x": -9,
      "y": 14,
      "z": -13,
      "name": "Wood_Beech_Trunk_Full",
      "support": 15
    },
    {
      "x": -9,
      "y": 15,
      "z": -13,
      "name": "Wood_Beech_Branch_Long",
      "support": 15
    },
    {
      "x": -9,
      "y": 16,
      "z": -13,
      "name": "Survival_Trap_Spike_Wood_Large"
    },
    {
      "x": -9,
      "y": 10,
      "z": -12,
      "name": "Soil_Pathway"
    },
    {
      "x": -9,
      "y": 11,
      "z": -12,
      "name": "Empty"
    },
    {
      "x": -9,
      "y": 10,
      "z": -11,
      "name": "Soil_Pathway"
    },
    {
      "x": -9,
      "y": 11,
      "z": -11,
      "name": "Empty"
    },
    {
      "x": -9,
      "y": 10,
      "z": -10,
      "name": "Soil_Pathway"
    },
    {
      "x": -9,
      "y": 11,
      "z": -10,
      "name": "Empty"
    },
    {
      "x": -9,
      "y": 10,
      "z": -7,
      "name": "Soil_Dirt"
    },
    {
      "x": -9,
      "y": 11,
      "z": -7,
      "name": "Empty"
    },
    {
      "x": -9,
      "y": 10,
      "z": -6,
      "name": "Soil_Dirt"
    },
    {
      "x": -9,
      "y": 11,
      "z": -6,
      "name": "Empty"
    },
    {
      "x": -9,
      "y": 10,
      "z": -5,
      "name": "Soil_Pathway"
    },
    {
      "x": -9,
      "y": 11,
      "z": -5,
      "name": "Empty"
    },
    {
      "x": -9,
      "y": 10,
      "z": -4,
      "name": "Soil_Pathway"
    },
    {
      "x": -9,
      "y": 11,
      "z": -4,
      "name": "Empty"
    },
    {
      "x": -9,
      "y": 10,
      "z": -3,
      "name": "Soil_Pathway"
    },
    {
      "x": -9,
      "y": 11,
      "z": -3,
      "name": "Empty"
    },
    {
      "x": -9,
      "y": 10,
      "z": -2,
      "name": "Soil_Pathway"
    },
    {
      "x": -9,
      "y": 11,
      "z": -2,
      "name": "Empty"
    },
    {
      "x": -9,
      "y": 10,
      "z": -1,
      "name": "Rock_Stone"
    },
    {
      "x": -9,
      "y": 11,
      "z": -1,
      "name": "Soil_Pathway_Half"
    },
    {
      "x": -9,
      "y": 10,
      "z": 0,
      "name": "Rock_Stone"
    },
    {
      "x": -9,
      "y": 11,
      "z": 0,
      "name": "Soil_Pathway_Half"
    },
    {
      "x": -9,
      "y": 10,
      "z": 1,
      "name": "Rock_Stone"
    },
    {
      "x": -9,
      "y": 11,
      "z": 1,
      "name": "Rock_Stone"
    },
    {
      "x": -9,
      "y": 12,
      "z": 1,
      "name": "Rock_Stone"
    },
    {
      "x": -9,
      "y": 10,
      "z": 2,
      "name": "Rock_Stone"
    },
    {
      "x": -9,
      "y": 11,
      "z": 2,
      "name": "Rock_Stone"
    },
    {
      "x": -9,
      "y": 12,
      "z": 2,
      "name": "Rock_Stone"
    },
    {
      "x": -9,
      "y": 10,
      "z": 3,
      "name": "Rock_Stone"
    },
    {
      "x": -9,
      "y": 11,
      "z": 3,
      "name": "Rock_Stone"
    },
    {
      "x": -9,
      "y": 12,
      "z": 3,
      "name": "Rock_Stone"
    },
    {
      "x": -9,
      "y": 10,
      "z": 4,
      "name": "Rock_Stone"
    },
    {
      "x": -9,
      "y": 11,
      "z": 4,
      "name": "Rock_Stone"
    },
    {
      "x": -9,
      "y": 10,
      "z": 5,
      "name": "Rock_Stone"
    },
    {
      "x": -9,
      "y": 11,
      "z": 5,
      "name": "Rock_Stone"
    },
    {
      "x": -9,
      "y": 10,
      "z": 6,
      "name": "Soil_Pathway"
    },
    {
      "x": -9,
      "y": 11,
      "z": 6,
      "name": "Empty"
    },
    {
      "x": -9,
      "y": 10,
      "z": 7,
      "name": "Soil_Pathway"
    },
    {
      "x": -9,
      "y": 11,
      "z": 7,
      "name": "Empty"
    },
    {
      "x": -9,
      "y": 10,
      "z": 8,
      "name": "Soil_Pathway"
    },
    {
      "x": -9,
      "y": 11,
      "z": 8,
      "name": "Empty"
    },
    {
      "x": -9,
      "y": 10,
      "z": 9,
      "name": "Soil_Pathway"
    },
    {
      "x": -9,
      "y": 11,
      "z": 9,
      "name": "Empty"
    },
    {
      "x": -9,
      "y": 10,
      "z": 10,
      "name": "Soil_Pathway"
    },
    {
      "x": -9,
      "y": 11,
      "z": 10,
      "name": "Empty"
    },
    {
      "x": -9,
      "y": 10,
      "z": 11,
      "name": "Soil_Pathway"
    },
    {
      "x": -9,
      "y": 11,
      "z": 11,
      "name": "Empty"
    },
    {
      "x": -9,
      "y": 10,
      "z": 12,
      "name": "Soil_Pathway"
    },
    {
      "x": -9,
      "y": 11,
      "z": 12,
      "name": "Empty"
    },
    {
      "x": -9,
      "y": 10,
      "z": 13,
      "name": "Soil_Dirt"
    },
    {
      "x": -9,
      "y": 11,
      "z": 13,
      "name": "Empty"
    },
    {
      "x": -9,
      "y": 10,
      "z": 14,
      "name": "Soil_Dirt"
    },
    {
      "x": -9,
      "y": 11,
      "z": 14,
      "name": "Empty"
    },
    {
      "x": -9,
      "y": 10,
      "z": 15,
      "name": "Soil_Dirt"
    },
    {
      "x": -9,
      "y": 11,
      "z": 15,
      "name": "Empty"
    },
    {
      "x": -9,
      "y": 10,
      "z": 16,
      "name": "Soil_Dirt"
    },
    {
      "x": -9,
      "y": 11,
      "z": 16,
      "name": "Empty"
    },
    {
      "x": -9,
      "y": 10,
      "z": 17,
      "name": "Prefab_Spawner_Block",
      "components": {
        "Components": {
          "prefabspawner": {
            "PrefabPath": "Npc.Trork.Resource.Lumber.Forest_Gully.*",
            "FitHeightmap": false,
            "InheritSeed": true,
            "InheritHeightCondition": true
          }
        }
      },
      "rotation": 1
    },
    {
      "x": -9,
      "y": 11,
      "z": 17,
      "name": "Empty"
    },
    {
      "x": -9,
      "y": 10,
      "z": 18,
      "name": "Soil_Dirt"
    },
    {
      "x": -9,
      "y": 11,
      "z": 18,
      "name": "Empty"
    },
    {
      "x": -9,
      "y": 10,
      "z": 19,
      "name": "Soil_Dirt"
    },
    {
      "x": -9,
      "y": 11,
      "z": 19,
      "name": "Empty"
    },
    {
      "x": -9,
      "y": 10,
      "z": 20,
      "name": "Prefab_Spawner_Block",
      "components": {
        "Components": {
          "prefabspawner": {
            "PrefabPath": "Npc.Trork.Resource.Lumber.Forest_Gully.*",
            "FitHeightmap": false,
            "InheritSeed": true,
            "InheritHeightCondition": true
          }
        }
      },
      "rotation": 1
    },
    {
      "x": -9,
      "y": 11,
      "z": 20,
      "name": "Empty"
    },
    {
      "x": -9,
      "y": 10,
      "z": 21,
      "name": "Soil_Dirt"
    },
    {
      "x": -9,
      "y": 11,
      "z": 21,
      "name": "Empty"
    },
    {
      "x": -9,
      "y": 10,
      "z": 22,
      "name": "Soil_Pathway"
    },
    {
      "x": -9,
      "y": 11,
      "z": 22,
      "name": "Empty"
    },
    {
      "x": -8,
      "y": 11,
      "z": -20,
      "name": "Rock_Stone"
    },
    {
      "x": -8,
      "y": 12,
      "z": -20,
      "name": "Rock_Stone"
    },
    {
      "x": -8,
      "y": 9,
      "z": -19,
      "name": "Rock_Stone"
    },
    {
      "x": -8,
      "y": 10,
      "z": -19,
      "name": "Rock_Stone"
    },
    {
      "x": -8,
      "y": 11,
      "z": -19,
      "name": "Rock_Stone"
    },
    {
      "x": -8,
      "y": 12,
      "z": -19,
      "name": "Rock_Stone"
    },
    {
      "x": -8,
      "y": 8,
      "z": -18,
      "name": "Rock_Stone"
    },
    {
      "x": -8,
      "y": 9,
      "z": -18,
      "name": "Rock_Stone"
    },
    {
      "x": -8,
      "y": 10,
      "z": -18,
      "name": "Rock_Stone"
    },
    {
      "x": -8,
      "y": 11,
      "z": -18,
      "name": "Rock_Stone"
    },
    {
      "x": -8,
      "y": 12,
      "z": -18,
      "name": "Rock_Stone"
    },
    {
      "x": -8,
      "y": 8,
      "z": -17,
      "name": "Rock_Stone"
    },
    {
      "x": -8,
      "y": 9,
      "z": -17,
      "name": "Rock_Stone"
    },
    {
      "x": -8,
      "y": 10,
      "z": -17,
      "name": "Rock_Stone"
    },
    {
      "x": -8,
      "y": 11,
      "z": -17,
      "name": "Rock_Stone"
    },
    {
      "x": -8,
      "y": 12,
      "z": -17,
      "name": "Rock_Stone"
    },
    {
      "x": -8,
      "y": 9,
      "z": -16,
      "name": "Rock_Stone"
    },
    {
      "x": -8,
      "y": 10,
      "z": -16,
      "name": "Rock_Stone"
    },
    {
      "x": -8,
      "y": 11,
      "z": -16,
      "name": "Rock_Stone"
    },
    {
      "x": -8,
      "y": 12,
      "z": -16,
      "name": "Rock_Stone"
    },
    {
      "x": -8,
      "y": 8,
      "z": -13,
      "name": "Wood_Beech_Trunk",
      "support": 15
    },
    {
      "x": -8,
      "y": 9,
      "z": -13,
      "name": "Wood_Beech_Trunk",
      "support": 15
    },
    {
      "x": -8,
      "y": 10,
      "z": -13,
      "name": "Wood_Beech_Trunk",
      "support": 15
    },
    {
      "x": -8,
      "y": 11,
      "z": -13,
      "name": "Wood_Beech_Trunk",
      "support": 15
    },
    {
      "x": -8,
      "y": 12,
      "z": -13,
      "name": "Wood_Beech_Trunk",
      "support": 15
    },
    {
      "x": -8,
      "y": 13,
      "z": -13,
      "name": "Wood_Beech_Trunk",
      "support": 15
    },
    {
      "x": -8,
      "y": 10,
      "z": -12,
      "name": "Soil_Pathway"
    },
    {
      "x": -8,
      "y": 11,
      "z": -12,
      "name": "Empty"
    },
    {
      "x": -8,
      "y": 10,
      "z": -7,
      "name": "Rock_Stone"
    },
    {
      "x": -8,
      "y": 11,
      "z": -7,
      "name": "Empty"
    },
    {
      "x": -8,
      "y": 10,
      "z": -6,
      "name": "Soil_Dirt"
    },
    {
      "x": -8,
      "y": 11,
      "z": -6,
      "name": "Empty"
    },
    {
      "x": -8,
      "y": 10,
      "z": -5,
      "name": "Soil_Dirt"
    },
    {
      "x": -8,
      "y": 11,
      "z": -5,
      "name": "Empty"
    },
    {
      "x": -8,
      "y": 10,
      "z": -4,
      "name": "Soil_Pathway"
    },
    {
      "x": -8,
      "y": 11,
      "z": -4,
      "name": "Empty"
    },
    {
      "x": -8,
      "y": 10,
      "z": -3,
      "name": "Soil_Pathway"
    },
    {
      "x": -8,
      "y": 11,
      "z": -3,
      "name": "Empty"
    },
    {
      "x": -8,
      "y": 10,
      "z": -2,
      "name": "Soil_Pathway"
    },
    {
      "x": -8,
      "y": 11,
      "z": -2,
      "name": "Empty"
    },
    {
      "x": -8,
      "y": 10,
      "z": -1,
      "name": "Rock_Stone"
    },
    {
      "x": -8,
      "y": 11,
      "z": -1,
      "name": "Soil_Pathway_Half"
    },
    {
      "x": -8,
      "y": 10,
      "z": 0,
      "name": "Rock_Stone"
    },
    {
      "x": -8,
      "y": 11,
      "z": 0,
      "name": "Soil_Pathway"
    },
    {
      "x": -8,
      "y": 10,
      "z": 1,
      "name": "Rock_Stone"
    },
    {
      "x": -8,
      "y": 11,
      "z": 1,
      "name": "Rock_Stone"
    },
    {
      "x": -8,
      "y": 12,
      "z": 1,
      "name": "Soil_Pathway_Half"
    },
    {
      "x": -8,
      "y": 10,
      "z": 2,
      "name": "Rock_Stone"
    },
    {
      "x": -8,
      "y": 11,
      "z": 2,
      "name": "Rock_Stone"
    },
    {
      "x": -8,
      "y": 12,
      "z": 2,
      "name": "Rock_Stone"
    },
    {
      "x": -8,
      "y": 10,
      "z": 3,
      "name": "Rock_Stone"
    },
    {
      "x": -8,
      "y": 11,
      "z": 3,
      "name": "Rock_Stone"
    },
    {
      "x": -8,
      "y": 12,
      "z": 3,
      "name": "Rock_Stone"
    },
    {
      "x": -8,
      "y": 10,
      "z": 4,
      "name": "Rock_Stone"
    },
    {
      "x": -8,
      "y": 11,
      "z": 4,
      "name": "Rock_Stone"
    },
    {
      "x": -8,
      "y": 12,
      "z": 4,
      "name": "Rock_Stone"
    },
    {
      "x": -8,
      "y": 10,
      "z": 5,
      "name": "Rock_Stone"
    },
    {
      "x": -8,
      "y": 11,
      "z": 5,
      "name": "Rock_Stone"
    },
    {
      "x": -8,
      "y": 10,
      "z": 6,
      "name": "Soil_Pathway"
    },
    {
      "x": -8,
      "y": 11,
      "z": 6,
      "name": "Empty"
    },
    {
      "x": -8,
      "y": 10,
      "z": 7,
      "name": "Soil_Pathway"
    },
    {
      "x": -8,
      "y": 11,
      "z": 7,
      "name": "Empty"
    },
    {
      "x": -8,
      "y": 10,
      "z": 8,
      "name": "Soil_Pathway"
    },
    {
      "x": -8,
      "y": 11,
      "z": 8,
      "name": "Empty"
    },
    {
      "x": -8,
      "y": 10,
      "z": 9,
      "name": "Soil_Pathway"
    },
    {
      "x": -8,
      "y": 11,
      "z": 9,
      "name": "Empty"
    },
    {
      "x": -8,
      "y": 10,
      "z": 10,
      "name": "Soil_Pathway"
    },
    {
      "x": -8,
      "y": 11,
      "z": 10,
      "name": "Empty"
    },
    {
      "x": -8,
      "y": 10,
      "z": 11,
      "name": "Soil_Pathway"
    },
    {
      "x": -8,
      "y": 11,
      "z": 11,
      "name": "Empty"
    },
    {
      "x": -8,
      "y": 10,
      "z": 12,
      "name": "Soil_Pathway"
    },
    {
      "x": -8,
      "y": 11,
      "z": 12,
      "name": "Empty"
    },
    {
      "x": -8,
      "y": 10,
      "z": 13,
      "name": "Soil_Dirt"
    },
    {
      "x": -8,
      "y": 11,
      "z": 13,
      "name": "Empty"
    },
    {
      "x": -8,
      "y": 10,
      "z": 14,
      "name": "Soil_Dirt"
    },
    {
      "x": -8,
      "y": 11,
      "z": 14,
      "name": "Empty"
    },
    {
      "x": -8,
      "y": 10,
      "z": 15,
      "name": "Soil_Dirt"
    },
    {
      "x": -8,
      "y": 11,
      "z": 15,
      "name": "Empty"
    },
    {
      "x": -8,
      "y": 10,
      "z": 16,
      "name": "Soil_Dirt"
    },
    {
      "x": -8,
      "y": 11,
      "z": 16,
      "name": "Empty"
    },
    {
      "x": -8,
      "y": 10,
      "z": 17,
      "name": "Soil_Dirt"
    },
    {
      "x": -8,
      "y": 11,
      "z": 17,
      "name": "Empty"
    },
    {
      "x": -8,
      "y": 10,
      "z": 18,
      "name": "Soil_Dirt"
    },
    {
      "x": -8,
      "y": 11,
      "z": 18,
      "name": "Empty"
    },
    {
      "x": -8,
      "y": 10,
      "z": 19,
      "name": "Soil_Dirt"
    },
    {
      "x": -8,
      "y": 11,
      "z": 19,
      "name": "Empty"
    },
    {
      "x": -8,
      "y": 10,
      "z": 20,
      "name": "Soil_Dirt"
    },
    {
      "x": -8,
      "y": 11,
      "z": 20,
      "name": "Empty"
    },
    {
      "x": -8,
      "y": 10,
      "z": 21,
      "name": "Soil_Dirt"
    },
    {
      "x": -8,
      "y": 11,
      "z": 21,
      "name": "Empty"
    },
    {
      "x": -8,
      "y": 10,
      "z": 22,
      "name": "Soil_Pathway"
    },
    {
      "x": -8,
      "y": 11,
      "z": 22,
      "name": "Empty"
    },
    {
      "x": -7,
      "y": 10,
      "z": -19,
      "name": "Rock_Stone"
    },
    {
      "x": -7,
      "y": 11,
      "z": -19,
      "name": "Rock_Stone"
    },
    {
      "x": -7,
      "y": 12,
      "z": -19,
      "name": "Rock_Stone"
    },
    {
      "x": -7,
      "y": 9,
      "z": -18,
      "name": "Rock_Stone"
    },
    {
      "x": -7,
      "y": 10,
      "z": -18,
      "name": "Rock_Stone"
    },
    {
      "x": -7,
      "y": 11,
      "z": -18,
      "name": "Rock_Stone"
    },
    {
      "x": -7,
      "y": 12,
      "z": -18,
      "name": "Rock_Stone"
    },
    {
      "x": -7,
      "y": 9,
      "z": -17,
      "name": "Rock_Stone"
    },
    {
      "x": -7,
      "y": 10,
      "z": -17,
      "name": "Rock_Stone"
    },
    {
      "x": -7,
      "y": 11,
      "z": -17,
      "name": "Rock_Stone"
    },
    {
      "x": -7,
      "y": 10,
      "z": -16,
      "name": "Rock_Stone"
    },
    {
      "x": -7,
      "y": 11,
      "z": -16,
      "name": "Rock_Stone"
    },
    {
      "x": -7,
      "y": 10,
      "z": -10,
      "name": "Prefab_Spawner_Block",
      "components": {
        "Components": {
          "prefabspawner": {
            "PrefabPath": "Npc.Trork.Tier_2.Watchtower.*",
            "FitHeightmap": false,
            "InheritSeed": true,
            "InheritHeightCondition": true
          }
        }
      },
      "rotation": 3
    },
    {
      "x": -7,
      "y": 10,
      "z": -7,
      "name": "Rock_Stone"
    },
    {
      "x": -7,
      "y": 11,
      "z": -7,
      "name": "Empty"
    },
    {
      "x": -7,
      "y": 10,
      "z": -6,
      "name": "Rock_Stone"
    },
    {
      "x": -7,
      "y": 11,
      "z": -6,
      "name": "Rock_Stone"
    },
    {
      "x": -7,
      "y": 10,
      "z": -5,
      "name": "Rock_Stone"
    },
    {
      "x": -7,
      "y": 11,
      "z": -5,
      "name": "Rock_Stone"
    },
    {
      "x": -7,
      "y": 10,
      "z": -4,
      "name": "Rock_Stone"
    },
    {
      "x": -7,
      "y": 11,
      "z": -4,
      "name": "Rock_Stone"
    },
    {
      "x": -7,
      "y": 10,
      "z": -3,
      "name": "Rock_Stone"
    },
    {
      "x": -7,
      "y": 11,
      "z": -3,
      "name": "Rock_Stone"
    },
    {
      "x": -7,
      "y": 10,
      "z": -2,
      "name": "Rock_Stone"
    },
    {
      "x": -7,
      "y": 11,
      "z": -2,
      "name": "Soil_Pathway_Half"
    },
    {
      "x": -7,
      "y": 10,
      "z": -1,
      "name": "Rock_Stone"
    },
    {
      "x": -7,
      "y": 11,
      "z": -1,
      "name": "Soil_Pathway_Half"
    },
    {
      "x": -7,
      "y": 10,
      "z": 0,
      "name": "Rock_Stone"
    },
    {
      "x": -7,
      "y": 11,
      "z": 0,
      "name": "Soil_Pathway"
    },
    {
      "x": -7,
      "y": 10,
      "z": 1,
      "name": "Rock_Stone"
    },
    {
      "x": -7,
      "y": 11,
      "z": 1,
      "name": "Rock_Stone"
    },
    {
      "x": -7,
      "y": 12,
      "z": 1,
      "name": "Soil_Pathway_Half"
    },
    {
      "x": -7,
      "y": 10,
      "z": 2,
      "name": "Rock_Stone"
    },
    {
      "x": -7,
      "y": 11,
      "z": 2,
      "name": "Rock_Stone"
    },
    {
      "x": -7,
      "y": 12,
      "z": 2,
      "name": "Soil_Pathway_Half"
    },
    {
      "x": -7,
      "y": 10,
      "z": 3,
      "name": "Rock_Stone"
    },
    {
      "x": -7,
      "y": 11,
      "z": 3,
      "name": "Rock_Stone"
    },
    {
      "x": -7,
      "y": 12,
      "z": 3,
      "name": "Soil_Pathway"
    },
    {
      "x": -7,
      "y": 10,
      "z": 4,
      "name": "Rock_Stone"
    },
    {
      "x": -7,
      "y": 11,
      "z": 4,
      "name": "Rock_Stone"
    },
    {
      "x": -7,
      "y": 12,
      "z": 4,
      "name": "Rock_Stone"
    },
    {
      "x": -7,
      "y": 13,
      "z": 4,
      "name": "Block_Spawner_Block",
      "components": {
        "Components": {
          "BlockSpawner": {
            "BlockSpawnerId": "Zone1_Trork_Tier2"
          }
        }
      }
    },
    {
      "x": -7,
      "y": 10,
      "z": 5,
      "name": "Rock_Stone"
    },
    {
      "x": -7,
      "y": 11,
      "z": 5,
      "name": "Rock_Stone"
    },
    {
      "x": -7,
      "y": 12,
      "z": 5,
      "name": "Rock_Stone"
    },
    {
      "x": -7,
      "y": 10,
      "z": 6,
      "name": "Rock_Stone"
    },
    {
      "x": -7,
      "y": 11,
      "z": 6,
      "name": "Rock_Stone"
    },
    {
      "x": -7,
      "y": 10,
      "z": 7,
      "name": "Soil_Pathway"
    },
    {
      "x": -7,
      "y": 11,
      "z": 7,
      "name": "Empty"
    },
    {
      "x": -7,
      "y": 10,
      "z": 8,
      "name": "Soil_Pathway"
    },
    {
      "x": -7,
      "y": 11,
      "z": 8,
      "name": "Empty"
    },
    {
      "x": -7,
      "y": 10,
      "z": 9,
      "name": "Soil_Pathway"
    },
    {
      "x": -7,
      "y": 11,
      "z": 9,
      "name": "Empty"
    },
    {
      "x": -7,
      "y": 10,
      "z": 10,
      "name": "Soil_Pathway"
    },
    {
      "x": -7,
      "y": 11,
      "z": 10,
      "name": "Empty"
    },
    {
      "x": -7,
      "y": 10,
      "z": 11,
      "name": "Soil_Pathway"
    },
    {
      "x": -7,
      "y": 11,
      "z": 11,
      "name": "Empty"
    },
    {
      "x": -7,
      "y": 10,
      "z": 12,
      "name": "Soil_Pathway"
    },
    {
      "x": -7,
      "y": 11,
      "z": 12,
      "name": "Empty"
    },
    {
      "x": -7,
      "y": 10,
      "z": 13,
      "name": "Soil_Pathway"
    },
    {
      "x": -7,
      "y": 11,
      "z": 13,
      "name": "Empty"
    },
    {
      "x": -7,
      "y": 10,
      "z": 14,
      "name": "Soil_Dirt"
    },
    {
      "x": -7,
      "y": 11,
      "z": 14,
      "name": "Empty"
    },
    {
      "x": -7,
      "y": 10,
      "z": 15,
      "name": "Soil_Dirt"
    },
    {
      "x": -7,
      "y": 11,
      "z": 15,
      "name": "Empty"
    },
    {
      "x": -7,
      "y": 10,
      "z": 16,
      "name": "Soil_Dirt"
    },
    {
      "x": -7,
      "y": 11,
      "z": 16,
      "name": "Empty"
    },
    {
      "x": -7,
      "y": 10,
      "z": 17,
      "name": "Soil_Dirt"
    },
    {
      "x": -7,
      "y": 11,
      "z": 17,
      "name": "Empty"
    },
    {
      "x": -7,
      "y": 10,
      "z": 18,
      "name": "Soil_Dirt"
    },
    {
      "x": -7,
      "y": 11,
      "z": 18,
      "name": "Empty"
    },
    {
      "x": -7,
      "y": 10,
      "z": 19,
      "name": "Soil_Dirt"
    },
    {
      "x": -7,
      "y": 11,
      "z": 19,
      "name": "Empty"
    },
    {
      "x": -7,
      "y": 10,
      "z": 20,
      "name": "Soil_Dirt"
    },
    {
      "x": -7,
      "y": 11,
      "z": 20,
      "name": "Empty"
    },
    {
      "x": -7,
      "y": 10,
      "z": 21,
      "name": "Soil_Dirt"
    },
    {
      "x": -7,
      "y": 11,
      "z": 21,
      "name": "Empty"
    },
    {
      "x": -6,
      "y": 11,
      "z": -19,
      "name": "Rock_Stone"
    },
    {
      "x": -6,
      "y": 9,
      "z": -18,
      "name": "Rock_Stone"
    },
    {
      "x": -6,
      "y": 10,
      "z": -18,
      "name": "Rock_Stone"
    },
    {
      "x": -6,
      "y": 11,
      "z": -18,
      "name": "Rock_Stone"
    },
    {
      "x": -6,
      "y": 10,
      "z": -17,
      "name": "Rock_Stone"
    },
    {
      "x": -6,
      "y": 11,
      "z": -17,
      "name": "Rock_Stone"
    },
    {
      "x": -6,
      "y": 10,
      "z": -13,
      "name": "Rock_Stone_Cobble"
    },
    {
      "x": -6,
      "y": 11,
      "z": -13,
      "name": "Rock_Stone_Cobble"
    },
    {
      "x": -6,
      "y": 12,
      "z": -13,
      "name": "Rock_Stone_Cobble"
    },
    {
      "x": -6,
      "y": 10,
      "z": -7,
      "name": "Rock_Stone"
    },
    {
      "x": -6,
      "y": 11,
      "z": -7,
      "name": "Rock_Stone"
    },
    {
      "x": -6,
      "y": 10,
      "z": -6,
      "name": "Rock_Stone"
    },
    {
      "x": -6,
      "y": 11,
      "z": -6,
      "name": "Rock_Stone"
    },
    {
      "x": -6,
      "y": 10,
      "z": -5,
      "name": "Rock_Stone"
    },
    {
      "x": -6,
      "y": 11,
      "z": -5,
      "name": "Rock_Stone"
    },
    {
      "x": -6,
      "y": 10,
      "z": -4,
      "name": "Rock_Stone"
    },
    {
      "x": -6,
      "y": 11,
      "z": -4,
      "name": "Rock_Stone"
    },
    {
      "x": -6,
      "y": 12,
      "z": -4,
      "name": "Rock_Stone"
    },
    {
      "x": -6,
      "y": 10,
      "z": -3,
      "name": "Rock_Stone"
    },
    {
      "x": -6,
      "y": 11,
      "z": -3,
      "name": "Rock_Stone"
    },
    {
      "x": -6,
      "y": 12,
      "z": -3,
      "name": "Rock_Stone"
    },
    {
      "x": -6,
      "y": 10,
      "z": -2,
      "name": "Rock_Stone"
    },
    {
      "x": -6,
      "y": 11,
      "z": -2,
      "name": "Soil_Pathway"
    },
    {
      "x": -6,
      "y": 10,
      "z": -1,
      "name": "Rock_Stone"
    },
    {
      "x": -6,
      "y": 11,
      "z": -1,
      "name": "Soil_Pathway"
    },
    {
      "x": -6,
      "y": 10,
      "z": 0,
      "name": "Rock_Stone"
    },
    {
      "x": -6,
      "y": 11,
      "z": 0,
      "name": "Soil_Pathway"
    },
    {
      "x": -6,
      "y": 10,
      "z": 1,
      "name": "Rock_Stone"
    },
    {
      "x": -6,
      "y": 11,
      "z": 1,
      "name": "Rock_Stone"
    },
    {
      "x": -6,
      "y": 12,
      "z": 1,
      "name": "Soil_Pathway_Half"
    },
    {
      "x": -6,
      "y": 10,
      "z": 2,
      "name": "Rock_Stone"
    },
    {
      "x": -6,
      "y": 11,
      "z": 2,
      "name": "Rock_Stone"
    },
    {
      "x": -6,
      "y": 12,
      "z": 2,
      "name": "Soil_Pathway"
    },
    {
      "x": -6,
      "y": 10,
      "z": 3,
      "name": "Rock_Stone"
    },
    {
      "x": -6,
      "y": 11,
      "z": 3,
      "name": "Rock_Stone"
    },
    {
      "x": -6,
      "y": 12,
      "z": 3,
      "name": "Soil_Pathway"
    },
    {
      "x": -6,
      "y": 10,
      "z": 4,
      "name": "Rock_Stone"
    },
    {
      "x": -6,
      "y": 11,
      "z": 4,
      "name": "Rock_Stone"
    },
    {
      "x": -6,
      "y": 12,
      "z": 4,
      "name": "Rock_Stone"
    },
    {
      "x": -6,
      "y": 10,
      "z": 5,
      "name": "Rock_Stone"
    },
    {
      "x": -6,
      "y": 11,
      "z": 5,
      "name": "Rock_Stone"
    },
    {
      "x": -6,
      "y": 12,
      "z": 5,
      "name": "Rock_Stone"
    },
    {
      "x": -6,
      "y": 10,
      "z": 6,
      "name": "Rock_Stone"
    },
    {
      "x": -6,
      "y": 11,
      "z": 6,
      "name": "Rock_Stone"
    },
    {
      "x": -6,
      "y": 10,
      "z": 7,
      "name": "Soil_Pathway"
    },
    {
      "x": -6,
      "y": 11,
      "z": 7,
      "name": "Empty"
    },
    {
      "x": -6,
      "y": 10,
      "z": 8,
      "name": "Soil_Pathway"
    },
    {
      "x": -6,
      "y": 11,
      "z": 8,
      "name": "Empty"
    },
    {
      "x": -6,
      "y": 10,
      "z": 9,
      "name": "Soil_Pathway"
    },
    {
      "x": -6,
      "y": 11,
      "z": 9,
      "name": "Empty"
    },
    {
      "x": -6,
      "y": 10,
      "z": 10,
      "name": "Soil_Pathway"
    },
    {
      "x": -6,
      "y": 11,
      "z": 10,
      "name": "Empty"
    },
    {
      "x": -6,
      "y": 10,
      "z": 11,
      "name": "Soil_Pathway"
    },
    {
      "x": -6,
      "y": 11,
      "z": 11,
      "name": "Empty"
    },
    {
      "x": -6,
      "y": 10,
      "z": 12,
      "name": "Soil_Pathway"
    },
    {
      "x": -6,
      "y": 11,
      "z": 12,
      "name": "Empty"
    },
    {
      "x": -6,
      "y": 10,
      "z": 13,
      "name": "Soil_Pathway"
    },
    {
      "x": -6,
      "y": 11,
      "z": 13,
      "name": "Empty"
    },
    {
      "x": -6,
      "y": 10,
      "z": 14,
      "name": "Soil_Dirt"
    },
    {
      "x": -6,
      "y": 11,
      "z": 14,
      "name": "Empty"
    },
    {
      "x": -6,
      "y": 10,
      "z": 15,
      "name": "Soil_Dirt"
    },
    {
      "x": -6,
      "y": 11,
      "z": 15,
      "name": "Empty"
    },
    {
      "x": -6,
      "y": 10,
      "z": 16,
      "name": "Soil_Dirt"
    },
    {
      "x": -6,
      "y": 11,
      "z": 16,
      "name": "Empty"
    },
    {
      "x": -6,
      "y": 10,
      "z": 17,
      "name": "Soil_Dirt"
    },
    {
      "x": -6,
      "y": 11,
      "z": 17,
      "name": "Empty"
    },
    {
      "x": -6,
      "y": 10,
      "z": 18,
      "name": "Soil_Dirt"
    },
    {
      "x": -6,
      "y": 11,
      "z": 18,
      "name": "Empty"
    },
    {
      "x": -6,
      "y": 10,
      "z": 19,
      "name": "Soil_Dirt"
    },
    {
      "x": -6,
      "y": 11,
      "z": 19,
      "name": "Empty"
    },
    {
      "x": -6,
      "y": 10,
      "z": 20,
      "name": "Soil_Dirt"
    },
    {
      "x": -6,
      "y": 11,
      "z": 20,
      "name": "Empty"
    },
    {
      "x": -6,
      "y": 10,
      "z": 21,
      "name": "Soil_Dirt"
    },
    {
      "x": -6,
      "y": 11,
      "z": 21,
      "name": "Empty"
    },
    {
      "x": -5,
      "y": 10,
      "z": -13,
      "name": "Rock_Stone_Cobble"
    },
    {
      "x": -5,
      "y": 11,
      "z": -13,
      "name": "Rock_Stone_Cobble"
    },
    {
      "x": -5,
      "y": 12,
      "z": -13,
      "name": "Rock_Stone_Cobble"
    },
    {
      "x": -5,
      "y": 10,
      "z": -12,
      "name": "Rock_Stone"
    },
    {
      "x": -5,
      "y": 11,
      "z": -12,
      "name": "Rock_Stone"
    },
    {
      "x": -5,
      "y": 10,
      "z": -11,
      "name": "Rock_Stone"
    },
    {
      "x": -5,
      "y": 11,
      "z": -11,
      "name": "Rock_Stone"
    },
    {
      "x": -5,
      "y": 10,
      "z": -10,
      "name": "Rock_Stone"
    },
    {
      "x": -5,
      "y": 11,
      "z": -10,
      "name": "Rock_Stone"
    },
    {
      "x": -5,
      "y": 10,
      "z": -9,
      "name": "Rock_Stone"
    },
    {
      "x": -5,
      "y": 11,
      "z": -9,
      "name": "Rock_Stone"
    },
    {
      "x": -5,
      "y": 10,
      "z": -8,
      "name": "Rock_Stone"
    },
    {
      "x": -5,
      "y": 11,
      "z": -8,
      "name": "Rock_Stone"
    },
    {
      "x": -5,
      "y": 10,
      "z": -7,
      "name": "Rock_Stone"
    },
    {
      "x": -5,
      "y": 11,
      "z": -7,
      "name": "Rock_Stone"
    },
    {
      "x": -5,
