{
  "version": 8,
  "blockIdVersion": 8,
  "anchorX": -5,
  "anchorY": 14,
  "anchorZ": 6,
  "blocks": [
    {
      "x": -9,
      "y": 4,
      "z": -3,
      "name": "Rock_Shale"
    },
    {
      "x": -9,
      "y": 5,
      "z": -3,
      "name": "Rock_Shale"
    },
    {
      "x": -9,
      "y": 6,
      "z": -3,
      "name": "Rock_Shale"
    },
    {
      "x": -9,
      "y": 7,
      "z": -3,
      "name": "Rock_Shale_Brick"
    },
    {
      "x": -9,
      "y": 8,
      "z": -3,
      "name": "Rock_Shale_Brick"
    },
    {
      "x": -9,
      "y": 9,
      "z": -3,
      "name": "Rock_Shale_Brick"
    },
    {
      "x": -9,
      "y": 10,
      "z": -3,
      "name": "Rock_Shale_Brick"
    },
    {
      "x": -9,
      "y": 11,
      "z": -3,
      "name": "Rock_Shale_Brick"
    },
    {
      "x": -9,
      "y": 12,
      "z": -3,
      "name": "Rock_Shale_Brick"
    },
    {
      "x": -9,
      "y": 13,
      "z": -3,
      "name": "Rock_Shale_Brick"
    },
    {
      "x": -9,
      "y": 14,
      "z": -3,
      "name": "Rock_Shale_Brick"
    },
    {
      "x": -9,
      "y": 15,
      "z": -3,
      "name": "Rock_Shale_Brick"
    },
    {
      "x": -9,
      "y": 3,
      "z": -2,
      "name": "Rock_Shale"
    },
    {
      "x": -9,
      "y": 4,
      "z": -2,
      "name": "Rock_Shale"
    },
    {
      "x": -9,
      "y": 5,
      "z": -2,
      "name": "Rock_Shale"
    },
    {
      "x": -9,
      "y": 6,
      "z": -2,
      "name": "Rock_Shale"
    },
    {
      "x": -9,
      "y": 7,
      "z": -2,
      "name": "Rock_Shale"
    },
    {
      "x": -9,
      "y": 8,
      "z": -2,
      "name": "Rock_Shale"
    },
    {
      "x": -9,
      "y": 9,
      "z": -2,
      "name": "Rock_Shale"
    },
    {
      "x": -9,
      "y": 10,
      "z": -2,
      "name": "Rock_Shale"
    },
    {
      "x": -9,
      "y": 11,
      "z": -2,
      "name": "Rock_Shale"
    },
    {
      "x": -9,
      "y": 12,
      "z": -2,
      "name": "Rock_Shale"
    },
    {
      "x": -9,
      "y": 13,
      "z": -2,
      "name": "Rock_Shale"
    },
    {
      "x": -9,
      "y": 14,
      "z": -2,
      "name": "Rock_Shale"
    },
    {
      "x": -9,
      "y": 15,
      "z": -2,
      "name": "Soil_Pebbles_Frozen"
    },
    {
      "x": -9,
      "y": 1,
      "z": -1,
      "name": "Rock_Shale"
    },
    {
      "x": -9,
      "y": 2,
      "z": -1,
      "name": "Rock_Shale"
    },
    {
      "x": -9,
      "y": 3,
      "z": -1,
      "name": "Rock_Shale"
    },
    {
      "x": -9,
      "y": 4,
      "z": -1,
      "name": "Rock_Shale"
    },
    {
      "x": -9,
      "y": 5,
      "z": -1,
      "name": "Rock_Shale"
    },
    {
      "x": -9,
      "y": 6,
      "z": -1,
      "name": "Rock_Shale_Brick"
    },
    {
      "x": -9,
      "y": 7,
      "z": -1,
      "name": "Rock_Shale_Brick"
    },
    {
      "x": -9,
      "y": 8,
      "z": -1,
      "name": "Rock_Shale_Brick"
    },
    {
      "x": -9,
      "y": 9,
      "z": -1,
      "name": "Rock_Shale_Brick"
    },
    {
      "x": -9,
      "y": 10,
      "z": -1,
      "name": "Rock_Shale_Brick"
    },
    {
      "x": -9,
      "y": 11,
      "z": -1,
      "name": "Rock_Shale_Brick"
    },
    {
      "x": -9,
      "y": 12,
      "z": -1,
      "name": "Rock_Shale_Brick"
    },
    {
      "x": -9,
      "y": 13,
      "z": -1,
      "name": "Rock_Shale_Brick"
    },
    {
      "x": -9,
      "y": 14,
      "z": -1,
      "name": "Rock_Shale_Brick"
    },
    {
      "x": -9,
      "y": 23,
      "z": -1,
      "name": "Empty"
    },
    {
      "x": -9,
      "y": 24,
      "z": -1,
      "name": "Empty"
    },
    {
      "x": -9,
      "y": 1,
      "z": 0,
      "name": "Rock_Shale"
    },
    {
      "x": -9,
      "y": 2,
      "z": 0,
      "name": "Rock_Shale"
    },
    {
      "x": -9,
      "y": 3,
      "z": 0,
      "name": "Rock_Shale"
    },
    {
      "x": -9,
      "y": 4,
      "z": 0,
      "name": "Rock_Shale"
    },
    {
      "x": -9,
      "y": 5,
      "z": 0,
      "name": "Rock_Shale"
    },
    {
      "x": -9,
      "y": 6,
      "z": 0,
      "name": "Rock_Shale_Cobble"
    },
    {
      "x": -9,
      "y": 7,
      "z": 0,
      "name": "Rock_Shale_Cobble"
    },
    {
      "x": -9,
      "y": 8,
      "z": 0,
      "name": "Rock_Shale_Cobble"
    },
    {
      "x": -9,
      "y": 9,
      "z": 0,
      "name": "Rock_Shale_Cobble"
    },
    {
      "x": -9,
      "y": 10,
      "z": 0,
      "name": "Rock_Shale_Cobble"
    },
    {
      "x": -9,
      "y": 11,
      "z": 0,
      "name": "Rock_Shale_Cobble"
    },
    {
      "x": -9,
      "y": 12,
      "z": 0,
      "name": "Rock_Shale_Cobble"
    },
    {
      "x": -9,
      "y": 13,
      "z": 0,
      "name": "Rock_Shale_Cobble"
    },
    {
      "x": -9,
      "y": 14,
      "z": 0,
      "name": "Rock_Shale_Cobble"
    },
    {
      "x": -9,
      "y": 22,
      "z": 0,
      "name": "Empty"
    },
    {
      "x": -9,
      "y": 23,
      "z": 0,
      "name": "Empty"
    },
    {
      "x": -9,
      "y": 24,
      "z": 0,
      "name": "Empty"
    },
    {
      "x": -9,
      "y": 25,
      "z": 0,
      "name": "Empty"
    },
    {
      "x": -9,
      "y": 1,
      "z": 1,
      "name": "Rock_Shale"
    },
    {
      "x": -9,
      "y": 2,
      "z": 1,
      "name": "Rock_Shale"
    },
    {
      "x": -9,
      "y": 3,
      "z": 1,
      "name": "Rock_Shale"
    },
    {
      "x": -9,
      "y": 4,
      "z": 1,
      "name": "Rock_Shale"
    },
    {
      "x": -9,
      "y": 5,
      "z": 1,
      "name": "Rock_Shale"
    },
    {
      "x": -9,
      "y": 6,
      "z": 1,
      "name": "Rock_Shale_Cobble"
    },
    {
      "x": -9,
      "y": 7,
      "z": 1,
      "name": "Rock_Shale_Cobble"
    },
    {
      "x": -9,
      "y": 8,
      "z": 1,
      "name": "Rock_Shale_Cobble"
    },
    {
      "x": -9,
      "y": 9,
      "z": 1,
      "name": "Rock_Shale_Brick"
    },
    {
      "x": -9,
      "y": 10,
      "z": 1,
      "name": "Rock_Shale_Brick"
    },
    {
      "x": -9,
      "y": 11,
      "z": 1,
      "name": "Rock_Shale_Brick"
    },
    {
      "x": -9,
      "y": 12,
      "z": 1,
      "name": "Rock_Shale_Brick"
    },
    {
      "x": -9,
      "y": 13,
      "z": 1,
      "name": "Rock_Shale_Brick"
    },
    {
      "x": -9,
      "y": 14,
      "z": 1,
      "name": "Rock_Shale_Brick"
    },
    {
      "x": -9,
      "y": 22,
      "z": 1,
      "name": "Empty"
    },
    {
      "x": -9,
      "y": 23,
      "z": 1,
      "name": "Empty"
    },
    {
      "x": -9,
      "y": 24,
      "z": 1,
      "name": "Empty"
    },
    {
      "x": -9,
      "y": 25,
      "z": 1,
      "name": "Empty"
    },
    {
      "x": -9,
      "y": 16,
      "z": 2,
      "name": "Empty"
    },
    {
      "x": -9,
      "y": 17,
      "z": 2,
      "name": "Empty"
    },
    {
      "x": -9,
      "y": 18,
      "z": 2,
      "name": "Empty"
    },
    {
      "x": -9,
      "y": 19,
      "z": 2,
      "name": "Empty"
    },
    {
      "x": -9,
      "y": 20,
      "z": 2,
      "name": "Empty"
    },
    {
      "x": -9,
      "y": 21,
      "z": 2,
      "name": "Empty"
    },
    {
      "x": -9,
      "y": 22,
      "z": 2,
      "name": "Empty"
    },
    {
      "x": -9,
      "y": 23,
      "z": 2,
      "name": "Empty"
    },
    {
      "x": -9,
      "y": 24,
      "z": 2,
      "name": "Empty"
    },
    {
      "x": -9,
      "y": 25,
      "z": 2,
      "name": "Empty"
    },
    {
      "x": -9,
      "y": 16,
      "z": 3,
      "name": "Empty"
    },
    {
      "x": -9,
      "y": 17,
      "z": 3,
      "name": "Empty"
    },
    {
      "x": -9,
      "y": 18,
      "z": 3,
      "name": "Empty"
    },
    {
      "x": -9,
      "y": 19,
      "z": 3,
      "name": "Empty"
    },
    {
      "x": -9,
      "y": 20,
      "z": 3,
      "name": "Empty"
    },
    {
      "x": -9,
      "y": 21,
      "z": 3,
      "name": "Empty"
    },
    {
      "x": -9,
      "y": 22,
      "z": 3,
      "name": "Empty"
    },
    {
      "x": -9,
      "y": 23,
      "z": 3,
      "name": "Empty"
    },
    {
      "x": -9,
      "y": 24,
      "z": 3,
      "name": "Empty"
    },
    {
      "x": -9,
      "y": 25,
      "z": 3,
      "name": "Empty"
    },
    {
      "x": -9,
      "y": 16,
      "z": 4,
      "name": "Empty"
    },
    {
      "x": -9,
      "y": 17,
      "z": 4,
      "name": "Empty"
    },
    {
      "x": -9,
      "y": 18,
      "z": 4,
      "name": "Empty"
    },
    {
      "x": -9,
      "y": 19,
      "z": 4,
      "name": "Empty"
    },
    {
      "x": -9,
      "y": 20,
      "z": 4,
      "name": "Empty"
    },
    {
      "x": -9,
      "y": 21,
      "z": 4,
      "name": "Empty"
    },
    {
      "x": -9,
      "y": 22,
      "z": 4,
      "name": "Empty"
    },
    {
      "x": -9,
      "y": 23,
      "z": 4,
      "name": "Empty"
    },
    {
      "x": -9,
      "y": 24,
      "z": 4,
      "name": "Empty"
    },
    {
      "x": -9,
      "y": 25,
      "z": 4,
      "name": "Empty"
    },
    {
      "x": -9,
      "y": 14,
      "z": 5,
      "name": "Empty"
    },
    {
      "x": -9,
      "y": 15,
      "z": 5,
      "name": "Empty"
    },
    {
      "x": -9,
      "y": 16,
      "z": 5,
      "name": "Empty"
    },
    {
      "x": -9,
      "y": 17,
      "z": 5,
      "name": "Empty"
    },
    {
      "x": -9,
      "y": 18,
      "z": 5,
      "name": "Empty"
    },
    {
      "x": -9,
      "y": 19,
      "z": 5,
      "name": "Empty"
    },
    {
      "x": -9,
      "y": 20,
      "z": 5,
      "name": "Empty"
    },
    {
      "x": -9,
      "y": 21,
      "z": 5,
      "name": "Empty"
    },
    {
      "x": -9,
      "y": 22,
      "z": 5,
      "name": "Empty"
    },
    {
      "x": -9,
      "y": 23,
      "z": 5,
      "name": "Empty"
    },
    {
      "x": -9,
      "y": 24,
      "z": 5,
      "name": "Empty"
    },
    {
      "x": -9,
      "y": 25,
      "z": 5,
      "name": "Empty"
    },
    {
      "x": -8,
      "y": 2,
      "z": -3,
      "name": "Rock_Shale"
    },
    {
      "x": -8,
      "y": 3,
      "z": -3,
      "name": "Rock_Shale"
    },
    {
      "x": -8,
      "y": 4,
      "z": -3,
      "name": "Rock_Shale"
    },
    {
      "x": -8,
      "y": 5,
      "z": -3,
      "name": "Rock_Shale"
    },
    {
      "x": -8,
      "y": 6,
      "z": -3,
      "name": "Rock_Shale"
    },
    {
      "x": -8,
      "y": 7,
      "z": -3,
      "name": "Rock_Shale_Brick"
    },
    {
      "x": -8,
      "y": 8,
      "z": -3,
      "name": "Rock_Shale_Brick"
    },
    {
      "x": -8,
      "y": 9,
      "z": -3,
      "name": "Rock_Shale_Brick"
    },
    {
      "x": -8,
      "y": 10,
      "z": -3,
      "name": "Rock_Shale_Brick"
    },
    {
      "x": -8,
      "y": 11,
      "z": -3,
      "name": "Rock_Shale_Brick"
    },
    {
      "x": -8,
      "y": 12,
      "z": -3,
      "name": "Rock_Shale_Brick"
    },
    {
      "x": -8,
      "y": 13,
      "z": -3,
      "name": "Rock_Shale_Brick"
    },
    {
      "x": -8,
      "y": 14,
      "z": -3,
      "name": "Rock_Shale_Brick"
    },
    {
      "x": -8,
      "y": 15,
      "z": -3,
      "name": "Rock_Shale_Brick"
    },
    {
      "x": -8,
      "y": 16,
      "z": -3,
      "name": "Rock_Shale_Cobble"
    },
    {
      "x": -8,
      "y": 17,
      "z": -3,
      "name": "Empty"
    },
    {
      "x": -8,
      "y": 18,
      "z": -3,
      "name": "Empty"
    },
    {
      "x": -8,
      "y": 19,
      "z": -3,
      "name": "Empty"
    },
    {
      "x": -8,
      "y": 20,
      "z": -3,
      "name": "Empty"
    },
    {
      "x": -8,
      "y": 21,
      "z": -3,
      "name": "Empty"
    },
    {
      "x": -8,
      "y": 22,
      "z": -3,
      "name": "Empty"
    },
    {
      "x": -8,
      "y": 1,
      "z": -2,
      "name": "Rock_Shale"
    },
    {
      "x": -8,
      "y": 2,
      "z": -2,
      "name": "Rock_Shale"
    },
    {
      "x": -8,
      "y": 3,
      "z": -2,
      "name": "Rock_Shale"
    },
    {
      "x": -8,
      "y": 4,
      "z": -2,
      "name": "Rock_Shale"
    },
    {
      "x": -8,
      "y": 5,
      "z": -2,
      "name": "Rock_Shale"
    },
    {
      "x": -8,
      "y": 6,
      "z": -2,
      "name": "Rock_Shale"
    },
    {
      "x": -8,
      "y": 7,
      "z": -2,
      "name": "Rock_Shale"
    },
    {
      "x": -8,
      "y": 8,
      "z": -2,
      "name": "Rock_Shale"
    },
    {
      "x": -8,
      "y": 9,
      "z": -2,
      "name": "Rock_Shale"
    },
    {
      "x": -8,
      "y": 10,
      "z": -2,
      "name": "Rock_Shale"
    },
    {
      "x": -8,
      "y": 11,
      "z": -2,
      "name": "Rock_Shale"
    },
    {
      "x": -8,
      "y": 12,
      "z": -2,
      "name": "Rock_Shale"
    },
    {
      "x": -8,
      "y": 13,
      "z": -2,
      "name": "Rock_Shale"
    },
    {
      "x": -8,
      "y": 14,
      "z": -2,
      "name": "Rock_Shale"
    },
    {
      "x": -8,
      "y": 15,
      "z": -2,
      "name": "Soil_Pebbles_Frozen"
    },
    {
      "x": -8,
      "y": 16,
      "z": -2,
      "name": "Empty"
    },
    {
      "x": -8,
      "y": 17,
      "z": -2,
      "name": "Empty"
    },
    {
      "x": -8,
      "y": 18,
      "z": -2,
      "name": "Empty"
    },
    {
      "x": -8,
      "y": 19,
      "z": -2,
      "name": "Empty"
    },
    {
      "x": -8,
      "y": 20,
      "z": -2,
      "name": "Empty"
    },
    {
      "x": -8,
      "y": 21,
      "z": -2,
      "name": "Empty"
    },
    {
      "x": -8,
      "y": 22,
      "z": -2,
      "name": "Empty"
    },
    {
      "x": -8,
      "y": 23,
      "z": -2,
      "name": "Empty"
    },
    {
      "x": -8,
      "y": 24,
      "z": -2,
      "name": "Empty"
    },
    {
      "x": -8,
      "y": 1,
      "z": -1,
      "name": "Rock_Shale"
    },
    {
      "x": -8,
      "y": 2,
      "z": -1,
      "name": "Rock_Shale"
    },
    {
      "x": -8,
      "y": 3,
      "z": -1,
      "name": "Rock_Shale"
    },
    {
      "x": -8,
      "y": 4,
      "z": -1,
      "name": "Rock_Shale"
    },
    {
      "x": -8,
      "y": 5,
      "z": -1,
      "name": "Rock_Shale_Brick"
    },
    {
      "x": -8,
      "y": 6,
      "z": -1,
      "name": "Rock_Shale_Brick"
    },
    {
      "x": -8,
      "y": 7,
      "z": -1,
      "name": "Rock_Shale_Brick"
    },
    {
      "x": -8,
      "y": 8,
      "z": -1,
      "name": "Rock_Shale_Brick"
    },
    {
      "x": -8,
      "y": 9,
      "z": -1,
      "name": "Rock_Shale_Brick"
    },
    {
      "x": -8,
      "y": 10,
      "z": -1,
      "name": "Rock_Shale_Brick"
    },
    {
      "x": -8,
      "y": 11,
      "z": -1,
      "name": "Rock_Shale_Brick"
    },
    {
      "x": -8,
      "y": 12,
      "z": -1,
      "name": "Rock_Shale_Brick"
    },
    {
      "x": -8,
      "y": 13,
      "z": -1,
      "name": "Rock_Shale_Brick"
    },
    {
      "x": -8,
      "y": 14,
      "z": -1,
      "name": "Soil_Pebbles_Frozen"
    },
    {
      "x": -8,
      "y": 15,
      "z": -1,
      "name": "Empty"
    },
    {
      "x": -8,
      "y": 16,
      "z": -1,
      "name": "Empty"
    },
    {
      "x": -8,
      "y": 17,
      "z": -1,
      "name": "Empty"
    },
    {
      "x": -8,
      "y": 18,
      "z": -1,
      "name": "Empty"
    },
    {
      "x": -8,
      "y": 19,
      "z": -1,
      "name": "Empty"
    },
    {
      "x": -8,
      "y": 20,
      "z": -1,
      "name": "Empty"
    },
    {
      "x": -8,
      "y": 21,
      "z": -1,
      "name": "Empty"
    },
    {
      "x": -8,
      "y": 22,
      "z": -1,
      "name": "Empty"
    },
    {
      "x": -8,
      "y": 23,
      "z": -1,
      "name": "Empty"
    },
    {
      "x": -8,
      "y": 24,
      "z": -1,
      "name": "Empty"
    },
    {
      "x": -8,
      "y": 25,
      "z": -1,
      "name": "Empty"
    },
    {
      "x": -8,
      "y": 1,
      "z": 0,
      "name": "Rock_Shale"
    },
    {
      "x": -8,
      "y": 2,
      "z": 0,
      "name": "Rock_Shale"
    },
    {
      "x": -8,
      "y": 3,
      "z": 0,
      "name": "Rock_Shale"
    },
    {
      "x": -8,
      "y": 4,
      "z": 0,
      "name": "Rock_Shale"
    },
    {
      "x": -8,
      "y": 5,
      "z": 0,
      "name": "Rock_Shale"
    },
    {
      "x": -8,
      "y": 6,
      "z": 0,
      "name": "Rock_Shale_Cobble"
    },
    {
      "x": -8,
      "y": 7,
      "z": 0,
      "name": "Rock_Shale_Cobble"
    },
    {
      "x": -8,
      "y": 8,
      "z": 0,
      "name": "Rock_Shale_Cobble"
    },
    {
      "x": -8,
      "y": 9,
      "z": 0,
      "name": "Rock_Shale_Cobble"
    },
    {
      "x": -8,
      "y": 10,
      "z": 0,
      "name": "Rock_Shale_Cobble"
    },
    {
      "x": -8,
      "y": 11,
      "z": 0,
      "name": "Rock_Shale_Cobble"
    },
    {
      "x": -8,
      "y": 12,
      "z": 0,
      "name": "Rock_Shale_Cobble"
    },
    {
      "x": -8,
      "y": 13,
      "z": 0,
      "name": "Rock_Shale_Cobble"
    },
    {
      "x": -8,
      "y": 14,
      "z": 0,
      "name": "Soil_Pebbles_Frozen"
    },
    {
      "x": -8,
      "y": 15,
      "z": 0,
      "name": "Empty"
    },
    {
      "x": -8,
      "y": 16,
      "z": 0,
      "name": "Empty"
    },
    {
      "x": -8,
      "y": 17,
      "z": 0,
      "name": "Empty"
    },
    {
      "x": -8,
      "y": 18,
      "z": 0,
      "name": "Empty"
    },
    {
      "x": -8,
      "y": 19,
      "z": 0,
      "name": "Empty"
    },
    {
      "x": -8,
      "y": 20,
      "z": 0,
      "name": "Empty"
    },
    {
      "x": -8,
      "y": 21,
      "z": 0,
      "name": "Empty"
    },
    {
      "x": -8,
      "y": 22,
      "z": 0,
      "name": "Empty"
    },
    {
      "x": -8,
      "y": 23,
      "z": 0,
      "name": "Empty"
    },
    {
      "x": -8,
      "y": 24,
      "z": 0,
      "name": "Empty"
    },
    {
      "x": -8,
      "y": 25,
      "z": 0,
      "name": "Empty"
    },
    {
      "x": -8,
      "y": 1,
      "z": 1,
      "name": "Rock_Shale"
    },
    {
      "x": -8,
      "y": 2,
      "z": 1,
      "name": "Rock_Shale"
    },
    {
      "x": -8,
      "y": 3,
      "z": 1,
      "name": "Rock_Shale"
    },
    {
      "x": -8,
      "y": 4,
      "z": 1,
      "name": "Rock_Shale"
    },
    {
      "x": -8,
      "y": 5,
      "z": 1,
      "name": "Rock_Shale_Cobble"
    },
    {
      "x": -8,
      "y": 6,
      "z": 1,
      "name": "Rock_Shale_Cobble"
    },
    {
      "x": -8,
      "y": 7,
      "z": 1,
      "name": "Rock_Shale_Cobble"
    },
    {
      "x": -8,
      "y": 8,
      "z": 1,
      "name": "Rock_Shale_Cobble"
    },
    {
      "x": -8,
      "y": 9,
      "z": 1,
      "name": "Rock_Shale_Cobble"
    },
    {
      "x": -8,
      "y": 10,
      "z": 1,
      "name": "Rock_Shale_Cobble"
    },
    {
      "x": -8,
      "y": 11,
      "z": 1,
      "name": "Rock_Shale_Brick"
    },
    {
      "x": -8,
      "y": 12,
      "z": 1,
      "name": "Rock_Shale_Brick"
    },
    {
      "x": -8,
      "y": 13,
      "z": 1,
      "name": "Rock_Shale_Brick"
    },
    {
      "x": -8,
      "y": 14,
      "z": 1,
      "name": "Rock_Shale_Brick"
    },
    {
      "x": -8,
      "y": 15,
      "z": 1,
      "name": "Empty"
    },
    {
      "x": -8,
      "y": 16,
      "z": 1,
      "name": "Empty"
    },
    {
      "x": -8,
      "y": 17,
      "z": 1,
      "name": "Empty"
    },
    {
      "x": -8,
      "y": 18,
      "z": 1,
      "name": "Empty"
    },
    {
      "x": -8,
      "y": 19,
      "z": 1,
      "name": "Empty"
    },
    {
      "x": -8,
      "y": 20,
      "z": 1,
      "name": "Empty"
    },
    {
      "x": -8,
      "y": 21,
      "z": 1,
      "name": "Empty"
    },
    {
      "x": -8,
      "y": 22,
      "z": 1,
      "name": "Empty"
    },
    {
      "x": -8,
      "y": 23,
      "z": 1,
      "name": "Empty"
    },
    {
      "x": -8,
      "y": 24,
      "z": 1,
      "name": "Empty"
    },
    {
      "x": -8,
      "y": 25,
      "z": 1,
      "name": "Empty"
    },
    {
      "x": -8,
      "y": 16,
      "z": 2,
      "name": "Empty"
    },
    {
      "x": -8,
      "y": 17,
      "z": 2,
      "name": "Empty"
    },
    {
      "x": -8,
      "y": 18,
      "z": 2,
      "name": "Empty"
    },
    {
      "x": -8,
      "y": 19,
      "z": 2,
      "name": "Empty"
    },
    {
      "x": -8,
      "y": 20,
      "z": 2,
      "name": "Empty"
    },
    {
      "x": -8,
      "y": 21,
      "z": 2,
      "name": "Empty"
    },
    {
      "x": -8,
      "y": 22,
      "z": 2,
      "name": "Empty"
    },
    {
      "x": -8,
      "y": 23,
      "z": 2,
      "name": "Empty"
    },
    {
      "x": -8,
      "y": 24,
      "z": 2,
      "name": "Empty"
    },
    {
      "x": -8,
      "y": 25,
      "z": 2,
      "name": "Empty"
    },
    {
      "x": -8,
      "y": 16,
      "z": 3,
      "name": "Empty"
    },
    {
      "x": -8,
      "y": 17,
      "z": 3,
      "name": "Empty"
    },
    {
      "x": -8,
      "y": 18,
      "z": 3,
      "name": "Empty"
    },
    {
      "x": -8,
      "y": 19,
      "z": 3,
      "name": "Empty"
    },
    {
      "x": -8,
      "y": 20,
      "z": 3,
      "name": "Empty"
    },
    {
      "x": -8,
      "y": 21,
      "z": 3,
      "name": "Empty"
    },
    {
      "x": -8,
      "y": 22,
      "z": 3,
      "name": "Empty"
    },
    {
      "x": -8,
      "y": 23,
      "z": 3,
      "name": "Empty"
    },
    {
      "x": -8,
      "y": 24,
      "z": 3,
      "name": "Empty"
    },
    {
      "x": -8,
      "y": 25,
      "z": 3,
      "name": "Empty"
    },
    {
      "x": -8,
      "y": 16,
      "z": 4,
      "name": "Empty"
    },
    {
      "x": -8,
      "y": 17,
      "z": 4,
      "name": "Empty"
    },
    {
      "x": -8,
      "y": 18,
      "z": 4,
      "name": "Empty"
    },
    {
      "x": -8,
      "y": 19,
      "z": 4,
      "name": "Empty"
    },
    {
      "x": -8,
      "y": 20,
      "z": 4,
      "name": "Empty"
    },
    {
      "x": -8,
      "y": 21,
      "z": 4,
      "name": "Empty"
    },
    {
      "x": -8,
      "y": 22,
      "z": 4,
      "name": "Empty"
    },
    {
      "x": -8,
      "y": 23,
      "z": 4,
      "name": "Empty"
    },
    {
      "x": -8,
      "y": 24,
      "z": 4,
      "name": "Empty"
    },
    {
      "x": -8,
      "y": 25,
      "z": 4,
      "name": "Empty"
    },
    {
      "x": -8,
      "y": 14,
      "z": 5,
      "name": "Empty"
    },
    {
      "x": -8,
      "y": 15,
      "z": 5,
      "name": "Empty"
    },
    {
      "x": -8,
      "y": 16,
      "z": 5,
      "name": "Empty"
    },
    {
      "x": -8,
      "y": 17,
      "z": 5,
      "name": "Empty"
    },
    {
      "x": -8,
      "y": 18,
      "z": 5,
      "name": "Empty"
    },
    {
      "x": -8,
      "y": 19,
      "z": 5,
      "name": "Empty"
    },
    {
      "x": -8,
      "y": 20,
      "z": 5,
      "name": "Empty"
    },
    {
      "x": -8,
      "y": 21,
      "z": 5,
      "name": "Empty"
    },
    {
      "x": -8,
      "y": 22,
      "z": 5,
      "name": "Empty"
    },
    {
      "x": -8,
      "y": 23,
      "z": 5,
      "name": "Empty"
    },
    {
      "x": -8,
      "y": 24,
      "z": 5,
      "name": "Empty"
    },
    {
      "x": -8,
      "y": 25,
      "z": 5,
      "name": "Empty"
    },
    {
      "x": -7,
      "y": 1,
      "z": -3,
      "name": "Rock_Shale"
    },
    {
      "x": -7,
      "y": 2,
      "z": -3,
      "name": "Rock_Shale"
    },
    {
      "x": -7,
      "y": 3,
      "z": -3,
      "name": "Rock_Shale"
    },
    {
      "x": -7,
      "y": 4,
      "z": -3,
      "name": "Rock_Shale"
    },
    {
      "x": -7,
      "y": 5,
      "z": -3,
      "name": "Rock_Shale"
    },
    {
      "x": -7,
      "y": 6,
      "z": -3,
      "name": "Rock_Shale"
    },
    {
      "x": -7,
      "y": 7,
      "z": -3,
      "name": "Rock_Shale"
    },
    {
      "x": -7,
      "y": 8,
      "z": -3,
      "name": "Rock_Shale_Cobble_Stairs",
      "rotation": 2
    },
    {
      "x": -7,
      "y": 9,
      "z": -3,
      "name": "Rock_Shale_Cobble"
    },
    {
      "x": -7,
      "y": 10,
      "z": -3,
      "name": "Rock_Shale_Cobble_Half",
      "rotation": 6
    },
    {
      "x": -7,
      "y": 11,
      "z": -3,
      "name": "Rock_Shale_Cobble_Half",
      "rotation": 6
    },
    {
      "x": -7,
      "y": 12,
      "z": -3,
      "name": "Rock_Shale_Brick"
    },
    {
      "x": -7,
      "y": 13,
      "z": -3,
      "name": "Rock_Shale_Brick"
    },
    {
      "x": -7,
      "y": 14,
      "z": -3,
      "name": "Rock_Shale_Brick"
    },
    {
      "x": -7,
      "y": 15,
      "z": -3,
      "name": "Rock_Shale_Cobble"
    },
    {
      "x": -7,
      "y": 16,
      "z": -3,
      "name": "Rock_Shale_Cobble"
    },
    {
      "x": -7,
      "y": 17,
      "z": -3,
      "name": "Rock_Shale_Brick"
    },
    {
      "x": -7,
      "y": 18,
      "z": -3,
      "name": "Empty"
    },
    {
      "x": -7,
      "y": 19,
      "z": -3,
      "name": "Empty"
    },
    {
      "x": -7,
      "y": 20,
      "z": -3,
      "name": "Empty"
    },
    {
      "x": -7,
      "y": 21,
      "z": -3,
      "name": "Empty"
    },
    {
      "x": -7,
      "y": 22,
      "z": -3,
      "name": "Empty"
    },
    {
      "x": -7,
      "y": 23,
      "z": -3,
      "name": "Empty"
    },
    {
      "x": -7,
      "y": 24,
      "z": -3,
      "name": "Empty"
    },
    {
      "x": -7,
      "y": 1,
      "z": -2,
      "name": "Rock_Shale"
    },
    {
      "x": -7,
      "y": 2,
      "z": -2,
      "name": "Rock_Shale"
    },
    {
      "x": -7,
      "y": 3,
      "z": -2,
      "name": "Rock_Shale"
    },
    {
      "x": -7,
      "y": 4,
      "z": -2,
      "name": "Rock_Shale"
    },
    {
      "x": -7,
      "y": 5,
      "z": -2,
      "name": "Rock_Shale"
    },
    {
      "x": -7,
      "y": 6,
      "z": -2,
      "name": "Rock_Shale"
    },
    {
      "x": -7,
      "y": 7,
      "z": -2,
      "name": "Rock_Shale"
    },
    {
      "x": -7,
      "y": 8,
      "z": -2,
      "name": "Rock_Shale"
    },
    {
      "x": -7,
      "y": 9,
      "z": -2,
      "name": "Rock_Shale"
    },
    {
      "x": -7,
      "y": 10,
      "z": -2,
      "name": "Rock_Shale"
    },
    {
      "x": -7,
      "y": 11,
      "z": -2,
      "name": "Rock_Shale"
    },
    {
      "x": -7,
      "y": 12,
      "z": -2,
      "name": "Rock_Shale"
    },
    {
      "x": -7,
      "y": 13,
      "z": -2,
      "name": "Rock_Shale"
    },
    {
      "x": -7,
      "y": 14,
      "z": -2,
      "name": "Rock_Shale"
    },
    {
      "x": -7,
      "y": 15,
      "z": -2,
      "name": "Soil_Pebbles_Frozen"
    },
    {
      "x": -7,
      "y": 16,
      "z": -2,
      "name": "Empty"
    },
    {
      "x": -7,
      "y": 17,
      "z": -2,
      "name": "Wood_Torch_Wall"
    },
    {
      "x": -7,
      "y": 18,
      "z": -2,
      "name": "Empty"
    },
    {
      "x": -7,
      "y": 19,
      "z": -2,
      "name": "Empty"
    },
    {
      "x": -7,
      "y": 20,
      "z": -2,
      "name": "Empty"
    },
    {
      "x": -7,
      "y": 21,
      "z": -2,
      "name": "Empty"
    },
    {
      "x": -7,
      "y": 22,
      "z": -2,
      "name": "Empty"
    },
    {
      "x": -7,
      "y": 23,
      "z": -2,
      "name": "Empty"
    },
    {
      "x": -7,
      "y": 24,
      "z": -2,
      "name": "Empty"
    },
    {
      "x": -7,
      "y": 25,
      "z": -2,
      "name": "Empty"
    },
    {
      "x": -7,
      "y": 1,
      "z": -1,
      "name": "Rock_Shale"
    },
    {
      "x": -7,
      "y": 2,
      "z": -1,
      "name": "Rock_Shale"
    },
    {
      "x": -7,
      "y": 3,
      "z": -1,
      "name": "Rock_Shale"
    },
    {
      "x": -7,
      "y": 4,
      "z": -1,
      "name": "Rock_Shale"
    },
    {
      "x": -7,
      "y": 5,
      "z": -1,
      "name": "Rock_Shale_Cobble"
    },
    {
      "x": -7,
      "y": 6,
      "z": -1,
      "name": "Rock_Shale_Brick"
    },
    {
      "x": -7,
      "y": 7,
      "z": -1,
      "name": "Rock_Shale_Brick"
    },
    {
      "x": -7,
      "y": 8,
      "z": -1,
      "name": "Rock_Shale_Brick"
    },
    {
      "x": -7,
      "y": 9,
      "z": -1,
      "name": "Rock_Shale_Brick"
    },
    {
      "x": -7,
      "y": 10,
      "z": -1,
      "name": "Rock_Shale_Brick"
    },
    {
      "x": -7,
      "y": 11,
      "z": -1,
      "name": "Rock_Shale_Brick"
    },
    {
      "x": -7,
      "y": 12,
      "z": -1,
      "name": "Rock_Shale_Brick"
    },
    {
      "x": -7,
      "y": 13,
      "z": -1,
      "name": "Rock_Shale_Brick"
    },
    {
      "x": -7,
      "y": 14,
      "z": -1,
      "name": "Rock_Shale_Brick"
    },
    {
      "x": -7,
      "y": 15,
      "z": -1,
      "name": "Soil_Pebbles_Frozen"
    },
    {
      "x": -7,
      "y": 16,
      "z": -1,
      "name": "Empty"
    },
    {
      "x": -7,
      "y": 17,
      "z": -1,
      "name": "Empty"
    },
    {
      "x": -7,
      "y": 18,
      "z": -1,
      "name": "Empty"
    },
    {
      "x": -7,
      "y": 19,
      "z": -1,
      "name": "Empty"
    },
    {
      "x": -7,
      "y": 20,
      "z": -1,
      "name": "Empty"
    },
    {
      "x": -7,
      "y": 21,
      "z": -1,
      "name": "Empty"
    },
    {
      "x": -7,
      "y": 22,
      "z": -1,
      "name": "Empty"
    },
    {
      "x": -7,
      "y": 23,
      "z": -1,
      "name": "Empty"
    },
    {
      "x": -7,
      "y": 24,
      "z": -1,
      "name": "Empty"
    },
    {
      "x": -7,
      "y": 25,
      "z": -1,
      "name": "Empty"
    },
    {
      "x": -7,
      "y": 1,
      "z": 0,
      "name": "Rock_Shale"
    },
    {
      "x": -7,
      "y": 2,
      "z": 0,
      "name": "Rock_Shale"
    },
    {
      "x": -7,
      "y": 3,
      "z": 0,
      "name": "Rock_Shale"
    },
    {
      "x": -7,
      "y": 4,
      "z": 0,
      "name": "Rock_Shale_Cobble"
    },
    {
      "x": -7,
      "y": 5,
      "z": 0,
      "name": "Rock_Shale_Cobble"
    },
    {
      "x": -7,
      "y": 6,
      "z": 0,
      "name": "Rock_Shale_Cobble"
    },
    {
      "x": -7,
      "y": 7,
      "z": 0,
      "name": "Rock_Shale_Cobble"
    },
    {
      "x": -7,
      "y": 8,
      "z": 0,
      "name": "Rock_Shale_Cobble"
    },
    {
      "x": -7,
      "y": 9,
      "z": 0,
      "name": "Rock_Shale_Cobble"
    },
    {
      "x": -7,
      "y": 10,
      "z": 0,
      "name": "Rock_Shale_Cobble"
    },
    {
      "x": -7,
      "y": 11,
      "z": 0,
      "name": "Rock_Shale_Cobble"
    },
    {
      "x": -7,
      "y": 12,
      "z": 0,
      "name": "Rock_Shale_Cobble"
    },
    {
      "x": -7,
      "y": 13,
      "z": 0,
      "name": "Rock_Shale_Cobble"
    },
    {
      "x": -7,
      "y": 14,
      "z": 0,
      "name": "Rock_Shale_Cobble"
    },
    {
      "x": -7,
      "y": 15,
      "z": 0,
      "name": "Soil_Pebbles_Frozen"
    },
    {
      "x": -7,
      "y": 16,
      "z": 0,
      "name": "Empty"
    },
    {
      "x": -7,
      "y": 17,
      "z": 0,
      "name": "Empty"
    },
    {
      "x": -7,
      "y": 18,
      "z": 0,
      "name": "Empty"
    },
    {
      "x": -7,
      "y": 19,
      "z": 0,
      "name": "Empty"
    },
    {
      "x": -7,
      "y": 20,
      "z": 0,
      "name": "Empty"
    },
    {
      "x": -7,
      "y": 21,
      "z": 0,
      "name": "Empty"
    },
    {
      "x": -7,
      "y": 22,
      "z": 0,
      "name": "Empty"
    },
    {
      "x": -7,
      "y": 23,
      "z": 0,
      "name": "Empty"
    },
    {
      "x": -7,
      "y": 24,
      "z": 0,
      "name": "Empty"
    },
    {
      "x": -7,
      "y": 25,
      "z": 0,
      "name": "Empty"
    },
    {
      "x": -7,
      "y": 1,
      "z": 1,
      "name": "Rock_Shale"
    },
    {
      "x": -7,
      "y": 2,
      "z": 1,
      "name": "Rock_Shale"
    },
    {
      "x": -7,
      "y": 3,
      "z": 1,
      "name": "Rock_Shale"
    },
    {
      "x": -7,
      "y": 4,
      "z": 1,
      "name": "Rock_Shale_Cobble"
    },
    {
      "x": -7,
      "y": 5,
      "z": 1,
      "name": "Rock_Shale_Cobble"
    },
    {
      "x": -7,
      "y": 6,
      "z": 1,
      "name": "Rock_Shale_Cobble"
    },
    {
      "x": -7,
      "y": 7,
      "z": 1,
      "name": "Rock_Shale_Brick"
    },
    {
      "x": -7,
      "y": 8,
      "z": 1,
      "name": "Rock_Shale_Brick"
    },
    {
      "x": -7,
      "y": 9,
      "z": 1,
      "name": "Rock_Shale_Brick"
    },
    {
      "x": -7,
      "y": 10,
      "z": 1,
      "name": "Rock_Shale_Brick"
    },
    {
      "x": -7,
      "y": 11,
      "z": 1,
      "name": "Rock_Shale_Brick"
    },
    {
      "x": -7,
      "y": 12,
      "z": 1,
      "name": "Rock_Shale_Brick"
    },
    {
      "x": -7,
      "y": 13,
      "z": 1,
      "name": "Rock_Shale_Brick"
    },
    {
      "x": -7,
      "y": 14,
      "z": 1,
      "name": "Rock_Shale_Brick"
    },
    {
      "x": -7,
      "y": 15,
      "z": 1,
      "name": "Empty"
    },
    {
      "x": -7,
      "y": 16,
      "z": 1,
      "name": "Empty"
    },
    {
      "x": -7,
      "y": 17,
      "z": 1,
      "name": "Empty"
    },
    {
      "x": -7,
      "y": 18,
      "z": 1,
      "name": "Empty"
    },
    {
      "x": -7,
      "y": 19,
      "z": 1,
      "name": "Empty"
    },
    {
      "x": -7,
      "y": 20,
      "z": 1,
      "name": "Empty"
    },
    {
      "x": -7,
      "y": 21,
      "z": 1,
      "name": "Empty"
    },
    {
      "x": -7,
      "y": 22,
      "z": 1,
      "name": "Empty"
    },
    {
      "x": -7,
      "y": 23,
      "z": 1,
      "name": "Empty"
    },
    {
      "x": -7,
      "y": 24,
      "z": 1,
      "name": "Empty"
    },
    {
      "x": -7,
      "y": 25,
      "z": 1,
      "name": "Empty"
    },
    {
      "x": -7,
      "y": 16,
      "z": 2,
      "name": "Empty"
    },
    {
      "x": -7,
      "y": 17,
      "z": 2,
      "name": "Empty"
    },
    {
      "x": -7,
      "y": 18,
      "z": 2,
      "name": "Empty"
    },
    {
      "x": -7,
      "y": 19,
      "z": 2,
      "name": "Empty"
    },
    {
      "x": -7,
      "y": 20,
      "z": 2,
      "name": "Empty"
    },
    {
      "x": -7,
      "y": 21,
      "z": 2,
      "name": "Empty"
    },
    {
      "x": -7,
      "y": 22,
      "z": 2,
      "name": "Empty"
    },
    {
      "x": -7,
      "y": 23,
      "z": 2,
      "name": "Empty"
    },
    {
      "x": -7,
      "y": 24,
      "z": 2,
      "name": "Empty"
    },
    {
      "x": -7,
      "y": 25,
      "z": 2,
      "name": "Empty"
    },
    {
      "x": -7,
      "y": 16,
      "z": 3,
      "name": "Empty"
    },
    {
      "x": -7,
      "y": 17,
      "z": 3,
      "name": "Empty"
    },
    {
      "x": -7,
      "y": 18,
      "z": 3,
      "name": "Empty"
    },
    {
      "x": -7,
      "y": 19,
      "z": 3,
      "name": "Empty"
    },
    {
      "x": -7,
      "y": 20,
      "z": 3,
      "name": "Empty"
    },
    {
      "x": -7,
      "y": 21,
      "z": 3,
      "name": "Empty"
    },
    {
      "x": -7,
      "y": 22,
      "z": 3,
      "name": "Empty"
    },
    {
      "x": -7,
      "y": 23,
      "z": 3,
      "name": "Empty"
    },
    {
      "x": -7,
      "y": 24,
      "z": 3,
      "name": "Empty"
    },
    {
      "x": -7,
      "y": 25,
      "z": 3,
      "name": "Empty"
    },
    {
      "x": -7,
      "y": 16,
      "z": 4,
      "name": "Empty"
    },
    {
      "x": -7,
      "y": 17,
      "z": 4,
      "name": "Empty"
    },
    {
      "x": -7,
      "y": 18,
      "z": 4,
      "name": "Empty"
    },
    {
      "x": -7,
      "y": 19,
      "z": 4,
      "name": "Empty"
    },
    {
      "x": -7,
      "y": 20,
      "z": 4,
      "name": "Empty"
    },
    {
      "x": -7,
      "y": 21,
      "z": 4,
      "name": "Empty"
    },
    {
      "x": -7,
      "y": 22,
      "z": 4,
      "name": "Empty"
    },
    {
      "x": -7,
      "y": 23,
      "z": 4,
      "name": "Empty"
    },
    {
      "x": -7,
      "y": 24,
      "z": 4,
      "name": "Empty"
    },
    {
      "x": -7,
      "y": 25,
      "z": 4,
      "name": "Empty"
    },
    {
      "x": -7,
      "y": 14,
      "z": 5,
      "name": "Empty"
    },
    {
      "x": -7,
      "y": 15,
      "z": 5,
      "name": "Empty"
    },
    {
      "x": -7,
      "y": 16,
      "z": 5,
      "name": "Empty"
    },
    {
      "x": -7,
      "y": 17,
      "z": 5,
      "name": "Empty"
    },
    {
      "x": -7,
      "y": 18,
      "z": 5,
      "name": "Empty"
    },
    {
      "x": -7,
      "y": 19,
      "z": 5,
      "name": "Empty"
    },
    {
      "x": -7,
      "y": 20,
      "z": 5,
      "name": "Empty"
    },
    {
      "x": -7,
      "y": 21,
      "z": 5,
      "name": "Empty"
    },
    {
      "x": -7,
      "y": 22,
      "z": 5,
      "name": "Empty"
    },
    {
      "x": -7,
      "y": 23,
      "z": 5,
      "name": "Empty"
    },
    {
      "x": -7,
      "y": 24,
      "z": 5,
      "name": "Empty"
    },
    {
      "x": -7,
      "y": 25,
      "z": 5,
      "name": "Empty"
    },
    {
      "x": -6,
      "y": 1,
      "z": -3,
      "name": "Rock_Shale"
    },
    {
      "x": -6,
      "y": 2,
      "z": -3,
      "name": "Rock_Shale"
    },
    {
      "x": -6,
      "y": 3,
      "z": -3,
      "name": "Rock_Shale"
    },
    {
      "x": -6,
      "y": 4,
      "z": -3,
      "name": "Rock_Shale"
    },
    {
      "x": -6,
      "y": 5,
      "z": -3,
      "name": "Rock_Shale_Cobble"
    },
    {
      "x": -6,
      "y": 6,
      "z": -3,
      "name": "Rock_Shale_Cobble"
    },
    {
      "x": -6,
      "y": 7,
      "z": -3,
      "name": "Rock_Shale_Cobble"
    },
    {
      "x": -6,
      "y": 8,
      "z": -3,
      "name": "Rock_Shale_Cobble"
    },
    {
      "x": -6,
      "y": 9,
      "z": -3,
      "name": "Rock_Shale_Cobble"
    },
    {
      "x": -6,
      "y": 10,
      "z": -3,
      "name": "Rock_Shale_Cobble_Half",
      "rotation": 6
    },
    {
      "x": -6,
      "y": 11,
      "z": -3,
      "name": "Rock_Shale_Cobble_Half",
      "rotation": 6
    },
    {
      "x": -6,
      "y": 12,
      "z": -3,
      "name": "Rock_Shale_Cobble_Half",
      "rotation": 6
    },
    {
      "x": -6,
      "y": 13,
      "z": -3,
      "name": "Rock_Shale_Cobble_Half",
      "rotation": 6
    },
    {
      "x": -6,
      "y": 14,
      "z": -3,
      "name": "Rock_Shale_Brick"
    },
    {
      "x": -6,
      "y": 15,
      "z": -3,
      "name": "Rock_Shale_Brick"
    },
    {
      "x": -6,
      "y": 16,
      "z": -3,
      "name": "Rock_Shale_Cobble"
    },
    {
      "x": -6,
      "y": 17,
      "z": -3,
      "name": "Rock_Shale_Brick"
    },
    {
      "x": -6,
      "y": 18,
      "z": -3,
      "name": "Empty"
    },
    {
      "x": -6,
      "y": 19,
      "z": -3,
      "name": "Empty"
    },
    {
      "x": -6,
      "y": 20,
      "z": -3,
      "name": "Empty"
    },
    {
      "x": -6,
      "y": 21,
      "z": -3,
      "name": "Empty"
    },
    {
      "x": -6,
      "y": 22,
      "z": -3,
      "name": "Empty"
    },
    {
      "x": -6,
      "y": 23,
      "z": -3,
      "name": "Empty"
    },
    {
      "x": -6,
      "y": 24,
      "z": -3,
      "name": "Empty"
    },
    {
      "x": -6,
      "y": 1,
      "z": -2,
      "name": "Rock_Shale"
    },
    {
      "x": -6,
      "y": 2,
      "z": -2,
      "name": "Rock_Shale"
    },
    {
      "x": -6,
      "y": 3,
      "z": -2,
      "name": "Rock_Shale"
    },
    {
      "x": -6,
      "y": 4,
      "z": -2,
      "name": "Rock_Shale"
    },
    {
      "x": -6,
      "y": 5,
      "z": -2,
      "name": "Rock_Shale"
    },
    {
      "x": -6,
      "y": 6,
      "z": -2,
      "name": "Rock_Shale"
    },
    {
      "x": -6,
      "y": 7,
      "z": -2,
      "name": "Rock_Shale"
    },
    {
      "x": -6,
      "y": 8,
      "z": -2,
      "name": "Rock_Shale"
    },
    {
      "x": -6,
      "y": 9,
      "z": -2,
      "name": "Rock_Shale"
    },
    {
      "x": -6,
      "y": 10,
      "z": -2,
      "name": "Rock_Shale"
    },
    {
      "x": -6,
      "y": 11,
      "z": -2,
      "name": "Rock_Shale"
    },
    {
      "x": -6,
      "y": 12,
      "z": -2,
      "name": "Rock_Shale"
    },
    {
      "x": -6,
      "y": 13,
      "z": -2,
      "name": "Rock_Shale"
    },
    {
      "x": -6,
      "y": 14,
      "z": -2,
      "name": "Rock_Shale"
    },
    {
      "x": -6,
      "y": 15,
      "z": -2,
      "name": "Rock_Shale"
    },
    {
      "x": -6,
      "y": 16,
      "z": -2,
      "name": "Rock_Shale"
    },
    {
      "x": -6,
      "y": 17,
      "z": -2,
      "name": "Soil_Pathway"
    },
    {
      "x": -6,
      "y": 18,
      "z": -2,
      "name": "Empty"
    },
    {
      "x": -6,
      "y": 19,
      "z": -2,
      "name": "Empty"
    },
    {
      "x": -6,
      "y": 20,
      "z": -2,
      "name": "Empty"
    },
    {
      "x": -6,
      "y": 21,
      "z": -2,
      "name": "Empty"
    },
    {
      "x": -6,
      "y": 22,
      "z": -2,
      "name": "Empty"
    },
    {
      "x": -6,
      "y": 23,
      "z": -2,
      "name": "Empty"
    },
    {
      "x": -6,
      "y": 24,
      "z": -2,
      "name": "Empty"
    },
    {
      "x": -6,
      "y": 25,
      "z": -2,
      "name": "Empty"
    },
    {
      "x": -6,
      "y": 1,
      "z": -1,
      "name": "Rock_Shale"
    },
    {
      "x": -6,
      "y": 2,
      "z": -1,
      "name": "Rock_Shale"
    },
    {
      "x": -6,
      "y": 3,
      "z": -1,
      "name": "Rock_Shale"
    },
    {
      "x": -6,
      "y": 4,
      "z": -1,
      "name": "Rock_Shale"
    },
    {
      "x": -6,
      "y": 5,
      "z": -1,
      "name": "Rock_Shale"
    },
    {
      "x": -6,
      "y": 6,
      "z": -1,
      "name": "Rock_Shale_Cobble"
    },
    {
      "x": -6,
      "y": 7,
      "z": -1,
      "name": "Rock_Shale_Brick"
    },
    {
      "x": -6,
      "y": 8,
      "z": -1,
      "name": "Rock_Shale_Brick"
    },
    {
      "x": -6,
      "y": 9,
      "z": -1,
      "name": "Rock_Shale_Brick"
    },
    {
      "x": -6,
      "y": 10,
      "z": -1,
      "name": "Rock_Shale_Brick"
    },
    {
      "x": -6,
      "y": 11,
      "z": -1,
      "name": "Rock_Shale_Brick"
    },
    {
      "x": -6,
      "y": 12,
      "z": -1,
      "name": "Rock_Shale_Brick"
    },
    {
      "x": -6,
      "y": 13,
      "z": -1,
      "name": "Rock_Shale_Brick"
    },
    {
      "x": -6,
      "y": 14,
      "z": -1,
      "name": "Rock_Shale_Brick"
    },
    {
      "x": -6,
      "y": 15,
      "z": -1,
      "name": "Rock_Shale_Brick"
    },
    {
      "x": -6,
      "y": 16,
      "z": -1,
      "name": "Soil_Pebbles_Frozen"
    },
    {
      "x": -6,
      "y": 17,
      "z": -1,
      "name": "Empty"
    },
    {
      "x": -6,
      "y": 18,
      "z": -1,
      "name": "Empty"
    },
    {
      "x": -6,
      "y": 19,
      "z": -1,
      "name": "Empty"
    },
    {
      "x": -6,
      "y": 20,
      "z": -1,
      "name": "Empty"
    },
    {
      "x": -6,
      "y": 21,
      "z": -1,
      "name": "Empty"
    },
    {
      "x": -6,
      "y": 22,
      "z": -1,
      "name": "Empty"
    },
    {
      "x": -6,
      "y": 23,
      "z": -1,
      "name": "Empty"
    },
    {
      "x": -6,
      "y": 24,
      "z": -1,
      "name": "Empty"
    },
    {
      "x": -6,
      "y": 25,
      "z": -1,
      "name": "Empty"
    },
    {
      "x": -6,
      "y": 1,
      "z": 0,
      "name": "Rock_Shale"
    },
    {
      "x": -6,
      "y": 2,
      "z": 0,
      "name": "Rock_Shale"
    },
    {
      "x": -6,
      "y": 3,
      "z": 0,
      "name": "Rock_Shale"
    },
    {
      "x": -6,
      "y": 4,
      "z": 0,
      "name": "Rock_Shale"
    },
    {
      "x": -6,
      "y": 5,
      "z": 0,
      "name": "Rock_Shale_Cobble"
    },
    {
      "x": -6,
      "y": 6,
      "z": 0,
      "name": "Rock_Shale_Cobble"
    },
    {
      "x": -6,
      "y": 7,
      "z": 0,
      "name": "Rock_Shale_Cobble"
    },
    {
      "x": -6,
      "y": 8,
      "z": 0,
      "name": "Rock_Shale_Cobble"
    },
    {
      "x": -6,
      "y": 9,
      "z": 0,
      "name": "Rock_Shale_Cobble"
    },
    {
      "x": -6,
      "y": 10,
      "z": 0,
      "name": "Rock_Shale_Cobble"
    },
    {
      "x": -6,
      "y": 11,
      "z": 0,
      "name": "Rock_Shale_Cobble"
    },
    {
      "x": -6,
      "y": 12,
      "z": 0,
      "name": "Rock_Shale_Cobble"
    },
    {
      "x": -6,
      "y": 13,
      "z": 0,
      "name": "Rock_Shale_Cobble"
    },
    {
      "x": -6,
      "y": 14,
      "z": 0,
      "name": "Rock_Shale_Cobble"
    },
    {
      "x": -6,
      "y": 15,
      "z": 0,
      "name": "Soil_Pebbles_Frozen"
    },
    {
      "x": -6,
      "y": 16,
      "z": 0,
      "name": "Empty"
    },
    {
      "x": -6,
      "y": 17,
      "z": 0,
      "name": "Empty"
    },
    {
      "x": -6,
      "y": 18,
      "z": 0,
      "name": "Empty"
    },
    {
      "x": -6,
      "y": 19,
      "z": 0,
      "name": "Empty"
    },
    {
      "x": -6,
      "y": 20,
      "z": 0,
      "name": "Empty"
    },
    {
      "x": -6,
      "y": 21,
      "z": 0,
      "name": "Empty"
    },
    {
      "x": -6,
      "y": 22,
      "z": 0,
      "name": "Empty"
    },
    {
      "x": -6,
      "y": 23,
      "z": 0,
      "name": "Empty"
    },
    {
      "x": -6,
      "y": 24,
      "z": 0,
      "name": "Empty"
    },
    {
      "x": -6,
      "y": 25,
      "z": 0,
      "name": "Empty"
    },
    {
      "x": -6,
      "y": 1,
      "z": 1,
      "name": "Rock_Shale"
    },
    {
      "x": -6,
      "y": 2,
      "z": 1,
      "name": "Rock_Shale"
    },
    {
      "x": -6,
      "y": 3,
      "z": 1,
      "name": "Rock_Shale"
    },
    {
      "x": -6,
      "y": 4,
      "z": 1,
      "name": "Rock_Shale"
    },
    {
      "x": -6,
      "y": 5,
      "z": 1,
      "name": "Rock_Shale"
    },
    {
      "x": -6,
      "y": 6,
      "z": 1,
      "name": "Rock_Shale_Brick"
    },
    {
      "x": -6,
      "y": 7,
      "z": 1,
      "name": "Rock_Shale_Brick"
    },
    {
      "x": -6,
      "y": 8,
      "z": 1,
      "name": "Rock_Shale_Brick"
    },
    {
      "x": -6,
      "y": 9,
      "z": 1,
      "name": "Rock_Shale_Brick"
    },
    {
      "x": -6,
      "y": 10,
      "z": 1,
      "name": "Rock_Shale_Brick"
    },
    {
      "x": -6,
      "y": 11,
      "z": 1,
      "name": "Rock_Shale_Brick"
    },
    {
      "x": -6,
      "y": 12,
      "z": 1,
      "name": "Rock_Shale_Brick"
    },
    {
      "x": -6,
      "y": 13,
      "z": 1,
      "name": "Rock_Shale_Brick"
    },
    {
      "x": -6,
      "y": 14,
      "z": 1,
      "name": "Rock_Shale_Brick"
    },
    {
      "x": -6,
      "y": 15,
      "z": 1,
      "name": "Rock_Shale_Brick"
    },
    {
      "x": -6,
      "y": 16,
      "z": 1,
      "name": "Empty"
    },
    {
      "x": -6,
      "y": 17,
      "z": 1,
      "name": "Empty"
    },
    {
      "x": -6,
      "y": 18,
      "z": 1,
      "name": "Empty"
    },
    {
      "x": -6,
      "y": 19,
      "z": 1,
      "name": "Empty"
    },
    {
      "x": -6,
      "y": 20,
      "z": 1,
      "name": "Empty"
    },
    {
      "x": -6,
      "y": 21,
      "z": 1,
      "name": "Empty"
    },
    {
      "x": -6,
      "y": 22,
      "z": 1,
      "name": "Empty"
    },
    {
      "x": -6,
      "y": 23,
      "z": 1,
      "name": "Empty"
    },
    {
      "x": -6,
      "y": 24,
      "z": 1,
      "name": "Empty"
    },
    {
      "x": -6,
      "y": 25,
      "z": 1,
      "name": "Empty"
    },
    {
      "x": -6,
      "y": 1,
      "z": 2,
      "name": "Rock_Shale"
    },
    {
      "x": -6,
      "y": 2,
      "z": 2,
      "name": "Rock_Shale"
    },
    {
      "x": -6,
      "y": 3,
      "z": 2,
      "name": "Rock_Shale"
    },
    {
      "x": -6,
      "y": 4,
      "z": 2,
      "name": "Rock_Shale"
    },
    {
      "x": -6,
      "y": 5,
      "z": 2,
      "name": "Rock_Shale_Cobble"
    },
    {
      "x": -6,
      "y": 6,
      "z": 2,
      "name": "Rock_Shale_Cobble"
    },
    {
      "x": -6,
      "y": 7,
      "z": 2,
      "name": "Rock_Shale_Cobble"
    },
    {
      "x": -6,
      "y": 8,
      "z": 2,
      "name": "Rock_Shale_Cobble"
    },
    {
      "x": -6,
      "y": 9,
      "z": 2,
      "name": "Rock_Shale_Cobble"
    },
    {
      "x": -6,
      "y": 10,
      "z": 2,
      "name": "Rock_Shale_Brick"
    },
    {
      "x": -6,
      "y": 11,
      "z": 2,
      "name": "Rock_Shale_Brick"
    },
    {
      "x": -6,
      "y": 12,
      "z": 2,
      "name": "Rock_Shale_Brick"
    },
    {
      "x": -6,
      "y": 16,
      "z": 2,
      "name": "Empty"
    },
    {
      "x": -6,
      "y": 17,
      "z": 2,
      "name": "Empty"
    },
    {
      "x": -6,
      "y": 18,
      "z": 2,
      "name": "Empty"
    },
    {
      "x": -6,
      "y": 19,
      "z": 2,
      "name": "Empty"
    },
    {
      "x": -6,
      "y": 20,
      "z": 2,
      "name": "Empty"
    },
    {
      "x": -6,
      "y": 21,
      "z": 2,
      "name": "Empty"
    },
    {
      "x": -6,
      "y": 22,
      "z": 2,
      "name": "Empty"
    },
    {
      "x": -6,
      "y": 23,
      "z": 2,
      "name": "Empty"
    },
    {
      "x": -6,
      "y": 24,
      "z": 2,
      "name": "Empty"
    },
    {
      "x": -6,
      "y": 25,
      "z": 2,
      "name": "Empty"
    },
    {
      "x": -6,
      "y": 1,
      "z": 3,
      "name": "Rock_Shale"
    },
    {
      "x": -6,
      "y": 2,
      "z": 3,
      "name": "Rock_Shale"
    },
    {
      "x": -6,
      "y": 3,
      "z": 3,
      "name": "Rock_Shale_Cobble"
    },
    {
      "x": -6,
      "y": 4,
      "z": 3,
      "name": "Rock_Shale_Cobble"
    },
    {
      "x": -6,
      "y": 5,
      "z": 3,
      "name": "Rock_Shale_Cobble"
    },
    {
      "x": -6,
      "y": 6,
      "z": 3,
      "name": "Rock_Shale_Cobble"
    },
    {
      "x": -6,
      "y": 7,
      "z": 3,
      "name": "Rock_Shale_Cobble"
    },
    {
      "x": -6,
      "y": 8,
      "z": 3,
      "name": "Rock_Shale_Brick"
    },
    {
      "x": -6,
      "y": 9,
      "z": 3,
      "name": "Rock_Shale_Brick"
    },
    {
      "x": -6,
      "y": 10,
      "z": 3,
      "name": "Rock_Shale_Brick"
    },
    {
      "x": -6,
      "y": 11,
      "z": 3,
      "name": "Rock_Shale_Brick"
    },
    {
      "x": -6,
      "y": 12,
      "z": 3,
      "name": "Rock_Shale_Brick"
    },
    {
      "x": -6,
      "y": 16,
      "z": 3,
      "name": "Empty"
    },
    {
      "x": -6,
      "y": 17,
      "z": 3,
      "name": "Empty"
    },
    {
      "x": -6,
      "y": 18,
      "z": 3,
      "name": "Empty"
    },
    {
      "x": -6,
      "y": 19,
      "z": 3,
      "name": "Empty"
    },
    {
      "x": -6,
      "y": 20,
      "z": 3,
      "name": "Empty"
    },
    {
      "x": -6,
      "y": 21,
      "z": 3,
      "name": "Empty"
    },
    {
      "x": -6,
      "y": 22,
      "z": 3,
      "name": "Empty"
    },
    {
      "x": -6,
      "y": 23,
      "z": 3,
      "name": "Empty"
    },
    {
      "x": -6,
      "y": 24,
      "z": 3,
      "name": "Empty"
    },
    {
      "x": -6,
      "y": 25,
      "z": 3,
      "name": "Empty"
    },
    {
      "x": -6,
      "y": 1,
      "z": 4,
      "name": "Rock_Shale_Cobble"
    },
    {
      "x": -6,
      "y": 2,
      "z": 4,
      "name": "Rock_Shale_Cobble"
    },
    {
      "x": -6,
      "y": 3,
      "z": 4,
      "name": "Rock_Shale_Cobble"
    },
    {
      "x": -6,
      "y": 4,
      "z": 4,
      "name": "Rock_Shale_Cobble"
    },
    {
      "x": -6,
      "y": 5,
      "z": 4,
      "name": "Rock_Shale_Brick"
    },
    {
      "x": -6,
      "y": 6,
      "z": 4,
      "name": "Rock_Shale_Brick"
    },
    {
      "x": -6,
      "y": 7,
      "z": 4,
      "name": "Rock_Shale_Brick"
    },
    {
      "x": -6,
      "y": 8,
      "z": 4,
      "name": "Rock_Shale_Brick"
    },
    {
      "x": -6,
      "y": 9,
      "z": 4,
      "name": "Rock_Shale_Brick"
    },
    {
      "x": -6,
      "y": 10,
      "z": 4,
      "name": "Rock_Shale_Brick"
    },
    {
      "x": -6,
      "y": 11,
      "z": 4,
      "name": "Rock_Shale_Brick"
    },
    {
      "x": -6,
      "y": 12,
      "z": 4,
      "name": "Rock_Shale_Brick"
    },
    {
      "x": -6,
      "y": 16,
      "z": 4,
      "name": "Empty"
    },
    {
      "x": -6,
      "y": 17,
      "z": 4,
      "name": "Empty"
    },
    {
      "x": -6,
      "y": 18,
      "z": 4,
      "name": "Empty"
    },
    {
      "x": -6,
      "y": 19,
      "z": 4,
      "name": "Empty"
    },
    {
      "x": -6,
      "y": 20,
      "z": 4,
      "name": "Empty"
    },
    {
      "x": -6,
      "y": 21,
      "z": 4,
      "name": "Empty"
    },
    {
      "x": -6,
      "y": 22,
      "z": 4,
      "name": "Empty"
    },
    {
      "x": -6,
      "y": 23,
      "z": 4,
      "name": "Empty"
    },
    {
      "x": -6,
      "y": 24,
      "z": 4,
      "name": "Empty"
    },
    {
      "x": -6,
      "y": 25,
      "z": 4,
      "name": "Empty"
    },
    {
      "x": -6,
      "y": 14,
      "z": 5,
      "name": "Empty"
    },
    {
      "x": -6,
      "y": 15,
      "z": 5,
      "name": "Empty"
    },
    {
      "x": -6,
      "y": 16,
      "z": 5,
      "name": "Empty"
    },
    {
      "x": -6,
      "y": 17,
      "z": 5,
      "name": "Empty"
    },
    {
      "x": -6,
      "y": 18,
      "z": 5,
      "name": "Empty"
    },
    {
      "x": -6,
      "y": 19,
      "z": 5,
      "name": "Empty"
    },
    {
      "x": -6,
      "y": 20,
      "z": 5,
      "name": "Empty"
    },
    {
      "x": -6,
      "y": 21,
      "z": 5,
      "name": "Empty"
    },
    {
      "x": -6,
      "y": 22,
      "z": 5,
      "name": "Empty"
    },
    {
      "x": -6,
      "y": 23,
      "z": 5,
      "name": "Empty"
    },
    {
      "x": -6,
      "y": 24,
      "z": 5,
      "name": "Empty"
    },
    {
      "x": -6,
      "y": 25,
      "z": 5,
      "name": "Empty"
    },
    {
      "x": -5,
      "y": 17,
      "z": -4,
      "name": "Rock_Shale_Brick"
    },
    {
      "x": -5,
      "y": 18,
      "z": -4,
      "name": "Rock_Shale_Brick"
    },
    {
      "x": -5,
      "y": 1,
      "z": -3,
      "name": "Rock_Shale"
    },
    {
      "x": -5,
      "y": 2,
      "z": -3,
      "name": "Rock_Shale"
    },
    {
      "x": -5,
      "y": 3,
      "z": -3,
      "name": "Rock_Shale"
    },
    {
      "x": -5,
      "y": 4,
      "z": -3,
      "name": "Rock_Shale"
    },
    {
      "x": -5,
      "y": 5,
      "z": -3,
      "name": "Rock_Shale"
    },
    {
      "x": -5,
      "y": 6,
      "z": -3,
      "name": "Rock_Shale_Cobble"
    },
    {
      "x": -5,
      "y": 7,
      "z": -3,
      "name": "Rock_Shale_Cobble"
    },
    {
      "x": -5,
      "y": 8,
      "z": -3,
      "name": "Rock_Shale_Cobble"
    },
    {
      "x": -5,
      "y": 9,
      "z": -3,
      "name": "Rock_Shale_Cobble_Half",
      "rotation": 6
    },
    {
      "x": -5,
      "y": 10,
      "z": -3,
      "name": "Rock_Shale_Cobble_Half",
      "rotation": 6
    },
    {
      "x": -5,
      "y": 11,
      "z": -3,
      "name": "Rock_Shale_Brick"
    },
    {
      "x": -5,
      "y": 12,
      "z": -3,
      "name": "Rock_Shale_Brick"
    },
    {
      "x": -5,
      "y": 13,
      "z": -3,
      "name": "Rock_Shale_Brick"
    },
    {
      "x": -5,
      "y": 14,
      "z": -3,
      "name": "Rock_Shale_Brick"
    },
    {
      "x": -5,
      "y": 15,
      "z": -3,
      "name": "Rock_Shale_Brick"
    },
    {
      "x": -5,
      "y": 16,
      "z": -3,
      "name": "Rock_Shale_Cobble"
    },
    {
      "x": -5,
      "y": 17,
      "z": -3,
      "name": "Rock_Shale_Brick"
    },
    {
      "x": -5,
      "y": 18,
      "z": -3,
      "name": "Rock_Shale_Brick"
    },
    {
      "x": -5,
      "y": 19,
      "z": -3,
      "name": "Soil_Grass_Cold"
    },
    {
      "x": -5,
      "y": 20,
      "z": -3,
      "name": "Plant_Fern_Forest"
    },
    {
      "x": -5,
      "y": 21,
      "z": -3,
      "name": "Empty"
    },
    {
      "x": -5,
      "y": 22,
      "z": -3,
      "name": "Empty"
    },
    {
      "x": -5,
      "y": 23,
      "z": -3,
      "name": "Empty"
    },
    {
      "x": -5,
      "y": 24,
      "z": -3,
      "name": "Empty"
    },
    {
      "x": -5,
      "y": 25,
      "z": -3,
      "name": "Empty"
    },
    {
      "x": -5,
      "y": 1,
      "z": -2,
      "name": "Rock_Shale"
    },
    {
      "x": -5,
      "y": 2,
      "z": -2,
      "name": "Rock_Shale"
    },
    {
      "x": -5,
      "y": 3,
      "z": -2,
      "name": "Rock_Shale"
    },
    {
      "x": -5,
      "y": 4,
      "z": -2,
      "name": "Rock_Shale"
    },
    {
      "x": -5,
      "y": 5,
      "z": -2,
      "name": "Rock_Shale"
    },
    {
      "x": -5,
      "y": 6,
      "z": -2,
      "name": "Rock_Shale"
    },
    {
      "x": -5,
      "y": 7,
      "z": -2,
      "name": "Rock_Shale"
    },
    {
      "x": -5,
      "y": 8,
      "z": -2,
      "name": "Rock_Shale"
    },
    {
      "x": -5,
      "y": 9,
      "z": -2,
      "name": "Rock_Shale"
    },
    {
      "x": -5,
      "y": 10,
      "z": -2,
      "name": "Rock_Shale"
    },
    {
      "x": -5,
      "y": 11,
      "z": -2,
      "name": "Rock_Shale"
    },
    {
      "x": -5,
      "y": 12,
      "z": -2,
      "name": "Rock_Shale"
    },
    {
      "x": -5,
      "y": 13,
      "z": -2,
      "name": "Rock_Shale"
    },
    {
      "x": -5,
      "y": 14,
      "z": -2,
      "name": "Rock_Shale"
    },
    {
      "x": -5,
      "y": 15,
      "z": -2,
      "name": "Rock_Shale"
    },
    {
      "x": -5,
      "y": 16,
      "z": -2,
      "name": "Rock_Shale"
    },
    {
      "x": -5,
      "y": 17,
      "z": -2,
      "name": "Rock_Shale"
    },
    {
      "x": -5,
      "y": 18,
      "z": -2,
      "name": "Soil_Pathway"
    },
    {
      "x": -5,
      "y": 19,
      "z": -2,
      "name": "Empty"
    },
    {
      "x": -5,
      "y": 20,
      "z": -2,
      "name": "Empty"
    },
    {
      "x": -5,
      "y": 21,
      "z": -2,
      "name": "Empty"
    },
    {
      "x": -5,
      "y": 22,
      "z": -2,
      "name": "Empty"
    },
    {
      "x": -5,
      "y": 23,
      "z": -2,
      "name": "Empty"
    },
    {
      "x": -5,
      "y": 24,
      "z": -2,
      "name": "Empty"
    },
    {
      "x": -5,
      "y": 25,
      "z": -2,
      "name": "Empty"
    },
    {
      "x": -5,
      "y": 1,
      "z": -1,
      "name": "Rock_Shale"
    },
    {
      "x": -5,
      "y": 2,
      "z": -1,
      "name": "Rock_Shale"
    },
    {
      "x": -5,
      "y": 3,
      "z": -1,
      "name": "Rock_Shale"
    },
    {
      "x": -5,
      "y": 4,
      "z": -1,
      "name": "Rock_Shale"
    },
    {
      "x": -5,
      "y": 5,
      "z": -1,
      "name": "Rock_Shale_Cobble"
    },
    {
      "x": -5,
      "y": 6,
      "z": -1,
      "name": "Rock_Shale_Cobble"
    },
    {
      "x": -5,
      "y": 7,
      "z": -1,
      "name": "Rock_Shale_Brick"
    },
    {
      "x": -5,
      "y": 8,
      "z": -1,
      "name": "Rock_Shale_Brick"
    },
    {
      "x": -5,
      "y": 9,
      "z": -1,
      "name": "Rock_Shale_Brick"
    },
    {
      "x": -5,
      "y": 10,
      "z": -1,
      "name": "Rock_Shale_Brick"
    },
    {
      "x": -5,
      "y": 11,
      "z": -1,
      "name": "Rock_Shale_Brick"
    },
    {
      "x": -5,
      "y": 12,
      "z": -1,
      "name": "Rock_Shale_Brick"
    },
    {
      "x": -5,
      "y": 13,
      "z": -1,
      "name": "Rock_Shale_Brick"
    },
    {
      "x": -5,
      "y": 14,
      "z": -1,
      "name": "Rock_Shale_Brick"
    },
    {
      "x": -5,
      "y": 15,
      "z": -1,
      "name": "Rock_Shale_Brick"
    },
    {
      "x": -5,
      "y": 16,
      "z": -1,
      "name": "Rock_Shale_Brick"
    },
    {
      "x": -5,
      "y": 17,
      "z": -1,
      "name": "Rock_Shale_Brick"
    },
    {
      "x": -5,
      "y": 18,
      "z": -1,
      "name": "Empty"
    },
    {
      "x": -5,
      "y": 19,
      "z": -1,
      "name": "Empty"
    },
    {
      "x": -5,
      "y": 20,
      "z": -1,
      "name": "Empty"
    },
    {
      "x": -5,
      "y": 21,
      "z": -1,
      "name": "Empty"
    },
    {
      "x": -5,
      "y": 22,
      "z": -1,
      "name": "Empty"
    },
    {
      "x": -5,
      "y": 23,
      "z": -1,
      "name": "Empty"
    },
    {
      "x": -5,
      "y": 24,
      "z": -1,
      "name": "Empty"
    },
    {
      "x": -5,
      "y": 25,
      "z": -1,
      "name": "Empty"
    },
    {
      "x": -5,
      "y": 1,
      "z": 0,
      "name": "Rock_Shale"
    },
    {
      "x": -5,
      "y": 2,
      "z": 0,
      "name": "Rock_Shale"
    },
    {
      "x": -5,
      "y": 3,
      "z": 0,
      "name": "Rock_Shale"
    },
    {
      "x": -5,
      "y": 4,
      "z": 0,
      "name": "Rock_Shale"
    },
    {
      "x": -5,
      "y": 5,
      "z": 0,
      "name": "Rock_Shale"
    },
    {
      "x": -5,
      "y": 6,
      "z": 0,
      "name": "Rock_Shale_Cobble"
    },
    {
      "x": -5,
      "y": 7,
      "z": 0,
      "name": "Rock_Shale_Cobble"
    },
    {
      "x": -5,
      "y": 8,
      "z": 0,
      "name": "Rock_Shale_Cobble"
    },
    {
      "x": -5,
      "y": 9,
      "z": 0,
      "name": "Rock_Shale_Cobble"
    },
    {
      "x": -5,
      "y": 10,
      "z": 0,
      "name": "Rock_Shale_Cobble"
    },
    {
      "x": -5,
      "y": 11,
      "z": 0,
      "name": "Rock_Shale_Cobble"
    },
    {
      "x": -5,
      "y": 12,
      "z": 0,
      "name": "Rock_Shale_Cobble"
    },
    {
      "x": -5,
      "y": 13,
      "z": 0,
      "name": "Rock_Shale_Cobble"
    },
    {
      "x": -5,
      "y": 14,
      "z": 0,
      "name": "Rock_Shale_Cobble"
    },
    {
      "x": -5,
      "y": 15,
      "z": 0,
      "name": "Soil_Pebbles_Frozen"
    },
    {
      "x": -5,
      "y": 16,
      "z": 0,
      "name": "Empty"
    },
    {
      "x": -5,
      "y": 17,
      "z": 0,
      "name": "Empty"
    },
    {
      "x": -5,
      "y": 18,
      "z": 0,
      "name": "Empty"
    },
    {
      "x": -5,
      "y": 19,
      "z": 0,
      "name": "Empty"
    },
    {
      "x": -5,
      "y": 20,
      "z": 0,
      "name": "Empty"
    },
    {
      "x": -5,
      "y": 21,
      "z": 0,
      "name": "Empty"
    },
    {
      "x": -5,
      "y": 22,
      "z": 0,
      "name": "Empty"
    },
    {
      "x": -5,
      "y": 23,
      "z": 0,
      "name": "Empty"
    },
    {
      "x": -5,
      "y": 24,
      "z": 0,
      "name": "Empty"
    },
    {
      "x": -5,
      "y": 25,
      "z": 0,
      "name": "Empty"
    },
    {
      "x": -5,
      "y": 1,
      "z": 1,
      "name": "Rock_Shale"
    },
    {
      "x": -5,
      "y": 2,
      "z": 1,
      "name": "Rock_Shale"
    },
    {
      "x": -5,
      "y": 3,
      "z": 1,
      "name": "Rock_Shale"
    },
    {
      "x": -5,
      "y": 4,
      "z": 1,
      "name": "Rock_Shale"
    },
    {
      "x": -5,
      "y": 5,
      "z": 1,
      "name": "Rock_Shale"
    },
    {
      "x": -5,
      "y": 6,
      "z": 1,
      "name": "Rock_Shale_Cobble"
    },
    {
      "x": -5,
      "y": 7,
      "z": 1,
      "name": "Rock_Shale_Cobble"
    },
    {
      "x": -5,
      "y": 8,
      "z": 1,
      "name": "Rock_Shale_Cobble"
    },
    {
      "x": -5,
      "y": 9,
      "z": 1,
      "name": "Rock_Shale_Brick"
    },
    {
      "x": -5,
      "y": 10,
      "z": 1,
      "name": "Rock_Shale_Brick"
    },
    {
      "x": -5,
      "y": 11,
      "z": 1,
      "name": "Rock_Shale_Brick"
    },
    {
      "x": -5,
      "y": 12,
      "z": 1,
      "name": "Rock_Shale_Brick"
    },
    {
      "x": -5,
      "y": 13,
      "z": 1,
      "name": "Rock_Shale_Brick"
    },
    {
      "x": -5,
      "y": 14,
      "z": 1,
      "name": "Rock_Shale_Brick"
    },
    {
      "x": -5,
      "y": 15,
      "z": 1,
      "name": "Rock_Shale_Brick"
    },
    {
      "x": -5,
      "y": 16,
      "z": 1,
      "name": "Empty"
    },
    {
      "x": -5,
      "y": 17,
      "z": 1,
      "name": "Empty"
    },
    {
      "x": -5,
      "y": 18,
      "z": 1,
      "name": "Empty"
    },
    {
      "x": -5,
      "y": 19,
      "z": 1,
      "name": "Empty"
    },
    {
      "x": -5,
      "y": 20,
      "z": 1,
      "name": "Empty"
    },
    {
      "x": -5,
      "y": 21,
      "z": 1,
      "name": "Empty"
    },
    {
      "x": -5,
      "y": 22,
      "z": 1,
      "name": "Empty"
    },
    {
      "x": -5,
      "y": 23,
      "z": 1,
      "name": "Empty"
    },
    {
      "x": -5,
      "y": 24,
      "z": 1,
      "name": "Empty"
    },
    {
      "x": -5,
      "y": 25,
      "z": 1,
      "name": "Empty"
    },
    {
      "x": -5,
      "y": 16,
      "z": 2,
      "name": "Empty"
    },
    {
      "x": -5,
      "y": 17,
      "z": 2,
      "name": "Empty"
    },
    {
      "x": -5,
      "y": 18,
      "z": 2,
      "name": "Empty"
    },
    {
      "x": -5,
      "y": 19,
      "z": 2,
      "name": "Empty"
    },
    {
      "x": -5,
      "y": 20,
      "z": 2,
      "name": "Empty"
    },
    {
      "x": -5,
      "y": 21,
      "z": 2,
      "name": "Empty"
    },
    {
      "x": -5,
      "y": 22,
      "z": 2,
      "name": "Empty"
    },
    {
      "x": -5,
      "y": 23,
      "z": 2,
      "name": "Empty"
    },
    {
      "x": -5,
      "y": 24,
      "z": 2,
      "name": "Empty"
    },
    {
      "x": -5,
      "y": 25,
      "z": 2,
      "name": "Empty"
    },
    {
      "x": -5,
      "y": 16,
      "z": 3,
      "name": "Empty"
    },
    {
      "x": -5,
      "y": 17,
      "z": 3,
      "name": "Empty"
    },
    {
      "x": -5,
      "y": 18,
      "z": 3,
      "name": "Empty"
    },
    {
      "x": -5,
      "y": 19,
      "z": 3,
      "name": "Empty"
    },
    {
      "x": -5,
      "y": 20,
      "z": 3,
      "name": "Empty"
    },
    {
      "x": -5,
      "y": 21,
      "z": 3,
      "name": "Empty"
    },
    {
      "x": -5,
      "y": 22,
      "z": 3,
      "name": "Empty"
    },
    {
      "x": -5,
      "y": 23,
      "z": 3,
      "name": "Empty"
    },
    {
      "x": -5,
      "y": 24,
      "z": 3,
      "name": "Empty"
    },
    {
      "x": -5,
      "y": 25,
      "z": 3,
      "name": "Empty"
    },
    {
      "x": -5,
      "y": 1,
      "z": 4,
      "name": "Rock_Shale_Cobble"
    },
    {
      "x": -5,
      "y": 2,
      "z": 4,
      "name": "Rock_Shale_Cobble"
    },
    {
      "x": -5,
      "y": 3,
      "z": 4,
      "name": "Rock_Shale_Cobble"
    },
    {
      "x": -5,
      "y": 4,
      "z": 4,
      "name": "Rock_Shale_Cobble"
    },
    {
      "x": -5,
      "y": 5,
      "z": 4,
      "name": "Rock_Shale_Brick"
    },
    {
      "x": -5,
      "y": 6,
      "z": 4,
      "name": "Rock_Shale_Brick"
    },
    {
      "x": -5,
      "y": 7,
      "z": 4,
      "name": "Rock_Shale_Brick"
    },
    {
      "x": -5,
      "y": 8,
      "z": 4,
      "name": "Rock_Shale_Brick"
    },
    {
      "x": -5,
      "y": 9,
      "z": 4,
      "name": "Rock_Shale_Brick"
    },
    {
      "x": -5,
      "y": 10,
      "z": 4,
      "name": "Rock_Shale_Brick"
    },
    {
      "x": -5,
      "y": 11,
      "z": 4,
      "name": "Rock_Shale_Brick"
    },
    {
      "x": -5,
      "y": 12,
      "z": 4,
      "name": "Rock_Shale_Brick"
    },
    {
      "x": -5,
      "y": 16,
      "z": 4,
      "name": "Empty"
    },
    {
      "x": -5,
      "y": 17,
      "z": 4,
      "name": "Empty"
    },
    {
      "x": -5,
      "y": 18,
      "z": 4,
      "name": "Empty"
    },
    {
      "x": -5,
      "y": 19,
      "z": 4,
      "name": "Empty"
    },
    {
      "x": -5,
      "y": 20,
      "z": 4,
      "name": "Empty"
    },
    {
      "x": -5,
      "y": 21,
      "z": 4,
      "name": "Empty"
    },
    {
      "x": -5,
      "y": 22,
      "z": 4,
      "name": "Empty"
    },
    {
      "x": -5,
      "y": 23,
      "z": 4,
      "name": "Empty"
    },
    {
      "x": -5,
      "y": 24,
      "z": 4,
      "name": "Empty"
    },
    {
      "x": -5,
      "y": 25,
      "z": 4,
      "name": "Empty"
    },
    {
      "x": -5,
      "y": 14,
      "z": 5,
      "name": "Rock_Shale_Brick_Half",
      "rotation": 7
    },
    {
      "x": -5,
      "y": 15,
      "z": 5,
      "name": "Empty"
    },
    {
      "x": -5,
      "y": 16,
      "z": 5,
      "name": "Empty"
    },
    {
      "x": -5,
      "y": 17,
      "z": 5,
      "name": "Empty"
    },
    {
      "x": -5,
      "y": 18,
      "z": 5,
      "name": "Empty"
    },
    {
      "x": -5,
      "y": 19,
      "z": 5,
      "name": "Empty"
    },
    {
      "x": -5,
      "y": 20,
      "z": 5,
      "name": "Empty"
    },
    {
      "x": -5,
      "y": 21,
      "z": 5,
      "name": "Empty"
    },
    {
      "x": -5,
      "y": 22,
      "z": 5,
      "name": "Empty"
    },
    {
      "x": -5,
      "y": 23,
      "z": 5,
      "name": "Empty"
    },
    {
      "x": -5,
      "y": 24,
      "z": 5,
      "name": "Empty"
    },
    {
      "x": -5,
      "y": 25,
      "z": 5,
      "name": "Empty"
    },
    {
      "x": -4,
      "y": 19,
      "z": -5,
      "name": "Plant_Moss_Wall_Green",
      "rotation": 2
    },
    {
      "x": -4,
      "y": 17,
      "z": -4,
      "name": "Rock_Shale_Brick"
    },
    {
      "x": -4,
      "y": 18,
      "z": -4,
      "name": "Rock_Shale_Brick"
    },
    {
      "x": -4,
      "y": 19,
      "z": -4,
      "name": "Soil_Grass_Cold"
    },
    {
      "x": -4,
      "y": 20,
      "z": -4,
      "name": "Plant_Moss_Rug_Green"
    },
    {
      "x": -4,
      "y": 1,
      "z": -3,
      "name": "Rock_Shale"
    },
    {
      "x": -4,
      "y": 2,
      "z": -3,
      "name": "Rock_Shale"
    },
    {
      "x": -4,
      "y": 3,
      "z": -3,
      "name": "Rock_Shale"
    },
    {
      "x": -4,
      "y": 4,
      "z": -3,
      "name": "Rock_Shale"
    },
    {
      "x": -4,
      "y": 5,
      "z": -3,
      "name": "Rock_Shale"
    },
    {
      "x": -4,
      "y": 6,
      "z": -3,
      "name": "Rock_Shale"
    },
    {
      "x": -4,
      "y": 7,
      "z": -3,
      "name": "Rock_Shale_Cobble"
    },
    {
      "x": -4,
      "y": 8,
      "z": -3,
      "name": "Rock_Shale_Cobble"
    },
    {
      "x": -4,
      "y": 9,
      "z": -3,
      "name": "Rock_Shale_Brick"
    },
    {
      "x": -4,
      "y": 10,
      "z": -3,
      "name": "Rock_Shale_Brick"
    },
    {
      "x": -4,
      "y": 11,
      "z": -3,
      "name": "Rock_Shale_Brick"
    },
    {
      "x": -4,
      "y": 12,
      "z": -3,
      "name": "Rock_Shale_Brick"
    },
    {
      "x": -4,
      "y": 13,
      "z": -3,
      "name": "Rock_Shale_Brick"
    },
    {
      "x": -4,
      "y": 14,
      "z": -3,
      "name": "Rock_Shale_Brick"
    },
    {
      "x": -4,
      "y": 15,
      "z": -3,
      "name": "Rock_Shale_Brick"
    },
    {
      "x": -4,
      "y": 16,
      "z": -3,
      "name": "Rock_Shale_Cobble"
    },
    {
      "x": -4,
      "y": 17,
      "z": -3,
      "name": "Rock_Shale_Brick"
    },
    {
      "x": -4,
      "y": 18,
      "z": -3,
      "name": "Rock_Shale_Brick"
    },
    {
      "x": -4,
      "y": 19,
      "z": -3,
      "name": "Soil_Grass_Cold"
    },
    {
      "x": -4,
      "y": 20,
      "z": -3,
      "name": "Plant_Fern_Winter"
    },
    {
      "x": -4,
      "y": 21,
      "z": -3,
      "name": "Empty"
    },
    {
      "x": -4,
      "y": 22,
      "z": -3,
      "name": "Empty"
    },
    {
      "x": -4,
      "y": 23,
      "z": -3,
      "name": "Empty"
    },
    {
      "x": -4,
      "y": 24,
      "z": -3,
      "name": "Empty"
    },
    {
      "x": -4,
      "y": 25,
      "z": -3,
      "name": "Empty"
    },
    {
      "x": -4,
      "y": 1,
      "z": -2,
      "name": "Rock_Shale"
    },
    {
      "x": -4,
      "y": 2,
      "z": -2,
      "name": "Rock_Shale"
    },
    {
      "x": -4,
      "y": 3,
      "z": -2,
      "name": "Rock_Shale"
    },
    {
      "x": -4,
      "y": 4,
      "z": -2,
      "name": "Rock_Shale"
    },
    {
      "x": -4,
      "y": 5,
      "z": -2,
      "name": "Rock_Shale"
    },
    {
      "x": -4,
      "y": 6,
      "z": -2,
      "name": "Rock_Shale"
    },
    {
      "x": -4,
      "y": 7,
      "z": -2,
      "name": "Rock_Shale"
    },
    {
      "x": -4,
      "y": 8,
      "z": -2,
      "name": "Rock_Shale"
    },
    {
      "x": -4,
      "y": 9,
      "z": -2,
      "name": "Rock_Shale"
    },
    {
      "x": -4,
      "y": 10,
      "z": -2,
      "name": "Rock_Shale"
    },
    {
      "x": -4,
      "y": 11,
      "z": -2,
      "name": "Rock_Shale"
    },
    {
      "x": -4,
      "y": 12,
      "z": -2,
      "name": "Rock_Shale"
    },
    {
      "x": -4,
      "y": 13,
      "z": -2,
      "name": "Rock_Shale"
    },
    {
      "x": -4,
      "y": 14,
      "z": -2,
      "name": "Rock_Shale"
    },
    {
      "x": -4,
      "y": 15,
      "z": -2,
      "name": "Rock_Shale"
    },
    {
      "x": -4,
      "y": 16,
      "z": -2,
      "name": "Rock_Shale"
    },
    {
      "x": -4,
      "y": 17,
      "z": -2,
      "name": "Rock_Shale"
    },
    {
      "x": -4,
      "y": 18,
      "z": -2,
      "name": "Rock_Shale"
    },
    {
      "x": -4,
      "y": 19,
      "z": -2,
      "name": "Soil_Pathway"
    },
    {
      "x": -4,
      "y": 20,
      "z": -2,
      "name": "Plant_Moss_Rug_Lime"
    },
    {
      "x": -4,
      "y": 21,
      "z": -2,
      "name": "Empty"
    },
    {
      "x": -4,
      "y": 22,
      "z": -2,
      "name": "Empty"
    },
    {
      "x": -4,
      "y": 23,
      "z": -2,
      "name": "Empty"
    },
    {
      "x": -4,
      "y": 24,
      "z": -2,
      "name": "Empty"
    },
    {
      "x": -4,
      "y": 25,
      "z": -2,
      "name": "Empty"
    },
    {
      "x": -4,
      "y": 1,
      "z": -1,
      "name": "Rock_Shale"
    },
    {
      "x": -4,
      "y": 2,
      "z": -1,
      "name": "Rock_Shale"
    },
    {
      "x": -4,
      "y": 3,
      "z": -1,
      "name": "Rock_Shale"
    },
    {
      "x": -4,
      "y": 4,
      "z": -1,
      "name": "Rock_Shale_Cobble"
    },
    {
      "x": -4,
      "y": 5,
      "z": -1,
      "name": "Rock_Shale_Cobble"
    },
    {
      "x": -4,
      "y": 6,
      "z": -1,
      "name": "Rock_Shale_Cobble"
    },
    {
      "x": -4,
      "y": 7,
      "z": -1,
      "name": "Rock_Shale_Brick"
    },
    {
      "x": -4,
      "y": 8,
      "z": -1,
      "name": "Rock_Shale_Brick"
    },
    {
      "x": -4,
      "y": 9,
      "z": -1,
      "name": "Rock_Shale_Brick"
    },
    {
      "x": -4,
      "y": 10,
      "z": -1,
      "name": "Rock_Shale_Brick"
    },
    {
      "x": -4,
      "y": 11,
      "z": -1,
      "name": "Rock_Shale_Brick"
    },
    {
      "x": -4,
      "y": 12,
      "z": -1,
      "name": "Rock_Shale_Brick"
    },
    {
      "x": -4,
      "y": 13,
      "z": -1,
      "name": "Rock_Shale_Brick"
    },
    {
      "x": -4,
      "y": 14,
      "z": -1,
      "name": "Rock_Shale_Brick"
    },
    {
      "x": -4,
      "y": 15,
      "z": -1,
      "name": "Rock_Shale_Brick"
    },
    {
      "x": -4,
      "y": 16,
      "z": -1,
      "name": "Rock_Shale_Brick"
    },
    {
      "x": -4,
      "y": 17,
      "z": -1,
      "name": "Rock_Shale_Brick"
    },
    {
      "x": -4,
      "y": 18,
      "z": -1,
      "name": "Soil_Pathway"
    },
    {
      "x": -4,
      "y": 19,
      "z": -1,
      "name": "Soil_Pathway"
    },
    {
      "x": -4,
      "y": 20,
      "z": -1,
      "name": "Empty"
    },
    {
      "x": -4,
      "y": 21,
      "z": -1,
      "name": "Empty"
    },
    {
      "x": -4,
      "y": 22,
      "z": -1,
      "name": "Empty"
    },
    {
      "x": -4,
      "y": 23,
      "z": -1,
      "name": "Empty"
    },
    {
      "x": -4,
      "y": 24,
      "z": -1,
      "name": "Empty"
    },
    {
      "x": -4,
      "y": 25,
      "z": -1,
      "name": "Empty"
    },
    {
      "x": -4,
      "y": 1,
      "z": 0,
      "name": "Rock_Shale"
    },
    {
      "x": -4,
      "y": 2,
      "z": 0,
      "name": "Rock_Shale"
    },
    {
      "x": -4,
      "y": 3,
      "z": 0,
      "name": "Rock_Shale"
    },
    {
      "x": -4,
      "y": 4,
      "z": 0,
      "name": "Rock_Shale"
    },
    {
      "x": -4,
      "y": 5,
      "z": 0,
      "name": "Rock_Shale_Cobble"
    },
    {
      "x": -4,
      "y": 6,
      "z": 0,
      "name": "Rock_Shale_Cobble"
    },
    {
      "x": -4,
      "y": 7,
      "z": 0,
      "name": "Rock_Shale_Cobble"
    },
    {
      "x": -4,
      "y": 8,
      "z": 0,
      "name": "Rock_Shale_Cobble"
    },
    {
      "x": -4,
      "y": 9,
      "z": 0,
      "name": "Rock_Shale_Cobble"
    },
    {
      "x": -4,
      "y": 10,
      "z": 0,
      "name": "Rock_Shale_Cobble"
    },
    {
      "x": -4,
      "y": 11,
      "z": 0,
      "name": "Rock_Shale_Cobble"
    },
    {
      "x": -4,
      "y": 12,
      "z": 0,
      "name": "Rock_Shale_Cobble"
    },
    {
      "x": -4,
      "y": 13,
      "z": 0,
      "name": "Rock_Shale_Cobble"
    },
    {
      "x": -4,
      "y": 14,
      "z": 0,
      "name": "Rock_Shale_Cobble"
    },
    {
      "x": -4,
      "y": 15,
      "z": 0,
      "name": "Rock_Shale_Cobble"
    },
    {
      "x": -4,
      "y": 16,
      "z": 0,
      "name": "Rock_Shale_Brick_Smooth"
    },
    {
      "x": -4,
      "y": 17,
      "z": 0,
      "name": "Empty"
    },
    {
      "x": -4,
      "y": 18,
      "z": 0,
      "name": "Empty"
    },
    {
      "x": -4,
      "y": 20,
      "z": 0,
      "name": "Empty"
    },
    {
      "x": -4,
      "y": 21,
      "z": 0,
      "name": "Empty"
    },
    {
      "x": -4,
      "y": 22,
      "z": 0,
      "name": "Empty"
    },
    {
      "x": -4,
      "y": 23,
      "z": 0,
      "name": "Empty"
    },
    {
      "x": -4,
      "y": 24,
      "z": 0,
      "name": "Empty"
    },
    {
      "x": -4,
      "y": 25,
      "z": 0,
      "name": "Empty"
    },
    {
      "x": -4,
      "y": 1,
      "z": 1,
      "name": "Rock_Shale"
    },
    {
      "x": -4,
      "y": 2,
      "z": 1,
      "name": "Rock_Shale"
    },
    {
      "x": -4,
      "y": 3,
      "z": 1,
      "name": "Rock_Shale"
    },
    {
      "x": -4,
      "y": 4,
      "z": 1,
      "name": "Rock_Shale"
    },
    {
      "x": -4,
      "y": 5,
      "z": 1,
      "name": "Rock_Shale"
    },
    {
      "x": -4,
      "y": 6,
      "z": 1,
      "name": "Rock_Shale_Brick"
    },
    {
      "x": -4,
      "y": 7,
      "z": 1,
      "name": "Rock_Shale_Cobble"
    },
    {
      "x": -4,
      "y": 8,
      "z": 1,
      "name": "Rock_Shale_Brick"
    },
    {
      "x": -4,
      "y": 9,
      "z": 1,
      "name": "Rock_Shale_Brick"
    },
    {
      "x": -4,
      "y": 10,
      "z": 1,
      "name": "Rock_Shale_Brick"
    },
    {
      "x": -4,
      "y": 11,
      "z": 1,
      "name": "Rock_Shale_Brick"
    },
    {
      "x": -4,
      "y": 12,
      "z": 1,
      "name": "Rock_Shale_Brick"
    },
    {
      "x": -4,
      "y": 13,
      "z": 1,
      "name": "Rock_Shale_Brick"
    },
    {
      "x": -4,
      "y": 14,
      "z": 1,
      "name": "Rock_Shale_Brick"
    },
    {
      "x": -4,
      "y": 15,
      "z": 1,
      "name": "Rock_Shale_Brick"
    },
    {
      "x": -4,
      "y": 16,
      "z": 1,
      "name": "Rock_Shale_Brick_Smooth"
    },
    {
      "x": -4,
      "y": 17,
      "z": 1,
      "name": "Empty"
    },
    {
      "x": -4,
      "y": 18,
      "z": 1,
      "name": "Empty"
    },
    {
      "x": -4,
      "y": 19,
      "z": 1,
      "name": "Empty"
    },
    {
      "x": -4,
      "y": 20,
      "z": 1,
      "name": "Empty"
    },
    {
      "x": -4,
      "y": 21,
      "z": 1,
      "name": "Empty"
    },
    {
      "x": -4,
      "y": 22,
      "z": 1,
      "name": "Empty"
    },
    {
      "x": -4,
      "y": 23,
      "z": 1,
      "name": "Empty"
    },
    {
      "x": -4,
      "y": 24,
      "z": 1,
      "name": "Empty"
    },
    {
      "x": -4,
      "y": 25,
      "z": 1,
      "name": "Empty"
    },
    {
      "x": -4,
      "y": 16,
      "z": 2,
      "name": "Empty"
    },
    {
      "x": -4,
      "y": 17,
      "z": 2,
      "name": "Empty"
    },
    {
      "x": -4,
      "y": 18,
      "z": 2,
      "name": "Empty"
    },
    {
      "x": -4,
      "y": 19,
      "z": 2,
      "name": "Empty"
    },
    {
      "x": -4,
      "y": 20,
      "z": 2,
      "name": "Empty"
    },
    {
      "x": -4,
      "y": 21,
      "z": 2,
      "name": "Empty"
    },
    {
      "x": -4,
      "y": 22,
      "z": 2,
      "name": "Empty"
    },
    {
      "x": -4,
      "y": 23,
      "z": 2,
      "name": "Empty"
    },
    {
      "x": -4,
      "y": 24,
      "z": 2,
      "name": "Empty"
    },
    {
      "x": -4,
      "y": 25,
      "z": 2,
      "name": "Empty"
    },
    {
      "x": -4,
      "y": 16,
      "z": 3,
      "name": "Empty"
    },
    {
      "x": -4,
      "y": 17,
      "z": 3,
      "name": "Empty"
    },
    {
      "x": -4,
      "y": 18,
      "z": 3,
      "name": "Empty"
    },
    {
      "x": -4,
      "y": 19,
      "z": 3,
      "name": "Empty"
    },
    {
      "x": -4,
      "y": 20,
      "z": 3,
      "name": "Empty"
    },
    {
      "x": -4,
      "y": 21,
      "z": 3,
      "name": "Empty"
    },
    {
      "x": -4,
      "y": 22,
      "z": 3,
      "name": "Empty"
    },
    {
      "x": -4,
      "y": 23,
      "z": 3,
      "name": "Empty"
    },
    {
      "x": -4,
      "y": 24,
      "z": 3,
      "name": "Empty"
    },
    {
      "x": -4,
      "y": 25,
      "z": 3,
      "name": "Empty"
    },
    {
      "x": -4,
      "y": 1,
      "z": 4,
      "name": "Rock_Shale_Cobble"
    },
    {
      "x": -4,
      "y": 2,
      "z": 4,
      "name": "Rock_Shale_Cobble"
    },
    {
      "x": -4,
      "y": 3,
      "z": 4,
      "name": "Rock_Shale_Cobble"
    },
    {
      "x": -4,
      "y": 4,
      "z": 4,
      "name": "Rock_Shale_Cobble"
    },
    {
      "x": -4,
      "y": 5,
      "z": 4,
      "name": "Rock_Shale_Brick"
    },
    {
      "x": -4,
      "y": 6,
      "z": 4,
      "name": "Rock_Shale_Brick"
    },
    {
      "x": -4,
      "y": 7,
      "z": 4,
      "name": "Rock_Shale_Brick"
    },
    {
      "x": -4,
      "y": 8,
      "z": 4,
      "name": "Rock_Shale_Brick"
    },
    {
      "x": -4,
      "y": 9,
      "z": 4,
      "name": "Rock_Shale_Brick"
    },
    {
      "x": -4,
      "y": 10,
      "z": 4,
      "name": "Rock_Shale_Brick"
    },
    {
      "x": -4,
      "y": 11,
      "z": 4,
      "name": "Rock_Shale_Brick"
    },
    {
      "x": -4,
      "y": 12,
      "z": 4,
      "name": "Rock_Shale_Brick"
    },
    {
      "x": -4,
      "y": 13,
      "z": 4,
      "name": "Rock_Shale_Brick"
    },
    {
      "x": -4,
      "y": 14,
      "z": 4,
      "name": "Rock_Shale_Brick_Stairs",
      "rotation": 3
    },
    {
      "x": -4,
      "y": 15,
      "z": 4,
      "name": "Rock_Shale_Brick_Half",
      "rotation": 7
    },
    {
      "x": -4,
      "y": 16,
      "z": 4,
      "name": "Rock_Shale_Brick_Half",
      "rotation": 7
    },
    {
      "x": -4,
      "y": 17,
      "z": 4,
      "name": "Rock_Shale_Brick_Half",
      "rotation": 7
    },
    {
      "x": -4,
      "y": 18,
      "z": 4,
      "name": "Empty"
    },
    {
      "x": -4,
      "y": 19,
      "z": 4,
      "name": "Empty"
    },
    {
      "x": -4,
      "y": 20,
      "z": 4,
      "name": "Empty"
    },
    {
      "x": -4,
      "y": 21,
      "z": 4,
      "name": "Empty"
    },
    {
      "x": -4,
      "y": 22,
      "z": 4,
      "name": "Empty"
    },
    {
      "x": -4,
      "y": 23,
      "z": 4,
      "name": "Empty"
    },
    {
      "x": -4,
      "y": 24,
      "z": 4,
      "name": "Empty"
    },
    {
      "x": -4,
      "y": 25,
      "z": 4,
      "name": "Empty"
    },
    {
      "x": -4,
      "y": 1,
      "z": 5,
      "name": "Rock_Shale_Cobble"
    },
    {
      "x": -4,
      "y": 2,
      "z": 5,
      "name": "Rock_Shale_Cobble"
    },
    {
      "x": -4,
      "y": 3,
      "z": 5,
      "name": "Rock_Shale_Cobble"
    },
    {
      "x": -4,
      "y": 4,
      "z": 5,
      "name": "Rock_Shale_Cobble"
    },
    {
      "x": -4,
      "y": 5,
      "z": 5,
      "name": "Rock_Shale_Brick"
    },
    {
      "x": -4,
      "y": 6,
      "z": 5,
      "name": "Rock_Shale_Brick"
    },
    {
      "x": -4,
      "y": 7,
      "z": 5,
      "name": "Rock_Shale_Brick"
    },
    {
      "x": -4,
      "y": 8,
      "z": 5,
      "name": "Rock_Shale_Brick"
    },
    {
      "x": -4,
      "y": 9,
      "z": 5,
      "name": "Rock_Shale_Brick"
    },
    {
      "x": -4,
      "y": 10,
      "z": 5,
      "name": "Rock_Shale_Brick"
    },
    {
      "x": -4,
      "y": 11,
      "z": 5,
      "name": "Rock_Shale_Brick"
    },
    {
      "x": -4,
      "y": 12,
      "z": 5,
      "name": "Rock_Shale_Brick"
    },
    {
      "x": -4,
      "y": 13,
      "z": 5,
      "name": "Rock_Shale_Brick_Stairs",
      "rotation": 3
    },
    {
      "x": -4,
      "y": 14,
      "z": 5,
      "name": "Rock_Shale_Brick_Half",
      "rotation": 7
    },
    {
      "x": -4,
      "y": 15,
      "z": 5,
      "name": "Rock_Shale_Brick_Half",
      "rotation": 7
    },
    {
      "x": -4,
      "y": 16,
      "z": 5,
      "name": "Empty"
    },
    {
      "x": -4,
      "y": 17,
      "z": 5,
      "name": "Empty"
    },
    {
      "x": -4,
      "y": 18,
      "z": 5,
      "name": "Empty"
    },
    {
      "x": -4,
      "y": 19,
      "z": 5,
      "name": "Empty"
    },
    {
      "x": -4,
      "y": 20,
      "z": 5,
      "name": "Empty"
    },
    {
      "x": -4,
      "y": 21,
      "z": 5,
      "name": "Empty"
    },
    {
      "x": -4,
      "y": 22,
      "z": 5,
      "name": "Empty"
    },
    {
      "x": -4,
      "y": 23,
      "z": 5,
      "name": "Empty"
    },
    {
      "x": -4,
      "y": 24,
      "z": 5,
      "name": "Empty"
    },
    {
      "x": -4,
      "y": 25,
      "z": 5,
      "name": "Empty"
    },
    {
      "x": -3,
      "y": 17,
      "z": -4,
      "name": "Rock_Shale_Brick"
    },
    {
      "x": -3,
      "y": 18,
      "z": -4,
      "name": "Rock_Shale_Brick"
    },
    {
      "x": -3,
      "y": 19,
      "z": -4,
      "name": "Soil_Grass_Cold"
    },
    {
      "x": -3,
      "y": 20,
      "z": -4,
      "name": "Plant_Grass_Winter"
    },
    {
      "x": -3,
      "y": 21,
      "z": -4,
      "name": "Empty"
    },
    {
      "x": -3,
      "y": 22,
      "z": -4,
      "name": "Empty"
    },
    {
      "x": -3,
      "y": 23,
      "z": -4,
      "name": "Empty"
    },
    {
      "x": -3,
      "y": 1,
      "z": -3,
      "name": "Rock_Shale"
    },
    {
      "x": -3,
      "y": 2,
      "z": -3,
      "name": "Rock_Shale"
    },
    {
      "x": -3,
      "y": 3,
      "z": -3,
      "name": "Rock_Shale"
    },
    {
      "x": -3,
      "y": 4,
      "z": -3,
      "name": "Rock_Shale_Cobble"
    },
    {
      "x": -3,
      "y": 5,
      "z": -3,
      "name": "Rock_Shale_Cobble"
    },
    {
      "x": -3,
      "y": 6,
      "z": -3,
      "name": "Rock_Shale_Cobble"
    },
    {
      "x": -3,
      "y": 7,
      "z": -3,
      "name": "Rock_Shale_Cobble"
    },
    {
      "x": -3,
      "y": 8,
      "z": -3,
      "name": "Rock_Shale_Brick"
    },
    {
      "x": -3,
      "y": 9,
      "z": -3,
      "name": "Rock_Shale_Brick"
    },
    {
      "x": -3,
      "y": 10,
      "z": -3,
      "name": "Rock_Shale_Brick"
    },
    {
      "x": -3,
      "y": 11,
      "z": -3,
      "name": "Rock_Shale_Brick"
    },
    {
      "x": -3,
      "y": 12,
      "z": -3,
      "name": "Rock_Shale_Brick"
    },
    {
      "x": -3,
      "y": 13,
      "z": -3,
      "name": "Rock_Shale_Brick"
    },
    {
      "x": -3,
      "y": 14,
      "z": -3,
      "name": "Rock_Shale_Brick"
    },
    {
      "x": -3,
      "y": 15,
      "z": -3,
      "name": "Rock_Shale_Brick"
    },
    {
      "x": -3,
      "y": 16,
      "z": -3,
      "name": "Rock_Shale_Cobble"
    },
    {
      "x": -3,
      "y": 17,
      "z": -3,
      "name": "Rock_Shale_Brick"
    },
    {
      "x": -3,
      "y": 18,
      "z": -3,
      "name": "Rock_Shale_Brick"
    },
    {
      "x": -3,
      "y": 19,
      "z": -3,
      "name": "Rock_Shale_Brick"
    },
    {
      "x": -3,
      "y": 20,
      "z": -3,
      "name": "Plant_Moss_Rug_Lime"
    },
    {
      "x": -3,
      "y": 21,
      "z": -3,
      "name": "Empty"
    },
    {
      "x": -3,
      "y": 22,
      "z": -3,
      "name": "Empty"
    },
    {
      "x": -3,
      "y": 23,
      "z": -3,
      "name": "Empty"
    },
    {
      "x": -3,
      "y": 24,
      "z": -3,
      "name": "Empty"
    },
    {
      "x": -3,
      "y": 25,
      "z": -3,
      "name": "Empty"
    },
    {
      "x": -3,
      "y": 1,
      "z": -2,
      "name": "Rock_Shale"
    },
    {
      "x": -3,
      "y": 2,
      "z": -2,
      "name": "Rock_Shale"
    },
    {
      "x": -3,
      "y": 3,
      "z": -2,
      "name": "Rock_Shale"
    },
    {
      "x": -3,
      "y": 4,
      "z": -2,
      "name": "Rock_Shale"
    },
    {
      "x": -3,
      "y": 5,
      "z": -2,
      "name": "Rock_Shale"
    },
    {
      "x": -3,
      "y": 6,
      "z": -2,
      "name": "Rock_Shale"
    },
    {
      "x": -3,
      "y": 7,
      "z": -2,
      "name": "Rock_Shale"
    },
    {
      "x": -3,
      "y": 8,
      "z": -2,
      "name": "Rock_Shale"
    },
    {
      "x": -3,
      "y": 9,
      "z": -2,
      "name": "Rock_Shale"
    },
    {
      "x": -3,
      "y": 10,
      "z": -2,
      "name": "Rock_Shale"
    },
    {
      "x": -3,
      "y": 11,
      "z": -2,
      "name": "Rock_Shale"
    },
    {
      "x": -3,
      "y": 12,
      "z": -2,
      "name": "Rock_Shale"
    },
    {
      "x": -3,
      "y": 13,
      "z": -2,
      "name": "Rock_Shale"
    },
    {
      "x": -3,
      "y": 14,
      "z": -2,
      "name": "Rock_Shale"
    },
    {
      "x": -3,
      "y": 15,
      "z": -2,
      "name": "Rock_Shale"
    },
    {
      "x": -3,
      "y": 16,
      "z": -2,
      "name": "Rock_Shale"
    },
    {
      "x": -3,
      "y": 17,
      "z": -2,
      "name": "Rock_Shale"
    },
    {
      "x": -3,
      "y": 18,
      "z": -2,
      "name": "Rock_Shale"
    },
    {
      "x": -3,
      "y": 19,
      "z": -2,
      "name": "Soil_Pathway"
    },
    {
      "x": -3,
      "y": 20,
      "z": -2,
      "name": "Plant_Moss_Rug_Lime"
    },
    {
      "x": -3,
      "y": 21,
      "z": -2,
      "name": "Empty"
    },
    {
      "x": -3,
      "y": 22,
      "z": -2,
      "name": "Empty"
    },
    {
      "x": -3,
      "y": 23,
      "z": -2,
      "name": "Empty"
    },
    {
      "x": -3,
      "y": 24,
      "z": -2,
      "name": "Empty"
    },
    {
      "x": -3,
      "y": 25,
      "z": -2,
      "name": "Empty"
    },
    {
      "x": -3,
      "y": 1,
      "z": -1,
      "name": "Rock_Shale"
    },
    {
      "x": -3,
      "y": 2,
      "z": -1,
      "name": "Rock_Shale"
    },
    {
      "x": -3,
      "y": 3,
      "z": -1,
      "name": "Rock_Shale_Cobble"
    },
    {
      "x": -3,
      "y": 4,
      "z": -1,
      "name": "Rock_Shale_Cobble"
    },
    {
      "x": -3,
      "y": 5,
      "z": -1,
      "name": "Rock_Shale_Cobble"
    },
    {
      "x": -3,
      "y": 6,
      "z": -1,
      "name": "Rock_Shale_Brick"
    },
    {
      "x": -3,
      "y": 7,
      "z": -1,
      "name": "Rock_Shale_Brick"
    },
    {
      "x": -3,
      "y": 8,
      "z": -1,
      "name": "Rock_Shale_Brick"
    },
    {
      "x": -3,
      "y": 9,
      "z": -1,
      "name": "Rock_Shale_Brick"
    },
    {
      "x": -3,
      "y": 10,
      "z": -1,
      "name": "Rock_Shale_Brick"
    },
    {
      "x": -3,
      "y": 11,
      "z": -1,
      "name": "Rock_Shale_Brick"
    },
    {
      "x": -3,
      "y": 12,
      "z": -1,
      "name": "Rock_Shale_Brick"
    },
    {
      "x": -3,
      "y": 13,
      "z": -1,
      "name": "Rock_Shale_Brick"
    },
    {
      "x": -3,
      "y": 14,
      "z": -1,
      "name": "Rock_Shale_Brick"
    },
    {
      "x": -3,
      "y": 15,
      "z": -1,
      "name": "Rock_Shale_Brick"
    },
    {
      "x": -3,
      "y": 16,
      "z": -1,
      "name": "Rock_Shale_Brick"
    },
    {
      "x": -3,
      "y": 17,
      "z": -1,
      "name": "Rock_Shale_Brick"
    },
    {
      "x": -3,
      "y": 18,
      "z": -1,
      "name": "Rock_Shale_Brick"
    },
    {
      "x": -3,
      "y": 19,
      "z": -1,
      "name": "Soil_Pathway"
    },
    {
      "x": -3,
      "y": 20,
      "z": -1,
      "name": "Plant_Moss_Rug_Lime"
    },
    {
      "x": -3,
      "y": 21,
      "z": -1,
      "name": "Empty"
    },
    {
      "x": -3,
      "y": 22,
      "z": -1,
      "name": "Empty"
    },
    {
      "x": -3,
      "y": 23,
      "z": -1,
      "name": "Empty"
    },
    {
      "x": -3,
      "y": 24,
      "z": -1,
      "name": "Empty"
    },
    {
      "x": -3,
      "y": 25,
      "z": -1,
      "name": "Empty"
    },
    {
      "x": -3,
      "y": 1,
      "z": 0,
      "name": "Rock_Shale"
    },
    {
      "x": -3,
      "y": 2,
      "z": 0,
      "name": "Rock_Shale"
    },
    {
      "x": -3,
      "y": 3,
      "z": 0,
      "name": "Rock_Shale"
    },
    {
      "x": -3,
      "y": 4,
      "z": 0,
      "name": "Rock_Shale"
    },
    {
      "x": -3,
      "y": 5,
      "z": 0,
      "name": "Rock_Shale_Cobble"
    },
    {
      "x": -3,
      "y": 6,
      "z": 0,
      "name": "Rock_Shale_Cobble"
    },
    {
      "x": -3,
      "y": 7,
      "z": 0,
      "name": "Rock_Shale_Cobble"
    },
    {
      "x": -3,
      "y": 8,
      "z": 0,
      "name": "Rock_Shale_Cobble"
    },
    {
      "x": -3,
      "y": 9,
      "z": 0,
      "name": "Rock_Shale_Cobble"
    },
    {
      "x": -3,
      "y": 10,
      "z": 0,
      "name": "Rock_Shale_Cobble"
    },
    {
      "x": -3,
      "y": 11,
      "z": 0,
      "name": "Rock_Shale_Cobble"
    },
    {
      "x": -3,
      "y": 12,
      "z": 0,
      "name": "Rock_Shale_Cobble"
    },
    {
      "x": -3,
      "y": 13,
      "z": 0,
      "name": "Rock_Shale_Cobble"
    },
    {
      "x": -3,
      "y": 14,
      "z": 0,
      "name": "Rock_Shale_Cobble"
    },
    {
      "x": -3,
      "y": 15,
      "z": 0,
      "name": "Rock_Shale_Cobble"
    },
    {
      "x": -3,
      "y": 16,
      "z": 0,
      "name": "Rock_Shale_Brick_Smooth"
    },
    {
      "x": -3,
      "y": 17,
      "z": 0,
      "name": "Wood_Fir_Branch_Long"
    },
    {
      "x": -3,
      "y": 18,
      "z": 0,
      "name": "Wood_Fir_Branch_Long"
    },
    {
      "x": -3,
      "y": 19,
      "z": 0,
      "name": "Wood_Darkwood_Planks_Half"
    },
    {
      "x": -3,
      "y": 20,
      "z": 0,
      "name": "Empty"
    },
    {
      "x": -3,
      "y": 21,
      "z": 0,
      "name": "Empty"
    },
    {
      "x": -3,
      "y": 22,
      "z": 0,
      "name": "Empty"
    },
    {
      "x": -3,
      "y": 23,
      "z": 0,
      "name": "Empty"
    },
    {
      "x": -3,
      "y": 24,
      "z": 0,
      "name": "Empty"
    },
    {
      "x": -3,
      "y": 25,
      "z": 0,
      "name": "Empty"
    },
    {
      "x": -3,
      "y": 1,
      "z": 1,
      "name": "Rock_Shale"
    },
    {
      "x": -3,
      "y": 2,
      "z": 1,
      "name": "Rock_Shale"
    },
    {
      "x": -3,
      "y": 3,
      "z": 1,
      "name": "Rock_Shale"
    },
    {
      "x": -3,
      "y": 4,
      "z": 1,
      "name": "Rock_Shale"
    },
    {
      "x": -3,
      "y": 5,
      "z": 1,
      "name": "Rock_Shale"
    },
    {
      "x": -3,
      "y": 6,
      "z": 1,
      "name": "Rock_Shale_Brick"
    },
    {
      "x": -3,
      "y": 7,
      "z": 1,
      "name": "Rock_Shale_Brick"
    },
    {
      "x": -3,
      "y": 8,
      "z": 1,
      "name": "Rock_Shale_Brick"
    },
    {
      "x": -3,
      "y": 9,
      "z": 1,
      "name": "Rock_Shale_Brick"
    },
    {
      "x": -3,
      "y": 10,
      "z": 1,
      "name": "Rock_Shale_Brick"
    },
    {
      "x": -3,
      "y": 11,
      "z": 1,
      "name": "Rock_Shale_Brick"
    },
    {
      "x": -3,
      "y": 12,
      "z": 1,
      "name": "Rock_Shale_Brick"
    },
    {
      "x": -3,
      "y": 13,
      "z": 1,
      "name": "Rock_Shale_Brick"
    },
    {
      "x": -3,
      "y": 14,
      "z": 1,
      "name": "Rock_Shale_Brick"
    },
    {
      "x": -3,
      "y": 15,
      "z": 1,
      "name": "Rock_Shale_Brick"
    },
    {
      "x": -3,
      "y": 16,
      "z": 1,
      "name": "Rock_Shale_Brick_Smooth"
    },
    {
      "x": -3,
      "y": 17,
      "z": 1,
      "name": "Wood_Fir_Branch_Long"
    },
    {
      "x": -3,
      "y": 18,
      "z": 1,
      "name": "Wood_Fir_Branch_Long"
    },
    {
      "x": -3,
      "y": 19,
      "z": 1,
      "name": "Wood_Darkwood_Planks_Half"
    },
    {
      "x": -3,
      "y": 20,
      "z": 1,
      "name": "Empty"
    },
    {
      "x": -3,
      "y": 21,
      "z": 1,
      "name": "Empty"
    },
    {
      "x": -3,
      "y": 22,
      "z": 1,
      "name": "Empty"
    },
    {
      "x": -3,
      "y": 23,
      "z": 1,
      "name": "Empty"
    },
    {
      "x": -3,
      "y": 24,
      "z": 1,
      "name": "Empty"
    },
    {
      "x": -3,
      "y": 25,
      "z": 1,
      "name": "Empty"
    },
    {
      "x": -3,
      "y": 16,
      "z": 2,
      "name": "Empty"
    },
    {
      "x": -3,
      "y": 17,
      "z": 2,
      "name": "Empty"
    },
    {
      "x": -3,
      "y": 18,
      "z": 2,
      "name": "Empty"
    },
    {
      "x": -3,
      "y": 19,
      "z": 2,
      "name": "Empty"
    },
    {
      "x": -3,
      "y": 20,
      "z": 2,
      "name": "Empty"
    },
    {
      "x": -3,
      "y": 21,
      "z": 2,
      "name": "Empty"
    },
    {
      "x": -3,
      "y": 22,
      "z": 2,
      "name": "Empty"
    },
    {
      "x": -3,
      "y": 23,
      "z": 2,
      "name": "Empty"
    },
    {
      "x": -3,
      "y": 24,
      "z": 2,
      "name": "Empty"
    },
    {
      "x": -3,
      "y": 25,
      "z": 2,
      "name": "Empty"
    },
    {
      "x": -3,
      "y": 16,
      "z": 3,
      "name": "Empty"
    },
    {
      "x": -3,
      "y": 17,
      "z": 3,
      "name": "Empty"
    },
    {
      "x": -3,
      "y": 18,
      "z": 3,
      "name": "Empty"
    },
    {
      "x": -3,
      "y": 19,
      "z": 3,
      "name": "Empty"
    },
    {
      "x": -3,
      "y": 20,
      "z": 3,
      "name": "Empty"
    },
    {
      "x": -3,
      "y": 21,
      "z": 3,
      "name": "Empty"
    },
    {
      "x": -3,
      "y": 22,
      "z": 3,
      "name": "Empty"
    },
    {
      "x": -3,
      "y": 23,
      "z": 3,
      "name": "Empty"
    },
    {
      "x": -3,
      "y": 24,
      "z": 3,
