{
  "version": 8,
  "blockIdVersion": 0,
  "anchorX": 0,
  "anchorY": 3,
  "anchorZ": 0,
  "blocks": [
    {
      "x": -4,
      "y": 1,
      "z": 0,
      "name": "Soil_Dirt"
    },
    {
      "x": -4,
      "y": 2,
      "z": 0,
      "name": "Soil_Dirt"
    },
    {
      "x": -4,
      "y": 3,
      "z": 0,
      "name": "Soil_Grass"
    },
    {
      "x": -4,
      "y": 4,
      "z": 0,
      "name": "Plant_Bush_Berry"
    },
    {
      "x": -3,
      "y": 1,
      "z": -2,
      "name": "Soil_Dirt"
    },
    {
      "x": -3,
      "y": 2,
      "z": -2,
      "name": "Soil_Dirt"
    },
    {
      "x": -3,
      "y": 3,
      "z": -2,
      "name": "Soil_Grass"
    },
    {
      "x": -3,
      "y": 1,
      "z": -1,
      "name": "Soil_Dirt"
    },
    {
      "x": -3,
      "y": 2,
      "z": -1,
      "name": "Soil_Dirt"
    },
    {
      "x": -3,
      "y": 3,
      "z": -1,
      "name": "Soil_Grass"
    },
    {
      "x": -3,
      "y": 1,
      "z": 0,
      "name": "Soil_Dirt"
    },
    {
      "x": -3,
      "y": 2,
      "z": 0,
      "name": "Soil_Dirt"
    },
    {
      "x": -3,
      "y": 3,
      "z": 0,
      "name": "Soil_Grass"
    },
    {
      "x": -3,
      "y": 4,
      "z": 0,
      "name": "Plant_Bush_Berry"
    },
    {
      "x": -3,
      "y": 1,
      "z": 1,
      "name": "Soil_Dirt"
    },
    {
      "x": -3,
      "y": 2,
      "z": 1,
      "name": "Soil_Dirt"
    },
    {
      "x": -3,
      "y": 3,
      "z": 1,
      "name": "Soil_Grass"
    },
    {
      "x": -3,
      "y": 4,
      "z": 1,
      "name": "Plant_Bush"
    },
    {
      "x": -3,
      "y": 1,
      "z": 2,
      "name": "Soil_Dirt"
    },
    {
      "x": -3,
      "y": 2,
      "z": 2,
      "name": "Soil_Dirt"
    },
    {
      "x": -3,
      "y": 3,
      "z": 2,
      "name": "Soil_Grass"
    },
    {
      "x": -3,
      "y": 4,
      "z": 2,
      "name": "Plant_Vine_Wall",
      "rotation": 3
    },
    {
      "x": -3,
      "y": 5,
      "z": 2,
      "name": "Plant_Vine",
      "rotation": 3
    },
    {
      "x": -3,
      "y": 1,
      "z": 3,
      "name": "Soil_Dirt"
    },
    {
      "x": -3,
      "y": 2,
      "z": 3,
      "name": "Soil_Dirt"
    },
    {
      "x": -3,
      "y": 3,
      "z": 3,
      "name": "Soil_Grass"
    },
    {
      "x": -3,
      "y": 4,
      "z": 3,
      "name": "Plant_Vine",
      "rotation": 3
    },
    {
      "x": -3,
      "y": 1,
      "z": 4,
      "name": "Soil_Dirt"
    },
    {
      "x": -3,
      "y": 2,
      "z": 4,
      "name": "Soil_Dirt"
    },
    {
      "x": -3,
      "y": 3,
      "z": 4,
      "name": "Soil_Grass"
    },
    {
      "x": -2,
      "y": 1,
      "z": -4,
      "name": "Soil_Dirt"
    },
    {
      "x": -2,
      "y": 2,
      "z": -4,
      "name": "Soil_Dirt"
    },
    {
      "x": -2,
      "y": 3,
      "z": -4,
      "name": "Soil_Grass"
    },
    {
      "x": -2,
      "y": 1,
      "z": -3,
      "name": "Soil_Dirt"
    },
    {
      "x": -2,
      "y": 2,
      "z": -3,
      "name": "Soil_Dirt"
    },
    {
      "x": -2,
      "y": 3,
      "z": -3,
      "name": "Soil_Grass"
    },
    {
      "x": -2,
      "y": 1,
      "z": -2,
      "name": "Soil_Dirt"
    },
    {
      "x": -2,
      "y": 2,
      "z": -2,
      "name": "Soil_Dirt"
    },
    {
      "x": -2,
      "y": 3,
      "z": -2,
      "name": "Soil_Grass"
    },
    {
      "x": -2,
      "y": 1,
      "z": -1,
      "name": "Soil_Dirt"
    },
    {
      "x": -2,
      "y": 2,
      "z": -1,
      "name": "Soil_Dirt"
    },
    {
      "x": -2,
      "y": 3,
      "z": -1,
      "name": "Soil_Pathway"
    },
    {
      "x": -2,
      "y": 4,
      "z": -1,
      "name": "Furniture_Crude_Chest_Small",
      "components": {
        "Components": {
          "container": {
            "Custom": false,
            "AllowViewing": true,
            "Droplist": "Unique_Start",
            "ItemContainer": {
              "Capacity": 18,
              "Items": {}
            }
          }
        }
      },
      "rotation": 1
    },
    {
      "x": -2,
      "y": 5,
      "z": -1,
      "name": "Empty"
    },
    {
      "x": -2,
      "y": 6,
      "z": -1,
      "name": "Empty"
    },
    {
      "x": -2,
      "y": 1,
      "z": 0,
      "name": "Soil_Dirt"
    },
    {
      "x": -2,
      "y": 2,
      "z": 0,
      "name": "Soil_Dirt"
    },
    {
      "x": -2,
      "y": 3,
      "z": 0,
      "name": "Soil_Pathway"
    },
    {
      "x": -2,
      "y": 4,
      "z": 0,
      "name": "Empty"
    },
    {
      "x": -2,
      "y": 5,
      "z": 0,
      "name": "Empty"
    },
    {
      "x": -2,
      "y": 6,
      "z": 0,
      "name": "Empty"
    },
    {
      "x": -2,
      "y": 1,
      "z": 1,
      "name": "Soil_Dirt"
    },
    {
      "x": -2,
      "y": 2,
      "z": 1,
      "name": "Soil_Dirt"
    },
    {
      "x": -2,
      "y": 3,
      "z": 1,
      "name": "Soil_Dirt"
    },
    {
      "x": -2,
      "y": 4,
      "z": 1,
      "name": "Wood_Oak_Branch_Long",
      "support": 15
    },
    {
      "x": -2,
      "y": 5,
      "z": 1,
      "name": "Wood_Oak_Branch_Long",
      "support": 15
    },
    {
      "x": -2,
      "y": 6,
      "z": 1,
      "name": "Wood_Oak_Trunk",
      "support": 15,
      "rotation": 5
    },
    {
      "x": -2,
      "y": 7,
      "z": 1,
      "name": "Plant_Moss_Rug_Green"
    },
    {
      "x": -2,
      "y": 1,
      "z": 2,
      "name": "Soil_Dirt"
    },
    {
      "x": -2,
      "y": 2,
      "z": 2,
      "name": "Soil_Dirt"
    },
    {
      "x": -2,
      "y": 3,
      "z": 2,
      "name": "Soil_Dirt"
    },
    {
      "x": -2,
      "y": 4,
      "z": 2,
      "name": "Empty"
    },
    {
      "x": -2,
      "y": 5,
      "z": 2,
      "name": "Wood_Hardwood_Stairs",
      "rotation": 8
    },
    {
      "x": -2,
      "y": 6,
      "z": 2,
      "name": "Wood_Hardwood_Stairs"
    },
    {
      "x": -2,
      "y": 1,
      "z": 3,
      "name": "Soil_Dirt"
    },
    {
      "x": -2,
      "y": 2,
      "z": 3,
      "name": "Soil_Dirt"
    },
    {
      "x": -2,
      "y": 3,
      "z": 3,
      "name": "Soil_Grass"
    },
    {
      "x": -2,
      "y": 4,
      "z": 3,
      "name": "Wood_Hardwood_Stairs",
      "rotation": 8
    },
    {
      "x": -2,
      "y": 5,
      "z": 3,
      "name": "Wood_Hardwood_Stairs"
    },
    {
      "x": -2,
      "y": 1,
      "z": 4,
      "name": "Soil_Dirt"
    },
    {
      "x": -2,
      "y": 2,
      "z": 4,
      "name": "Soil_Dirt"
    },
    {
      "x": -2,
      "y": 3,
      "z": 4,
      "name": "Soil_Dirt"
    },
    {
      "x": -2,
      "y": 4,
      "z": 4,
      "name": "Wood_Hardwood_Stairs"
    },
    {
      "x": -2,
      "y": 1,
      "z": 5,
      "name": "Soil_Dirt"
    },
    {
      "x": -2,
      "y": 2,
      "z": 5,
      "name": "Soil_Dirt"
    },
    {
      "x": -2,
      "y": 3,
      "z": 5,
      "name": "Soil_Grass"
    },
    {
      "x": -1,
      "y": 1,
      "z": -5,
      "name": "Soil_Dirt"
    },
    {
      "x": -1,
      "y": 2,
      "z": -5,
      "name": "Soil_Dirt"
    },
    {
      "x": -1,
      "y": 3,
      "z": -5,
      "name": "Soil_Grass"
    },
    {
      "x": -1,
      "y": 1,
      "z": -4,
      "name": "Soil_Dirt"
    },
    {
      "x": -1,
      "y": 2,
      "z": -4,
      "name": "Soil_Dirt"
    },
    {
      "x": -1,
      "y": 3,
      "z": -4,
      "name": "Soil_Grass"
    },
    {
      "x": -1,
      "y": 1,
      "z": -3,
      "name": "Soil_Dirt"
    },
    {
      "x": -1,
      "y": 2,
      "z": -3,
      "name": "Soil_Dirt"
    },
    {
      "x": -1,
      "y": 3,
      "z": -3,
      "name": "Soil_Dirt"
    },
    {
      "x": -1,
      "y": 4,
      "z": -3,
      "name": "Empty"
    },
    {
      "x": -1,
      "y": 5,
      "z": -3,
      "name": "Empty"
    },
    {
      "x": -1,
      "y": 6,
      "z": -3,
      "name": "Empty"
    },
    {
      "x": -1,
      "y": 1,
      "z": -2,
      "name": "Soil_Dirt"
    },
    {
      "x": -1,
      "y": 2,
      "z": -2,
      "name": "Soil_Dirt"
    },
    {
      "x": -1,
      "y": 3,
      "z": -2,
      "name": "Soil_Pathway"
    },
    {
      "x": -1,
      "y": 4,
      "z": -2,
      "name": "Empty"
    },
    {
      "x": -1,
      "y": 5,
      "z": -2,
      "name": "Empty"
    },
    {
      "x": -1,
      "y": 6,
      "z": -2,
      "name": "Empty"
    },
    {
      "x": -1,
      "y": 1,
      "z": -1,
      "name": "Soil_Dirt"
    },
    {
      "x": -1,
      "y": 2,
      "z": -1,
      "name": "Soil_Dirt"
    },
    {
      "x": -1,
      "y": 3,
      "z": -1,
      "name": "Soil_Pathway"
    },
    {
      "x": -1,
      "y": 4,
      "z": -1,
      "name": "Empty"
    },
    {
      "x": -1,
      "y": 5,
      "z": -1,
      "name": "Empty"
    },
    {
      "x": -1,
      "y": 6,
      "z": -1,
      "name": "Empty"
    },
    {
      "x": -1,
      "y": 1,
      "z": 0,
      "name": "Soil_Dirt"
    },
    {
      "x": -1,
      "y": 2,
      "z": 0,
      "name": "Soil_Dirt"
    },
    {
      "x": -1,
      "y": 3,
      "z": 0,
      "name": "Soil_Pathway"
    },
    {
      "x": -1,
      "y": 4,
      "z": 0,
      "name": "Empty"
    },
    {
      "x": -1,
      "y": 5,
      "z": 0,
      "name": "Empty"
    },
    {
      "x": -1,
      "y": 6,
      "z": 0,
      "name": "Empty"
    },
    {
      "x": -1,
      "y": 1,
      "z": 1,
      "name": "Soil_Dirt"
    },
    {
      "x": -1,
      "y": 2,
      "z": 1,
      "name": "Soil_Dirt"
    },
    {
      "x": -1,
      "y": 3,
      "z": 1,
      "name": "Soil_Dirt"
    },
    {
      "x": -1,
      "y": 4,
      "z": 1,
      "name": "Empty"
    },
    {
      "x": -1,
      "y": 5,
      "z": 1,
      "name": "Empty"
    },
    {
      "x": -1,
      "y": 6,
      "z": 1,
      "name": "Wood_Oak_Trunk",
      "support": 15,
      "rotation": 5
    },
    {
      "x": -1,
      "y": 7,
      "z": 1,
      "name": "Plant_Moss_Rug_Green"
    },
    {
      "x": -1,
      "y": 1,
      "z": 2,
      "name": "Soil_Dirt"
    },
    {
      "x": -1,
      "y": 2,
      "z": 2,
      "name": "Soil_Dirt"
    },
    {
      "x": -1,
      "y": 3,
      "z": 2,
      "name": "Soil_Dirt"
    },
    {
      "x": -1,
      "y": 4,
      "z": 2,
      "name": "Empty"
    },
    {
      "x": -1,
      "y": 5,
      "z": 2,
      "name": "Empty"
    },
    {
      "x": -1,
      "y": 6,
      "z": 2,
      "name": "Soil_Grass"
    },
    {
      "x": -1,
      "y": 7,
      "z": 2,
      "name": "Plant_Moss_Rug_Green"
    },
    {
      "x": -1,
      "y": 1,
      "z": 3,
      "name": "Soil_Dirt"
    },
    {
      "x": -1,
      "y": 2,
      "z": 3,
      "name": "Soil_Dirt"
    },
    {
      "x": -1,
      "y": 3,
      "z": 3,
      "name": "Soil_Pathway"
    },
    {
      "x": -1,
      "y": 4,
      "z": 3,
      "name": "Empty"
    },
    {
      "x": -1,
      "y": 5,
      "z": 3,
      "name": "Soil_Dirt"
    },
    {
      "x": -1,
      "y": 6,
      "z": 3,
      "name": "Soil_Grass"
    },
    {
      "x": -1,
      "y": 1,
      "z": 4,
      "name": "Soil_Dirt"
    },
    {
      "x": -1,
      "y": 2,
      "z": 4,
      "name": "Soil_Dirt"
    },
    {
      "x": -1,
      "y": 3,
      "z": 4,
      "name": "Soil_Dirt"
    },
    {
      "x": -1,
      "y": 4,
      "z": 4,
      "name": "Soil_Dirt"
    },
    {
      "x": -1,
      "y": 5,
      "z": 4,
      "name": "Soil_Grass"
    },
    {
      "x": -1,
      "y": 6,
      "z": 4,
      "name": "Plant_Moss_Short_Green"
    },
    {
      "x": -1,
      "y": 1,
      "z": 5,
      "name": "Soil_Dirt"
    },
    {
      "x": -1,
      "y": 2,
      "z": 5,
      "name": "Soil_Dirt"
    },
    {
      "x": -1,
      "y": 3,
      "z": 5,
      "name": "Soil_Dirt"
    },
    {
      "x": -1,
      "y": 4,
      "z": 5,
      "name": "Soil_Grass"
    },
    {
      "x": 0,
      "y": 1,
      "z": -5,
      "name": "Soil_Dirt"
    },
    {
      "x": 0,
      "y": 2,
      "z": -5,
      "name": "Soil_Dirt"
    },
    {
      "x": 0,
      "y": 3,
      "z": -5,
      "name": "Soil_Grass"
    },
    {
      "x": 0,
      "y": 1,
      "z": -4,
      "name": "Soil_Dirt"
    },
    {
      "x": 0,
      "y": 2,
      "z": -4,
      "name": "Soil_Dirt"
    },
    {
      "x": 0,
      "y": 3,
      "z": -4,
      "name": "Soil_Pathway"
    },
    {
      "x": 0,
      "y": 4,
      "z": -4,
      "name": "Empty"
    },
    {
      "x": 0,
      "y": 5,
      "z": -4,
      "name": "Empty"
    },
    {
      "x": 0,
      "y": 6,
      "z": -4,
      "name": "Empty"
    },
    {
      "x": 0,
      "y": 1,
      "z": -3,
      "name": "Soil_Dirt"
    },
    {
      "x": 0,
      "y": 2,
      "z": -3,
      "name": "Soil_Dirt"
    },
    {
      "x": 0,
      "y": 3,
      "z": -3,
      "name": "Soil_Pathway"
    },
    {
      "x": 0,
      "y": 4,
      "z": -3,
      "name": "Empty"
    },
    {
      "x": 0,
      "y": 5,
      "z": -3,
      "name": "Empty"
    },
    {
      "x": 0,
      "y": 6,
      "z": -3,
      "name": "Empty"
    },
    {
      "x": 0,
      "y": 1,
      "z": -2,
      "name": "Soil_Dirt"
    },
    {
      "x": 0,
      "y": 2,
      "z": -2,
      "name": "Soil_Dirt"
    },
    {
      "x": 0,
      "y": 3,
      "z": -2,
      "name": "Soil_Pathway"
    },
    {
      "x": 0,
      "y": 4,
      "z": -2,
      "name": "Empty"
    },
    {
      "x": 0,
      "y": 5,
      "z": -2,
      "name": "Empty"
    },
    {
      "x": 0,
      "y": 6,
      "z": -2,
      "name": "Empty"
    },
    {
      "x": 0,
      "y": 1,
      "z": -1,
      "name": "Soil_Dirt"
    },
    {
      "x": 0,
      "y": 2,
      "z": -1,
      "name": "Soil_Dirt"
    },
    {
      "x": 0,
      "y": 3,
      "z": -1,
      "name": "Soil_Dirt"
    },
    {
      "x": 0,
      "y": 4,
      "z": -1,
      "name": "Empty"
    },
    {
      "x": 0,
      "y": 5,
      "z": -1,
      "name": "Empty"
    },
    {
      "x": 0,
      "y": 6,
      "z": -1,
      "name": "Empty"
    },
    {
      "x": 0,
      "y": 1,
      "z": 0,
      "name": "Soil_Dirt"
    },
    {
      "x": 0,
      "y": 2,
      "z": 0,
      "name": "Soil_Dirt"
    },
    {
      "x": 0,
      "y": 3,
      "z": 0,
      "name": "Soil_Dirt"
    },
    {
      "x": 0,
      "y": 4,
      "z": 0,
      "name": "Empty"
    },
    {
      "x": 0,
      "y": 5,
      "z": 0,
      "name": "Empty"
    },
    {
      "x": 0,
      "y": 6,
      "z": 0,
      "name": "Empty"
    },
    {
      "x": 0,
      "y": 1,
      "z": 1,
      "name": "Soil_Dirt"
    },
    {
      "x": 0,
      "y": 2,
      "z": 1,
      "name": "Soil_Dirt"
    },
    {
      "x": 0,
      "y": 3,
      "z": 1,
      "name": "Soil_Dirt"
    },
    {
      "x": 0,
      "y": 4,
      "z": 1,
      "name": "Empty"
    },
    {
      "x": 0,
      "y": 5,
      "z": 1,
      "name": "Empty"
    },
    {
      "x": 0,
      "y": 6,
      "z": 1,
      "name": "Wood_Oak_Trunk",
      "support": 15,
      "rotation": 5
    },
    {
      "x": 0,
      "y": 1,
      "z": 2,
      "name": "Soil_Dirt"
    },
    {
      "x": 0,
      "y": 2,
      "z": 2,
      "name": "Soil_Dirt"
    },
    {
      "x": 0,
      "y": 3,
      "z": 2,
      "name": "Soil_Dirt"
    },
    {
      "x": 0,
      "y": 4,
      "z": 2,
      "name": "Empty"
    },
    {
      "x": 0,
      "y": 5,
      "z": 2,
      "name": "Empty"
    },
    {
      "x": 0,
      "y": 6,
      "z": 2,
      "name": "Soil_Grass"
    },
    {
      "x": 0,
      "y": 1,
      "z": 3,
      "name": "Soil_Dirt"
    },
    {
      "x": 0,
      "y": 2,
      "z": 3,
      "name": "Soil_Dirt"
    },
    {
      "x": 0,
      "y": 3,
      "z": 3,
      "name": "Soil_Pathway"
    },
    {
      "x": 0,
      "y": 4,
      "z": 3,
      "name": "Empty"
    },
    {
      "x": 0,
      "y": 5,
      "z": 3,
      "name": "Soil_Dirt"
    },
    {
      "x": 0,
      "y": 6,
      "z": 3,
      "name": "Soil_Grass"
    },
    {
      "x": 0,
      "y": 1,
      "z": 4,
      "name": "Soil_Dirt"
    },
    {
      "x": 0,
      "y": 2,
      "z": 4,
      "name": "Soil_Dirt"
    },
    {
      "x": 0,
      "y": 3,
      "z": 4,
      "name": "Soil_Dirt"
    },
    {
      "x": 0,
      "y": 4,
      "z": 4,
      "name": "Soil_Dirt"
    },
    {
      "x": 0,
      "y": 5,
      "z": 4,
      "name": "Soil_Grass"
    },
    {
      "x": 0,
      "y": 1,
      "z": 5,
      "name": "Soil_Dirt"
    },
    {
      "x": 0,
      "y": 2,
      "z": 5,
      "name": "Soil_Dirt"
    },
    {
      "x": 0,
      "y": 3,
      "z": 5,
      "name": "Soil_Dirt"
    },
    {
      "x": 0,
      "y": 4,
      "z": 5,
      "name": "Soil_Grass"
    },
    {
      "x": 0,
      "y": 5,
      "z": 5,
      "name": "Plant_Grass_Lush_Short"
    },
    {
      "x": 1,
      "y": 1,
      "z": -5,
      "name": "Soil_Dirt"
    },
    {
      "x": 1,
      "y": 2,
      "z": -5,
      "name": "Soil_Dirt"
    },
    {
      "x": 1,
      "y": 3,
      "z": -5,
      "name": "Soil_Grass"
    },
    {
      "x": 1,
      "y": 1,
      "z": -4,
      "name": "Soil_Dirt"
    },
    {
      "x": 1,
      "y": 2,
      "z": -4,
      "name": "Soil_Dirt"
    },
    {
      "x": 1,
      "y": 3,
      "z": -4,
      "name": "Soil_Pathway"
    },
    {
      "x": 1,
      "y": 4,
      "z": -4,
      "name": "Empty"
    },
    {
      "x": 1,
      "y": 5,
      "z": -4,
      "name": "Empty"
    },
    {
      "x": 1,
      "y": 6,
      "z": -4,
      "name": "Empty"
    },
    {
      "x": 1,
      "y": 1,
      "z": -3,
      "name": "Soil_Dirt"
    },
    {
      "x": 1,
      "y": 2,
      "z": -3,
      "name": "Soil_Dirt"
    },
    {
      "x": 1,
      "y": 3,
      "z": -3,
      "name": "Soil_Pathway"
    },
    {
      "x": 1,
      "y": 4,
      "z": -3,
      "name": "Empty"
    },
    {
      "x": 1,
      "y": 5,
      "z": -3,
      "name": "Empty"
    },
    {
      "x": 1,
      "y": 6,
      "z": -3,
      "name": "Empty"
    },
    {
      "x": 1,
      "y": 1,
      "z": -2,
      "name": "Soil_Dirt"
    },
    {
      "x": 1,
      "y": 2,
      "z": -2,
      "name": "Soil_Dirt"
    },
    {
      "x": 1,
      "y": 3,
      "z": -2,
      "name": "Soil_Pathway"
    },
    {
      "x": 1,
      "y": 4,
      "z": -2,
      "name": "Empty"
    },
    {
      "x": 1,
      "y": 5,
      "z": -2,
      "name": "Empty"
    },
    {
      "x": 1,
      "y": 6,
      "z": -2,
      "name": "Empty"
    },
    {
      "x": 1,
      "y": 1,
      "z": -1,
      "name": "Soil_Dirt"
    },
    {
      "x": 1,
      "y": 2,
      "z": -1,
      "name": "Soil_Dirt"
    },
    {
      "x": 1,
      "y": 3,
      "z": -1,
      "name": "Soil_Pathway"
    },
    {
      "x": 1,
      "y": 4,
      "z": -1,
      "name": "Empty"
    },
    {
      "x": 1,
      "y": 5,
      "z": -1,
      "name": "Empty"
    },
    {
      "x": 1,
      "y": 6,
      "z": -1,
      "name": "Empty"
    },
    {
      "x": 1,
      "y": 1,
      "z": 0,
      "name": "Soil_Dirt"
    },
    {
      "x": 1,
      "y": 2,
      "z": 0,
      "name": "Soil_Dirt"
    },
    {
      "x": 1,
      "y": 3,
      "z": 0,
      "name": "Soil_Dirt"
    },
    {
      "x": 1,
      "y": 4,
      "z": 0,
      "name": "Empty"
    },
    {
      "x": 1,
      "y": 5,
      "z": 0,
      "name": "Empty"
    },
    {
      "x": 1,
      "y": 6,
      "z": 0,
      "name": "Empty"
    },
    {
      "x": 1,
      "y": 1,
      "z": 1,
      "name": "Soil_Dirt"
    },
    {
      "x": 1,
      "y": 2,
      "z": 1,
      "name": "Soil_Dirt"
    },
    {
      "x": 1,
      "y": 3,
      "z": 1,
      "name": "Soil_Dirt"
    },
    {
      "x": 1,
      "y": 4,
      "z": 1,
      "name": "Empty"
    },
    {
      "x": 1,
      "y": 5,
      "z": 1,
      "name": "Empty"
    },
    {
      "x": 1,
      "y": 6,
      "z": 1,
      "name": "Wood_Oak_Trunk",
      "support": 15,
      "rotation": 5
    },
    {
      "x": 1,
      "y": 1,
      "z": 2,
      "name": "Soil_Dirt"
    },
    {
      "x": 1,
      "y": 2,
      "z": 2,
      "name": "Soil_Dirt"
    },
    {
      "x": 1,
      "y": 3,
      "z": 2,
      "name": "Soil_Dirt"
    },
    {
      "x": 1,
      "y": 4,
      "z": 2,
      "name": "Furniture_Crude_Bed",
      "rotation": 2
    },
    {
      "x": 1,
      "y": 5,
      "z": 2,
      "name": "Empty"
    },
    {
      "x": 1,
      "y": 6,
      "z": 2,
      "name": "Soil_Grass"
    },
    {
      "x": 1,
      "y": 7,
      "z": 2,
      "name": "Plant_Moss_Short_Green"
    },
    {
      "x": 1,
      "y": 1,
      "z": 3,
      "name": "Soil_Dirt"
    },
    {
      "x": 1,
      "y": 2,
      "z": 3,
      "name": "Soil_Dirt"
    },
    {
      "x": 1,
      "y": 3,
      "z": 3,
      "name": "Soil_Pathway"
    },
    {
      "x": 1,
      "y": 4,
      "z": 3,
      "name": "Empty"
    },
    {
      "x": 1,
      "y": 5,
      "z": 3,
      "name": "Soil_Dirt"
    },
    {
      "x": 1,
      "y": 6,
      "z": 3,
      "name": "Plant_Moss_Rug_Green"
    },
    {
      "x": 1,
      "y": 1,
      "z": 4,
      "name": "Soil_Dirt"
    },
    {
      "x": 1,
      "y": 2,
      "z": 4,
      "name": "Soil_Dirt"
    },
    {
      "x": 1,
      "y": 3,
      "z": 4,
      "name": "Soil_Dirt"
    },
    {
      "x": 1,
      "y": 4,
      "z": 4,
      "name": "Soil_Dirt"
    },
    {
      "x": 1,
      "y": 5,
      "z": 4,
      "name": "Plant_Moss_Green"
    },
    {
      "x": 1,
      "y": 1,
      "z": 5,
      "name": "Soil_Dirt"
    },
    {
      "x": 1,
      "y": 2,
      "z": 5,
      "name": "Soil_Dirt"
    },
    {
      "x": 1,
      "y": 3,
      "z": 5,
      "name": "Soil_Dirt"
    },
    {
      "x": 1,
      "y": 4,
      "z": 5,
      "name": "Soil_Grass"
    },
    {
      "x": 2,
      "y": 1,
      "z": -5,
      "name": "Soil_Dirt"
    },
    {
      "x": 2,
      "y": 2,
      "z": -5,
      "name": "Soil_Dirt"
    },
    {
      "x": 2,
      "y": 3,
      "z": -5,
      "name": "Soil_Grass"
    },
    {
      "x": 2,
      "y": 1,
      "z": -4,
      "name": "Soil_Dirt"
    },
    {
      "x": 2,
      "y": 2,
      "z": -4,
      "name": "Soil_Dirt"
    },
    {
      "x": 2,
      "y": 3,
      "z": -4,
      "name": "Soil_Grass"
    },
    {
      "x": 2,
      "y": 1,
      "z": -3,
      "name": "Soil_Dirt"
    },
    {
      "x": 2,
      "y": 2,
      "z": -3,
      "name": "Soil_Dirt"
    },
    {
      "x": 2,
      "y": 3,
      "z": -3,
      "name": "Soil_Pathway"
    },
    {
      "x": 2,
      "y": 4,
      "z": -3,
      "name": "Empty"
    },
    {
      "x": 2,
      "y": 5,
      "z": -3,
      "name": "Empty"
    },
    {
      "x": 2,
      "y": 6,
      "z": -3,
      "name": "Empty"
    },
    {
      "x": 2,
      "y": 1,
      "z": -2,
      "name": "Soil_Dirt"
    },
    {
      "x": 2,
      "y": 2,
      "z": -2,
      "name": "Soil_Dirt"
    },
    {
      "x": 2,
      "y": 3,
      "z": -2,
      "name": "Soil_Pathway"
    },
    {
      "x": 2,
      "y": 4,
      "z": -2,
      "name": "Empty"
    },
    {
      "x": 2,
      "y": 5,
      "z": -2,
      "name": "Empty"
    },
    {
      "x": 2,
      "y": 6,
      "z": -2,
      "name": "Empty"
    },
    {
      "x": 2,
      "y": 1,
      "z": -1,
      "name": "Soil_Dirt"
    },
    {
      "x": 2,
      "y": 2,
      "z": -1,
      "name": "Soil_Dirt"
    },
    {
      "x": 2,
      "y": 3,
      "z": -1,
      "name": "Soil_Pathway"
    },
    {
      "x": 2,
      "y": 4,
      "z": -1,
      "name": "Empty"
    },
    {
      "x": 2,
      "y": 5,
      "z": -1,
      "name": "Empty"
    },
    {
      "x": 2,
      "y": 6,
      "z": -1,
      "name": "Empty"
    },
    {
      "x": 2,
      "y": 1,
      "z": 0,
      "name": "Soil_Dirt"
    },
    {
      "x": 2,
      "y": 2,
      "z": 0,
      "name": "Soil_Dirt"
    },
    {
      "x": 2,
      "y": 3,
      "z": 0,
      "name": "Soil_Dirt"
    },
    {
      "x": 2,
      "y": 4,
      "z": 0,
      "name": "Empty"
    },
    {
      "x": 2,
      "y": 5,
      "z": 0,
      "name": "Empty"
    },
    {
      "x": 2,
      "y": 6,
      "z": 0,
      "name": "Empty"
    },
    {
      "x": 2,
      "y": 1,
      "z": 1,
      "name": "Soil_Dirt"
    },
    {
      "x": 2,
      "y": 2,
      "z": 1,
      "name": "Soil_Dirt"
    },
    {
      "x": 2,
      "y": 3,
      "z": 1,
      "name": "Soil_Grass"
    },
    {
      "x": 2,
      "y": 4,
      "z": 1,
      "name": "Wood_Oak_Branch_Long",
      "support": 15
    },
    {
      "x": 2,
      "y": 5,
      "z": 1,
      "name": "Wood_Oak_Branch_Long",
      "support": 15
    },
    {
      "x": 2,
      "y": 6,
      "z": 1,
      "name": "Wood_Oak_Trunk",
      "support": 15,
      "rotation": 5
    },
    {
      "x": 2,
      "y": 7,
      "z": 1,
      "name": "Plant_Moss_Rug_Green"
    },
    {
      "x": 2,
      "y": 1,
      "z": 2,
      "name": "Soil_Dirt"
    },
    {
      "x": 2,
      "y": 2,
      "z": 2,
      "name": "Soil_Dirt"
    },
    {
      "x": 2,
      "y": 3,
      "z": 2,
      "name": "Soil_Pathway"
    },
    {
      "x": 2,
      "y": 4,
      "z": 2,
      "name": "Wood_Softwood_Fence",
      "rotation": 1
    },
    {
      "x": 2,
      "y": 5,
      "z": 2,
      "name": "Wood_Hardwood_Stairs",
      "rotation": 8
    },
    {
      "x": 2,
      "y": 6,
      "z": 2,
      "name": "Wood_Hardwood_Stairs"
    },
    {
      "x": 2,
      "y": 1,
      "z": 3,
      "name": "Soil_Dirt"
    },
    {
      "x": 2,
      "y": 2,
      "z": 3,
      "name": "Soil_Dirt"
    },
    {
      "x": 2,
      "y": 3,
      "z": 3,
      "name": "Soil_Pathway"
    },
    {
      "x": 2,
      "y": 4,
      "z": 3,
      "name": "Wood_Hardwood_Stairs",
      "rotation": 8
    },
    {
      "x": 2,
      "y": 5,
      "z": 3,
      "name": "Wood_Hardwood_Stairs"
    },
    {
      "x": 2,
      "y": 1,
      "z": 4,
      "name": "Soil_Dirt"
    },
    {
      "x": 2,
      "y": 2,
      "z": 4,
      "name": "Soil_Dirt"
    },
    {
      "x": 2,
      "y": 3,
      "z": 4,
      "name": "Soil_Dirt"
    },
    {
      "x": 2,
      "y": 4,
      "z": 4,
      "name": "Wood_Hardwood_Stairs"
    },
    {
      "x": 2,
      "y": 1,
      "z": 5,
      "name": "Soil_Dirt"
    },
    {
      "x": 2,
      "y": 2,
      "z": 5,
      "name": "Soil_Dirt"
    },
    {
      "x": 2,
      "y": 3,
      "z": 5,
      "name": "Soil_Grass"
    },
    {
      "x": 3,
      "y": 1,
      "z": -4,
      "name": "Soil_Dirt"
    },
    {
      "x": 3,
      "y": 2,
      "z": -4,
      "name": "Soil_Dirt"
    },
    {
      "x": 3,
      "y": 3,
      "z": -4,
      "name": "Soil_Grass"
    },
    {
      "x": 3,
      "y": 1,
      "z": -3,
      "name": "Soil_Dirt"
    },
    {
      "x": 3,
      "y": 2,
      "z": -3,
      "name": "Soil_Dirt"
    },
    {
      "x": 3,
      "y": 3,
      "z": -3,
      "name": "Soil_Grass"
    },
    {
      "x": 3,
      "y": 1,
      "z": -2,
      "name": "Soil_Dirt"
    },
    {
      "x": 3,
      "y": 2,
      "z": -2,
      "name": "Soil_Dirt"
    },
    {
      "x": 3,
      "y": 3,
      "z": -2,
      "name": "Soil_Dirt"
    },
    {
      "x": 3,
      "y": 4,
      "z": -2,
      "name": "Furniture_Crude_Stool"
    },
    {
      "x": 3,
      "y": 5,
      "z": -2,
      "name": "Empty"
    },
    {
      "x": 3,
      "y": 6,
      "z": -2,
      "name": "Empty"
    },
    {
      "x": 3,
      "y": 1,
      "z": -1,
      "name": "Soil_Dirt"
    },
    {
      "x": 3,
      "y": 2,
      "z": -1,
      "name": "Soil_Dirt"
    },
    {
      "x": 3,
      "y": 3,
      "z": -1,
      "name": "Soil_Dirt"
    },
    {
      "x": 3,
      "y": 4,
      "z": -1,
      "name": "Empty"
    },
    {
      "x": 3,
      "y": 5,
      "z": -1,
      "name": "Empty"
    },
    {
      "x": 3,
      "y": 6,
      "z": -1,
      "name": "Empty"
    },
    {
      "x": 3,
      "y": 1,
      "z": 0,
      "name": "Soil_Dirt"
    },
    {
      "x": 3,
      "y": 2,
      "z": 0,
      "name": "Soil_Dirt"
    },
    {
      "x": 3,
      "y": 3,
      "z": 0,
      "name": "Soil_Grass"
    },
    {
      "x": 3,
      "y": 4,
      "z": 0,
      "name": "Plant_Bush_Berry"
    },
    {
      "x": 3,
      "y": 1,
      "z": 1,
      "name": "Soil_Dirt"
    },
    {
      "x": 3,
      "y": 2,
      "z": 1,
      "name": "Soil_Dirt"
    },
    {
      "x": 3,
      "y": 3,
      "z": 1,
      "name": "Soil_Grass"
    },
    {
      "x": 3,
      "y": 4,
      "z": 1,
      "name": "Plant_Bush"
    },
    {
      "x": 3,
      "y": 5,
      "z": 1,
      "name": "Plant_Vine_Wall",
      "rotation": 1
    },
    {
      "x": 3,
      "y": 6,
      "z": 1,
      "name": "Plant_Vine",
      "rotation": 1
    },
    {
      "x": 3,
      "y": 1,
      "z": 2,
      "name": "Soil_Dirt"
    },
    {
      "x": 3,
      "y": 2,
      "z": 2,
      "name": "Soil_Dirt"
    },
    {
      "x": 3,
      "y": 3,
      "z": 2,
      "name": "Soil_Grass"
    },
    {
      "x": 3,
      "y": 4,
      "z": 2,
      "name": "Plant_Vine",
      "rotation": 1
    },
    {
      "x": 3,
      "y": 5,
      "z": 2,
      "name": "Plant_Vine",
      "rotation": 1
    },
    {
      "x": 3,
      "y": 1,
      "z": 3,
      "name": "Soil_Dirt"
    },
    {
      "x": 3,
      "y": 2,
      "z": 3,
      "name": "Soil_Dirt"
    },
    {
      "x": 3,
      "y": 3,
      "z": 3,
      "name": "Soil_Grass"
    },
    {
      "x": 3,
      "y": 1,
      "z": 4,
      "name": "Soil_Dirt"
    },
    {
      "x": 3,
      "y": 2,
      "z": 4,
      "name": "Soil_Dirt"
    },
    {
      "x": 3,
      "y": 3,
      "z": 4,
      "name": "Soil_Grass"
    },
    {
      "x": 4,
      "y": 1,
      "z": -3,
      "name": "Soil_Dirt"
    },
    {
      "x": 4,
      "y": 2,
      "z": -3,
      "name": "Soil_Dirt"
    },
    {
      "x": 4,
      "y": 3,
      "z": -3,
      "name": "Soil_Grass"
    },
    {
      "x": 4,
      "y": 1,
      "z": -2,
      "name": "Soil_Dirt"
    },
    {
      "x": 4,
      "y": 2,
      "z": -2,
      "name": "Soil_Dirt"
    },
    {
      "x": 4,
      "y": 3,
      "z": -2,
      "name": "Soil_Grass"
    },
    {
      "x": 4,
      "y": 1,
      "z": -1,
      "name": "Soil_Dirt"
    },
    {
      "x": 4,
      "y": 2,
      "z": -1,
      "name": "Soil_Dirt"
    },
    {
      "x": 4,
      "y": 3,
      "z": -1,
      "name": "Soil_Grass"
    },
    {
      "x": 4,
      "y": 4,
      "z": -1,
      "name": "Plant_Bush"
    }
  ],
  "entities": [
    {
      "Components": {
        "SpawnSuppressor": {
          "Position": {
            "X": 0.2719879150390625,
            "Y": 5.01568603515625,
            "Z": -0.14290237426757812
          },
          "HeadRotation": {
            "Pitch": 0.0,
            "Yaw": -3.08907413482666,
            "Roll": 0.0
          },
          "BodyRotation": {
            "Pitch": 0.0,
            "Yaw": 0.052518606185913086,
            "Roll": 0.0
          },
          "Usable": false,
          "DisplayName": "SpawnSuppression: Spawn_Camp",
          "NameTagVisible": true,
          "UUID": {
            "$binary": "RyTZn1hgMNmXx0eNCOVEIQ==",
            "$type": "04"
          },
          "Model": {
            "Id": "NPC_Spawn_Marker",
            "Scale": 1.0
          },
          "Metadata": {},
          "Velocity": {
            "X": 0.0,
            "Y": 0.0,
            "Z": 0.0
          }
        },
        "SpawnSuppression": {
          "SpawnSuppression": "Spawn_Camp"
        }
      }
    }
  ]
}