{
  "version": 8,
  "blockIdVersion": 0,
  "anchorX": 1,
  "anchorY": 3,
  "anchorZ": 1,
  "blocks": [
    {
      "x": -4,
      "y": 1,
      "z": 0,
      "name": "Soil_Dirt"
    },
    {
      "x": -4,
      "y": 2,
      "z": 0,
      "name": "Soil_Dirt"
    },
    {
      "x": -4,
      "y": 3,
      "z": 0,
      "name": "Soil_Grass"
    },
    {
      "x": -4,
      "y": 4,
      "z": 0,
      "name": "Plant_Bush"
    },
    {
      "x": -4,
      "y": 3,
      "z": 1,
      "name": "Rock_Stone"
    },
    {
      "x": -4,
      "y": 4,
      "z": 1,
      "name": "Rock_Stone_Mossy"
    },
    {
      "x": -4,
      "y": 5,
      "z": 1,
      "name": "Rock_Stone"
    },
    {
      "x": -4,
      "y": 6,
      "z": 1,
      "name": "Plant_Moss_Rug_Green"
    },
    {
      "x": -4,
      "y": 3,
      "z": 2,
      "name": "Rock_Stone_Mossy"
    },
    {
      "x": -4,
      "y": 4,
      "z": 2,
      "name": "Rock_Stone"
    },
    {
      "x": -4,
      "y": 5,
      "z": 2,
      "name": "Rock_Stone"
    },
    {
      "x": -4,
      "y": 3,
      "z": 3,
      "name": "Rock_Stone"
    },
    {
      "x": -4,
      "y": 4,
      "z": 3,
      "name": "Rock_Stone"
    },
    {
      "x": -3,
      "y": 1,
      "z": -2,
      "name": "Soil_Dirt"
    },
    {
      "x": -3,
      "y": 2,
      "z": -2,
      "name": "Soil_Dirt"
    },
    {
      "x": -3,
      "y": 3,
      "z": -2,
      "name": "Soil_Grass"
    },
    {
      "x": -3,
      "y": 1,
      "z": -1,
      "name": "Soil_Dirt"
    },
    {
      "x": -3,
      "y": 2,
      "z": -1,
      "name": "Soil_Dirt"
    },
    {
      "x": -3,
      "y": 3,
      "z": -1,
      "name": "Soil_Grass"
    },
    {
      "x": -3,
      "y": 4,
      "z": -1,
      "name": "Plant_Bush_Berry"
    },
    {
      "x": -3,
      "y": 1,
      "z": 0,
      "name": "Soil_Dirt"
    },
    {
      "x": -3,
      "y": 2,
      "z": 0,
      "name": "Soil_Dirt"
    },
    {
      "x": -3,
      "y": 3,
      "z": 0,
      "name": "Rock_Stone"
    },
    {
      "x": -3,
      "y": 4,
      "z": 0,
      "name": "Rock_Stone"
    },
    {
      "x": -3,
      "y": 5,
      "z": 0,
      "name": "Rock_Stone"
    },
    {
      "x": -3,
      "y": 1,
      "z": 1,
      "name": "Rock_Stone"
    },
    {
      "x": -3,
      "y": 2,
      "z": 1,
      "name": "Rock_Stone"
    },
    {
      "x": -3,
      "y": 3,
      "z": 1,
      "name": "Rock_Stone"
    },
    {
      "x": -3,
      "y": 4,
      "z": 1,
      "name": "Rock_Stone"
    },
    {
      "x": -3,
      "y": 5,
      "z": 1,
      "name": "Rock_Stone"
    },
    {
      "x": -3,
      "y": 6,
      "z": 1,
      "name": "Rock_Stone_Mossy"
    },
    {
      "x": -3,
      "y": 1,
      "z": 2,
      "name": "Rock_Stone"
    },
    {
      "x": -3,
      "y": 2,
      "z": 2,
      "name": "Rock_Stone"
    },
    {
      "x": -3,
      "y": 3,
      "z": 2,
      "name": "Rock_Stone"
    },
    {
      "x": -3,
      "y": 4,
      "z": 2,
      "name": "Rock_Stone"
    },
    {
      "x": -3,
      "y": 5,
      "z": 2,
      "name": "Rock_Stone"
    },
    {
      "x": -3,
      "y": 6,
      "z": 2,
      "name": "Rock_Stone"
    },
    {
      "x": -3,
      "y": 1,
      "z": 3,
      "name": "Rock_Stone"
    },
    {
      "x": -3,
      "y": 2,
      "z": 3,
      "name": "Rock_Stone"
    },
    {
      "x": -3,
      "y": 3,
      "z": 3,
      "name": "Rock_Stone"
    },
    {
      "x": -3,
      "y": 4,
      "z": 3,
      "name": "Rock_Stone"
    },
    {
      "x": -3,
      "y": 5,
      "z": 3,
      "name": "Rock_Stone"
    },
    {
      "x": -3,
      "y": 3,
      "z": 4,
      "name": "Rock_Stone"
    },
    {
      "x": -3,
      "y": 4,
      "z": 4,
      "name": "Rock_Stone"
    },
    {
      "x": -2,
      "y": 1,
      "z": -3,
      "name": "Soil_Dirt"
    },
    {
      "x": -2,
      "y": 2,
      "z": -3,
      "name": "Soil_Dirt"
    },
    {
      "x": -2,
      "y": 3,
      "z": -3,
      "name": "Soil_Grass"
    },
    {
      "x": -2,
      "y": 1,
      "z": -2,
      "name": "Soil_Dirt"
    },
    {
      "x": -2,
      "y": 2,
      "z": -2,
      "name": "Soil_Dirt"
    },
    {
      "x": -2,
      "y": 3,
      "z": -2,
      "name": "Soil_Grass"
    },
    {
      "x": -2,
      "y": 1,
      "z": -1,
      "name": "Soil_Dirt"
    },
    {
      "x": -2,
      "y": 2,
      "z": -1,
      "name": "Soil_Dirt"
    },
    {
      "x": -2,
      "y": 3,
      "z": -1,
      "name": "Soil_Dirt"
    },
    {
      "x": -2,
      "y": 4,
      "z": -1,
      "name": "Empty"
    },
    {
      "x": -2,
      "y": 5,
      "z": -1,
      "name": "Plant_Vine_Wall",
      "rotation": 2
    },
    {
      "x": -2,
      "y": 1,
      "z": 0,
      "name": "Soil_Dirt"
    },
    {
      "x": -2,
      "y": 2,
      "z": 0,
      "name": "Soil_Dirt"
    },
    {
      "x": -2,
      "y": 3,
      "z": 0,
      "name": "Rock_Stone"
    },
    {
      "x": -2,
      "y": 4,
      "z": 0,
      "name": "Rock_Stone"
    },
    {
      "x": -2,
      "y": 5,
      "z": 0,
      "name": "Rock_Stone_Mossy"
    },
    {
      "x": -2,
      "y": 6,
      "z": 0,
      "name": "Rock_Stone_Mossy"
    },
    {
      "x": -2,
      "y": 7,
      "z": 0,
      "name": "Plant_Moss_Rug_Green"
    },
    {
      "x": -2,
      "y": 1,
      "z": 1,
      "name": "Rock_Stone"
    },
    {
      "x": -2,
      "y": 2,
      "z": 1,
      "name": "Rock_Stone"
    },
    {
      "x": -2,
      "y": 3,
      "z": 1,
      "name": "Rock_Stone"
    },
    {
      "x": -2,
      "y": 4,
      "z": 1,
      "name": "Rock_Stone"
    },
    {
      "x": -2,
      "y": 5,
      "z": 1,
      "name": "Rock_Stone"
    },
    {
      "x": -2,
      "y": 6,
      "z": 1,
      "name": "Rock_Stone_Mossy"
    },
    {
      "x": -2,
      "y": 7,
      "z": 1,
      "name": "Plant_Moss_Rug_Green"
    },
    {
      "x": -2,
      "y": 1,
      "z": 2,
      "name": "Rock_Stone"
    },
    {
      "x": -2,
      "y": 2,
      "z": 2,
      "name": "Rock_Stone"
    },
    {
      "x": -2,
      "y": 3,
      "z": 2,
      "name": "Rock_Stone"
    },
    {
      "x": -2,
      "y": 4,
      "z": 2,
      "name": "Rock_Stone"
    },
    {
      "x": -2,
      "y": 5,
      "z": 2,
      "name": "Rock_Stone"
    },
    {
      "x": -2,
      "y": 6,
      "z": 2,
      "name": "Rock_Stone_Mossy"
    },
    {
      "x": -2,
      "y": 7,
      "z": 2,
      "name": "Plant_Moss_Green"
    },
    {
      "x": -2,
      "y": 1,
      "z": 3,
      "name": "Rock_Stone"
    },
    {
      "x": -2,
      "y": 2,
      "z": 3,
      "name": "Rock_Stone"
    },
    {
      "x": -2,
      "y": 3,
      "z": 3,
      "name": "Rock_Stone"
    },
    {
      "x": -2,
      "y": 4,
      "z": 3,
      "name": "Rock_Stone"
    },
    {
      "x": -2,
      "y": 5,
      "z": 3,
      "name": "Rock_Stone"
    },
    {
      "x": -2,
      "y": 6,
      "z": 3,
      "name": "Rock_Stone_Mossy"
    },
    {
      "x": -2,
      "y": 1,
      "z": 4,
      "name": "Rock_Stone"
    },
    {
      "x": -2,
      "y": 2,
      "z": 4,
      "name": "Rock_Stone"
    },
    {
      "x": -2,
      "y": 3,
      "z": 4,
      "name": "Rock_Stone"
    },
    {
      "x": -2,
      "y": 4,
      "z": 4,
      "name": "Rock_Stone"
    },
    {
      "x": -2,
      "y": 5,
      "z": 4,
      "name": "Rock_Stone"
    },
    {
      "x": -2,
      "y": 6,
      "z": 4,
      "name": "Plant_Moss_Rug_Green"
    },
    {
      "x": -1,
      "y": 1,
      "z": -4,
      "name": "Soil_Dirt"
    },
    {
      "x": -1,
      "y": 2,
      "z": -4,
      "name": "Soil_Dirt"
    },
    {
      "x": -1,
      "y": 3,
      "z": -4,
      "name": "Soil_Grass"
    },
    {
      "x": -1,
      "y": 1,
      "z": -3,
      "name": "Soil_Dirt"
    },
    {
      "x": -1,
      "y": 2,
      "z": -3,
      "name": "Soil_Dirt"
    },
    {
      "x": -1,
      "y": 3,
      "z": -3,
      "name": "Soil_Grass"
    },
    {
      "x": -1,
      "y": 1,
      "z": -2,
      "name": "Soil_Dirt"
    },
    {
      "x": -1,
      "y": 2,
      "z": -2,
      "name": "Soil_Dirt"
    },
    {
      "x": -1,
      "y": 3,
      "z": -2,
      "name": "Soil_Dirt"
    },
    {
      "x": -1,
      "y": 4,
      "z": -2,
      "name": "Empty"
    },
    {
      "x": -1,
      "y": 5,
      "z": -2,
      "name": "Empty"
    },
    {
      "x": -1,
      "y": 6,
      "z": -2,
      "name": "Empty"
    },
    {
      "x": -1,
      "y": 1,
      "z": -1,
      "name": "Soil_Dirt"
    },
    {
      "x": -1,
      "y": 2,
      "z": -1,
      "name": "Soil_Dirt"
    },
    {
      "x": -1,
      "y": 3,
      "z": -1,
      "name": "Soil_Dirt"
    },
    {
      "x": -1,
      "y": 4,
      "z": -1,
      "name": "Empty"
    },
    {
      "x": -1,
      "y": 5,
      "z": -1,
      "name": "Empty"
    },
    {
      "x": -1,
      "y": 6,
      "z": -1,
      "name": "Empty"
    },
    {
      "x": -1,
      "y": 1,
      "z": 0,
      "name": "Soil_Dirt"
    },
    {
      "x": -1,
      "y": 2,
      "z": 0,
      "name": "Soil_Dirt"
    },
    {
      "x": -1,
      "y": 3,
      "z": 0,
      "name": "Soil_Dirt"
    },
    {
      "x": -1,
      "y": 4,
      "z": 0,
      "name": "Empty"
    },
    {
      "x": -1,
      "y": 5,
      "z": 0,
      "name": "Empty"
    },
    {
      "x": -1,
      "y": 6,
      "z": 0,
      "name": "Wood_Oak_Branch_Long",
      "rotation": 5
    },
    {
      "x": -1,
      "y": 1,
      "z": 1,
      "name": "Soil_Dirt"
    },
    {
      "x": -1,
      "y": 2,
      "z": 1,
      "name": "Soil_Dirt"
    },
    {
      "x": -1,
      "y": 3,
      "z": 1,
      "name": "Soil_Dirt"
    },
    {
      "x": -1,
      "y": 4,
      "z": 1,
      "name": "Rock_Stone"
    },
    {
      "x": -1,
      "y": 5,
      "z": 1,
      "name": "Rock_Stone"
    },
    {
      "x": -1,
      "y": 6,
      "z": 1,
      "name": "Rock_Stone_Mossy"
    },
    {
      "x": -1,
      "y": 7,
      "z": 1,
      "name": "Plant_Moss_Rug_Green"
    },
    {
      "x": -1,
      "y": 1,
      "z": 2,
      "name": "Rock_Stone"
    },
    {
      "x": -1,
      "y": 2,
      "z": 2,
      "name": "Rock_Stone"
    },
    {
      "x": -1,
      "y": 3,
      "z": 2,
      "name": "Rock_Stone"
    },
    {
      "x": -1,
      "y": 4,
      "z": 2,
      "name": "Rock_Stone"
    },
    {
      "x": -1,
      "y": 5,
      "z": 2,
      "name": "Rock_Stone"
    },
    {
      "x": -1,
      "y": 6,
      "z": 2,
      "name": "Rock_Stone"
    },
    {
      "x": -1,
      "y": 1,
      "z": 3,
      "name": "Rock_Stone"
    },
    {
      "x": -1,
      "y": 2,
      "z": 3,
      "name": "Rock_Stone"
    },
    {
      "x": -1,
      "y": 3,
      "z": 3,
      "name": "Rock_Stone"
    },
    {
      "x": -1,
      "y": 4,
      "z": 3,
      "name": "Rock_Stone"
    },
    {
      "x": -1,
      "y": 5,
      "z": 3,
      "name": "Soil_Dirt"
    },
    {
      "x": -1,
      "y": 6,
      "z": 3,
      "name": "Soil_Grass"
    },
    {
      "x": -1,
      "y": 7,
      "z": 3,
      "name": "Plant_Grass_Lush_Short"
    },
    {
      "x": -1,
      "y": 1,
      "z": 4,
      "name": "Soil_Dirt"
    },
    {
      "x": -1,
      "y": 2,
      "z": 4,
      "name": "Soil_Dirt"
    },
    {
      "x": -1,
      "y": 3,
      "z": 4,
      "name": "Soil_Dirt"
    },
    {
      "x": -1,
      "y": 4,
      "z": 4,
      "name": "Soil_Dirt"
    },
    {
      "x": -1,
      "y": 5,
      "z": 4,
      "name": "Soil_Dirt"
    },
    {
      "x": -1,
      "y": 1,
      "z": 5,
      "name": "Soil_Dirt"
    },
    {
      "x": -1,
      "y": 2,
      "z": 5,
      "name": "Soil_Dirt"
    },
    {
      "x": -1,
      "y": 3,
      "z": 5,
      "name": "Soil_Dirt"
    },
    {
      "x": -1,
      "y": 4,
      "z": 5,
      "name": "Soil_Dirt"
    },
    {
      "x": -1,
      "y": 5,
      "z": 5,
      "name": "Plant_Moss_Green"
    },
    {
      "x": 0,
      "y": 1,
      "z": -4,
      "name": "Soil_Dirt"
    },
    {
      "x": 0,
      "y": 2,
      "z": -4,
      "name": "Soil_Dirt"
    },
    {
      "x": 0,
      "y": 3,
      "z": -4,
      "name": "Soil_Grass"
    },
    {
      "x": 0,
      "y": 1,
      "z": -3,
      "name": "Soil_Dirt"
    },
    {
      "x": 0,
      "y": 2,
      "z": -3,
      "name": "Soil_Dirt"
    },
    {
      "x": 0,
      "y": 3,
      "z": -3,
      "name": "Soil_Pathway"
    },
    {
      "x": 0,
      "y": 4,
      "z": -3,
      "name": "Empty"
    },
    {
      "x": 0,
      "y": 5,
      "z": -3,
      "name": "Empty"
    },
    {
      "x": 0,
      "y": 6,
      "z": -3,
      "name": "Empty"
    },
    {
      "x": 0,
      "y": 1,
      "z": -2,
      "name": "Soil_Dirt"
    },
    {
      "x": 0,
      "y": 2,
      "z": -2,
      "name": "Soil_Dirt"
    },
    {
      "x": 0,
      "y": 3,
      "z": -2,
      "name": "Soil_Pathway"
    },
    {
      "x": 0,
      "y": 4,
      "z": -2,
      "name": "Empty"
    },
    {
      "x": 0,
      "y": 5,
      "z": -2,
      "name": "Empty"
    },
    {
      "x": 0,
      "y": 6,
      "z": -2,
      "name": "Empty"
    },
    {
      "x": 0,
      "y": 1,
      "z": -1,
      "name": "Soil_Dirt"
    },
    {
      "x": 0,
      "y": 2,
      "z": -1,
      "name": "Soil_Dirt"
    },
    {
      "x": 0,
      "y": 3,
      "z": -1,
      "name": "Soil_Pathway"
    },
    {
      "x": 0,
      "y": 4,
      "z": -1,
      "name": "Furniture_Crude_Stool"
    },
    {
      "x": 0,
      "y": 5,
      "z": -1,
      "name": "Empty"
    },
    {
      "x": 0,
      "y": 6,
      "z": -1,
      "name": "Empty"
    },
    {
      "x": 0,
      "y": 1,
      "z": 0,
      "name": "Soil_Dirt"
    },
    {
      "x": 0,
      "y": 2,
      "z": 0,
      "name": "Soil_Dirt"
    },
    {
      "x": 0,
      "y": 3,
      "z": 0,
      "name": "Soil_Dirt"
    },
    {
      "x": 0,
      "y": 4,
      "z": 0,
      "name": "Empty"
    },
    {
      "x": 0,
      "y": 5,
      "z": 0,
      "name": "Empty"
    },
    {
      "x": 0,
      "y": 6,
      "z": 0,
      "name": "Wood_Oak_Branch_Long",
      "rotation": 5
    },
    {
      "x": 0,
      "y": 1,
      "z": 1,
      "name": "Soil_Dirt"
    },
    {
      "x": 0,
      "y": 2,
      "z": 1,
      "name": "Soil_Dirt"
    },
    {
      "x": 0,
      "y": 3,
      "z": 1,
      "name": "Soil_Pathway"
    },
    {
      "x": 0,
      "y": 4,
      "z": 1,
      "name": "Empty"
    },
    {
      "x": 0,
      "y": 5,
      "z": 1,
      "name": "Empty"
    },
    {
      "x": 0,
      "y": 6,
      "z": 1,
      "name": "Empty"
    },
    {
      "x": 0,
      "y": 1,
      "z": 2,
      "name": "Soil_Dirt"
    },
    {
      "x": 0,
      "y": 2,
      "z": 2,
      "name": "Soil_Dirt"
    },
    {
      "x": 0,
      "y": 3,
      "z": 2,
      "name": "Soil_Pathway"
    },
    {
      "x": 0,
      "y": 4,
      "z": 2,
      "name": "Empty"
    },
    {
      "x": 0,
      "y": 5,
      "z": 2,
      "name": "Empty"
    },
    {
      "x": 0,
      "y": 6,
      "z": 2,
      "name": "Wood_Oak_Branch_Long",
      "support": 15,
      "rotation": 5
    },
    {
      "x": 0,
      "y": 1,
      "z": 3,
      "name": "Soil_Dirt"
    },
    {
      "x": 0,
      "y": 2,
      "z": 3,
      "name": "Soil_Dirt"
    },
    {
      "x": 0,
      "y": 3,
      "z": 3,
      "name": "Soil_Dirt"
    },
    {
      "x": 0,
      "y": 4,
      "z": 3,
      "name": "Empty"
    },
    {
      "x": 0,
      "y": 5,
      "z": 3,
      "name": "Empty"
    },
    {
      "x": 0,
      "y": 6,
      "z": 3,
      "name": "Soil_Grass"
    },
    {
      "x": 0,
      "y": 7,
      "z": 3,
      "name": "Plant_Moss_Rug_Green"
    },
    {
      "x": 0,
      "y": 1,
      "z": 4,
      "name": "Soil_Dirt"
    },
    {
      "x": 0,
      "y": 2,
      "z": 4,
      "name": "Soil_Dirt"
    },
    {
      "x": 0,
      "y": 3,
      "z": 4,
      "name": "Soil_Dirt"
    },
    {
      "x": 0,
      "y": 4,
      "z": 4,
      "name": "Soil_Dirt"
    },
    {
      "x": 0,
      "y": 5,
      "z": 4,
      "name": "Soil_Dirt"
    },
    {
      "x": 0,
      "y": 1,
      "z": 5,
      "name": "Soil_Dirt"
    },
    {
      "x": 0,
      "y": 2,
      "z": 5,
      "name": "Soil_Dirt"
    },
    {
      "x": 0,
      "y": 3,
      "z": 5,
      "name": "Soil_Dirt"
    },
    {
      "x": 0,
      "y": 4,
      "z": 5,
      "name": "Soil_Dirt"
    },
    {
      "x": 0,
      "y": 5,
      "z": 5,
      "name": "Soil_Grass"
    },
    {
      "x": 0,
      "y": 1,
      "z": 6,
      "name": "Soil_Dirt"
    },
    {
      "x": 0,
      "y": 2,
      "z": 6,
      "name": "Soil_Dirt"
    },
    {
      "x": 0,
      "y": 3,
      "z": 6,
      "name": "Soil_Dirt"
    },
    {
      "x": 0,
      "y": 4,
      "z": 6,
      "name": "Soil_Grass"
    },
    {
      "x": 1,
      "y": 1,
      "z": -4,
      "name": "Soil_Dirt"
    },
    {
      "x": 1,
      "y": 2,
      "z": -4,
      "name": "Soil_Dirt"
    },
    {
      "x": 1,
      "y": 3,
      "z": -4,
      "name": "Soil_Grass"
    },
    {
      "x": 1,
      "y": 1,
      "z": -3,
      "name": "Soil_Dirt"
    },
    {
      "x": 1,
      "y": 2,
      "z": -3,
      "name": "Soil_Dirt"
    },
    {
      "x": 1,
      "y": 3,
      "z": -3,
      "name": "Soil_Pathway"
    },
    {
      "x": 1,
      "y": 4,
      "z": -3,
      "name": "Empty"
    },
    {
      "x": 1,
      "y": 5,
      "z": -3,
      "name": "Empty"
    },
    {
      "x": 1,
      "y": 6,
      "z": -3,
      "name": "Empty"
    },
    {
      "x": 1,
      "y": 1,
      "z": -2,
      "name": "Soil_Dirt"
    },
    {
      "x": 1,
      "y": 2,
      "z": -2,
      "name": "Soil_Dirt"
    },
    {
      "x": 1,
      "y": 3,
      "z": -2,
      "name": "Soil_Pathway"
    },
    {
      "x": 1,
      "y": 4,
      "z": -2,
      "name": "Empty"
    },
    {
      "x": 1,
      "y": 5,
      "z": -2,
      "name": "Empty"
    },
    {
      "x": 1,
      "y": 6,
      "z": -2,
      "name": "Empty"
    },
    {
      "x": 1,
      "y": 1,
      "z": -1,
      "name": "Soil_Dirt"
    },
    {
      "x": 1,
      "y": 2,
      "z": -1,
      "name": "Soil_Dirt"
    },
    {
      "x": 1,
      "y": 3,
      "z": -1,
      "name": "Soil_Pathway"
    },
    {
      "x": 1,
      "y": 4,
      "z": -1,
      "name": "Empty"
    },
    {
      "x": 1,
      "y": 5,
      "z": -1,
      "name": "Empty"
    },
    {
      "x": 1,
      "y": 6,
      "z": -1,
      "name": "Empty"
    },
    {
      "x": 1,
      "y": 1,
      "z": 0,
      "name": "Soil_Dirt"
    },
    {
      "x": 1,
      "y": 2,
      "z": 0,
      "name": "Soil_Dirt"
    },
    {
      "x": 1,
      "y": 3,
      "z": 0,
      "name": "Soil_Dirt"
    },
    {
      "x": 1,
      "y": 4,
      "z": 0,
      "name": "Empty"
    },
    {
      "x": 1,
      "y": 5,
      "z": 0,
      "name": "Empty"
    },
    {
      "x": 1,
      "y": 6,
      "z": 0,
      "name": "Wood_Oak_Branch_Long",
      "rotation": 5
    },
    {
      "x": 1,
      "y": 1,
      "z": 1,
      "name": "Soil_Dirt"
    },
    {
      "x": 1,
      "y": 2,
      "z": 1,
      "name": "Soil_Dirt"
    },
    {
      "x": 1,
      "y": 3,
      "z": 1,
      "name": "Soil_Dirt"
    },
    {
      "x": 1,
      "y": 4,
      "z": 1,
      "name": "Empty"
    },
    {
      "x": 1,
      "y": 5,
      "z": 1,
      "name": "Empty"
    },
    {
      "x": 1,
      "y": 6,
      "z": 1,
      "name": "Empty"
    },
    {
      "x": 1,
      "y": 1,
      "z": 2,
      "name": "Soil_Dirt"
    },
    {
      "x": 1,
      "y": 2,
      "z": 2,
      "name": "Soil_Dirt"
    },
    {
      "x": 1,
      "y": 3,
      "z": 2,
      "name": "Soil_Dirt"
    },
    {
      "x": 1,
      "y": 4,
      "z": 2,
      "name": "Empty"
    },
    {
      "x": 1,
      "y": 5,
      "z": 2,
      "name": "Empty"
    },
    {
      "x": 1,
      "y": 6,
      "z": 2,
      "name": "Wood_Oak_Branch_Long",
      "support": 15,
      "rotation": 5
    },
    {
      "x": 1,
      "y": 1,
      "z": 3,
      "name": "Soil_Dirt"
    },
    {
      "x": 1,
      "y": 2,
      "z": 3,
      "name": "Soil_Dirt"
    },
    {
      "x": 1,
      "y": 3,
      "z": 3,
      "name": "Soil_Dirt"
    },
    {
      "x": 1,
      "y": 4,
      "z": 3,
      "name": "Furniture_Crude_Bed",
      "rotation": 1
    },
    {
      "x": 1,
      "y": 5,
      "z": 3,
      "name": "Empty"
    },
    {
      "x": 1,
      "y": 6,
      "z": 3,
      "name": "Soil_Grass"
    },
    {
      "x": 1,
      "y": 7,
      "z": 3,
      "name": "Plant_Grass_Lush"
    },
    {
      "x": 1,
      "y": 1,
      "z": 4,
      "name": "Soil_Dirt"
    },
    {
      "x": 1,
      "y": 2,
      "z": 4,
      "name": "Soil_Dirt"
    },
    {
      "x": 1,
      "y": 3,
      "z": 4,
      "name": "Soil_Dirt"
    },
    {
      "x": 1,
      "y": 4,
      "z": 4,
      "name": "Empty"
    },
    {
      "x": 1,
      "y": 5,
      "z": 4,
      "name": "Soil_Dirt"
    },
    {
      "x": 1,
      "y": 6,
      "z": 4,
      "name": "Plant_Moss_Short_Green"
    },
    {
      "x": 1,
      "y": 1,
      "z": 5,
      "name": "Soil_Dirt"
    },
    {
      "x": 1,
      "y": 2,
      "z": 5,
      "name": "Soil_Dirt"
    },
    {
      "x": 1,
      "y": 3,
      "z": 5,
      "name": "Soil_Dirt"
    },
    {
      "x": 1,
      "y": 4,
      "z": 5,
      "name": "Soil_Dirt"
    },
    {
      "x": 1,
      "y": 5,
      "z": 5,
      "name": "Soil_Grass"
    },
    {
      "x": 1,
      "y": 1,
      "z": 6,
      "name": "Soil_Dirt"
    },
    {
      "x": 1,
      "y": 2,
      "z": 6,
      "name": "Soil_Dirt"
    },
    {
      "x": 1,
      "y": 3,
      "z": 6,
      "name": "Soil_Dirt"
    },
    {
      "x": 1,
      "y": 4,
      "z": 6,
      "name": "Soil_Grass"
    },
    {
      "x": 1,
      "y": 5,
      "z": 6,
      "name": "Plant_Grass_Lush_Short"
    },
    {
      "x": 2,
      "y": 1,
      "z": -4,
      "name": "Soil_Dirt"
    },
    {
      "x": 2,
      "y": 2,
      "z": -4,
      "name": "Soil_Dirt"
    },
    {
      "x": 2,
      "y": 3,
      "z": -4,
      "name": "Soil_Grass"
    },
    {
      "x": 2,
      "y": 1,
      "z": -3,
      "name": "Soil_Dirt"
    },
    {
      "x": 2,
      "y": 2,
      "z": -3,
      "name": "Soil_Dirt"
    },
    {
      "x": 2,
      "y": 3,
      "z": -3,
      "name": "Soil_Grass"
    },
    {
      "x": 2,
      "y": 1,
      "z": -2,
      "name": "Soil_Dirt"
    },
    {
      "x": 2,
      "y": 2,
      "z": -2,
      "name": "Soil_Dirt"
    },
    {
      "x": 2,
      "y": 3,
      "z": -2,
      "name": "Soil_Pathway"
    },
    {
      "x": 2,
      "y": 4,
      "z": -2,
      "name": "Empty"
    },
    {
      "x": 2,
      "y": 5,
      "z": -2,
      "name": "Empty"
    },
    {
      "x": 2,
      "y": 6,
      "z": -2,
      "name": "Empty"
    },
    {
      "x": 2,
      "y": 1,
      "z": -1,
      "name": "Soil_Dirt"
    },
    {
      "x": 2,
      "y": 2,
      "z": -1,
      "name": "Soil_Dirt"
    },
    {
      "x": 2,
      "y": 3,
      "z": -1,
      "name": "Soil_Pathway"
    },
    {
      "x": 2,
      "y": 4,
      "z": -1,
      "name": "Empty"
    },
    {
      "x": 2,
      "y": 5,
      "z": -1,
      "name": "Empty"
    },
    {
      "x": 2,
      "y": 6,
      "z": -1,
      "name": "Empty"
    },
    {
      "x": 2,
      "y": 1,
      "z": 0,
      "name": "Soil_Dirt"
    },
    {
      "x": 2,
      "y": 2,
      "z": 0,
      "name": "Soil_Dirt"
    },
    {
      "x": 2,
      "y": 3,
      "z": 0,
      "name": "Soil_Pathway"
    },
    {
      "x": 2,
      "y": 4,
      "z": 0,
      "name": "Empty"
    },
    {
      "x": 2,
      "y": 5,
      "z": 0,
      "name": "Empty"
    },
    {
      "x": 2,
      "y": 6,
      "z": 0,
      "name": "Wood_Oak_Branch_Long",
      "rotation": 5
    },
    {
      "x": 2,
      "y": 1,
      "z": 1,
      "name": "Soil_Dirt"
    },
    {
      "x": 2,
      "y": 2,
      "z": 1,
      "name": "Soil_Dirt"
    },
    {
      "x": 2,
      "y": 3,
      "z": 1,
      "name": "Soil_Pathway"
    },
    {
      "x": 2,
      "y": 4,
      "z": 1,
      "name": "Empty"
    },
    {
      "x": 2,
      "y": 5,
      "z": 1,
      "name": "Empty"
    },
    {
      "x": 2,
      "y": 6,
      "z": 1,
      "name": "Empty"
    },
    {
      "x": 2,
      "y": 1,
      "z": 2,
      "name": "Soil_Dirt"
    },
    {
      "x": 2,
      "y": 2,
      "z": 2,
      "name": "Soil_Dirt"
    },
    {
      "x": 2,
      "y": 3,
      "z": 2,
      "name": "Soil_Dirt"
    },
    {
      "x": 2,
      "y": 4,
      "z": 2,
      "name": "Empty"
    },
    {
      "x": 2,
      "y": 5,
      "z": 2,
      "name": "Empty"
    },
    {
      "x": 2,
      "y": 6,
      "z": 2,
      "name": "Wood_Oak_Branch_Long",
      "support": 15,
      "rotation": 5
    },
    {
      "x": 2,
      "y": 1,
      "z": 3,
      "name": "Soil_Dirt"
    },
    {
      "x": 2,
      "y": 2,
      "z": 3,
      "name": "Soil_Dirt"
    },
    {
      "x": 2,
      "y": 3,
      "z": 3,
      "name": "Soil_Dirt"
    },
    {
      "x": 2,
      "y": 4,
      "z": 3,
      "name": "Empty"
    },
    {
      "x": 2,
      "y": 5,
      "z": 3,
      "name": "Wood_Hardwood_Stairs",
      "rotation": 8
    },
    {
      "x": 2,
      "y": 6,
      "z": 3,
      "name": "Wood_Hardwood_Stairs"
    },
    {
      "x": 2,
      "y": 1,
      "z": 4,
      "name": "Soil_Dirt"
    },
    {
      "x": 2,
      "y": 2,
      "z": 4,
      "name": "Soil_Dirt"
    },
    {
      "x": 2,
      "y": 3,
      "z": 4,
      "name": "Soil_Dirt"
    },
    {
      "x": 2,
      "y": 4,
      "z": 4,
      "name": "Wood_Hardwood_Stairs",
      "rotation": 8
    },
    {
      "x": 2,
      "y": 5,
      "z": 4,
      "name": "Wood_Hardwood_Stairs"
    },
    {
      "x": 2,
      "y": 1,
      "z": 5,
      "name": "Soil_Dirt"
    },
    {
      "x": 2,
      "y": 2,
      "z": 5,
      "name": "Soil_Dirt"
    },
    {
      "x": 2,
      "y": 3,
      "z": 5,
      "name": "Soil_Dirt"
    },
    {
      "x": 2,
      "y": 4,
      "z": 5,
      "name": "Wood_Hardwood_Stairs"
    },
    {
      "x": 2,
      "y": 1,
      "z": 6,
      "name": "Soil_Dirt"
    },
    {
      "x": 2,
      "y": 2,
      "z": 6,
      "name": "Soil_Dirt"
    },
    {
      "x": 2,
      "y": 3,
      "z": 6,
      "name": "Soil_Grass"
    },
    {
      "x": 3,
      "y": 1,
      "z": -3,
      "name": "Soil_Dirt"
    },
    {
      "x": 3,
      "y": 2,
      "z": -3,
      "name": "Soil_Dirt"
    },
    {
      "x": 3,
      "y": 3,
      "z": -3,
      "name": "Soil_Grass"
    },
    {
      "x": 3,
      "y": 1,
      "z": -2,
      "name": "Soil_Dirt"
    },
    {
      "x": 3,
      "y": 2,
      "z": -2,
      "name": "Soil_Dirt"
    },
    {
      "x": 3,
      "y": 3,
      "z": -2,
      "name": "Soil_Grass"
    },
    {
      "x": 3,
      "y": 1,
      "z": -1,
      "name": "Soil_Dirt"
    },
    {
      "x": 3,
      "y": 2,
      "z": -1,
      "name": "Soil_Dirt"
    },
    {
      "x": 3,
      "y": 3,
      "z": -1,
      "name": "Soil_Pathway"
    },
    {
      "x": 3,
      "y": 4,
      "z": -1,
      "name": "Furniture_Crude_Chest_Small",
      "components": {
        "Components": {
          "container": {
            "Custom": false,
            "AllowViewing": true,
            "Droplist": "Unique_Start",
            "ItemContainer": {
              "Capacity": 18,
              "Items": {}
            }
          }
        }
      },
      "rotation": 3
    },
    {
      "x": 3,
      "y": 5,
      "z": -1,
      "name": "Empty"
    },
    {
      "x": 3,
      "y": 6,
      "z": -1,
      "name": "Empty"
    },
    {
      "x": 3,
      "y": 1,
      "z": 0,
      "name": "Soil_Dirt"
    },
    {
      "x": 3,
      "y": 2,
      "z": 0,
      "name": "Soil_Dirt"
    },
    {
      "x": 3,
      "y": 3,
      "z": 0,
      "name": "Soil_Dirt"
    },
    {
      "x": 3,
      "y": 4,
      "z": 0,
      "name": "Wood_Oak_Branch_Long",
      "support": 15
    },
    {
      "x": 3,
      "y": 5,
      "z": 0,
      "name": "Wood_Oak_Branch_Long",
      "support": 15
    },
    {
      "x": 3,
      "y": 6,
      "z": 0,
      "name": "Wood_Oak_Trunk",
      "support": 15,
      "rotation": 4
    },
    {
      "x": 3,
      "y": 7,
      "z": 0,
      "name": "Plant_Moss_Rug_Green"
    },
    {
      "x": 3,
      "y": 1,
      "z": 1,
      "name": "Soil_Dirt"
    },
    {
      "x": 3,
      "y": 2,
      "z": 1,
      "name": "Soil_Dirt"
    },
    {
      "x": 3,
      "y": 3,
      "z": 1,
      "name": "Soil_Pathway"
    },
    {
      "x": 3,
      "y": 4,
      "z": 1,
      "name": "Empty"
    },
    {
      "x": 3,
      "y": 5,
      "z": 1,
      "name": "Empty"
    },
    {
      "x": 3,
      "y": 6,
      "z": 1,
      "name": "Wood_Oak_Trunk",
      "support": 15,
      "rotation": 4
    },
    {
      "x": 3,
      "y": 7,
      "z": 1,
      "name": "Plant_Moss_Rug_Green"
    },
    {
      "x": 3,
      "y": 1,
      "z": 2,
      "name": "Soil_Dirt"
    },
    {
      "x": 3,
      "y": 2,
      "z": 2,
      "name": "Soil_Dirt"
    },
    {
      "x": 3,
      "y": 3,
      "z": 2,
      "name": "Soil_Pathway"
    },
    {
      "x": 3,
      "y": 4,
      "z": 2,
      "name": "Empty"
    },
    {
      "x": 3,
      "y": 5,
      "z": 2,
      "name": "Empty"
    },
    {
      "x": 3,
      "y": 6,
      "z": 2,
      "name": "Wood_Oak_Trunk",
      "support": 15,
      "rotation": 4
    },
    {
      "x": 3,
      "y": 7,
      "z": 2,
      "name": "Plant_Moss_Short_Green"
    },
    {
      "x": 3,
      "y": 1,
      "z": 3,
      "name": "Soil_Dirt"
    },
    {
      "x": 3,
      "y": 2,
      "z": 3,
      "name": "Soil_Dirt"
    },
    {
      "x": 3,
      "y": 3,
      "z": 3,
      "name": "Soil_Pathway"
    },
    {
      "x": 3,
      "y": 4,
      "z": 3,
      "name": "Wood_Oak_Branch_Long",
      "support": 15
    },
    {
      "x": 3,
      "y": 5,
      "z": 3,
      "name": "Wood_Oak_Branch_Long",
      "support": 15
    },
    {
      "x": 3,
      "y": 6,
      "z": 3,
      "name": "Wood_Oak_Trunk",
      "support": 15,
      "rotation": 4
    },
    {
      "x": 3,
      "y": 1,
      "z": 4,
      "name": "Soil_Dirt"
    },
    {
      "x": 3,
      "y": 2,
      "z": 4,
      "name": "Soil_Dirt"
    },
    {
      "x": 3,
      "y": 3,
      "z": 4,
      "name": "Soil_Grass"
    },
    {
      "x": 3,
      "y": 5,
      "z": 4,
      "name": "Plant_Vine_Wall"
    },
    {
      "x": 3,
      "y": 6,
      "z": 4,
      "name": "Plant_Vine"
    },
    {
      "x": 3,
      "y": 1,
      "z": 5,
      "name": "Soil_Dirt"
    },
    {
      "x": 3,
      "y": 2,
      "z": 5,
      "name": "Soil_Dirt"
    },
    {
      "x": 3,
      "y": 3,
      "z": 5,
      "name": "Soil_Grass"
    },
    {
      "x": 4,
      "y": 1,
      "z": -2,
      "name": "Soil_Dirt"
    },
    {
      "x": 4,
      "y": 2,
      "z": -2,
      "name": "Soil_Dirt"
    },
    {
      "x": 4,
      "y": 3,
      "z": -2,
      "name": "Soil_Grass"
    },
    {
      "x": 4,
      "y": 1,
      "z": -1,
      "name": "Soil_Dirt"
    },
    {
      "x": 4,
      "y": 2,
      "z": -1,
      "name": "Soil_Dirt"
    },
    {
      "x": 4,
      "y": 3,
      "z": -1,
      "name": "Soil_Grass"
    },
    {
      "x": 4,
      "y": 1,
      "z": 0,
      "name": "Soil_Dirt"
    },
    {
      "x": 4,
      "y": 2,
      "z": 0,
      "name": "Soil_Dirt"
    },
    {
      "x": 4,
      "y": 3,
      "z": 0,
      "name": "Soil_Dirt"
    },
    {
      "x": 4,
      "y": 4,
      "z": 0,
      "name": "Plant_Vine_Wall",
      "rotation": 1
    },
    {
      "x": 4,
      "y": 5,
      "z": 0,
      "name": "Plant_Vine",
      "rotation": 1
    },
    {
      "x": 4,
      "y": 6,
      "z": 0,
      "name": "Plant_Vine",
      "rotation": 1
    },
    {
      "x": 4,
      "y": 1,
      "z": 1,
      "name": "Soil_Dirt"
    },
    {
      "x": 4,
      "y": 2,
      "z": 1,
      "name": "Soil_Dirt"
    },
    {
      "x": 4,
      "y": 3,
      "z": 1,
      "name": "Soil_Dirt"
    },
    {
      "x": 4,
      "y": 5,
      "z": 1,
      "name": "Plant_Vine_Wall",
      "rotation": 1
    },
    {
      "x": 4,
      "y": 6,
      "z": 1,
      "name": "Plant_Vine",
      "rotation": 1
    },
    {
      "x": 4,
      "y": 1,
      "z": 2,
      "name": "Soil_Dirt"
    },
    {
      "x": 4,
      "y": 2,
      "z": 2,
      "name": "Soil_Dirt"
    },
    {
      "x": 4,
      "y": 3,
      "z": 2,
      "name": "Soil_Grass"
    },
    {
      "x": 4,
      "y": 4,
      "z": 2,
      "name": "Plant_Bush"
    },
    {
      "x": 4,
      "y": 1,
      "z": 3,
      "name": "Soil_Dirt"
    },
    {
      "x": 4,
      "y": 2,
      "z": 3,
      "name": "Soil_Dirt"
    },
    {
      "x": 4,
      "y": 3,
      "z": 3,
      "name": "Soil_Grass"
    },
    {
      "x": 4,
      "y": 4,
      "z": 3,
      "name": "Plant_Bush"
    },
    {
      "x": 4,
      "y": 6,
      "z": 3,
      "name": "Plant_Vine_Wall",
      "rotation": 1
    },
    {
      "x": 4,
      "y": 1,
      "z": 4,
      "name": "Soil_Dirt"
    },
    {
      "x": 4,
      "y": 2,
      "z": 4,
      "name": "Soil_Dirt"
    },
    {
      "x": 4,
      "y": 3,
      "z": 4,
      "name": "Soil_Grass"
    },
    {
      "x": 5,
      "y": 1,
      "z": -1,
      "name": "Soil_Dirt"
    },
    {
      "x": 5,
      "y": 2,
      "z": -1,
      "name": "Soil_Dirt"
    },
    {
      "x": 5,
      "y": 3,
      "z": -1,
      "name": "Soil_Grass"
    },
    {
      "x": 5,
      "y": 1,
      "z": 0,
      "name": "Soil_Dirt"
    },
    {
      "x": 5,
      "y": 2,
      "z": 0,
      "name": "Soil_Dirt"
    },
    {
      "x": 5,
      "y": 3,
      "z": 0,
      "name": "Soil_Grass"
    },
    {
      "x": 5,
      "y": 1,
      "z": 1,
      "name": "Soil_Dirt"
    },
    {
      "x": 5,
      "y": 2,
      "z": 1,
      "name": "Soil_Dirt"
    },
    {
      "x": 5,
      "y": 3,
      "z": 1,
      "name": "Soil_Grass"
    },
    {
      "x": 5,
      "y": 4,
      "z": 1,
      "name": "Plant_Bush_Berry"
    },
    {
      "x": 5,
      "y": 1,
      "z": 2,
      "name": "Soil_Dirt"
    },
    {
      "x": 5,
      "y": 2,
      "z": 2,
      "name": "Soil_Dirt"
    },
    {
      "x": 5,
      "y": 3,
      "z": 2,
      "name": "Soil_Grass"
    },
    {
      "x": 5,
      "y": 4,
      "z": 2,
      "name": "Plant_Bush_Berry"
    }
  ]
}