{
  "version": 8,
  "blockIdVersion": 0,
  "anchorX": 2,
  "anchorY": 6,
  "anchorZ": 0,
  "blocks": [
    {
      "x": -2,
      "y": 4,
      "z": -4,
      "name": "Soil_Dirt"
    },
    {
      "x": -2,
      "y": 5,
      "z": -4,
      "name": "Soil_Dirt"
    },
    {
      "x": -2,
      "y": 6,
      "z": -4,
      "name": "Soil_Grass"
    },
    {
      "x": -2,
      "y": 4,
      "z": -3,
      "name": "Soil_Dirt"
    },
    {
      "x": -2,
      "y": 5,
      "z": -3,
      "name": "Soil_Dirt"
    },
    {
      "x": -2,
      "y": 6,
      "z": -3,
      "name": "Soil_Grass"
    },
    {
      "x": -2,
      "y": 4,
      "z": -2,
      "name": "Soil_Dirt"
    },
    {
      "x": -2,
      "y": 5,
      "z": -2,
      "name": "Soil_Dirt"
    },
    {
      "x": -2,
      "y": 6,
      "z": -2,
      "name": "Soil_Grass"
    },
    {
      "x": -2,
      "y": 4,
      "z": -1,
      "name": "Soil_Dirt"
    },
    {
      "x": -2,
      "y": 5,
      "z": -1,
      "name": "Soil_Dirt"
    },
    {
      "x": -2,
      "y": 6,
      "z": -1,
      "name": "Soil_Grass"
    },
    {
      "x": -2,
      "y": 4,
      "z": 0,
      "name": "Soil_Dirt"
    },
    {
      "x": -2,
      "y": 5,
      "z": 0,
      "name": "Soil_Dirt"
    },
    {
      "x": -2,
      "y": 6,
      "z": 0,
      "name": "Soil_Grass"
    },
    {
      "x": -2,
      "y": 4,
      "z": 2,
      "name": "Soil_Dirt"
    },
    {
      "x": -2,
      "y": 5,
      "z": 2,
      "name": "Soil_Dirt"
    },
    {
      "x": -2,
      "y": 6,
      "z": 2,
      "name": "Soil_Grass"
    },
    {
      "x": -2,
      "y": 7,
      "z": 2,
      "name": "Plant_Bush_Berry"
    },
    {
      "x": -2,
      "y": 4,
      "z": 3,
      "name": "Soil_Dirt"
    },
    {
      "x": -2,
      "y": 5,
      "z": 3,
      "name": "Soil_Dirt"
    },
    {
      "x": -2,
      "y": 6,
      "z": 3,
      "name": "Soil_Grass"
    },
    {
      "x": -2,
      "y": 7,
      "z": 3,
      "name": "Plant_Bush_Berry"
    },
    {
      "x": -1,
      "y": 4,
      "z": -5,
      "name": "Soil_Dirt"
    },
    {
      "x": -1,
      "y": 5,
      "z": -5,
      "name": "Soil_Dirt"
    },
    {
      "x": -1,
      "y": 6,
      "z": -5,
      "name": "Soil_Grass"
    },
    {
      "x": -1,
      "y": 4,
      "z": -4,
      "name": "Soil_Dirt"
    },
    {
      "x": -1,
      "y": 5,
      "z": -4,
      "name": "Soil_Dirt"
    },
    {
      "x": -1,
      "y": 6,
      "z": -4,
      "name": "Soil_Grass"
    },
    {
      "x": -1,
      "y": 4,
      "z": -3,
      "name": "Soil_Dirt"
    },
    {
      "x": -1,
      "y": 5,
      "z": -3,
      "name": "Soil_Dirt"
    },
    {
      "x": -1,
      "y": 6,
      "z": -3,
      "name": "Soil_Pathway"
    },
    {
      "x": -1,
      "y": 7,
      "z": -3,
      "name": "Empty"
    },
    {
      "x": -1,
      "y": 8,
      "z": -3,
      "name": "Empty"
    },
    {
      "x": -1,
      "y": 9,
      "z": -3,
      "name": "Empty"
    },
    {
      "x": -1,
      "y": 4,
      "z": -2,
      "name": "Soil_Dirt"
    },
    {
      "x": -1,
      "y": 5,
      "z": -2,
      "name": "Soil_Dirt"
    },
    {
      "x": -1,
      "y": 6,
      "z": -2,
      "name": "Soil_Pathway"
    },
    {
      "x": -1,
      "y": 7,
      "z": -2,
      "name": "Empty"
    },
    {
      "x": -1,
      "y": 8,
      "z": -2,
      "name": "Empty"
    },
    {
      "x": -1,
      "y": 9,
      "z": -2,
      "name": "Empty"
    },
    {
      "x": -1,
      "y": 4,
      "z": -1,
      "name": "Soil_Dirt"
    },
    {
      "x": -1,
      "y": 5,
      "z": -1,
      "name": "Soil_Dirt"
    },
    {
      "x": -1,
      "y": 6,
      "z": -1,
      "name": "Soil_Pathway"
    },
    {
      "x": -1,
      "y": 7,
      "z": -1,
      "name": "Empty"
    },
    {
      "x": -1,
      "y": 8,
      "z": -1,
      "name": "Empty"
    },
    {
      "x": -1,
      "y": 9,
      "z": -1,
      "name": "Empty"
    },
    {
      "x": -1,
      "y": 4,
      "z": 0,
      "name": "Soil_Dirt"
    },
    {
      "x": -1,
      "y": 5,
      "z": 0,
      "name": "Soil_Dirt"
    },
    {
      "x": -1,
      "y": 6,
      "z": 0,
      "name": "Soil_Grass"
    },
    {
      "x": -1,
      "y": 4,
      "z": 1,
      "name": "Soil_Dirt"
    },
    {
      "x": -1,
      "y": 5,
      "z": 1,
      "name": "Soil_Dirt"
    },
    {
      "x": -1,
      "y": 6,
      "z": 1,
      "name": "Soil_Grass"
    },
    {
      "x": -1,
      "y": 7,
      "z": 1,
      "name": "Wood_Hardwood_Fence",
      "rotation": 3
    },
    {
      "x": -1,
      "y": 8,
      "z": 1,
      "name": "Plant_Vine_Wall",
      "rotation": 3
    },
    {
      "x": -1,
      "y": 9,
      "z": 1,
      "name": "Plant_Vine",
      "rotation": 3
    },
    {
      "x": -1,
      "y": 4,
      "z": 2,
      "name": "Soil_Dirt"
    },
    {
      "x": -1,
      "y": 5,
      "z": 2,
      "name": "Soil_Dirt"
    },
    {
      "x": -1,
      "y": 6,
      "z": 2,
      "name": "Soil_Grass"
    },
    {
      "x": -1,
      "y": 7,
      "z": 2,
      "name": "Wood_Hardwood_Fence",
      "rotation": 3
    },
    {
      "x": -1,
      "y": 8,
      "z": 2,
      "name": "Plant_Vine",
      "rotation": 3
    },
    {
      "x": -1,
      "y": 4,
      "z": 3,
      "name": "Soil_Dirt"
    },
    {
      "x": -1,
      "y": 5,
      "z": 3,
      "name": "Soil_Dirt"
    },
    {
      "x": -1,
      "y": 6,
      "z": 3,
      "name": "Soil_Grass"
    },
    {
      "x": -1,
      "y": 7,
      "z": 3,
      "name": "Wood_Hardwood_Fence",
      "rotation": 3
    },
    {
      "x": 0,
      "y": 4,
      "z": -6,
      "name": "Soil_Dirt"
    },
    {
      "x": 0,
      "y": 5,
      "z": -6,
      "name": "Soil_Dirt"
    },
    {
      "x": 0,
      "y": 6,
      "z": -6,
      "name": "Soil_Grass"
    },
    {
      "x": 0,
      "y": 4,
      "z": -5,
      "name": "Soil_Dirt"
    },
    {
      "x": 0,
      "y": 5,
      "z": -5,
      "name": "Soil_Dirt"
    },
    {
      "x": 0,
      "y": 6,
      "z": -5,
      "name": "Soil_Grass"
    },
    {
      "x": 0,
      "y": 4,
      "z": -4,
      "name": "Soil_Dirt"
    },
    {
      "x": 0,
      "y": 5,
      "z": -4,
      "name": "Soil_Dirt"
    },
    {
      "x": 0,
      "y": 6,
      "z": -4,
      "name": "Soil_Pathway"
    },
    {
      "x": 0,
      "y": 7,
      "z": -4,
      "name": "Empty"
    },
    {
      "x": 0,
      "y": 8,
      "z": -4,
      "name": "Empty"
    },
    {
      "x": 0,
      "y": 9,
      "z": -4,
      "name": "Empty"
    },
    {
      "x": 0,
      "y": 4,
      "z": -3,
      "name": "Soil_Dirt"
    },
    {
      "x": 0,
      "y": 5,
      "z": -3,
      "name": "Soil_Dirt"
    },
    {
      "x": 0,
      "y": 6,
      "z": -3,
      "name": "Soil_Pathway"
    },
    {
      "x": 0,
      "y": 7,
      "z": -3,
      "name": "Empty"
    },
    {
      "x": 0,
      "y": 8,
      "z": -3,
      "name": "Empty"
    },
    {
      "x": 0,
      "y": 9,
      "z": -3,
      "name": "Empty"
    },
    {
      "x": 0,
      "y": 4,
      "z": -2,
      "name": "Soil_Dirt"
    },
    {
      "x": 0,
      "y": 5,
      "z": -2,
      "name": "Soil_Dirt"
    },
    {
      "x": 0,
      "y": 6,
      "z": -2,
      "name": "Soil_Pathway"
    },
    {
      "x": 0,
      "y": 7,
      "z": -2,
      "name": "Empty"
    },
    {
      "x": 0,
      "y": 8,
      "z": -2,
      "name": "Empty"
    },
    {
      "x": 0,
      "y": 9,
      "z": -2,
      "name": "Empty"
    },
    {
      "x": 0,
      "y": 4,
      "z": -1,
      "name": "Soil_Dirt"
    },
    {
      "x": 0,
      "y": 5,
      "z": -1,
      "name": "Soil_Dirt"
    },
    {
      "x": 0,
      "y": 6,
      "z": -1,
      "name": "Soil_Pathway"
    },
    {
      "x": 0,
      "y": 7,
      "z": -1,
      "name": "Empty"
    },
    {
      "x": 0,
      "y": 8,
      "z": -1,
      "name": "Empty"
    },
    {
      "x": 0,
      "y": 9,
      "z": -1,
      "name": "Empty"
    },
    {
      "x": 0,
      "y": 4,
      "z": 0,
      "name": "Soil_Dirt"
    },
    {
      "x": 0,
      "y": 5,
      "z": 0,
      "name": "Soil_Dirt"
    },
    {
      "x": 0,
      "y": 6,
      "z": 0,
      "name": "Soil_Pathway"
    },
    {
      "x": 0,
      "y": 7,
      "z": 0,
      "name": "Empty"
    },
    {
      "x": 0,
      "y": 8,
      "z": 0,
      "name": "Empty"
    },
    {
      "x": 0,
      "y": 9,
      "z": 0,
      "name": "Empty"
    },
    {
      "x": 0,
      "y": 4,
      "z": 1,
      "name": "Soil_Dirt"
    },
    {
      "x": 0,
      "y": 5,
      "z": 1,
      "name": "Soil_Dirt"
    },
    {
      "x": 0,
      "y": 6,
      "z": 1,
      "name": "Soil_Dirt"
    },
    {
      "x": 0,
      "y": 7,
      "z": 1,
      "name": "Wood_Oak_Branch_Long",
      "support": 15
    },
    {
      "x": 0,
      "y": 8,
      "z": 1,
      "name": "Wood_Oak_Branch_Long",
      "support": 15
    },
    {
      "x": 0,
      "y": 9,
      "z": 1,
      "name": "Wood_Oak_Trunk",
      "support": 15,
      "rotation": 5
    },
    {
      "x": 0,
      "y": 10,
      "z": 1,
      "name": "Plant_Moss_Rug_Green"
    },
    {
      "x": 0,
      "y": 4,
      "z": 2,
      "name": "Soil_Dirt"
    },
    {
      "x": 0,
      "y": 5,
      "z": 2,
      "name": "Soil_Dirt"
    },
    {
      "x": 0,
      "y": 6,
      "z": 2,
      "name": "Soil_Pathway"
    },
    {
      "x": 0,
      "y": 7,
      "z": 2,
      "name": "Empty"
    },
    {
      "x": 0,
      "y": 8,
      "z": 2,
      "name": "Wood_Hardwood_Stairs",
      "rotation": 8
    },
    {
      "x": 0,
      "y": 9,
      "z": 2,
      "name": "Wood_Hardwood_Stairs"
    },
    {
      "x": 0,
      "y": 4,
      "z": 3,
      "name": "Soil_Dirt"
    },
    {
      "x": 0,
      "y": 5,
      "z": 3,
      "name": "Soil_Dirt"
    },
    {
      "x": 0,
      "y": 6,
      "z": 3,
      "name": "Soil_Pathway"
    },
    {
      "x": 0,
      "y": 7,
      "z": 3,
      "name": "Wood_Hardwood_Stairs",
      "rotation": 8
    },
    {
      "x": 0,
      "y": 8,
      "z": 3,
      "name": "Wood_Hardwood_Stairs"
    },
    {
      "x": 0,
      "y": 4,
      "z": 4,
      "name": "Soil_Dirt"
    },
    {
      "x": 0,
      "y": 5,
      "z": 4,
      "name": "Soil_Dirt"
    },
    {
      "x": 0,
      "y": 6,
      "z": 4,
      "name": "Soil_Dirt"
    },
    {
      "x": 0,
      "y": 7,
      "z": 4,
      "name": "Wood_Hardwood_Stairs"
    },
    {
      "x": 1,
      "y": 4,
      "z": -6,
      "name": "Soil_Dirt"
    },
    {
      "x": 1,
      "y": 5,
      "z": -6,
      "name": "Soil_Dirt"
    },
    {
      "x": 1,
      "y": 6,
      "z": -6,
      "name": "Soil_Grass"
    },
    {
      "x": 1,
      "y": 4,
      "z": -5,
      "name": "Soil_Dirt"
    },
    {
      "x": 1,
      "y": 5,
      "z": -5,
      "name": "Soil_Dirt"
    },
    {
      "x": 1,
      "y": 6,
      "z": -5,
      "name": "Soil_Dirt"
    },
    {
      "x": 1,
      "y": 7,
      "z": -5,
      "name": "Empty"
    },
    {
      "x": 1,
      "y": 8,
      "z": -5,
      "name": "Empty"
    },
    {
      "x": 1,
      "y": 9,
      "z": -5,
      "name": "Empty"
    },
    {
      "x": 1,
      "y": 4,
      "z": -4,
      "name": "Soil_Dirt"
    },
    {
      "x": 1,
      "y": 5,
      "z": -4,
      "name": "Soil_Dirt"
    },
    {
      "x": 1,
      "y": 6,
      "z": -4,
      "name": "Soil_Pathway"
    },
    {
      "x": 1,
      "y": 7,
      "z": -4,
      "name": "Empty"
    },
    {
      "x": 1,
      "y": 8,
      "z": -4,
      "name": "Empty"
    },
    {
      "x": 1,
      "y": 9,
      "z": -4,
      "name": "Empty"
    },
    {
      "x": 1,
      "y": 4,
      "z": -3,
      "name": "Soil_Dirt"
    },
    {
      "x": 1,
      "y": 5,
      "z": -3,
      "name": "Soil_Dirt"
    },
    {
      "x": 1,
      "y": 6,
      "z": -3,
      "name": "Soil_Pathway"
    },
    {
      "x": 1,
      "y": 7,
      "z": -3,
      "name": "Empty"
    },
    {
      "x": 1,
      "y": 8,
      "z": -3,
      "name": "Empty"
    },
    {
      "x": 1,
      "y": 9,
      "z": -3,
      "name": "Empty"
    },
    {
      "x": 1,
      "y": 4,
      "z": -2,
      "name": "Soil_Dirt"
    },
    {
      "x": 1,
      "y": 5,
      "z": -2,
      "name": "Soil_Dirt"
    },
    {
      "x": 1,
      "y": 6,
      "z": -2,
      "name": "Soil_Pathway"
    },
    {
      "x": 1,
      "y": 7,
      "z": -2,
      "name": "Empty"
    },
    {
      "x": 1,
      "y": 8,
      "z": -2,
      "name": "Empty"
    },
    {
      "x": 1,
      "y": 9,
      "z": -2,
      "name": "Empty"
    },
    {
      "x": 1,
      "y": 4,
      "z": -1,
      "name": "Soil_Dirt"
    },
    {
      "x": 1,
      "y": 5,
      "z": -1,
      "name": "Soil_Dirt"
    },
    {
      "x": 1,
      "y": 6,
      "z": -1,
      "name": "Soil_Pathway"
    },
    {
      "x": 1,
      "y": 7,
      "z": -1,
      "name": "Empty"
    },
    {
      "x": 1,
      "y": 8,
      "z": -1,
      "name": "Empty"
    },
    {
      "x": 1,
      "y": 9,
      "z": -1,
      "name": "Empty"
    },
    {
      "x": 1,
      "y": 4,
      "z": 0,
      "name": "Soil_Dirt"
    },
    {
      "x": 1,
      "y": 5,
      "z": 0,
      "name": "Soil_Dirt"
    },
    {
      "x": 1,
      "y": 6,
      "z": 0,
      "name": "Soil_Pathway"
    },
    {
      "x": 1,
      "y": 7,
      "z": 0,
      "name": "Empty"
    },
    {
      "x": 1,
      "y": 8,
      "z": 0,
      "name": "Empty"
    },
    {
      "x": 1,
      "y": 9,
      "z": 0,
      "name": "Empty"
    },
    {
      "x": 1,
      "y": 4,
      "z": 1,
      "name": "Soil_Dirt"
    },
    {
      "x": 1,
      "y": 5,
      "z": 1,
      "name": "Soil_Dirt"
    },
    {
      "x": 1,
      "y": 6,
      "z": 1,
      "name": "Soil_Dirt"
    },
    {
      "x": 1,
      "y": 7,
      "z": 1,
      "name": "Empty"
    },
    {
      "x": 1,
      "y": 8,
      "z": 1,
      "name": "Empty"
    },
    {
      "x": 1,
      "y": 9,
      "z": 1,
      "name": "Wood_Oak_Trunk",
      "support": 15,
      "rotation": 5
    },
    {
      "x": 1,
      "y": 10,
      "z": 1,
      "name": "Plant_Moss_Short_Green"
    },
    {
      "x": 1,
      "y": 4,
      "z": 2,
      "name": "Soil_Dirt"
    },
    {
      "x": 1,
      "y": 5,
      "z": 2,
      "name": "Soil_Dirt"
    },
    {
      "x": 1,
      "y": 6,
      "z": 2,
      "name": "Soil_Dirt"
    },
    {
      "x": 1,
      "y": 7,
      "z": 2,
      "name": "Furniture_Crude_Bed",
      "rotation": 1
    },
    {
      "x": 1,
      "y": 8,
      "z": 2,
      "name": "Empty"
    },
    {
      "x": 1,
      "y": 9,
      "z": 2,
      "name": "Soil_Grass"
    },
    {
      "x": 1,
      "y": 4,
      "z": 3,
      "name": "Soil_Dirt"
    },
    {
      "x": 1,
      "y": 5,
      "z": 3,
      "name": "Soil_Dirt"
    },
    {
      "x": 1,
      "y": 6,
      "z": 3,
      "name": "Soil_Pathway"
    },
    {
      "x": 1,
      "y": 7,
      "z": 3,
      "name": "Empty"
    },
    {
      "x": 1,
      "y": 8,
      "z": 3,
      "name": "Soil_Dirt"
    },
    {
      "x": 1,
      "y": 9,
      "z": 3,
      "name": "Plant_Moss_Rug_Green"
    },
    {
      "x": 1,
      "y": 4,
      "z": 4,
      "name": "Soil_Dirt"
    },
    {
      "x": 1,
      "y": 5,
      "z": 4,
      "name": "Soil_Dirt"
    },
    {
      "x": 1,
      "y": 6,
      "z": 4,
      "name": "Soil_Dirt"
    },
    {
      "x": 1,
      "y": 7,
      "z": 4,
      "name": "Soil_Dirt"
    },
    {
      "x": 1,
      "y": 8,
      "z": 4,
      "name": "Soil_Grass"
    },
    {
      "x": 1,
      "y": 9,
      "z": 4,
      "name": "Plant_Grass_Lush_Short"
    },
    {
      "x": 1,
      "y": 4,
      "z": 5,
      "name": "Soil_Dirt"
    },
    {
      "x": 1,
      "y": 5,
      "z": 5,
      "name": "Soil_Dirt"
    },
    {
      "x": 1,
      "y": 6,
      "z": 5,
      "name": "Soil_Dirt"
    },
    {
      "x": 1,
      "y": 7,
      "z": 5,
      "name": "Soil_Grass"
    },
    {
      "x": 2,
      "y": 4,
      "z": -6,
      "name": "Rock_Stone"
    },
    {
      "x": 2,
      "y": 5,
      "z": -6,
      "name": "Rock_Stone"
    },
    {
      "x": 2,
      "y": 6,
      "z": -6,
      "name": "Rock_Stone"
    },
    {
      "x": 2,
      "y": 7,
      "z": -6,
      "name": "Rock_Stone_Mossy"
    },
    {
      "x": 2,
      "y": 4,
      "z": -5,
      "name": "Rock_Stone"
    },
    {
      "x": 2,
      "y": 5,
      "z": -5,
      "name": "Rock_Stone"
    },
    {
      "x": 2,
      "y": 6,
      "z": -5,
      "name": "Rock_Stone"
    },
    {
      "x": 2,
      "y": 7,
      "z": -5,
      "name": "Rock_Stone_Mossy"
    },
    {
      "x": 2,
      "y": 8,
      "z": -5,
      "name": "Rock_Stone"
    },
    {
      "x": 2,
      "y": 4,
      "z": -4,
      "name": "Soil_Dirt"
    },
    {
      "x": 2,
      "y": 5,
      "z": -4,
      "name": "Soil_Dirt"
    },
    {
      "x": 2,
      "y": 6,
      "z": -4,
      "name": "Soil_Dirt"
    },
    {
      "x": 2,
      "y": 7,
      "z": -4,
      "name": "Empty"
    },
    {
      "x": 2,
      "y": 8,
      "z": -4,
      "name": "Empty"
    },
    {
      "x": 2,
      "y": 9,
      "z": -4,
      "name": "Empty"
    },
    {
      "x": 2,
      "y": 4,
      "z": -3,
      "name": "Soil_Dirt"
    },
    {
      "x": 2,
      "y": 5,
      "z": -3,
      "name": "Soil_Dirt"
    },
    {
      "x": 2,
      "y": 6,
      "z": -3,
      "name": "Soil_Pathway"
    },
    {
      "x": 2,
      "y": 7,
      "z": -3,
      "name": "Empty"
    },
    {
      "x": 2,
      "y": 8,
      "z": -3,
      "name": "Empty"
    },
    {
      "x": 2,
      "y": 9,
      "z": -3,
      "name": "Empty"
    },
    {
      "x": 2,
      "y": 4,
      "z": -2,
      "name": "Soil_Dirt"
    },
    {
      "x": 2,
      "y": 5,
      "z": -2,
      "name": "Soil_Dirt"
    },
    {
      "x": 2,
      "y": 6,
      "z": -2,
      "name": "Soil_Pathway"
    },
    {
      "x": 2,
      "y": 7,
      "z": -2,
      "name": "Empty"
    },
    {
      "x": 2,
      "y": 8,
      "z": -2,
      "name": "Empty"
    },
    {
      "x": 2,
      "y": 9,
      "z": -2,
      "name": "Empty"
    },
    {
      "x": 2,
      "y": 4,
      "z": -1,
      "name": "Soil_Dirt"
    },
    {
      "x": 2,
      "y": 5,
      "z": -1,
      "name": "Soil_Dirt"
    },
    {
      "x": 2,
      "y": 6,
      "z": -1,
      "name": "Soil_Pathway"
    },
    {
      "x": 2,
      "y": 7,
      "z": -1,
      "name": "Empty"
    },
    {
      "x": 2,
      "y": 8,
      "z": -1,
      "name": "Empty"
    },
    {
      "x": 2,
      "y": 9,
      "z": -1,
      "name": "Empty"
    },
    {
      "x": 2,
      "y": 4,
      "z": 0,
      "name": "Soil_Dirt"
    },
    {
      "x": 2,
      "y": 5,
      "z": 0,
      "name": "Soil_Dirt"
    },
    {
      "x": 2,
      "y": 6,
      "z": 0,
      "name": "Soil_Dirt"
    },
    {
      "x": 2,
      "y": 7,
      "z": 0,
      "name": "Empty"
    },
    {
      "x": 2,
      "y": 8,
      "z": 0,
      "name": "Empty"
    },
    {
      "x": 2,
      "y": 9,
      "z": 0,
      "name": "Empty"
    },
    {
      "x": 2,
      "y": 4,
      "z": 1,
      "name": "Soil_Dirt"
    },
    {
      "x": 2,
      "y": 5,
      "z": 1,
      "name": "Soil_Dirt"
    },
    {
      "x": 2,
      "y": 6,
      "z": 1,
      "name": "Soil_Dirt"
    },
    {
      "x": 2,
      "y": 7,
      "z": 1,
      "name": "Empty"
    },
    {
      "x": 2,
      "y": 8,
      "z": 1,
      "name": "Empty"
    },
    {
      "x": 2,
      "y": 9,
      "z": 1,
      "name": "Wood_Oak_Trunk",
      "support": 15,
      "rotation": 5
    },
    {
      "x": 2,
      "y": 4,
      "z": 2,
      "name": "Soil_Dirt"
    },
    {
      "x": 2,
      "y": 5,
      "z": 2,
      "name": "Soil_Dirt"
    },
    {
      "x": 2,
      "y": 6,
      "z": 2,
      "name": "Soil_Dirt"
    },
    {
      "x": 2,
      "y": 7,
      "z": 2,
      "name": "Empty"
    },
    {
      "x": 2,
      "y": 8,
      "z": 2,
      "name": "Empty"
    },
    {
      "x": 2,
      "y": 9,
      "z": 2,
      "name": "Soil_Grass"
    },
    {
      "x": 2,
      "y": 4,
      "z": 3,
      "name": "Soil_Dirt"
    },
    {
      "x": 2,
      "y": 5,
      "z": 3,
      "name": "Soil_Dirt"
    },
    {
      "x": 2,
      "y": 6,
      "z": 3,
      "name": "Soil_Pathway"
    },
    {
      "x": 2,
      "y": 7,
      "z": 3,
      "name": "Empty"
    },
    {
      "x": 2,
      "y": 8,
      "z": 3,
      "name": "Soil_Dirt"
    },
    {
      "x": 2,
      "y": 9,
      "z": 3,
      "name": "Plant_Moss_Rug_Green"
    },
    {
      "x": 2,
      "y": 4,
      "z": 4,
      "name": "Soil_Dirt"
    },
    {
      "x": 2,
      "y": 5,
      "z": 4,
      "name": "Soil_Dirt"
    },
    {
      "x": 2,
      "y": 6,
      "z": 4,
      "name": "Soil_Dirt"
    },
    {
      "x": 2,
      "y": 7,
      "z": 4,
      "name": "Soil_Dirt"
    },
    {
      "x": 2,
      "y": 8,
      "z": 4,
      "name": "Soil_Grass"
    },
    {
      "x": 2,
      "y": 4,
      "z": 5,
      "name": "Soil_Dirt"
    },
    {
      "x": 2,
      "y": 5,
      "z": 5,
      "name": "Soil_Dirt"
    },
    {
      "x": 2,
      "y": 6,
      "z": 5,
      "name": "Soil_Dirt"
    },
    {
      "x": 2,
      "y": 7,
      "z": 5,
      "name": "Soil_Grass"
    },
    {
      "x": 3,
      "y": 6,
      "z": -6,
      "name": "Rock_Stone"
    },
    {
      "x": 3,
      "y": 7,
      "z": -6,
      "name": "Rock_Stone"
    },
    {
      "x": 3,
      "y": 8,
      "z": -6,
      "name": "Rock_Stone"
    },
    {
      "x": 3,
      "y": 4,
      "z": -5,
      "name": "Rock_Stone"
    },
    {
      "x": 3,
      "y": 5,
      "z": -5,
      "name": "Rock_Stone"
    },
    {
      "x": 3,
      "y": 6,
      "z": -5,
      "name": "Rock_Stone"
    },
    {
      "x": 3,
      "y": 7,
      "z": -5,
      "name": "Rock_Stone"
    },
    {
      "x": 3,
      "y": 8,
      "z": -5,
      "name": "Rock_Stone_Mossy"
    },
    {
      "x": 3,
      "y": 4,
      "z": -4,
      "name": "Soil_Dirt"
    },
    {
      "x": 3,
      "y": 5,
      "z": -4,
      "name": "Soil_Dirt"
    },
    {
      "x": 3,
      "y": 6,
      "z": -4,
      "name": "Soil_Dirt"
    },
    {
      "x": 3,
      "y": 7,
      "z": -4,
      "name": "Furniture_Crude_Chest_Small",
      "components": {
        "Components": {
          "container": {
            "Custom": false,
            "AllowViewing": true,
            "Droplist": "Unique_Start",
            "ItemContainer": {
              "Capacity": 18,
              "Items": {}
            }
          }
        }
      }
    },
    {
      "x": 3,
      "y": 8,
      "z": -4,
      "name": "Empty"
    },
    {
      "x": 3,
      "y": 9,
      "z": -4,
      "name": "Empty"
    },
    {
      "x": 3,
      "y": 4,
      "z": -3,
      "name": "Soil_Dirt"
    },
    {
      "x": 3,
      "y": 5,
      "z": -3,
      "name": "Soil_Dirt"
    },
    {
      "x": 3,
      "y": 6,
      "z": -3,
      "name": "Soil_Dirt"
    },
    {
      "x": 3,
      "y": 7,
      "z": -3,
      "name": "Empty"
    },
    {
      "x": 3,
      "y": 8,
      "z": -3,
      "name": "Empty"
    },
    {
      "x": 3,
      "y": 9,
      "z": -3,
      "name": "Empty"
    },
    {
      "x": 3,
      "y": 4,
      "z": -2,
      "name": "Soil_Dirt"
    },
    {
      "x": 3,
      "y": 5,
      "z": -2,
      "name": "Soil_Dirt"
    },
    {
      "x": 3,
      "y": 6,
      "z": -2,
      "name": "Soil_Dirt"
    },
    {
      "x": 3,
      "y": 7,
      "z": -2,
      "name": "Empty"
    },
    {
      "x": 3,
      "y": 8,
      "z": -2,
      "name": "Empty"
    },
    {
      "x": 3,
      "y": 9,
      "z": -2,
      "name": "Empty"
    },
    {
      "x": 3,
      "y": 4,
      "z": -1,
      "name": "Soil_Dirt"
    },
    {
      "x": 3,
      "y": 5,
      "z": -1,
      "name": "Soil_Dirt"
    },
    {
      "x": 3,
      "y": 6,
      "z": -1,
      "name": "Soil_Pathway"
    },
    {
      "x": 3,
      "y": 7,
      "z": -1,
      "name": "Wood_Oak_Branch_Long",
      "support": 15
    },
    {
      "x": 3,
      "y": 8,
      "z": -1,
      "name": "Wood_Oak_Branch_Long",
      "support": 15
    },
    {
      "x": 3,
      "y": 9,
      "z": -1,
      "name": "Wood_Oak_Trunk",
      "support": 15,
      "rotation": 4
    },
    {
      "x": 3,
      "y": 10,
      "z": -1,
      "name": "Plant_Moss_Short_Green"
    },
    {
      "x": 3,
      "y": 4,
      "z": 0,
      "name": "Soil_Dirt"
    },
    {
      "x": 3,
      "y": 5,
      "z": 0,
      "name": "Soil_Dirt"
    },
    {
      "x": 3,
      "y": 6,
      "z": 0,
      "name": "Soil_Pathway"
    },
    {
      "x": 3,
      "y": 7,
      "z": 0,
      "name": "Empty"
    },
    {
      "x": 3,
      "y": 8,
      "z": 0,
      "name": "Empty"
    },
    {
      "x": 3,
      "y": 9,
      "z": 0,
      "name": "Wood_Oak_Trunk",
      "support": 15,
      "rotation": 4
    },
    {
      "x": 3,
      "y": 10,
      "z": 0,
      "name": "Plant_Moss_Rug_Green"
    },
    {
      "x": 3,
      "y": 4,
      "z": 1,
      "name": "Soil_Dirt"
    },
    {
      "x": 3,
      "y": 5,
      "z": 1,
      "name": "Soil_Dirt"
    },
    {
      "x": 3,
      "y": 6,
      "z": 1,
      "name": "Soil_Dirt"
    },
    {
      "x": 3,
      "y": 7,
      "z": 1,
      "name": "Empty"
    },
    {
      "x": 3,
      "y": 8,
      "z": 1,
      "name": "Empty"
    },
    {
      "x": 3,
      "y": 9,
      "z": 1,
      "name": "Wood_Oak_Trunk",
      "support": 15,
      "rotation": 5
    },
    {
      "x": 3,
      "y": 10,
      "z": 1,
      "name": "Plant_Moss_Rug_Green"
    },
    {
      "x": 3,
      "y": 4,
      "z": 2,
      "name": "Soil_Dirt"
    },
    {
      "x": 3,
      "y": 5,
      "z": 2,
      "name": "Soil_Dirt"
    },
    {
      "x": 3,
      "y": 6,
      "z": 2,
      "name": "Soil_Dirt"
    },
    {
      "x": 3,
      "y": 7,
      "z": 2,
      "name": "Empty"
    },
    {
      "x": 3,
      "y": 8,
      "z": 2,
      "name": "Empty"
    },
    {
      "x": 3,
      "y": 9,
      "z": 2,
      "name": "Soil_Grass"
    },
    {
      "x": 3,
      "y": 4,
      "z": 3,
      "name": "Soil_Dirt"
    },
    {
      "x": 3,
      "y": 5,
      "z": 3,
      "name": "Soil_Dirt"
    },
    {
      "x": 3,
      "y": 6,
      "z": 3,
      "name": "Soil_Pathway"
    },
    {
      "x": 3,
      "y": 7,
      "z": 3,
      "name": "Plant_Roots_Cave",
      "rotation": 8
    },
    {
      "x": 3,
      "y": 8,
      "z": 3,
      "name": "Soil_Dirt"
    },
    {
      "x": 3,
      "y": 9,
      "z": 3,
      "name": "Plant_Moss_Green"
    },
    {
      "x": 3,
      "y": 4,
      "z": 4,
      "name": "Soil_Dirt"
    },
    {
      "x": 3,
      "y": 5,
      "z": 4,
      "name": "Soil_Dirt"
    },
    {
      "x": 3,
      "y": 6,
      "z": 4,
      "name": "Soil_Dirt"
    },
    {
      "x": 3,
      "y": 7,
      "z": 4,
      "name": "Soil_Dirt"
    },
    {
      "x": 3,
      "y": 8,
      "z": 4,
      "name": "Plant_Moss_Rug_Green"
    },
    {
      "x": 3,
      "y": 4,
      "z": 5,
      "name": "Soil_Dirt"
    },
    {
      "x": 3,
      "y": 5,
      "z": 5,
      "name": "Soil_Dirt"
    },
    {
      "x": 3,
      "y": 6,
      "z": 5,
      "name": "Soil_Dirt"
    },
    {
      "x": 3,
      "y": 7,
      "z": 5,
      "name": "Soil_Grass"
    },
    {
      "x": 4,
      "y": 4,
      "z": -4,
      "name": "Soil_Dirt"
    },
    {
      "x": 4,
      "y": 5,
      "z": -4,
      "name": "Soil_Dirt"
    },
    {
      "x": 4,
      "y": 6,
      "z": -4,
      "name": "Soil_Grass"
    },
    {
      "x": 4,
      "y": 7,
      "z": -4,
      "name": "Plant_Bush"
    },
    {
      "x": 4,
      "y": 4,
      "z": -3,
      "name": "Soil_Dirt"
    },
    {
      "x": 4,
      "y": 5,
      "z": -3,
      "name": "Soil_Dirt"
    },
    {
      "x": 4,
      "y": 6,
      "z": -3,
      "name": "Soil_Grass"
    },
    {
      "x": 4,
      "y": 4,
      "z": -2,
      "name": "Soil_Dirt"
    },
    {
      "x": 4,
      "y": 5,
      "z": -2,
      "name": "Soil_Dirt"
    },
    {
      "x": 4,
      "y": 6,
      "z": -2,
      "name": "Soil_Dirt"
    },
    {
      "x": 4,
      "y": 7,
      "z": -2,
      "name": "Empty"
    },
    {
      "x": 4,
      "y": 8,
      "z": -2,
      "name": "Empty"
    },
    {
      "x": 4,
      "y": 9,
      "z": -2,
      "name": "Empty"
    },
    {
      "x": 4,
      "y": 4,
      "z": -1,
      "name": "Soil_Dirt"
    },
    {
      "x": 4,
      "y": 5,
      "z": -1,
      "name": "Soil_Dirt"
    },
    {
      "x": 4,
      "y": 6,
      "z": -1,
      "name": "Soil_Dirt"
    },
    {
      "x": 4,
      "y": 7,
      "z": -1,
      "name": "Empty"
    },
    {
      "x": 4,
      "y": 8,
      "z": -1,
      "name": "Wood_Hardwood_Stairs",
      "rotation": 9
    },
    {
      "x": 4,
      "y": 9,
      "z": -1,
      "name": "Wood_Hardwood_Stairs",
      "rotation": 1
    },
    {
      "x": 4,
      "y": 4,
      "z": 0,
      "name": "Soil_Dirt"
    },
    {
      "x": 4,
      "y": 5,
      "z": 0,
      "name": "Soil_Dirt"
    },
    {
      "x": 4,
      "y": 6,
      "z": 0,
      "name": "Soil_Dirt"
    },
    {
      "x": 4,
      "y": 7,
      "z": 0,
      "name": "Empty"
    },
    {
      "x": 4,
      "y": 8,
      "z": 0,
      "name": "Plant_Roots_Cave",
      "rotation": 8
    },
    {
      "x": 4,
      "y": 9,
      "z": 0,
      "name": "Soil_Grass"
    },
    {
      "x": 4,
      "y": 10,
      "z": 0,
      "name": "Plant_Moss_Rug_Green"
    },
    {
      "x": 4,
      "y": 4,
      "z": 1,
      "name": "Soil_Dirt"
    },
    {
      "x": 4,
      "y": 5,
      "z": 1,
      "name": "Soil_Dirt"
    },
    {
      "x": 4,
      "y": 6,
      "z": 1,
      "name": "Soil_Pathway"
    },
    {
      "x": 4,
      "y": 7,
      "z": 1,
      "name": "Empty"
    },
    {
      "x": 4,
      "y": 8,
      "z": 1,
      "name": "Empty"
    },
    {
      "x": 4,
      "y": 9,
      "z": 1,
      "name": "Soil_Grass"
    },
    {
      "x": 4,
      "y": 4,
      "z": 2,
      "name": "Soil_Dirt"
    },
    {
      "x": 4,
      "y": 5,
      "z": 2,
      "name": "Soil_Dirt"
    },
    {
      "x": 4,
      "y": 6,
      "z": 2,
      "name": "Soil_Pathway"
    },
    {
      "x": 4,
      "y": 7,
      "z": 2,
      "name": "Furniture_Crude_Stool"
    },
    {
      "x": 4,
      "y": 8,
      "z": 2,
      "name": "Empty"
    },
    {
      "x": 4,
      "y": 9,
      "z": 2,
      "name": "Soil_Grass"
    },
    {
      "x": 4,
      "y": 10,
      "z": 2,
      "name": "Plant_Grass_Lush_Short"
    },
    {
      "x": 4,
      "y": 4,
      "z": 3,
      "name": "Soil_Dirt"
    },
    {
      "x": 4,
      "y": 5,
      "z": 3,
      "name": "Soil_Dirt"
    },
    {
      "x": 4,
      "y": 6,
      "z": 3,
      "name": "Soil_Dirt"
    },
    {
      "x": 4,
      "y": 7,
      "z": 3,
      "name": "Soil_Dirt"
    },
    {
      "x": 4,
      "y": 8,
      "z": 3,
      "name": "Soil_Dirt"
    },
    {
      "x": 4,
      "y": 4,
      "z": 4,
      "name": "Soil_Dirt"
    },
    {
      "x": 4,
      "y": 5,
      "z": 4,
      "name": "Soil_Dirt"
    },
    {
      "x": 4,
      "y": 6,
      "z": 4,
      "name": "Soil_Grass"
    },
    {
      "x": 5,
      "y": 4,
      "z": -3,
      "name": "Soil_Dirt"
    },
    {
      "x": 5,
      "y": 5,
      "z": -3,
      "name": "Soil_Dirt"
    },
    {
      "x": 5,
      "y": 6,
      "z": -3,
      "name": "Soil_Grass"
    },
    {
      "x": 5,
      "y": 7,
      "z": -3,
      "name": "Plant_Bush_Berry"
    },
    {
      "x": 5,
      "y": 4,
      "z": -2,
      "name": "Soil_Dirt"
    },
    {
      "x": 5,
      "y": 5,
      "z": -2,
      "name": "Soil_Dirt"
    },
    {
      "x": 5,
      "y": 6,
      "z": -2,
      "name": "Soil_Grass"
    },
    {
      "x": 5,
      "y": 7,
      "z": -2,
      "name": "Plant_Bush_Berry"
    },
    {
      "x": 5,
      "y": 4,
      "z": -1,
      "name": "Soil_Dirt"
    },
    {
      "x": 5,
      "y": 5,
      "z": -1,
      "name": "Soil_Dirt"
    },
    {
      "x": 5,
      "y": 6,
      "z": -1,
      "name": "Soil_Dirt"
    },
    {
      "x": 5,
      "y": 7,
      "z": -1,
      "name": "Wood_Hardwood_Stairs",
      "rotation": 9
    },
    {
      "x": 5,
      "y": 8,
      "z": -1,
      "name": "Wood_Hardwood_Stairs",
      "rotation": 1
    },
    {
      "x": 5,
      "y": 4,
      "z": 0,
      "name": "Soil_Dirt"
    },
    {
      "x": 5,
      "y": 5,
      "z": 0,
      "name": "Soil_Dirt"
    },
    {
      "x": 5,
      "y": 6,
      "z": 0,
      "name": "Soil_Pathway"
    },
    {
      "x": 5,
      "y": 7,
      "z": 0,
      "name": "Empty"
    },
    {
      "x": 5,
      "y": 8,
      "z": 0,
      "name": "Soil_Dirt"
    },
    {
      "x": 5,
      "y": 9,
      "z": 0,
      "name": "Soil_Grass"
    },
    {
      "x": 5,
      "y": 4,
      "z": 1,
      "name": "Soil_Dirt"
    },
    {
      "x": 5,
      "y": 5,
      "z": 1,
      "name": "Soil_Dirt"
    },
    {
      "x": 5,
      "y": 6,
      "z": 1,
      "name": "Soil_Pathway"
    },
    {
      "x": 5,
      "y": 7,
      "z": 1,
      "name": "Empty"
    },
    {
      "x": 5,
      "y": 8,
      "z": 1,
      "name": "Soil_Dirt"
    },
    {
      "x": 5,
      "y": 9,
      "z": 1,
      "name": "Soil_Grass"
    },
    {
      "x": 5,
      "y": 4,
      "z": 2,
      "name": "Soil_Dirt"
    },
    {
      "x": 5,
      "y": 5,
      "z": 2,
      "name": "Soil_Dirt"
    },
    {
      "x": 5,
      "y": 6,
      "z": 2,
      "name": "Soil_Pathway"
    },
    {
      "x": 5,
      "y": 7,
      "z": 2,
      "name": "Empty"
    },
    {
      "x": 5,
      "y": 8,
      "z": 2,
      "name": "Soil_Dirt"
    },
    {
      "x": 5,
      "y": 4,
      "z": 3,
      "name": "Soil_Dirt"
    },
    {
      "x": 5,
      "y": 5,
      "z": 3,
      "name": "Soil_Dirt"
    },
    {
      "x": 5,
      "y": 6,
      "z": 3,
      "name": "Soil_Dirt"
    },
    {
      "x": 5,
      "y": 7,
      "z": 3,
      "name": "Soil_Dirt"
    },
    {
      "x": 5,
      "y": 4,
      "z": 4,
      "name": "Soil_Dirt"
    },
    {
      "x": 5,
      "y": 5,
      "z": 4,
      "name": "Soil_Dirt"
    },
    {
      "x": 5,
      "y": 6,
      "z": 4,
      "name": "Soil_Grass"
    },
    {
      "x": 6,
      "y": 4,
      "z": -2,
      "name": "Soil_Dirt"
    },
    {
      "x": 6,
      "y": 5,
      "z": -2,
      "name": "Soil_Dirt"
    },
    {
      "x": 6,
      "y": 6,
      "z": -2,
      "name": "Soil_Grass"
    },
    {
      "x": 6,
      "y": 4,
      "z": -1,
      "name": "Soil_Dirt"
    },
    {
      "x": 6,
      "y": 5,
      "z": -1,
      "name": "Soil_Dirt"
    },
    {
      "x": 6,
      "y": 6,
      "z": -1,
      "name": "Soil_Dirt"
    },
    {
      "x": 6,
      "y": 7,
      "z": -1,
      "name": "Wood_Hardwood_Stairs",
      "rotation": 1
    },
    {
      "x": 6,
      "y": 4,
      "z": 0,
      "name": "Soil_Dirt"
    },
    {
      "x": 6,
      "y": 5,
      "z": 0,
      "name": "Soil_Dirt"
    },
    {
      "x": 6,
      "y": 6,
      "z": 0,
      "name": "Soil_Dirt"
    },
    {
      "x": 6,
      "y": 7,
      "z": 0,
      "name": "Soil_Dirt"
    },
    {
      "x": 6,
      "y": 8,
      "z": 0,
      "name": "Soil_Grass"
    },
    {
      "x": 6,
      "y": 9,
      "z": 0,
      "name": "Plant_Moss_Rug_Green"
    },
    {
      "x": 6,
      "y": 4,
      "z": 1,
      "name": "Soil_Dirt"
    },
    {
      "x": 6,
      "y": 5,
      "z": 1,
      "name": "Soil_Dirt"
    },
    {
      "x": 6,
      "y": 6,
      "z": 1,
      "name": "Soil_Dirt"
    },
    {
      "x": 6,
      "y": 7,
      "z": 1,
      "name": "Soil_Dirt"
    },
    {
      "x": 6,
      "y": 8,
      "z": 1,
      "name": "Soil_Grass"
    },
    {
      "x": 6,
      "y": 9,
      "z": 1,
      "name": "Plant_Grass_Lush"
    },
    {
      "x": 6,
      "y": 4,
      "z": 2,
      "name": "Soil_Dirt"
    },
    {
      "x": 6,
      "y": 5,
      "z": 2,
      "name": "Soil_Dirt"
    },
    {
      "x": 6,
      "y": 6,
      "z": 2,
      "name": "Soil_Dirt"
    },
    {
      "x": 6,
      "y": 7,
      "z": 2,
      "name": "Soil_Dirt"
    },
    {
      "x": 6,
      "y": 8,
      "z": 2,
      "name": "Plant_Moss_Rug_Green"
    },
    {
      "x": 6,
      "y": 4,
      "z": 3,
      "name": "Soil_Dirt"
    },
    {
      "x": 6,
      "y": 5,
      "z": 3,
      "name": "Soil_Dirt"
    },
    {
      "x": 6,
      "y": 6,
      "z": 3,
      "name": "Soil_Dirt"
    },
    {
      "x": 6,
      "y": 7,
      "z": 3,
      "name": "Soil_Dirt"
    },
    {
      "x": 6,
      "y": 8,
      "z": 3,
      "name": "Plant_Moss_Short_Green"
    },
    {
      "x": 7,
      "y": 4,
      "z": -1,
      "name": "Soil_Dirt"
    },
    {
      "x": 7,
      "y": 5,
      "z": -1,
      "name": "Soil_Dirt"
    },
    {
      "x": 7,
      "y": 6,
      "z": -1,
      "name": "Soil_Grass"
    },
    {
      "x": 7,
      "y": 4,
      "z": 0,
      "name": "Soil_Dirt"
    },
    {
      "x": 7,
      "y": 5,
      "z": 0,
      "name": "Soil_Dirt"
    },
    {
      "x": 7,
      "y": 6,
      "z": 0,
      "name": "Soil_Grass"
    },
    {
      "x": 7,
      "y": 4,
      "z": 1,
      "name": "Soil_Dirt"
    },
    {
      "x": 7,
      "y": 5,
      "z": 1,
      "name": "Soil_Dirt"
    },
    {
      "x": 7,
      "y": 6,
      "z": 1,
      "name": "Soil_Grass"
    },
    {
      "x": 7,
      "y": 4,
      "z": 2,
      "name": "Soil_Dirt"
    },
    {
      "x": 7,
      "y": 5,
      "z": 2,
      "name": "Soil_Dirt"
    },
    {
      "x": 7,
      "y": 6,
      "z": 2,
      "name": "Soil_Grass"
    }
  ],
  "entities": [
    {
      "Components": {
        "SpawnSuppressor": {
          "Position": {
            "X": 0.0,
            "Y": 0.0,
            "Z": 0.0
          },
          "HeadRotation": {
            "Pitch": 0.0,
            "Yaw": -3.08907413482666,
            "Roll": 0.0
          },
          "BodyRotation": {
            "Pitch": 0.0,
            "Yaw": 0.0,
            "Roll": 0.0
          },
          "Usable": false,
          "DisplayName": "SpawnSuppression: Spawn_Camp",
          "NameTagVisible": true,
          "UUID": {
            "$binary": "RyTZn1hgMNmXx0eNCOVEIQ==",
            "$type": "04"
          },
          "Model": {
            "Id": "NPC_Spawn_Marker",
            "Scale": 1.0
          },
          "Metadata": {},
          "Velocity": {
            "X": 0.0,
            "Y": 0.0,
            "Z": 0.0
          }
        },
        "SpawnSuppression": {
          "SpawnSuppression": "Spawn_Camp"
        }
      }
    }
  ]
}