{
  "version": 8,
  "blockIdVersion": 8,
  "anchorX": 0,
  "anchorY": 14,
  "anchorZ": 0,
  "blocks": [
    {
      "x": -4,
      "y": 11,
      "z": -1,
      "name": "Soil_Dirt_Cold"
    },
    {
      "x": -4,
      "y": 12,
      "z": -1,
      "name": "Soil_Dirt_Cold"
    },
    {
      "x": -4,
      "y": 13,
      "z": -1,
      "name": "Soil_Dirt_Cold"
    },
    {
      "x": -4,
      "y": 8,
      "z": 0,
      "name": "Rock_Shale"
    },
    {
      "x": -4,
      "y": 9,
      "z": 0,
      "name": "Rock_Shale"
    },
    {
      "x": -4,
      "y": 10,
      "z": 0,
      "name": "Rock_Shale"
    },
    {
      "x": -4,
      "y": 11,
      "z": 0,
      "name": "Soil_Dirt_Cold"
    },
    {
      "x": -4,
      "y": 12,
      "z": 0,
      "name": "Soil_Dirt_Cold"
    },
    {
      "x": -4,
      "y": 13,
      "z": 0,
      "name": "Soil_Dirt_Cold"
    },
    {
      "x": -4,
      "y": 8,
      "z": 1,
      "name": "Rock_Shale"
    },
    {
      "x": -4,
      "y": 9,
      "z": 1,
      "name": "Rock_Shale"
    },
    {
      "x": -4,
      "y": 10,
      "z": 1,
      "name": "Rock_Shale"
    },
    {
      "x": -4,
      "y": 11,
      "z": 1,
      "name": "Rock_Shale"
    },
    {
      "x": -4,
      "y": 12,
      "z": 1,
      "name": "Soil_Dirt_Cold"
    },
    {
      "x": -4,
      "y": 13,
      "z": 1,
      "name": "Soil_Dirt_Cold"
    },
    {
      "x": -4,
      "y": 8,
      "z": 2,
      "name": "Rock_Shale"
    },
    {
      "x": -4,
      "y": 9,
      "z": 2,
      "name": "Rock_Shale"
    },
    {
      "x": -4,
      "y": 10,
      "z": 2,
      "name": "Rock_Shale"
    },
    {
      "x": -4,
      "y": 11,
      "z": 2,
      "name": "Rock_Shale"
    },
    {
      "x": -4,
      "y": 12,
      "z": 2,
      "name": "Soil_Dirt_Cold"
    },
    {
      "x": -4,
      "y": 13,
      "z": 2,
      "name": "Soil_Dirt_Cold"
    },
    {
      "x": -4,
      "y": 14,
      "z": 2,
      "name": "Wood_Fir_Trunk",
      "rotation": 4
    },
    {
      "x": -4,
      "y": 15,
      "z": 2,
      "name": "*Wood_Deadwood_Fence_State_Definitions_Corner",
      "rotation": 1
    },
    {
      "x": -4,
      "y": 16,
      "z": 2,
      "name": "Furniture_Ancient_Torch",
      "rotation": 2
    },
    {
      "x": -4,
      "y": 17,
      "z": 2,
      "name": "Empty"
    },
    {
      "x": -4,
      "y": 8,
      "z": 3,
      "name": "Rock_Shale"
    },
    {
      "x": -4,
      "y": 9,
      "z": 3,
      "name": "Rock_Shale"
    },
    {
      "x": -4,
      "y": 10,
      "z": 3,
      "name": "Rock_Shale"
    },
    {
      "x": -4,
      "y": 11,
      "z": 3,
      "name": "Rock_Shale"
    },
    {
      "x": -4,
      "y": 12,
      "z": 3,
      "name": "Soil_Dirt_Cold"
    },
    {
      "x": -4,
      "y": 13,
      "z": 3,
      "name": "Soil_Dirt_Cold"
    },
    {
      "x": -4,
      "y": 14,
      "z": 3,
      "name": "Wood_Fir_Trunk",
      "rotation": 4
    },
    {
      "x": -4,
      "y": 15,
      "z": 3,
      "name": "Wood_Deadwood_Fence",
      "rotation": 3
    },
    {
      "x": -4,
      "y": 16,
      "z": 3,
      "name": "Empty"
    },
    {
      "x": -4,
      "y": 17,
      "z": 3,
      "name": "Empty"
    },
    {
      "x": -4,
      "y": 10,
      "z": 4,
      "name": "Rock_Shale"
    },
    {
      "x": -4,
      "y": 11,
      "z": 4,
      "name": "Rock_Shale"
    },
    {
      "x": -4,
      "y": 12,
      "z": 4,
      "name": "Soil_Dirt_Cold"
    },
    {
      "x": -4,
      "y": 13,
      "z": 4,
      "name": "Soil_Dirt_Cold"
    },
    {
      "x": -4,
      "y": 14,
      "z": 4,
      "name": "Wood_Fir_Trunk",
      "rotation": 4
    },
    {
      "x": -4,
      "y": 15,
      "z": 4,
      "name": "Wood_Deadwood_Fence",
      "rotation": 3
    },
    {
      "x": -4,
      "y": 16,
      "z": 4,
      "name": "Empty"
    },
    {
      "x": -3,
      "y": 10,
      "z": -5,
      "name": "Rock_Shale"
    },
    {
      "x": -3,
      "y": 11,
      "z": -5,
      "name": "Rock_Shale"
    },
    {
      "x": -3,
      "y": 12,
      "z": -5,
      "name": "Rock_Shale"
    },
    {
      "x": -3,
      "y": 13,
      "z": -5,
      "name": "Soil_Dirt_Cold"
    },
    {
      "x": -3,
      "y": 14,
      "z": -5,
      "name": "Wood_Fir_Trunk",
      "rotation": 4
    },
    {
      "x": -3,
      "y": 15,
      "z": -5,
      "name": "Wood_Deadwood_Roof",
      "rotation": 3
    },
    {
      "x": -3,
      "y": 8,
      "z": -4,
      "name": "Rock_Shale"
    },
    {
      "x": -3,
      "y": 9,
      "z": -4,
      "name": "Rock_Shale"
    },
    {
      "x": -3,
      "y": 10,
      "z": -4,
      "name": "Rock_Shale"
    },
    {
      "x": -3,
      "y": 11,
      "z": -4,
      "name": "Rock_Shale"
    },
    {
      "x": -3,
      "y": 12,
      "z": -4,
      "name": "Soil_Dirt_Cold"
    },
    {
      "x": -3,
      "y": 13,
      "z": -4,
      "name": "Soil_Dirt_Cold"
    },
    {
      "x": -3,
      "y": 14,
      "z": -4,
      "name": "Wood_Fir_Trunk",
      "rotation": 4
    },
    {
      "x": -3,
      "y": 15,
      "z": -4,
      "name": "Cloth_Roof_Hide",
      "rotation": 3
    },
    {
      "x": -3,
      "y": 6,
      "z": -3,
      "name": "Rock_Shale"
    },
    {
      "x": -3,
      "y": 7,
      "z": -3,
      "name": "Rock_Shale"
    },
    {
      "x": -3,
      "y": 8,
      "z": -3,
      "name": "Rock_Shale"
    },
    {
      "x": -3,
      "y": 9,
      "z": -3,
      "name": "Rock_Shale"
    },
    {
      "x": -3,
      "y": 10,
      "z": -3,
      "name": "Rock_Shale"
    },
    {
      "x": -3,
      "y": 11,
      "z": -3,
      "name": "Soil_Dirt_Cold"
    },
    {
      "x": -3,
      "y": 12,
      "z": -3,
      "name": "Soil_Dirt_Cold"
    },
    {
      "x": -3,
      "y": 13,
      "z": -3,
      "name": "Soil_Dirt_Cold"
    },
    {
      "x": -3,
      "y": 14,
      "z": -3,
      "name": "Wood_Fir_Trunk",
      "rotation": 4
    },
    {
      "x": -3,
      "y": 15,
      "z": -3,
      "name": "Cloth_Roof_Hide",
      "rotation": 3
    },
    {
      "x": -3,
      "y": 6,
      "z": -2,
      "name": "Rock_Shale"
    },
    {
      "x": -3,
      "y": 7,
      "z": -2,
      "name": "Rock_Shale"
    },
    {
      "x": -3,
      "y": 8,
      "z": -2,
      "name": "Rock_Shale"
    },
    {
      "x": -3,
      "y": 9,
      "z": -2,
      "name": "Rock_Shale"
    },
    {
      "x": -3,
      "y": 10,
      "z": -2,
      "name": "Rock_Shale"
    },
    {
      "x": -3,
      "y": 11,
      "z": -2,
      "name": "Soil_Dirt_Cold"
    },
    {
      "x": -3,
      "y": 12,
      "z": -2,
      "name": "Soil_Dirt_Cold"
    },
    {
      "x": -3,
      "y": 13,
      "z": -2,
      "name": "Soil_Dirt_Cold"
    },
    {
      "x": -3,
      "y": 14,
      "z": -2,
      "name": "Wood_Fir_Trunk",
      "rotation": 4
    },
    {
      "x": -3,
      "y": 15,
      "z": -2,
      "name": "Cloth_Roof_Hide",
      "rotation": 3
    },
    {
      "x": -3,
      "y": 6,
      "z": -1,
      "name": "Rock_Shale"
    },
    {
      "x": -3,
      "y": 7,
      "z": -1,
      "name": "Rock_Shale"
    },
    {
      "x": -3,
      "y": 8,
      "z": -1,
      "name": "Rock_Shale"
    },
    {
      "x": -3,
      "y": 9,
      "z": -1,
      "name": "Rock_Shale"
    },
    {
      "x": -3,
      "y": 10,
      "z": -1,
      "name": "Rock_Shale"
    },
    {
      "x": -3,
      "y": 11,
      "z": -1,
      "name": "Soil_Dirt_Cold"
    },
    {
      "x": -3,
      "y": 12,
      "z": -1,
      "name": "Soil_Dirt_Cold"
    },
    {
      "x": -3,
      "y": 13,
      "z": -1,
      "name": "Soil_Dirt_Cold"
    },
    {
      "x": -3,
      "y": 14,
      "z": -1,
      "name": "Wood_Fir_Trunk",
      "rotation": 4
    },
    {
      "x": -3,
      "y": 15,
      "z": -1,
      "name": "Cloth_Roof_Hide",
      "rotation": 3
    },
    {
      "x": -3,
      "y": 6,
      "z": 0,
      "name": "Rock_Shale"
    },
    {
      "x": -3,
      "y": 7,
      "z": 0,
      "name": "Rock_Shale"
    },
    {
      "x": -3,
      "y": 8,
      "z": 0,
      "name": "Rock_Shale"
    },
    {
      "x": -3,
      "y": 9,
      "z": 0,
      "name": "Rock_Shale"
    },
    {
      "x": -3,
      "y": 10,
      "z": 0,
      "name": "Rock_Shale"
    },
    {
      "x": -3,
      "y": 11,
      "z": 0,
      "name": "Soil_Dirt_Cold"
    },
    {
      "x": -3,
      "y": 12,
      "z": 0,
      "name": "Soil_Dirt_Cold"
    },
    {
      "x": -3,
      "y": 13,
      "z": 0,
      "name": "Soil_Dirt_Cold"
    },
    {
      "x": -3,
      "y": 14,
      "z": 0,
      "name": "Wood_Fir_Trunk",
      "rotation": 4
    },
    {
      "x": -3,
      "y": 15,
      "z": 0,
      "name": "Wood_Deadwood_Roof",
      "rotation": 3
    },
    {
      "x": -3,
      "y": 7,
      "z": 1,
      "name": "Rock_Shale"
    },
    {
      "x": -3,
      "y": 8,
      "z": 1,
      "name": "Rock_Shale"
    },
    {
      "x": -3,
      "y": 9,
      "z": 1,
      "name": "Rock_Shale"
    },
    {
      "x": -3,
      "y": 10,
      "z": 1,
      "name": "Rock_Shale"
    },
    {
      "x": -3,
      "y": 11,
      "z": 1,
      "name": "Soil_Dirt_Cold"
    },
    {
      "x": -3,
      "y": 12,
      "z": 1,
      "name": "Soil_Dirt_Cold"
    },
    {
      "x": -3,
      "y": 13,
      "z": 1,
      "name": "Soil_Dirt_Cold"
    },
    {
      "x": -3,
      "y": 14,
      "z": 1,
      "name": "Soil_Pebbles_Frozen"
    },
    {
      "x": -3,
      "y": 15,
      "z": 1,
      "name": "Empty"
    },
    {
      "x": -3,
      "y": 16,
      "z": 1,
      "name": "Empty"
    },
    {
      "x": -3,
      "y": 7,
      "z": 2,
      "name": "Rock_Shale"
    },
    {
      "x": -3,
      "y": 8,
      "z": 2,
      "name": "Rock_Shale"
    },
    {
      "x": -3,
      "y": 9,
      "z": 2,
      "name": "Rock_Shale"
    },
    {
      "x": -3,
      "y": 10,
      "z": 2,
      "name": "Rock_Shale"
    },
    {
      "x": -3,
      "y": 11,
      "z": 2,
      "name": "Soil_Dirt_Cold"
    },
    {
      "x": -3,
      "y": 12,
      "z": 2,
      "name": "Soil_Dirt_Cold"
    },
    {
      "x": -3,
      "y": 13,
      "z": 2,
      "name": "Soil_Pebbles_Frozen"
    },
    {
      "x": -3,
      "y": 14,
      "z": 2,
      "name": "Soil_Pebbles_Frozen"
    },
    {
      "x": -3,
      "y": 15,
      "z": 2,
      "name": "Furniture_Village_Crate"
    },
    {
      "x": -3,
      "y": 16,
      "z": 2,
      "name": "Empty"
    },
    {
      "x": -3,
      "y": 17,
      "z": 2,
      "name": "Empty"
    },
    {
      "x": -3,
      "y": 8,
      "z": 3,
      "name": "Rock_Shale"
    },
    {
      "x": -3,
      "y": 9,
      "z": 3,
      "name": "Rock_Shale"
    },
    {
      "x": -3,
      "y": 10,
      "z": 3,
      "name": "Rock_Shale"
    },
    {
      "x": -3,
      "y": 11,
      "z": 3,
      "name": "Soil_Dirt_Cold"
    },
    {
      "x": -3,
      "y": 12,
      "z": 3,
      "name": "Soil_Dirt_Cold"
    },
    {
      "x": -3,
      "y": 13,
      "z": 3,
      "name": "Soil_Pebbles_Frozen"
    },
    {
      "x": -3,
      "y": 14,
      "z": 3,
      "name": "Soil_Pebbles_Frozen"
    },
    {
      "x": -3,
      "y": 15,
      "z": 3,
      "name": "Bench_Lumbermill",
      "components": {
        "Components": {
          "processingBench": {
            "Position": {
              "X": -3,
              "Y": 1,
              "Z": 3
            },
            "TierLevel": 1,
            "UpgradeItems": [],
            "InputContainer": {
              "Id": "Simple",
              "Capacity": 2,
              "Items": {}
            },
            "FuelContainer": {
              "Id": "Simple",
              "Capacity": 0,
              "Items": {}
            },
            "OutputContainer": {
              "Id": "Simple",
              "Capacity": 1,
              "Items": {}
            },
            "Progress": 0.0,
            "FuelTime": 0.0,
            "Active": true,
            "NextExtra": 0
          }
        }
      },
      "rotation": 1
    },
    {
      "x": -3,
      "y": 16,
      "z": 3,
      "name": "Empty"
    },
    {
      "x": -3,
      "y": 17,
      "z": 3,
      "name": "Empty"
    },
    {
      "x": -3,
      "y": 9,
      "z": 4,
      "name": "Rock_Shale"
    },
    {
      "x": -3,
      "y": 10,
      "z": 4,
      "name": "Rock_Shale"
    },
    {
      "x": -3,
      "y": 11,
      "z": 4,
      "name": "Soil_Dirt_Cold"
    },
    {
      "x": -3,
      "y": 12,
      "z": 4,
      "name": "Soil_Pebbles_Frozen"
    },
    {
      "x": -3,
      "y": 13,
      "z": 4,
      "name": "Soil_Pebbles_Frozen"
    },
    {
      "x": -3,
      "y": 14,
      "z": 4,
      "name": "Soil_Pebbles_Frozen"
    },
    {
      "x": -3,
      "y": 15,
      "z": 4,
      "name": "Bench_Lumbermill",
      "components": {
        "Components": {
          "processingBench": {
            "Position": {
              "X": 29,
              "Y": 15,
              "Z": 4
            },
            "TierLevel": 1,
            "UpgradeItems": [],
            "Progress": 0.0,
            "FuelTime": 0.0,
            "Active": false,
            "NextExtra": -1
          }
        }
      },
      "filler": 32,
      "rotation": 1
    },
    {
      "x": -3,
      "y": 16,
      "z": 4,
      "name": "Empty"
    },
    {
      "x": -3,
      "y": 17,
      "z": 4,
      "name": "Empty"
    },
    {
      "x": -3,
      "y": 12,
      "z": 5,
      "name": "Soil_Pebbles_Frozen"
    },
    {
      "x": -3,
      "y": 13,
      "z": 5,
      "name": "Soil_Pebbles_Frozen"
    },
    {
      "x": -2,
      "y": 9,
      "z": -5,
      "name": "Rock_Shale"
    },
    {
      "x": -2,
      "y": 10,
      "z": -5,
      "name": "Rock_Shale"
    },
    {
      "x": -2,
      "y": 11,
      "z": -5,
      "name": "Rock_Shale"
    },
    {
      "x": -2,
      "y": 12,
      "z": -5,
      "name": "Rock_Shale"
    },
    {
      "x": -2,
      "y": 13,
      "z": -5,
      "name": "Soil_Dirt_Cold"
    },
    {
      "x": -2,
      "y": 14,
      "z": -5,
      "name": "Wood_Fir_Trunk",
      "rotation": 5
    },
    {
      "x": -2,
      "y": 15,
      "z": -5,
      "name": "Wood_Deadwood_Planks_Half",
      "rotation": 6
    },
    {
      "x": -2,
      "y": 16,
      "z": -5,
      "name": "Wood_Deadwood_Roof",
      "rotation": 3
    },
    {
      "x": -2,
      "y": 6,
      "z": -4,
      "name": "Rock_Shale"
    },
    {
      "x": -2,
      "y": 7,
      "z": -4,
      "name": "Rock_Shale"
    },
    {
      "x": -2,
      "y": 8,
      "z": -4,
      "name": "Rock_Shale"
    },
    {
      "x": -2,
      "y": 9,
      "z": -4,
      "name": "Rock_Shale"
    },
    {
      "x": -2,
      "y": 10,
      "z": -4,
      "name": "Rock_Shale"
    },
    {
      "x": -2,
      "y": 11,
      "z": -4,
      "name": "Soil_Dirt_Cold"
    },
    {
      "x": -2,
      "y": 12,
      "z": -4,
      "name": "Soil_Dirt_Cold"
    },
    {
      "x": -2,
      "y": 13,
      "z": -4,
      "name": "Soil_Dirt_Cold"
    },
    {
      "x": -2,
      "y": 14,
      "z": -4,
      "name": "Soil_Dirt_Cold"
    },
    {
      "x": -2,
      "y": 15,
      "z": -4,
      "name": "Empty"
    },
    {
      "x": -2,
      "y": 16,
      "z": -4,
      "name": "Cloth_Roof_Hide",
      "rotation": 3
    },
    {
      "x": -2,
      "y": 6,
      "z": -3,
      "name": "Rock_Shale"
    },
    {
      "x": -2,
      "y": 7,
      "z": -3,
      "name": "Rock_Shale"
    },
    {
      "x": -2,
      "y": 8,
      "z": -3,
      "name": "Rock_Shale"
    },
    {
      "x": -2,
      "y": 9,
      "z": -3,
      "name": "Rock_Shale"
    },
    {
      "x": -2,
      "y": 10,
      "z": -3,
      "name": "Rock_Shale"
    },
    {
      "x": -2,
      "y": 11,
      "z": -3,
      "name": "Soil_Dirt_Cold"
    },
    {
      "x": -2,
      "y": 12,
      "z": -3,
      "name": "Soil_Dirt_Cold"
    },
    {
      "x": -2,
      "y": 13,
      "z": -3,
      "name": "Soil_Dirt_Cold"
    },
    {
      "x": -2,
      "y": 14,
      "z": -3,
      "name": "Soil_Dirt_Cold"
    },
    {
      "x": -2,
      "y": 15,
      "z": -3,
      "name": "Empty"
    },
    {
      "x": -2,
      "y": 16,
      "z": -3,
      "name": "Cloth_Roof_Hide",
      "rotation": 3
    },
    {
      "x": -2,
      "y": 5,
      "z": -2,
      "name": "Rock_Shale"
    },
    {
      "x": -2,
      "y": 6,
      "z": -2,
      "name": "Rock_Shale"
    },
    {
      "x": -2,
      "y": 7,
      "z": -2,
      "name": "Rock_Shale"
    },
    {
      "x": -2,
      "y": 8,
      "z": -2,
      "name": "Rock_Shale"
    },
    {
      "x": -2,
      "y": 9,
      "z": -2,
      "name": "Rock_Shale"
    },
    {
      "x": -2,
      "y": 10,
      "z": -2,
      "name": "Rock_Shale"
    },
    {
      "x": -2,
      "y": 11,
      "z": -2,
      "name": "Soil_Dirt_Cold"
    },
    {
      "x": -2,
      "y": 12,
      "z": -2,
      "name": "Soil_Dirt_Cold"
    },
    {
      "x": -2,
      "y": 13,
      "z": -2,
      "name": "Soil_Dirt_Cold"
    },
    {
      "x": -2,
      "y": 14,
      "z": -2,
      "name": "Soil_Dirt_Cold"
    },
    {
      "x": -2,
      "y": 15,
      "z": -2,
      "name": "Empty"
    },
    {
      "x": -2,
      "y": 16,
      "z": -2,
      "name": "Cloth_Roof_Hide",
      "rotation": 3
    },
    {
      "x": -2,
      "y": 5,
      "z": -1,
      "name": "Rock_Shale"
    },
    {
      "x": -2,
      "y": 6,
      "z": -1,
      "name": "Rock_Shale"
    },
    {
      "x": -2,
      "y": 7,
      "z": -1,
      "name": "Rock_Shale"
    },
    {
      "x": -2,
      "y": 8,
      "z": -1,
      "name": "Rock_Shale"
    },
    {
      "x": -2,
      "y": 9,
      "z": -1,
      "name": "Rock_Shale"
    },
    {
      "x": -2,
      "y": 10,
      "z": -1,
      "name": "Rock_Shale"
    },
    {
      "x": -2,
      "y": 11,
      "z": -1,
      "name": "Soil_Dirt_Cold"
    },
    {
      "x": -2,
      "y": 12,
      "z": -1,
      "name": "Soil_Dirt_Cold"
    },
    {
      "x": -2,
      "y": 13,
      "z": -1,
      "name": "Soil_Dirt_Cold"
    },
    {
      "x": -2,
      "y": 14,
      "z": -1,
      "name": "Soil_Dirt_Cold"
    },
    {
      "x": -2,
      "y": 15,
      "z": -1,
      "name": "Furniture_Crude_Stool"
    },
    {
      "x": -2,
      "y": 16,
      "z": -1,
      "name": "Cloth_Roof_Hide",
      "rotation": 3
    },
    {
      "x": -2,
      "y": 5,
      "z": 0,
      "name": "Rock_Shale"
    },
    {
      "x": -2,
      "y": 6,
      "z": 0,
      "name": "Rock_Shale"
    },
    {
      "x": -2,
      "y": 7,
      "z": 0,
      "name": "Rock_Shale"
    },
    {
      "x": -2,
      "y": 8,
      "z": 0,
      "name": "Rock_Shale"
    },
    {
      "x": -2,
      "y": 9,
      "z": 0,
      "name": "Rock_Shale"
    },
    {
      "x": -2,
      "y": 10,
      "z": 0,
      "name": "Rock_Shale"
    },
    {
      "x": -2,
      "y": 11,
      "z": 0,
      "name": "Soil_Dirt_Cold"
    },
    {
      "x": -2,
      "y": 12,
      "z": 0,
      "name": "Soil_Dirt_Cold"
    },
    {
      "x": -2,
      "y": 13,
      "z": 0,
      "name": "Soil_Dirt_Cold"
    },
    {
      "x": -2,
      "y": 14,
      "z": 0,
      "name": "Soil_Dirt_Cold"
    },
    {
      "x": -2,
      "y": 15,
      "z": 0,
      "name": "Wood_Deadwood_Stairs",
      "rotation": 11
    },
    {
      "x": -2,
      "y": 16,
      "z": 0,
      "name": "Wood_Deadwood_Roof",
      "rotation": 3
    },
    {
      "x": -2,
      "y": 5,
      "z": 1,
      "name": "Rock_Shale"
    },
    {
      "x": -2,
      "y": 6,
      "z": 1,
      "name": "Rock_Shale"
    },
    {
      "x": -2,
      "y": 7,
      "z": 1,
      "name": "Rock_Shale"
    },
    {
      "x": -2,
      "y": 8,
      "z": 1,
      "name": "Rock_Shale"
    },
    {
      "x": -2,
      "y": 9,
      "z": 1,
      "name": "Rock_Shale"
    },
    {
      "x": -2,
      "y": 10,
      "z": 1,
      "name": "Rock_Shale"
    },
    {
      "x": -2,
      "y": 11,
      "z": 1,
      "name": "Soil_Dirt_Cold"
    },
    {
      "x": -2,
      "y": 12,
      "z": 1,
      "name": "Soil_Dirt_Cold"
    },
    {
      "x": -2,
      "y": 13,
      "z": 1,
      "name": "Soil_Dirt_Cold"
    },
    {
      "x": -2,
      "y": 14,
      "z": 1,
      "name": "Soil_Pebbles_Frozen"
    },
    {
      "x": -2,
      "y": 15,
      "z": 1,
      "name": "Empty"
    },
    {
      "x": -2,
      "y": 16,
      "z": 1,
      "name": "Empty"
    },
    {
      "x": -2,
      "y": 17,
      "z": 1,
      "name": "Empty"
    },
    {
      "x": -2,
      "y": 6,
      "z": 2,
      "name": "Rock_Shale"
    },
    {
      "x": -2,
      "y": 7,
      "z": 2,
      "name": "Rock_Shale"
    },
    {
      "x": -2,
      "y": 8,
      "z": 2,
      "name": "Rock_Shale"
    },
    {
      "x": -2,
      "y": 9,
      "z": 2,
      "name": "Rock_Shale"
    },
    {
      "x": -2,
      "y": 10,
      "z": 2,
      "name": "Rock_Shale"
    },
    {
      "x": -2,
      "y": 11,
      "z": 2,
      "name": "Soil_Dirt_Cold"
    },
    {
      "x": -2,
      "y": 12,
      "z": 2,
      "name": "Soil_Dirt_Cold"
    },
    {
      "x": -2,
      "y": 13,
      "z": 2,
      "name": "Soil_Pebbles_Frozen"
    },
    {
      "x": -2,
      "y": 14,
      "z": 2,
      "name": "Soil_Pebbles_Frozen"
    },
    {
      "x": -2,
      "y": 15,
      "z": 2,
      "name": "Empty"
    },
    {
      "x": -2,
      "y": 16,
      "z": 2,
      "name": "Empty"
    },
    {
      "x": -2,
      "y": 17,
      "z": 2,
      "name": "Empty"
    },
    {
      "x": -2,
      "y": 18,
      "z": 2,
      "name": "Empty"
    },
    {
      "x": -2,
      "y": 6,
      "z": 3,
      "name": "Rock_Shale"
    },
    {
      "x": -2,
      "y": 7,
      "z": 3,
      "name": "Rock_Shale"
    },
    {
      "x": -2,
      "y": 8,
      "z": 3,
      "name": "Rock_Shale"
    },
    {
      "x": -2,
      "y": 9,
      "z": 3,
      "name": "Rock_Shale"
    },
    {
      "x": -2,
      "y": 10,
      "z": 3,
      "name": "Rock_Shale"
    },
    {
      "x": -2,
      "y": 11,
      "z": 3,
      "name": "Soil_Dirt_Cold"
    },
    {
      "x": -2,
      "y": 12,
      "z": 3,
      "name": "Soil_Dirt_Cold"
    },
    {
      "x": -2,
      "y": 13,
      "z": 3,
      "name": "Soil_Pebbles_Frozen"
    },
    {
      "x": -2,
      "y": 14,
      "z": 3,
      "name": "Soil_Pebbles_Frozen"
    },
    {
      "x": -2,
      "y": 15,
      "z": 3,
      "name": "Empty"
    },
    {
      "x": -2,
      "y": 16,
      "z": 3,
      "name": "Empty"
    },
    {
      "x": -2,
      "y": 17,
      "z": 3,
      "name": "Empty"
    },
    {
      "x": -2,
      "y": 18,
      "z": 3,
      "name": "Empty"
    },
    {
      "x": -2,
      "y": 7,
      "z": 4,
      "name": "Rock_Shale"
    },
    {
      "x": -2,
      "y": 8,
      "z": 4,
      "name": "Rock_Shale"
    },
    {
      "x": -2,
      "y": 9,
      "z": 4,
      "name": "Rock_Shale"
    },
    {
      "x": -2,
      "y": 10,
      "z": 4,
      "name": "Rock_Shale"
    },
    {
      "x": -2,
      "y": 11,
      "z": 4,
      "name": "Soil_Dirt_Cold"
    },
    {
      "x": -2,
      "y": 12,
      "z": 4,
      "name": "Soil_Pebbles_Frozen"
    },
    {
      "x": -2,
      "y": 13,
      "z": 4,
      "name": "Soil_Pebbles_Frozen"
    },
    {
      "x": -2,
      "y": 14,
      "z": 4,
      "name": "Soil_Pebbles_Frozen"
    },
    {
      "x": -2,
      "y": 15,
      "z": 4,
      "name": "Empty"
    },
    {
      "x": -2,
      "y": 16,
      "z": 4,
      "name": "Empty"
    },
    {
      "x": -2,
      "y": 17,
      "z": 4,
      "name": "Empty"
    },
    {
      "x": -2,
      "y": 11,
      "z": 5,
      "name": "Soil_Dirt_Cold"
    },
    {
      "x": -2,
      "y": 12,
      "z": 5,
      "name": "Soil_Pebbles_Frozen"
    },
    {
      "x": -2,
      "y": 13,
      "z": 5,
      "name": "Soil_Pebbles_Frozen"
    },
    {
      "x": -1,
      "y": 8,
      "z": -5,
      "name": "Rock_Shale"
    },
    {
      "x": -1,
      "y": 9,
      "z": -5,
      "name": "Rock_Shale"
    },
    {
      "x": -1,
      "y": 10,
      "z": -5,
      "name": "Rock_Shale"
    },
    {
      "x": -1,
      "y": 11,
      "z": -5,
      "name": "Rock_Shale"
    },
    {
      "x": -1,
      "y": 12,
      "z": -5,
      "name": "Soil_Dirt_Cold"
    },
    {
      "x": -1,
      "y": 13,
      "z": -5,
      "name": "Soil_Dirt_Cold"
    },
    {
      "x": -1,
      "y": 14,
      "z": -5,
      "name": "Wood_Fir_Trunk",
      "rotation": 5
    },
    {
      "x": -1,
      "y": 15,
      "z": -5,
      "name": "Wood_Deadwood_Planks_Half",
      "rotation": 6
    },
    {
      "x": -1,
      "y": 16,
      "z": -5,
      "name": "Wood_Deadwood_Planks_Half",
      "rotation": 6
    },
    {
      "x": -1,
      "y": 17,
      "z": -5,
      "name": "Wood_Deadwood_Roof",
      "rotation": 3
    },
    {
      "x": -1,
      "y": 6,
      "z": -4,
      "name": "Rock_Shale"
    },
    {
      "x": -1,
      "y": 7,
      "z": -4,
      "name": "Rock_Shale"
    },
    {
      "x": -1,
      "y": 8,
      "z": -4,
      "name": "Rock_Shale"
    },
    {
      "x": -1,
      "y": 9,
      "z": -4,
      "name": "Rock_Shale"
    },
    {
      "x": -1,
      "y": 10,
      "z": -4,
      "name": "Rock_Shale"
    },
    {
      "x": -1,
      "y": 11,
      "z": -4,
      "name": "Soil_Dirt_Cold"
    },
    {
      "x": -1,
      "y": 12,
      "z": -4,
      "name": "Soil_Dirt_Cold"
    },
    {
      "x": -1,
      "y": 13,
      "z": -4,
      "name": "Soil_Dirt_Cold"
    },
    {
      "x": -1,
      "y": 14,
      "z": -4,
      "name": "Soil_Dirt_Cold"
    },
    {
      "x": -1,
      "y": 15,
      "z": -4,
      "name": "Furniture_Crude_Bed",
      "components": {
        "Components": {
          "RespawnBlock": {}
        }
      }
    },
    {
      "x": -1,
      "y": 16,
      "z": -4,
      "name": "Empty"
    },
    {
      "x": -1,
      "y": 17,
      "z": -4,
      "name": "Cloth_Roof_Hide",
      "rotation": 3
    },
    {
      "x": -1,
      "y": 6,
      "z": -3,
      "name": "Rock_Shale"
    },
    {
      "x": -1,
      "y": 7,
      "z": -3,
      "name": "Rock_Shale"
    },
    {
      "x": -1,
      "y": 8,
      "z": -3,
      "name": "Rock_Shale"
    },
    {
      "x": -1,
      "y": 9,
      "z": -3,
      "name": "Rock_Shale"
    },
    {
      "x": -1,
      "y": 10,
      "z": -3,
      "name": "Rock_Shale"
    },
    {
      "x": -1,
      "y": 11,
      "z": -3,
      "name": "Soil_Dirt_Cold"
    },
    {
      "x": -1,
      "y": 12,
      "z": -3,
      "name": "Soil_Dirt_Cold"
    },
    {
      "x": -1,
      "y": 13,
      "z": -3,
      "name": "Soil_Dirt_Cold"
    },
    {
      "x": -1,
      "y": 14,
      "z": -3,
      "name": "Soil_Dirt_Cold"
    },
    {
      "x": -1,
      "y": 15,
      "z": -3,
      "name": "Furniture_Crude_Bed",
      "components": {
        "Components": {
          "RespawnBlock": {}
        }
      },
      "filler": 32
    },
    {
      "x": -1,
      "y": 16,
      "z": -3,
      "name": "Empty"
    },
    {
      "x": -1,
      "y": 17,
      "z": -3,
      "name": "Cloth_Roof_Hide",
      "rotation": 3
    },
    {
      "x": -1,
      "y": 5,
      "z": -2,
      "name": "Rock_Shale"
    },
    {
      "x": -1,
      "y": 6,
      "z": -2,
      "name": "Rock_Shale"
    },
    {
      "x": -1,
      "y": 7,
      "z": -2,
      "name": "Rock_Shale"
    },
    {
      "x": -1,
      "y": 8,
      "z": -2,
      "name": "Rock_Shale"
    },
    {
      "x": -1,
      "y": 9,
      "z": -2,
      "name": "Rock_Shale"
    },
    {
      "x": -1,
      "y": 10,
      "z": -2,
      "name": "Rock_Shale"
    },
    {
      "x": -1,
      "y": 11,
      "z": -2,
      "name": "Soil_Dirt_Cold"
    },
    {
      "x": -1,
      "y": 12,
      "z": -2,
      "name": "Soil_Dirt_Cold"
    },
    {
      "x": -1,
      "y": 13,
      "z": -2,
      "name": "Soil_Dirt_Cold"
    },
    {
      "x": -1,
      "y": 14,
      "z": -2,
      "name": "Soil_Dirt_Cold"
    },
    {
      "x": -1,
      "y": 15,
      "z": -2,
      "name": "Empty"
    },
    {
      "x": -1,
      "y": 16,
      "z": -2,
      "name": "Empty"
    },
    {
      "x": -1,
      "y": 17,
      "z": -2,
      "name": "Cloth_Roof_Hide",
      "rotation": 3
    },
    {
      "x": -1,
      "y": 5,
      "z": -1,
      "name": "Rock_Shale"
    },
    {
      "x": -1,
      "y": 6,
      "z": -1,
      "name": "Rock_Shale"
    },
    {
      "x": -1,
      "y": 7,
      "z": -1,
      "name": "Rock_Shale"
    },
    {
      "x": -1,
      "y": 8,
      "z": -1,
      "name": "Rock_Shale"
    },
    {
      "x": -1,
      "y": 9,
      "z": -1,
      "name": "Rock_Shale"
    },
    {
      "x": -1,
      "y": 10,
      "z": -1,
      "name": "Rock_Shale"
    },
    {
      "x": -1,
      "y": 11,
      "z": -1,
      "name": "Soil_Dirt_Cold"
    },
    {
      "x": -1,
      "y": 12,
      "z": -1,
      "name": "Soil_Dirt_Cold"
    },
    {
      "x": -1,
      "y": 13,
      "z": -1,
      "name": "Soil_Dirt_Cold"
    },
    {
      "x": -1,
      "y": 14,
      "z": -1,
      "name": "Soil_Dirt_Cold"
    },
    {
      "x": -1,
      "y": 15,
      "z": -1,
      "name": "Empty"
    },
    {
      "x": -1,
      "y": 16,
      "z": -1,
      "name": "Empty"
    },
    {
      "x": -1,
      "y": 17,
      "z": -1,
      "name": "Cloth_Roof_Hide",
      "rotation": 3
    },
    {
      "x": -1,
      "y": 5,
      "z": 0,
      "name": "Rock_Shale"
    },
    {
      "x": -1,
      "y": 6,
      "z": 0,
      "name": "Rock_Shale"
    },
    {
      "x": -1,
      "y": 7,
      "z": 0,
      "name": "Rock_Shale"
    },
    {
      "x": -1,
      "y": 8,
      "z": 0,
      "name": "Rock_Shale"
    },
    {
      "x": -1,
      "y": 9,
      "z": 0,
      "name": "Rock_Shale"
    },
    {
      "x": -1,
      "y": 10,
      "z": 0,
      "name": "Rock_Shale"
    },
    {
      "x": -1,
      "y": 11,
      "z": 0,
      "name": "Soil_Dirt_Cold"
    },
    {
      "x": -1,
      "y": 12,
      "z": 0,
      "name": "Soil_Dirt_Cold"
    },
    {
      "x": -1,
      "y": 13,
      "z": 0,
      "name": "Soil_Dirt_Cold"
    },
    {
      "x": -1,
      "y": 14,
      "z": 0,
      "name": "Soil_Dirt_Cold"
    },
    {
      "x": -1,
      "y": 15,
      "z": 0,
      "name": "Empty"
    },
    {
      "x": -1,
      "y": 16,
      "z": 0,
      "name": "Wood_Deadwood_Stairs",
      "rotation": 11
    },
    {
      "x": -1,
      "y": 17,
      "z": 0,
      "name": "Wood_Deadwood_Roof",
      "rotation": 3
    },
    {
      "x": -1,
      "y": 5,
      "z": 1,
      "name": "Rock_Shale"
    },
    {
      "x": -1,
      "y": 6,
      "z": 1,
      "name": "Rock_Shale"
    },
    {
      "x": -1,
      "y": 7,
      "z": 1,
      "name": "Rock_Shale"
    },
    {
      "x": -1,
      "y": 8,
      "z": 1,
      "name": "Rock_Shale"
    },
    {
      "x": -1,
      "y": 9,
      "z": 1,
      "name": "Rock_Shale"
    },
    {
      "x": -1,
      "y": 10,
      "z": 1,
      "name": "Rock_Shale"
    },
    {
      "x": -1,
      "y": 11,
      "z": 1,
      "name": "Soil_Dirt_Cold"
    },
    {
      "x": -1,
      "y": 12,
      "z": 1,
      "name": "Soil_Dirt_Cold"
    },
    {
      "x": -1,
      "y": 13,
      "z": 1,
      "name": "Soil_Dirt_Cold"
    },
    {
      "x": -1,
      "y": 14,
      "z": 1,
      "name": "Soil_Dirt_Cold"
    },
    {
      "x": -1,
      "y": 15,
      "z": 1,
      "name": "Empty"
    },
    {
      "x": -1,
      "y": 16,
      "z": 1,
      "name": "Empty"
    },
    {
      "x": -1,
      "y": 17,
      "z": 1,
      "name": "Empty"
    },
    {
      "x": -1,
      "y": 18,
      "z": 1,
      "name": "Empty"
    },
    {
      "x": -1,
      "y": 5,
      "z": 2,
      "name": "Rock_Shale"
    },
    {
      "x": -1,
      "y": 6,
      "z": 2,
      "name": "Rock_Shale"
    },
    {
      "x": -1,
      "y": 7,
      "z": 2,
      "name": "Rock_Shale"
    },
    {
      "x": -1,
      "y": 8,
      "z": 2,
      "name": "Rock_Shale"
    },
    {
      "x": -1,
      "y": 9,
      "z": 2,
      "name": "Rock_Shale"
    },
    {
      "x": -1,
      "y": 10,
      "z": 2,
      "name": "Rock_Shale"
    },
    {
      "x": -1,
      "y": 11,
      "z": 2,
      "name": "Soil_Dirt_Cold"
    },
    {
      "x": -1,
      "y": 12,
      "z": 2,
      "name": "Soil_Dirt_Cold"
    },
    {
      "x": -1,
      "y": 13,
      "z": 2,
      "name": "Soil_Pebbles_Frozen"
    },
    {
      "x": -1,
      "y": 14,
      "z": 2,
      "name": "Soil_Pebbles_Frozen"
    },
    {
      "x": -1,
      "y": 15,
      "z": 2,
      "name": "Empty"
    },
    {
      "x": -1,
      "y": 16,
      "z": 2,
      "name": "Empty"
    },
    {
      "x": -1,
      "y": 17,
      "z": 2,
      "name": "Empty"
    },
    {
      "x": -1,
      "y": 18,
      "z": 2,
      "name": "Empty"
    },
    {
      "x": -1,
      "y": 6,
      "z": 3,
      "name": "Rock_Shale"
    },
    {
      "x": -1,
      "y": 7,
      "z": 3,
      "name": "Rock_Shale"
    },
    {
      "x": -1,
      "y": 8,
      "z": 3,
      "name": "Rock_Shale"
    },
    {
      "x": -1,
      "y": 9,
      "z": 3,
      "name": "Rock_Shale"
    },
    {
      "x": -1,
      "y": 10,
      "z": 3,
      "name": "Rock_Shale"
    },
    {
      "x": -1,
      "y": 11,
      "z": 3,
      "name": "Soil_Dirt_Cold"
    },
    {
      "x": -1,
      "y": 12,
      "z": 3,
      "name": "Soil_Dirt_Cold"
    },
    {
      "x": -1,
      "y": 13,
      "z": 3,
      "name": "Soil_Pebbles_Frozen"
    },
    {
      "x": -1,
      "y": 14,
      "z": 3,
      "name": "Soil_Pebbles_Frozen"
    },
    {
      "x": -1,
      "y": 15,
      "z": 3,
      "name": "Empty"
    },
    {
      "x": -1,
      "y": 16,
      "z": 3,
      "name": "Empty"
    },
    {
      "x": -1,
      "y": 17,
      "z": 3,
      "name": "Empty"
    },
    {
      "x": -1,
      "y": 18,
      "z": 3,
      "name": "Empty"
    },
    {
      "x": -1,
      "y": 6,
      "z": 4,
      "name": "Rock_Shale"
    },
    {
      "x": -1,
      "y": 7,
      "z": 4,
      "name": "Rock_Shale"
    },
    {
      "x": -1,
      "y": 8,
      "z": 4,
      "name": "Rock_Shale"
    },
    {
      "x": -1,
      "y": 9,
      "z": 4,
      "name": "Rock_Shale"
    },
    {
      "x": -1,
      "y": 10,
      "z": 4,
      "name": "Rock_Shale"
    },
    {
      "x": -1,
      "y": 11,
      "z": 4,
      "name": "Soil_Dirt_Cold"
    },
    {
      "x": -1,
      "y": 12,
      "z": 4,
      "name": "Soil_Dirt_Cold"
    },
    {
      "x": -1,
      "y": 13,
      "z": 4,
      "name": "Soil_Pebbles_Frozen"
    },
    {
      "x": -1,
      "y": 14,
      "z": 4,
      "name": "Soil_Pebbles_Frozen"
    },
    {
      "x": -1,
      "y": 15,
      "z": 4,
      "name": "Empty"
    },
    {
      "x": -1,
      "y": 16,
      "z": 4,
      "name": "Empty"
    },
    {
      "x": -1,
      "y": 17,
      "z": 4,
      "name": "Empty"
    },
    {
      "x": -1,
      "y": 18,
      "z": 4,
      "name": "Empty"
    },
    {
      "x": -1,
      "y": 9,
      "z": 5,
      "name": "Rock_Shale"
    },
    {
      "x": -1,
      "y": 10,
      "z": 5,
      "name": "Rock_Shale"
    },
    {
      "x": -1,
      "y": 11,
      "z": 5,
      "name": "Soil_Dirt_Cold"
    },
    {
      "x": -1,
      "y": 12,
      "z": 5,
      "name": "Soil_Dirt_Cold"
    },
    {
      "x": -1,
      "y": 13,
      "z": 5,
      "name": "Soil_Pebbles_Frozen"
    },
    {
      "x": -1,
      "y": 14,
      "z": 5,
      "name": "Soil_Pebbles_Frozen"
    },
    {
      "x": -1,
      "y": 15,
      "z": 5,
      "name": "Empty"
    },
    {
      "x": -1,
      "y": 16,
      "z": 5,
      "name": "Empty"
    },
    {
      "x": -1,
      "y": 17,
      "z": 5,
      "name": "Empty"
    },
    {
      "x": 0,
      "y": 8,
      "z": -5,
      "name": "Rock_Shale"
    },
    {
      "x": 0,
      "y": 9,
      "z": -5,
      "name": "Rock_Shale"
    },
    {
      "x": 0,
      "y": 10,
      "z": -5,
      "name": "Rock_Shale"
    },
    {
      "x": 0,
      "y": 11,
      "z": -5,
      "name": "Rock_Shale"
    },
    {
      "x": 0,
      "y": 12,
      "z": -5,
      "name": "Soil_Dirt_Cold"
    },
    {
      "x": 0,
      "y": 13,
      "z": -5,
      "name": "Soil_Dirt_Cold"
    },
    {
      "x": 0,
      "y": 14,
      "z": -5,
      "name": "Wood_Fir_Trunk",
      "rotation": 5
    },
    {
      "x": 0,
      "y": 15,
      "z": -5,
      "name": "Wood_Deadwood_Planks_Half",
      "rotation": 6
    },
    {
      "x": 0,
      "y": 16,
      "z": -5,
      "name": "Wood_Deadwood_Planks_Half",
      "rotation": 6
    },
    {
      "x": 0,
      "y": 17,
      "z": -5,
      "name": "Wood_Redwood_Trunk",
      "rotation": 4
    },
    {
      "x": 0,
      "y": 18,
      "z": -5,
      "name": "Wood_Deadwood_Roof_Flat",
      "rotation": 1
    },
    {
      "x": 0,
      "y": 6,
      "z": -4,
      "name": "Rock_Shale"
    },
    {
      "x": 0,
      "y": 7,
      "z": -4,
      "name": "Rock_Shale"
    },
    {
      "x": 0,
      "y": 8,
      "z": -4,
      "name": "Rock_Shale"
    },
    {
      "x": 0,
      "y": 9,
      "z": -4,
      "name": "Rock_Shale"
    },
    {
      "x": 0,
      "y": 10,
      "z": -4,
      "name": "Rock_Shale"
    },
    {
      "x": 0,
      "y": 11,
      "z": -4,
      "name": "Soil_Dirt_Cold"
    },
    {
      "x": 0,
      "y": 12,
      "z": -4,
      "name": "Soil_Dirt_Cold"
    },
    {
      "x": 0,
      "y": 13,
      "z": -4,
      "name": "Soil_Dirt_Cold"
    },
    {
      "x": 0,
      "y": 14,
      "z": -4,
      "name": "Soil_Dirt_Cold"
    },
    {
      "x": 0,
      "y": 15,
      "z": -4,
      "name": "Furniture_Village_Crate"
    },
    {
      "x": 0,
      "y": 16,
      "z": -4,
      "name": "Furniture_Crude_Candle"
    },
    {
      "x": 0,
      "y": 17,
      "z": -4,
      "name": "Wood_Redwood_Trunk",
      "rotation": 4
    },
    {
      "x": 0,
      "y": 18,
      "z": -4,
      "name": "Cloth_Roof_Hide_Flat"
    },
    {
      "x": 0,
      "y": 6,
      "z": -3,
      "name": "Rock_Shale"
    },
    {
      "x": 0,
      "y": 7,
      "z": -3,
      "name": "Rock_Shale"
    },
    {
      "x": 0,
      "y": 8,
      "z": -3,
      "name": "Rock_Shale"
    },
    {
      "x": 0,
      "y": 9,
      "z": -3,
      "name": "Rock_Shale"
    },
    {
      "x": 0,
      "y": 10,
      "z": -3,
      "name": "Rock_Shale"
    },
    {
      "x": 0,
      "y": 11,
      "z": -3,
      "name": "Soil_Dirt_Cold"
    },
    {
      "x": 0,
      "y": 12,
      "z": -3,
      "name": "Soil_Dirt_Cold"
    },
    {
      "x": 0,
      "y": 13,
      "z": -3,
      "name": "Soil_Dirt_Cold"
    },
    {
      "x": 0,
      "y": 14,
      "z": -3,
      "name": "Soil_Dirt_Cold"
    },
    {
      "x": 0,
      "y": 15,
      "z": -3,
      "name": "Empty"
    },
    {
      "x": 0,
      "y": 16,
      "z": -3,
      "name": "Empty"
    },
    {
      "x": 0,
      "y": 17,
      "z": -3,
      "name": "Wood_Redwood_Trunk",
      "rotation": 4
    },
    {
      "x": 0,
      "y": 18,
      "z": -3,
      "name": "Cloth_Roof_Hide_Flat"
    },
    {
      "x": 0,
      "y": 5,
      "z": -2,
      "name": "Rock_Shale"
    },
    {
      "x": 0,
      "y": 6,
      "z": -2,
      "name": "Rock_Shale"
    },
    {
      "x": 0,
      "y": 7,
      "z": -2,
      "name": "Rock_Shale"
    },
    {
      "x": 0,
      "y": 8,
      "z": -2,
      "name": "Rock_Shale"
    },
    {
      "x": 0,
      "y": 9,
      "z": -2,
      "name": "Rock_Shale"
    },
    {
      "x": 0,
      "y": 10,
      "z": -2,
      "name": "Rock_Shale"
    },
    {
      "x": 0,
      "y": 11,
      "z": -2,
      "name": "Soil_Dirt_Cold"
    },
    {
      "x": 0,
      "y": 12,
      "z": -2,
      "name": "Soil_Dirt_Cold"
    },
    {
      "x": 0,
      "y": 13,
      "z": -2,
      "name": "Soil_Dirt_Cold"
    },
    {
      "x": 0,
      "y": 14,
      "z": -2,
      "name": "Soil_Dirt_Cold"
    },
    {
      "x": 0,
      "y": 15,
      "z": -2,
      "name": "Empty"
    },
    {
      "x": 0,
      "y": 16,
      "z": -2,
      "name": "Empty"
    },
    {
      "x": 0,
      "y": 17,
      "z": -2,
      "name": "Wood_Redwood_Trunk",
      "rotation": 4
    },
    {
      "x": 0,
      "y": 18,
      "z": -2,
      "name": "Cloth_Roof_Hide_Flat"
    },
    {
      "x": 0,
      "y": 5,
      "z": -1,
      "name": "Rock_Shale"
    },
    {
      "x": 0,
      "y": 6,
      "z": -1,
      "name": "Rock_Shale"
    },
    {
      "x": 0,
      "y": 7,
      "z": -1,
      "name": "Rock_Shale"
    },
    {
      "x": 0,
      "y": 8,
      "z": -1,
      "name": "Rock_Shale"
    },
    {
      "x": 0,
      "y": 9,
      "z": -1,
      "name": "Rock_Shale"
    },
    {
      "x": 0,
      "y": 10,
      "z": -1,
      "name": "Rock_Shale"
    },
    {
      "x": 0,
      "y": 11,
      "z": -1,
      "name": "Soil_Dirt_Cold"
    },
    {
      "x": 0,
      "y": 12,
      "z": -1,
      "name": "Soil_Dirt_Cold"
    },
    {
      "x": 0,
      "y": 13,
      "z": -1,
      "name": "Soil_Dirt_Cold"
    },
    {
      "x": 0,
      "y": 14,
      "z": -1,
      "name": "Soil_Dirt_Cold"
    },
    {
      "x": 0,
      "y": 15,
      "z": -1,
      "name": "Empty"
    },
    {
      "x": 0,
      "y": 16,
      "z": -1,
      "name": "Empty"
    },
    {
      "x": 0,
      "y": 17,
      "z": -1,
      "name": "Wood_Redwood_Trunk",
      "rotation": 4
    },
    {
      "x": 0,
      "y": 18,
      "z": -1,
      "name": "Cloth_Roof_Hide_Flat"
    },
    {
      "x": 0,
      "y": 5,
      "z": 0,
      "name": "Rock_Shale"
    },
    {
      "x": 0,
      "y": 6,
      "z": 0,
      "name": "Rock_Shale"
    },
    {
      "x": 0,
      "y": 7,
      "z": 0,
      "name": "Rock_Shale"
    },
    {
      "x": 0,
      "y": 8,
      "z": 0,
      "name": "Rock_Shale"
    },
    {
      "x": 0,
      "y": 9,
      "z": 0,
      "name": "Rock_Shale"
    },
    {
      "x": 0,
      "y": 10,
      "z": 0,
      "name": "Rock_Shale"
    },
    {
      "x": 0,
      "y": 11,
      "z": 0,
      "name": "Soil_Dirt_Cold"
    },
    {
      "x": 0,
      "y": 12,
      "z": 0,
      "name": "Soil_Dirt_Cold"
    },
    {
      "x": 0,
      "y": 13,
      "z": 0,
      "name": "Soil_Dirt_Cold"
    },
    {
      "x": 0,
      "y": 14,
      "z": 0,
      "name": "Soil_Dirt_Cold"
    },
    {
      "x": 0,
      "y": 15,
      "z": 0,
      "name": "Empty"
    },
    {
      "x": 0,
      "y": 16,
      "z": 0,
      "name": "Empty"
    },
    {
      "x": 0,
      "y": 17,
      "z": 0,
      "name": "Wood_Redwood_Trunk",
      "rotation": 4
    },
    {
      "x": 0,
      "y": 18,
      "z": 0,
      "name": "Wood_Deadwood_Roof_Flat",
      "rotation": 1
    },
    {
      "x": 0,
      "y": 5,
      "z": 1,
      "name": "Rock_Shale"
    },
    {
      "x": 0,
      "y": 6,
      "z": 1,
      "name": "Rock_Shale"
    },
    {
      "x": 0,
      "y": 7,
      "z": 1,
      "name": "Rock_Shale"
    },
    {
      "x": 0,
      "y": 8,
      "z": 1,
      "name": "Rock_Shale"
    },
    {
      "x": 0,
      "y": 9,
      "z": 1,
      "name": "Rock_Shale"
    },
    {
      "x": 0,
      "y": 10,
      "z": 1,
      "name": "Rock_Shale"
    },
    {
      "x": 0,
      "y": 11,
      "z": 1,
      "name": "Soil_Dirt_Cold"
    },
    {
      "x": 0,
      "y": 12,
      "z": 1,
      "name": "Soil_Dirt_Cold"
    },
    {
      "x": 0,
      "y": 13,
      "z": 1,
      "name": "Soil_Dirt_Cold"
    },
    {
      "x": 0,
      "y": 14,
      "z": 1,
      "name": "Soil_Dirt_Cold"
    },
    {
      "x": 0,
      "y": 15,
      "z": 1,
      "name": "Empty"
    },
    {
      "x": 0,
      "y": 16,
      "z": 1,
      "name": "Empty"
    },
    {
      "x": 0,
      "y": 17,
      "z": 1,
      "name": "Empty"
    },
    {
      "x": 0,
      "y": 18,
      "z": 1,
      "name": "Empty"
    },
    {
      "x": 0,
      "y": 5,
      "z": 2,
      "name": "Rock_Shale"
    },
    {
      "x": 0,
      "y": 6,
      "z": 2,
      "name": "Rock_Shale"
    },
    {
      "x": 0,
      "y": 7,
      "z": 2,
      "name": "Rock_Shale"
    },
    {
      "x": 0,
      "y": 8,
      "z": 2,
      "name": "Rock_Shale"
    },
    {
      "x": 0,
      "y": 9,
      "z": 2,
      "name": "Rock_Shale"
    },
    {
      "x": 0,
      "y": 10,
      "z": 2,
      "name": "Rock_Shale"
    },
    {
      "x": 0,
      "y": 11,
      "z": 2,
      "name": "Soil_Dirt_Cold"
    },
    {
      "x": 0,
      "y": 12,
      "z": 2,
      "name": "Soil_Dirt_Cold"
    },
    {
      "x": 0,
      "y": 13,
      "z": 2,
      "name": "Soil_Pebbles_Frozen"
    },
    {
      "x": 0,
      "y": 14,
      "z": 2,
      "name": "Soil_Pebbles_Frozen"
    },
    {
      "x": 0,
      "y": 15,
      "z": 2,
      "name": "Empty"
    },
    {
      "x": 0,
      "y": 16,
      "z": 2,
      "name": "Empty"
    },
    {
      "x": 0,
      "y": 17,
      "z": 2,
      "name": "Empty"
    },
    {
      "x": 0,
      "y": 18,
      "z": 2,
      "name": "Empty"
    },
    {
      "x": 0,
      "y": 5,
      "z": 3,
      "name": "Rock_Shale"
    },
    {
      "x": 0,
      "y": 6,
      "z": 3,
      "name": "Rock_Shale"
    },
    {
      "x": 0,
      "y": 7,
      "z": 3,
      "name": "Rock_Shale"
    },
    {
      "x": 0,
      "y": 8,
      "z": 3,
      "name": "Rock_Shale"
    },
    {
      "x": 0,
      "y": 9,
      "z": 3,
      "name": "Rock_Shale"
    },
    {
      "x": 0,
      "y": 10,
      "z": 3,
      "name": "Rock_Shale"
    },
    {
      "x": 0,
      "y": 11,
      "z": 3,
      "name": "Soil_Dirt_Cold"
    },
    {
      "x": 0,
      "y": 12,
      "z": 3,
      "name": "Soil_Dirt_Cold"
    },
    {
      "x": 0,
      "y": 13,
      "z": 3,
      "name": "Soil_Pebbles_Frozen"
    },
    {
      "x": 0,
      "y": 14,
      "z": 3,
      "name": "Soil_Pebbles_Frozen"
    },
    {
      "x": 0,
      "y": 15,
      "z": 3,
      "name": "Empty"
    },
    {
      "x": 0,
      "y": 16,
      "z": 3,
      "name": "Empty"
    },
    {
      "x": 0,
      "y": 17,
      "z": 3,
      "name": "Empty"
    },
    {
      "x": 0,
      "y": 18,
      "z": 3,
      "name": "Empty"
    },
    {
      "x": 0,
      "y": 6,
      "z": 4,
      "name": "Rock_Shale"
    },
    {
      "x": 0,
      "y": 7,
      "z": 4,
      "name": "Rock_Shale"
    },
    {
      "x": 0,
      "y": 8,
      "z": 4,
      "name": "Rock_Shale"
    },
    {
      "x": 0,
      "y": 9,
      "z": 4,
      "name": "Rock_Shale"
    },
    {
      "x": 0,
      "y": 10,
      "z": 4,
      "name": "Rock_Shale"
    },
    {
      "x": 0,
      "y": 11,
      "z": 4,
      "name": "Soil_Dirt_Cold"
    },
    {
      "x": 0,
      "y": 12,
      "z": 4,
      "name": "Soil_Dirt_Cold"
    },
    {
      "x": 0,
      "y": 13,
      "z": 4,
      "name": "Soil_Pebbles_Frozen"
    },
    {
      "x": 0,
      "y": 14,
      "z": 4,
      "name": "Soil_Pebbles_Frozen"
    },
    {
      "x": 0,
      "y": 15,
      "z": 4,
      "name": "Empty"
    },
    {
      "x": 0,
      "y": 16,
      "z": 4,
      "name": "Empty"
    },
    {
      "x": 0,
      "y": 17,
      "z": 4,
      "name": "Empty"
    },
    {
      "x": 0,
      "y": 18,
      "z": 4,
      "name": "Empty"
    },
    {
      "x": 0,
      "y": 8,
      "z": 5,
      "name": "Rock_Shale"
    },
    {
      "x": 0,
      "y": 9,
      "z": 5,
      "name": "Rock_Shale"
    },
    {
      "x": 0,
      "y": 10,
      "z": 5,
      "name": "Rock_Shale"
    },
    {
      "x": 0,
      "y": 11,
      "z": 5,
      "name": "Soil_Dirt_Cold"
    },
    {
      "x": 0,
      "y": 12,
      "z": 5,
      "name": "Soil_Dirt_Cold"
    },
    {
      "x": 0,
      "y": 13,
      "z": 5,
      "name": "Soil_Pebbles_Frozen"
    },
    {
      "x": 0,
      "y": 14,
      "z": 5,
      "name": "Soil_Pebbles_Frozen"
    },
    {
      "x": 0,
      "y": 15,
      "z": 5,
      "name": "Empty"
    },
    {
      "x": 0,
      "y": 16,
      "z": 5,
      "name": "Empty"
    },
    {
      "x": 0,
      "y": 17,
      "z": 5,
      "name": "Empty"
    },
    {
      "x": 1,
      "y": 8,
      "z": -5,
      "name": "Rock_Shale"
    },
    {
      "x": 1,
      "y": 9,
      "z": -5,
      "name": "Rock_Shale"
    },
    {
      "x": 1,
      "y": 10,
      "z": -5,
      "name": "Rock_Shale"
    },
    {
      "x": 1,
      "y": 11,
      "z": -5,
      "name": "Rock_Shale"
    },
    {
      "x": 1,
      "y": 12,
      "z": -5,
      "name": "Soil_Dirt_Cold"
    },
    {
      "x": 1,
      "y": 13,
      "z": -5,
      "name": "Soil_Dirt_Cold"
    },
    {
      "x": 1,
      "y": 14,
      "z": -5,
      "name": "Wood_Fir_Trunk",
      "rotation": 5
    },
    {
      "x": 1,
      "y": 15,
      "z": -5,
      "name": "Wood_Deadwood_Planks_Half",
      "rotation": 6
    },
    {
      "x": 1,
      "y": 16,
      "z": -5,
      "name": "Wood_Deadwood_Planks_Half",
      "rotation": 6
    },
    {
      "x": 1,
      "y": 17,
      "z": -5,
      "name": "Wood_Deadwood_Roof",
      "rotation": 1
    },
    {
      "x": 1,
      "y": 7,
      "z": -4,
      "name": "Rock_Shale"
    },
    {
      "x": 1,
      "y": 8,
      "z": -4,
      "name": "Rock_Shale"
    },
    {
      "x": 1,
      "y": 9,
      "z": -4,
      "name": "Rock_Shale"
    },
    {
      "x": 1,
      "y": 10,
      "z": -4,
      "name": "Rock_Shale"
    },
    {
      "x": 1,
      "y": 11,
      "z": -4,
      "name": "Soil_Dirt_Cold"
    },
    {
      "x": 1,
      "y": 12,
      "z": -4,
      "name": "Soil_Dirt_Cold"
    },
    {
      "x": 1,
      "y": 13,
      "z": -4,
      "name": "Soil_Dirt_Cold"
    },
    {
      "x": 1,
      "y": 14,
      "z": -4,
      "name": "Soil_Dirt_Cold"
    },
    {
      "x": 1,
      "y": 15,
      "z": -4,
      "name": "Furniture_Crude_Bed",
      "components": {
        "Components": {
          "RespawnBlock": {}
        }
      }
    },
    {
      "x": 1,
      "y": 16,
      "z": -4,
      "name": "Empty"
    },
    {
      "x": 1,
      "y": 17,
      "z": -4,
      "name": "Cloth_Roof_Hide",
      "rotation": 1
    },
    {
      "x": 1,
      "y": 6,
      "z": -3,
      "name": "Rock_Shale"
    },
    {
      "x": 1,
      "y": 7,
      "z": -3,
      "name": "Rock_Shale"
    },
    {
      "x": 1,
      "y": 8,
      "z": -3,
      "name": "Rock_Shale"
    },
    {
      "x": 1,
      "y": 9,
      "z": -3,
      "name": "Rock_Shale"
    },
    {
      "x": 1,
      "y": 10,
      "z": -3,
      "name": "Rock_Shale"
    },
    {
      "x": 1,
      "y": 11,
      "z": -3,
      "name": "Soil_Dirt_Cold"
    },
    {
      "x": 1,
      "y": 12,
      "z": -3,
      "name": "Soil_Dirt_Cold"
    },
    {
      "x": 1,
      "y": 13,
      "z": -3,
      "name": "Soil_Dirt_Cold"
    },
    {
      "x": 1,
      "y": 14,
      "z": -3,
      "name": "Soil_Dirt_Cold"
    },
    {
      "x": 1,
      "y": 15,
      "z": -3,
      "name": "Furniture_Crude_Bed",
      "components": {
        "Components": {
          "RespawnBlock": {}
        }
      },
      "filler": 32
    },
    {
      "x": 1,
      "y": 16,
      "z": -3,
      "name": "Empty"
    },
    {
      "x": 1,
      "y": 17,
      "z": -3,
      "name": "Cloth_Roof_Hide",
      "rotation": 1
    },
    {
      "x": 1,
      "y": 5,
      "z": -2,
      "name": "Rock_Shale"
    },
    {
      "x": 1,
      "y": 6,
      "z": -2,
      "name": "Rock_Shale"
    },
    {
      "x": 1,
      "y": 7,
      "z": -2,
      "name": "Rock_Shale"
    },
    {
      "x": 1,
      "y": 8,
      "z": -2,
      "name": "Rock_Shale"
    },
    {
      "x": 1,
      "y": 9,
      "z": -2,
      "name": "Rock_Shale"
    },
    {
      "x": 1,
      "y": 10,
      "z": -2,
      "name": "Rock_Shale"
    },
    {
      "x": 1,
      "y": 11,
      "z": -2,
      "name": "Soil_Dirt_Cold"
    },
    {
      "x": 1,
      "y": 12,
      "z": -2,
      "name": "Soil_Dirt_Cold"
    },
    {
      "x": 1,
      "y": 13,
      "z": -2,
      "name": "Soil_Dirt_Cold"
    },
    {
      "x": 1,
      "y": 14,
      "z": -2,
      "name": "Soil_Dirt_Cold"
    },
    {
      "x": 1,
      "y": 15,
      "z": -2,
      "name": "Empty"
    },
    {
      "x": 1,
      "y": 16,
      "z": -2,
      "name": "Empty"
    },
    {
      "x": 1,
      "y": 17,
      "z": -2,
      "name": "Cloth_Roof_Hide",
      "rotation": 1
    },
    {
      "x": 1,
      "y": 5,
      "z": -1,
      "name": "Rock_Shale"
    },
    {
      "x": 1,
      "y": 6,
      "z": -1,
      "name": "Rock_Shale"
    },
    {
      "x": 1,
      "y": 7,
      "z": -1,
      "name": "Rock_Shale"
    },
    {
      "x": 1,
      "y": 8,
      "z": -1,
      "name": "Rock_Shale"
    },
    {
      "x": 1,
      "y": 9,
      "z": -1,
      "name": "Rock_Shale"
    },
    {
      "x": 1,
      "y": 10,
      "z": -1,
      "name": "Rock_Shale"
    },
    {
      "x": 1,
      "y": 11,
      "z": -1,
      "name": "Soil_Dirt_Cold"
    },
    {
      "x": 1,
      "y": 12,
      "z": -1,
      "name": "Soil_Dirt_Cold"
    },
    {
      "x": 1,
      "y": 13,
      "z": -1,
      "name": "Soil_Dirt_Cold"
    },
    {
      "x": 1,
      "y": 14,
      "z": -1,
      "name": "Soil_Dirt_Cold"
    },
    {
      "x": 1,
      "y": 15,
      "z": -1,
      "name": "Empty"
    },
    {
      "x": 1,
      "y": 16,
      "z": -1,
      "name": "Empty"
    },
    {
      "x": 1,
      "y": 17,
      "z": -1,
      "name": "Cloth_Roof_Hide",
      "rotation": 1
    },
    {
      "x": 1,
      "y": 5,
      "z": 0,
      "name": "Rock_Shale"
    },
    {
      "x": 1,
      "y": 6,
      "z": 0,
      "name": "Rock_Shale"
    },
    {
      "x": 1,
      "y": 7,
      "z": 0,
      "name": "Rock_Shale"
    },
    {
      "x": 1,
      "y": 8,
      "z": 0,
      "name": "Rock_Shale"
    },
    {
      "x": 1,
      "y": 9,
      "z": 0,
      "name": "Rock_Shale"
    },
    {
      "x": 1,
      "y": 10,
      "z": 0,
      "name": "Rock_Shale"
    },
    {
      "x": 1,
      "y": 11,
      "z": 0,
      "name": "Soil_Dirt_Cold"
    },
    {
      "x": 1,
      "y": 12,
      "z": 0,
      "name": "Soil_Dirt_Cold"
    },
    {
      "x": 1,
      "y": 13,
      "z": 0,
      "name": "Soil_Dirt_Cold"
    },
    {
      "x": 1,
      "y": 14,
      "z": 0,
      "name": "Soil_Dirt_Cold"
    },
    {
      "x": 1,
      "y": 15,
      "z": 0,
      "name": "Empty"
    },
    {
      "x": 1,
      "y": 16,
      "z": 0,
      "name": "Wood_Deadwood_Stairs",
      "rotation": 9
    },
    {
      "x": 1,
      "y": 17,
      "z": 0,
      "name": "Wood_Deadwood_Roof",
      "rotation": 1
    },
    {
      "x": 1,
      "y": 5,
      "z": 1,
      "name": "Rock_Shale"
    },
    {
      "x": 1,
      "y": 6,
      "z": 1,
      "name": "Rock_Shale"
    },
    {
      "x": 1,
      "y": 7,
      "z": 1,
      "name": "Rock_Shale"
    },
    {
      "x": 1,
      "y": 8,
      "z": 1,
      "name": "Rock_Shale"
    },
    {
      "x": 1,
      "y": 9,
      "z": 1,
      "name": "Rock_Shale"
    },
    {
      "x": 1,
      "y": 10,
      "z": 1,
      "name": "Rock_Shale"
    },
    {
      "x": 1,
      "y": 11,
      "z": 1,
      "name": "Soil_Dirt_Cold"
    },
    {
      "x": 1,
      "y": 12,
      "z": 1,
      "name": "Soil_Dirt_Cold"
    },
    {
      "x": 1,
      "y": 13,
      "z": 1,
      "name": "Soil_Dirt_Cold"
    },
    {
      "x": 1,
      "y": 14,
      "z": 1,
      "name": "Soil_Dirt_Cold"
    },
    {
      "x": 1,
      "y": 15,
      "z": 1,
      "name": "Empty"
    },
    {
      "x": 1,
      "y": 16,
      "z": 1,
      "name": "Empty"
    },
    {
      "x": 1,
      "y": 17,
      "z": 1,
      "name": "Empty"
    },
    {
      "x": 1,
      "y": 18,
      "z": 1,
      "name": "Empty"
    },
    {
      "x": 1,
      "y": 5,
      "z": 2,
      "name": "Rock_Shale"
    },
    {
      "x": 1,
      "y": 6,
      "z": 2,
      "name": "Rock_Shale"
    },
    {
      "x": 1,
      "y": 7,
      "z": 2,
      "name": "Rock_Shale"
    },
    {
      "x": 1,
      "y": 8,
      "z": 2,
      "name": "Rock_Shale"
    },
    {
      "x": 1,
      "y": 9,
      "z": 2,
      "name": "Rock_Shale"
    },
    {
      "x": 1,
      "y": 10,
      "z": 2,
      "name": "Rock_Shale"
    },
    {
      "x": 1,
      "y": 11,
      "z": 2,
      "name": "Soil_Dirt_Cold"
    },
    {
      "x": 1,
      "y": 12,
      "z": 2,
      "name": "Soil_Dirt_Cold"
    },
    {
      "x": 1,
      "y": 13,
      "z": 2,
      "name": "Soil_Pebbles_Frozen"
    },
    {
      "x": 1,
      "y": 14,
      "z": 2,
      "name": "Soil_Pebbles_Frozen"
    },
    {
      "x": 1,
      "y": 15,
      "z": 2,
      "name": "Empty"
    },
    {
      "x": 1,
      "y": 16,
      "z": 2,
      "name": "Empty"
    },
    {
      "x": 1,
      "y": 17,
      "z": 2,
      "name": "Empty"
    },
    {
      "x": 1,
      "y": 18,
      "z": 2,
      "name": "Empty"
    },
    {
      "x": 1,
      "y": 5,
      "z": 3,
      "name": "Rock_Shale"
    },
    {
      "x": 1,
      "y": 6,
      "z": 3,
      "name": "Rock_Shale"
    },
    {
      "x": 1,
      "y": 7,
      "z": 3,
      "name": "Rock_Shale"
    },
    {
      "x": 1,
      "y": 8,
      "z": 3,
      "name": "Rock_Shale"
    },
    {
      "x": 1,
      "y": 9,
      "z": 3,
      "name": "Rock_Shale"
    },
    {
      "x": 1,
      "y": 10,
      "z": 3,
      "name": "Rock_Shale"
    },
    {
      "x": 1,
      "y": 11,
      "z": 3,
      "name": "Soil_Dirt_Cold"
    },
    {
      "x": 1,
      "y": 12,
      "z": 3,
      "name": "Soil_Dirt_Cold"
    },
    {
      "x": 1,
      "y": 13,
      "z": 3,
      "name": "Soil_Pebbles_Frozen"
    },
    {
      "x": 1,
      "y": 14,
      "z": 3,
      "name": "Soil_Pebbles_Frozen"
    },
    {
      "x": 1,
      "y": 15,
      "z": 3,
      "name": "Empty"
    },
    {
      "x": 1,
      "y": 16,
      "z": 3,
      "name": "Empty"
    },
    {
      "x": 1,
      "y": 17,
      "z": 3,
      "name": "Empty"
    },
    {
      "x": 1,
      "y": 18,
      "z": 3,
      "name": "Empty"
    },
    {
      "x": 1,
      "y": 6,
      "z": 4,
      "name": "Rock_Shale"
    },
    {
      "x": 1,
      "y": 7,
      "z": 4,
      "name": "Rock_Shale"
    },
    {
      "x": 1,
      "y": 8,
      "z": 4,
      "name": "Rock_Shale"
    },
    {
      "x": 1,
      "y": 9,
      "z": 4,
      "name": "Rock_Shale"
    },
    {
      "x": 1,
      "y": 10,
      "z": 4,
      "name": "Rock_Shale"
    },
    {
      "x": 1,
      "y": 11,
      "z": 4,
      "name": "Soil_Dirt_Cold"
    },
    {
      "x": 1,
      "y": 12,
      "z": 4,
      "name": "Soil_Dirt_Cold"
    },
    {
      "x": 1,
      "y": 13,
      "z": 4,
      "name": "Soil_Pebbles_Frozen"
    },
    {
      "x": 1,
      "y": 14,
      "z": 4,
      "name": "Soil_Pebbles_Frozen"
    },
    {
      "x": 1,
      "y": 15,
      "z": 4,
      "name": "Empty"
    },
    {
      "x": 1,
      "y": 16,
      "z": 4,
      "name": "Empty"
    },
    {
      "x": 1,
      "y": 17,
      "z": 4,
      "name": "Empty"
    },
    {
      "x": 1,
      "y": 18,
      "z": 4,
      "name": "Empty"
    },
    {
      "x": 1,
      "y": 8,
      "z": 5,
      "name": "Rock_Shale"
    },
    {
      "x": 1,
      "y": 9,
      "z": 5,
      "name": "Rock_Shale"
    },
    {
      "x": 1,
      "y": 10,
      "z": 5,
      "name": "Rock_Shale"
    },
    {
      "x": 1,
      "y": 11,
      "z": 5,
      "name": "Rock_Shale"
    },
    {
      "x": 1,
      "y": 12,
      "z": 5,
      "name": "Soil_Dirt_Cold"
    },
    {
      "x": 1,
      "y": 13,
      "z": 5,
      "name": "Soil_Pebbles_Frozen"
    },
    {
      "x": 1,
      "y": 14,
      "z": 5,
      "name": "Soil_Pebbles_Frozen"
    },
    {
      "x": 1,
      "y": 15,
      "z": 5,
      "name": "Empty"
    },
    {
      "x": 1,
      "y": 16,
      "z": 5,
      "name": "Empty"
    },
    {
      "x": 1,
      "y": 17,
      "z": 5,
      "name": "Empty"
    },
    {
      "x": 2,
      "y": 8,
      "z": -5,
      "name": "Rock_Shale"
    },
    {
      "x": 2,
      "y": 9,
      "z": -5,
      "name": "Rock_Shale"
    },
    {
      "x": 2,
      "y": 10,
      "z": -5,
      "name": "Rock_Shale"
    },
    {
      "x": 2,
      "y": 11,
      "z": -5,
      "name": "Rock_Shale"
    },
    {
      "x": 2,
      "y": 12,
      "z": -5,
      "name": "Soil_Dirt_Cold"
    },
    {
      "x": 2,
      "y": 13,
      "z": -5,
      "name": "Soil_Dirt_Cold"
    },
    {
      "x": 2,
      "y": 14,
      "z": -5,
      "name": "Wood_Fir_Trunk",
      "rotation": 5
    },
    {
      "x": 2,
      "y": 15,
      "z": -5,
      "name": "Wood_Deadwood_Planks_Half",
      "rotation": 6
    },
    {
      "x": 2,
      "y": 16,
      "z": -5,
      "name": "Wood_Deadwood_Roof",
      "rotation": 1
    },
    {
      "x": 2,
      "y": 7,
      "z": -4,
      "name": "Rock_Shale"
    },
    {
      "x": 2,
      "y": 8,
      "z": -4,
      "name": "Rock_Shale"
    },
    {
      "x": 2,
      "y": 9,
      "z": -4,
      "name": "Rock_Shale"
    },
    {
      "x": 2,
      "y": 10,
      "z": -4,
      "name": "Rock_Shale"
    },
    {
      "x": 2,
      "y": 11,
      "z": -4,
      "name": "Soil_Dirt_Cold"
    },
    {
      "x": 2,
      "y": 12,
      "z": -4,
      "name": "Soil_Dirt_Cold"
    },
    {
      "x": 2,
      "y": 13,
      "z": -4,
      "name": "Soil_Dirt_Cold"
    },
    {
      "x": 2,
      "y": 14,
      "z": -4,
      "name": "Soil_Dirt_Cold"
    },
    {
      "x": 2,
      "y": 15,
      "z": -4,
      "name": "Empty"
    },
    {
      "x": 2,
      "y": 16,
      "z": -4,
      "name": "Cloth_Roof_Hide",
      "rotation": 1
    },
    {
      "x": 2,
      "y": 7,
      "z": -3,
      "name": "Rock_Shale"
    },
    {
      "x": 2,
      "y": 8,
      "z": -3,
      "name": "Rock_Shale"
    },
    {
      "x": 2,
      "y": 9,
      "z": -3,
      "name": "Rock_Shale"
    },
    {
      "x": 2,
      "y": 10,
      "z": -3,
      "name": "Rock_Shale"
    },
    {
      "x": 2,
      "y": 11,
      "z": -3,
      "name": "Soil_Dirt_Cold"
    },
    {
      "x": 2,
      "y": 12,
      "z": -3,
      "name": "Soil_Dirt_Cold"
    },
    {
      "x": 2,
      "y": 13,
      "z": -3,
      "name": "Soil_Dirt_Cold"
    },
    {
      "x": 2,
      "y": 14,
      "z": -3,
      "name": "Soil_Dirt_Cold"
    },
    {
      "x": 2,
      "y": 15,
      "z": -3,
      "name": "Empty"
    },
    {
      "x": 2,
      "y": 16,
      "z": -3,
      "name": "Cloth_Roof_Hide",
      "rotation": 1
    },
    {
      "x": 2,
      "y": 7,
      "z": -2,
      "name": "Rock_Shale"
    },
    {
      "x": 2,
      "y": 8,
      "z": -2,
      "name": "Rock_Shale"
    },
    {
      "x": 2,
      "y": 9,
      "z": -2,
      "name": "Rock_Shale"
    },
    {
      "x": 2,
      "y": 10,
      "z": -2,
      "name": "Rock_Shale"
    },
    {
      "x": 2,
      "y": 11,
      "z": -2,
      "name": "Soil_Dirt_Cold"
    },
    {
      "x": 2,
      "y": 12,
      "z": -2,
      "name": "Soil_Dirt_Cold"
    },
    {
      "x": 2,
      "y": 13,
      "z": -2,
      "name": "Soil_Dirt_Cold"
    },
    {
      "x": 2,
      "y": 14,
      "z": -2,
      "name": "Soil_Dirt_Cold"
    },
    {
      "x": 2,
      "y": 15,
      "z": -2,
      "name": "Empty"
    },
    {
      "x": 2,
      "y": 16,
      "z": -2,
      "name": "Cloth_Roof_Hide",
      "rotation": 1
    },
    {
      "x": 2,
      "y": 5,
      "z": -1,
      "name": "Rock_Shale"
    },
    {
      "x": 2,
      "y": 6,
      "z": -1,
      "name": "Rock_Shale"
    },
    {
      "x": 2,
      "y": 7,
      "z": -1,
      "name": "Rock_Shale"
    },
    {
      "x": 2,
      "y": 8,
      "z": -1,
      "name": "Rock_Shale"
    },
    {
      "x": 2,
      "y": 9,
      "z": -1,
      "name": "Rock_Shale"
    },
    {
      "x": 2,
      "y": 10,
      "z": -1,
      "name": "Rock_Shale"
    },
    {
      "x": 2,
      "y": 11,
      "z": -1,
      "name": "Soil_Dirt_Cold"
    },
    {
      "x": 2,
      "y": 12,
      "z": -1,
      "name": "Soil_Dirt_Cold"
    },
    {
      "x": 2,
      "y": 13,
      "z": -1,
      "name": "Soil_Dirt_Cold"
    },
    {
      "x": 2,
      "y": 14,
      "z": -1,
      "name": "Soil_Dirt_Cold"
    },
    {
      "x": 2,
      "y": 15,
      "z": -1,
      "name": "Block_Spawner_Block",
      "components": {
        "Components": {
          "BlockSpawner": {
            "BlockSpawnerId": "Zone3_Outlander_Tier1"
          }
        }
      },
      "rotation": 3
    },
    {
      "x": 2,
      "y": 16,
      "z": -1,
      "name": "Cloth_Roof_Hide",
      "rotation": 1
    },
    {
      "x": 2,
      "y": 5,
      "z": 0,
      "name": "Rock_Shale"
    },
    {
      "x": 2,
      "y": 6,
      "z": 0,
      "name": "Rock_Shale"
    },
    {
      "x": 2,
      "y": 7,
      "z": 0,
      "name": "Rock_Shale"
    },
    {
      "x": 2,
      "y": 8,
      "z": 0,
      "name": "Rock_Shale"
    },
    {
      "x": 2,
      "y": 9,
      "z": 0,
      "name": "Rock_Shale"
    },
    {
      "x": 2,
      "y": 10,
      "z": 0,
      "name": "Rock_Shale"
    },
    {
      "x": 2,
      "y": 11,
      "z": 0,
      "name": "Soil_Dirt_Cold"
    },
    {
      "x": 2,
      "y": 12,
      "z": 0,
      "name": "Soil_Dirt_Cold"
    },
    {
      "x": 2,
      "y": 13,
      "z": 0,
      "name": "Soil_Dirt_Cold"
    },
    {
      "x": 2,
      "y": 14,
      "z": 0,
      "name": "Soil_Dirt_Cold"
    },
    {
      "x": 2,
      "y": 15,
      "z": 0,
      "name": "Wood_Deadwood_Stairs",
      "rotation": 9
    },
    {
      "x": 2,
      "y": 16,
      "z": 0,
      "name": "Wood_Deadwood_Roof",
      "rotation": 1
    },
    {
      "x": 2,
      "y": 5,
      "z": 1,
      "name": "Rock_Shale"
    },
    {
      "x": 2,
      "y": 6,
      "z": 1,
      "name": "Rock_Shale"
    },
    {
      "x": 2,
      "y": 7,
      "z": 1,
      "name": "Rock_Shale"
    },
    {
      "x": 2,
      "y": 8,
      "z": 1,
      "name": "Rock_Shale"
    },
    {
      "x": 2,
      "y": 9,
      "z": 1,
      "name": "Rock_Shale"
    },
    {
      "x": 2,
      "y": 10,
      "z": 1,
      "name": "Rock_Shale"
    },
    {
      "x": 2,
      "y": 11,
      "z": 1,
      "name": "Soil_Dirt_Cold"
    },
    {
      "x": 2,
      "y": 12,
      "z": 1,
      "name": "Soil_Dirt_Cold"
    },
    {
      "x": 2,
      "y": 13,
      "z": 1,
      "name": "Soil_Dirt_Cold"
    },
    {
      "x": 2,
      "y": 14,
      "z": 1,
      "name": "Soil_Pebbles_Frozen"
    },
    {
      "x": 2,
      "y": 15,
      "z": 1,
      "name": "Empty"
    },
    {
      "x": 2,
      "y": 16,
      "z": 1,
      "name": "Empty"
    },
    {
      "x": 2,
      "y": 17,
      "z": 1,
      "name": "Empty"
    },
    {
      "x": 2,
      "y": 5,
      "z": 2,
      "name": "Rock_Shale"
    },
    {
      "x": 2,
      "y": 6,
      "z": 2,
      "name": "Rock_Shale"
    },
    {
      "x": 2,
      "y": 7,
      "z": 2,
      "name": "Rock_Shale"
    },
    {
      "x": 2,
      "y": 8,
      "z": 2,
      "name": "Rock_Shale"
    },
    {
      "x": 2,
      "y": 9,
      "z": 2,
      "name": "Rock_Shale"
    },
    {
      "x": 2,
      "y": 10,
      "z": 2,
      "name": "Rock_Shale"
    },
    {
      "x": 2,
      "y": 11,
      "z": 2,
      "name": "Soil_Dirt_Cold"
    },
    {
      "x": 2,
      "y": 12,
      "z": 2,
      "name": "Soil_Dirt_Cold"
    },
    {
      "x": 2,
      "y": 13,
      "z": 2,
      "name": "Soil_Pebbles_Frozen"
    },
    {
      "x": 2,
      "y": 14,
      "z": 2,
      "name": "Soil_Pebbles_Frozen"
    },
    {
      "x": 2,
      "y": 15,
      "z": 2,
      "name": "Empty"
    },
    {
      "x": 2,
      "y": 16,
      "z": 2,
      "name": "Empty"
    },
    {
      "x": 2,
      "y": 17,
      "z": 2,
      "name": "Empty"
    },
    {
      "x": 2,
      "y": 18,
      "z": 2,
      "name": "Empty"
    },
    {
      "x": 2,
      "y": 5,
      "z": 3,
      "name": "Rock_Shale"
    },
    {
      "x": 2,
      "y": 6,
      "z": 3,
      "name": "Rock_Shale"
    },
    {
      "x": 2,
      "y": 7,
      "z": 3,
      "name": "Rock_Shale"
    },
    {
      "x": 2,
      "y": 8,
      "z": 3,
      "name": "Rock_Shale"
    },
    {
      "x": 2,
      "y": 9,
      "z": 3,
      "name": "Rock_Shale"
    },
    {
      "x": 2,
      "y": 10,
      "z": 3,
      "name": "Rock_Shale"
    },
    {
      "x": 2,
      "y": 11,
      "z": 3,
      "name": "Soil_Dirt_Cold"
    },
    {
      "x": 2,
      "y": 12,
      "z": 3,
      "name": "Soil_Dirt_Cold"
    },
    {
      "x": 2,
      "y": 13,
      "z": 3,
      "name": "Soil_Pebbles_Frozen"
    },
    {
      "x": 2,
      "y": 14,
      "z": 3,
      "name": "Soil_Pebbles_Frozen"
    },
    {
      "x": 2,
      "y": 15,
      "z": 3,
      "name": "Furniture_Crude_Brazier"
    },
    {
      "x": 2,
      "y": 16,
      "z": 3,
      "name": "Empty"
    },
    {
      "x": 2,
      "y": 17,
      "z": 3,
      "name": "Empty"
    },
    {
      "x": 2,
      "y": 18,
      "z": 3,
      "name": "Empty"
    },
    {
      "x": 2,
      "y": 7,
      "z": 4,
      "name": "Rock_Shale"
    },
    {
      "x": 2,
      "y": 8,
      "z": 4,
      "name": "Rock_Shale"
    },
    {
      "x": 2,
      "y": 9,
      "z": 4,
      "name": "Rock_Shale"
    },
    {
      "x": 2,
      "y": 10,
      "z": 4,
      "name": "Rock_Shale"
    },
    {
      "x": 2,
      "y": 11,
      "z": 4,
      "name": "Soil_Dirt_Cold"
    },
    {
      "x": 2,
      "y": 12,
      "z": 4,
      "name": "Soil_Dirt_Cold"
    },
    {
      "x": 2,
      "y": 13,
      "z": 4,
      "name": "Soil_Pebbles_Frozen"
    },
    {
      "x": 2,
      "y": 14,
      "z": 4,
      "name": "Soil_Pebbles_Frozen"
    },
    {
      "x": 2,
      "y": 15,
      "z": 4,
      "name": "Rubble_Shale"
    },
    {
      "x": 2,
      "y": 16,
      "z": 4,
      "name": "Empty"
    },
    {
      "x": 2,
      "y": 17,
      "z": 4,
      "name": "Empty"
    },
    {
      "x": 2,
      "y": 18,
      "z": 4,
      "name": "Empty"
    },
    {
      "x": 2,
      "y": 10,
      "z": 5,
      "name": "Rock_Shale"
    },
    {
      "x": 2,
      "y": 11,
      "z": 5,
      "name": "Rock_Shale"
    },
    {
      "x": 2,
      "y": 12,
      "z": 5,
      "name": "Soil_Dirt_Cold"
    },
    {
      "x": 2,
      "y": 13,
      "z": 5,
      "name": "Soil_Pebbles_Frozen"
    },
    {
      "x": 2,
      "y": 14,
      "z": 5,
      "name": "Wood_Fir_Trunk",
      "rotation": 5
    },
    {
      "x": 2,
      "y": 15,
      "z": 5,
      "name": "Wood_Deadwood_Fence"
    },
    {
      "x": 3,
      "y": 10,
      "z": -5,
      "name": "Rock_Shale"
    },
    {
      "x": 3,
      "y": 11,
      "z": -5,
      "name": "Rock_Shale"
    },
    {
      "x": 3,
      "y": 12,
      "z": -5,
      "name": "Soil_Dirt_Cold"
    },
    {
      "x": 3,
      "y": 13,
      "z": -5,
      "name": "Soil_Dirt_Cold"
    },
    {
      "x": 3,
      "y": 14,
      "z": -5,
      "name": "Wood_Fir_Trunk",
      "rotation": 4
    },
    {
      "x": 3,
      "y": 15,
      "z": -5,
      "name": "Wood_Deadwood_Roof",
      "rotation": 1
    },
    {
      "x": 3,
      "y": 9,
      "z": -4,
      "name": "Rock_Shale"
    },
    {
      "x": 3,
      "y": 10,
      "z": -4,
      "name": "Rock_Shale"
    },
    {
      "x": 3,
      "y": 11,
      "z": -4,
      "name": "Rock_Shale"
    },
    {
      "x": 3,
      "y": 12,
      "z": -4,
      "name": "Soil_Dirt_Cold"
    },
    {
      "x": 3,
      "y": 13,
      "z": -4,
      "name": "Soil_Dirt_Cold"
    },
    {
      "x": 3,
      "y": 14,
      "z": -4,
      "name": "Wood_Fir_Trunk",
      "rotation": 4
    },
    {
      "x": 3,
      "y": 15,
      "z": -4,
      "name": "Cloth_Roof_Hide",
      "rotation": 1
    },
    {
      "x": 3,
      "y": 8,
      "z": -3,
      "name": "Rock_Shale"
    },
    {
      "x": 3,
      "y": 9,
      "z": -3,
      "name": "Rock_Shale"
    },
    {
      "x": 3,
      "y": 10,
      "z": -3,
      "name": "Rock_Shale"
    },
    {
      "x": 3,
      "y": 11,
      "z": -3,
      "name": "Soil_Dirt_Cold"
    },
    {
      "x": 3,
      "y": 12,
      "z": -3,
      "name": "Soil_Dirt_Cold"
    },
    {
      "x": 3,
      "y": 13,
      "z": -3,
      "name": "Soil_Dirt_Cold"
    },
    {
      "x": 3,
      "y": 14,
      "z": -3,
      "name": "Wood_Fir_Trunk",
      "rotation": 4
    },
    {
      "x": 3,
      "y": 15,
      "z": -3,
      "name": "Cloth_Roof_Hide",
      "rotation": 1
    },
    {
      "x": 3,
      "y": 7,
      "z": -2,
      "name": "Rock_Shale"
    },
    {
      "x": 3,
      "y": 8,
      "z": -2,
      "name": "Rock_Shale"
    },
    {
      "x": 3,
      "y": 9,
      "z": -2,
      "name": "Rock_Shale"
    },
    {
      "x": 3,
      "y": 10,
      "z": -2,
      "name": "Rock_Shale"
    },
    {
      "x": 3,
      "y": 11,
      "z": -2,
      "name": "Soil_Dirt_Cold"
    },
    {
      "x": 3,
      "y": 12,
      "z": -2,
      "name": "Soil_Dirt_Cold"
    },
    {
      "x": 3,
      "y": 13,
      "z": -2,
      "name": "Soil_Dirt_Cold"
    },
    {
      "x": 3,
      "y": 14,
      "z": -2,
      "name": "Wood_Fir_Trunk",
      "rotation": 4
    },
    {
      "x": 3,
      "y": 15,
      "z": -2,
      "name": "Cloth_Roof_Hide",
      "rotation": 1
    },
    {
      "x": 3,
      "y": 6,
      "z": -1,
      "name": "Rock_Shale"
    },
    {
      "x": 3,
      "y": 7,
      "z": -1,
      "name": "Rock_Shale"
    },
    {
      "x": 3,
      "y": 8,
      "z": -1,
      "name": "Rock_Shale"
    },
    {
      "x": 3,
      "y": 9,
      "z": -1,
      "name": "Rock_Shale"
    },
    {
      "x": 3,
      "y": 10,
      "z": -1,
      "name": "Rock_Shale"
    },
    {
      "x": 3,
      "y": 11,
      "z": -1,
      "name": "Soil_Dirt_Cold"
    },
    {
      "x": 3,
      "y": 12,
      "z": -1,
      "name": "Soil_Dirt_Cold"
    },
    {
      "x": 3,
      "y": 13,
      "z": -1,
      "name": "Soil_Dirt_Cold"
    },
    {
      "x": 3,
      "y": 14,
      "z": -1,
      "name": "Wood_Fir_Trunk",
      "rotation": 4
    },
    {
      "x": 3,
      "y": 15,
      "z": -1,
      "name": "Cloth_Roof_Hide",
      "rotation": 1
    },
    {
      "x": 3,
      "y": 6,
      "z": 0,
      "name": "Rock_Shale"
    },
    {
      "x": 3,
      "y": 7,
      "z": 0,
      "name": "Rock_Shale"
    },
    {
      "x": 3,
      "y": 8,
      "z": 0,
      "name": "Rock_Shale"
    },
    {
      "x": 3,
      "y": 9,
      "z": 0,
      "name": "Rock_Shale"
    },
    {
      "x": 3,
      "y": 10,
      "z": 0,
      "name": "Rock_Shale"
    },
    {
      "x": 3,
      "y": 11,
      "z": 0,
      "name": "Soil_Dirt_Cold"
    },
    {
      "x": 3,
      "y": 12,
      "z": 0,
      "name": "Soil_Dirt_Cold"
    },
    {
      "x": 3,
      "y": 13,
      "z": 0,
      "name": "Soil_Dirt_Cold"
    },
    {
      "x": 3,
      "y": 14,
      "z": 0,
      "name": "Wood_Fir_Trunk",
      "rotation": 4
    },
    {
      "x": 3,
      "y": 15,
      "z": 0,
      "name": "Wood_Deadwood_Roof",
      "rotation": 1
    },
    {
      "x": 3,
      "y": 6,
      "z": 1,
      "name": "Rock_Shale"
    },
    {
      "x": 3,
      "y": 7,
      "z": 1,
      "name": "Rock_Shale"
    },
    {
      "x": 3,
      "y": 8,
      "z": 1,
      "name": "Rock_Shale"
    },
    {
      "x": 3,
      "y": 9,
      "z": 1,
      "name": "Rock_Shale"
    },
    {
      "x": 3,
      "y": 10,
      "z": 1,
      "name": "Rock_Shale"
    },
    {
      "x": 3,
      "y": 11,
      "z": 1,
      "name": "Soil_Dirt_Cold"
    },
    {
      "x": 3,
      "y": 12,
      "z": 1,
      "name": "Soil_Dirt_Cold"
    },
    {
      "x": 3,
      "y": 13,
      "z": 1,
      "name": "Soil_Pebbles_Frozen"
    },
    {
      "x": 3,
      "y": 14,
      "z": 1,
      "name": "Soil_Pebbles_Frozen"
    },
    {
      "x": 3,
      "y": 15,
      "z": 1,
      "name": "Empty"
    },
    {
      "x": 3,
      "y": 16,
      "z": 1,
      "name": "Empty"
    },
    {
      "x": 3,
      "y": 17,
      "z": 1,
      "name": "Empty"
    },
    {
      "x": 3,
      "y": 6,
      "z": 2,
      "name": "Rock_Shale"
    },
    {
      "x": 3,
      "y": 7,
      "z": 2,
      "name": "Rock_Shale"
    },
    {
      "x": 3,
      "y": 8,
      "z": 2,
      "name": "Rock_Shale"
    },
    {
      "x": 3,
      "y": 9,
      "z": 2,
      "name": "Rock_Shale"
    },
    {
      "x": 3,
      "y": 10,
      "z": 2,
      "name": "Rock_Shale"
    },
    {
      "x": 3,
      "y": 11,
      "z": 2,
      "name": "Soil_Dirt_Cold"
    },
    {
      "x": 3,
      "y": 12,
      "z": 2,
      "name": "Soil_Dirt_Cold"
    },
    {
      "x": 3,
      "y": 13,
      "z": 2,
      "name": "Soil_Pebbles_Frozen"
    },
    {
      "x": 3,
      "y": 14,
      "z": 2,
      "name": "Soil_Pebbles_Frozen"
    },
    {
      "x": 3,
      "y": 15,
      "z": 2,
      "name": "Empty"
    },
    {
      "x": 3,
      "y": 16,
      "z": 2,
      "name": "Empty"
    },
    {
      "x": 3,
      "y": 17,
      "z": 2,
      "name": "Empty"
    },
    {
      "x": 3,
      "y": 7,
      "z": 3,
      "name": "Rock_Shale"
    },
    {
      "x": 3,
      "y": 8,
      "z": 3,
      "name": "Rock_Shale"
    },
    {
      "x": 3,
      "y": 9,
      "z": 3,
      "name": "Rock_Shale"
    },
    {
      "x": 3,
      "y": 10,
      "z": 3,
      "name": "Rock_Shale"
    },
    {
      "x": 3,
      "y": 11,
      "z": 3,
      "name": "Soil_Dirt_Cold"
    },
    {
      "x": 3,
      "y": 12,
      "z": 3,
      "name": "Soil_Dirt_Cold"
    },
    {
      "x": 3,
      "y": 13,
      "z": 3,
      "name": "Soil_Pebbles_Frozen"
    },
    {
      "x": 3,
      "y": 14,
      "z": 3,
      "name": "Soil_Pebbles_Frozen"
    },
    {
      "x": 3,
      "y": 15,
      "z": 3,
      "name": "Rubble_Shale_Medium"
    },
    {
      "x": 3,
      "y": 16,
      "z": 3,
      "name": "Empty"
    },
    {
      "x": 3,
      "y": 17,
      "z": 3,
      "name": "Empty"
    },
    {
      "x": 3,
      "y": 9,
      "z": 4,
      "name": "Rock_Shale"
    },
    {
      "x": 3,
      "y": 10,
      "z": 4,
      "name": "Rock_Shale"
    },
    {
      "x": 3,
      "y": 11,
      "z": 4,
      "name": "Soil_Dirt_Cold"
    },
    {
      "x": 3,
      "y": 12,
      "z": 4,
      "name": "Soil_Dirt_Cold"
    },
    {
      "x": 3,
      "y": 13,
      "z": 4,
      "name": "Soil_Pebbles_Frozen"
    },
    {
      "x": 3,
      "y": 14,
      "z": 4,
      "name": "Soil_Pebbles_Frozen"
    },
    {
      "x": 3,
      "y": 15,
      "z": 4,
      "name": "Empty"
    },
    {
      "x": 3,
      "y": 16,
      "z": 4,
      "name": "Empty"
    },
    {
      "x": 3,
      "y": 17,
      "z": 4,
      "name": "Empty"
    },
    {
      "x": 3,
      "y": 12,
      "z": 5,
      "name": "Soil_Dirt_Cold"
    },
    {
      "x": 3,
      "y": 13,
      "z": 5,
      "name": "Soil_Pebbles_Frozen"
    },
    {
      "x": 3,
      "y": 14,
      "z": 5,
      "name": "Wood_Fir_Trunk",
      "rotation": 5
    },
    {
      "x": 3,
      "y": 15,
      "z": 5,
      "name": "Wood_Deadwood_Fence"
    },
    {
      "x": 4,
      "y": 10,
      "z": -1,
      "name": "Rock_Shale"
    },
    {
      "x": 4,
      "y": 11,
      "z": -1,
      "name": "Rock_Shale"
    },
    {
      "x": 4,
      "y": 12,
      "z": -1,
      "name": "Soil_Pebbles_Frozen"
    },
    {
      "x": 4,
      "y": 13,
      "z": -1,
      "name": "Soil_Pebbles_Frozen"
    },
    {
      "x": 4,
      "y": 8,
      "z": 0,
      "name": "Rock_Shale"
    },
    {
      "x": 4,
      "y": 9,
      "z": 0,
      "name": "Rock_Shale"
    },
    {
      "x": 4,
      "y": 10,
      "z": 0,
      "name": "Rock_Shale"
    },
    {
      "x": 4,
      "y": 11,
      "z": 0,
      "name": "Rock_Shale"
    },
    {
      "x": 4,
      "y": 12,
      "z": 0,
      "name": "Soil_Pebbles_Frozen"
    },
    {
      "x": 4,
      "y": 13,
      "z": 0,
      "name": "Soil_Pebbles_Frozen"
    },
    {
      "x": 4,
      "y": 8,
      "z": 1,
      "name": "Rock_Shale"
    },
    {
      "x": 4,
      "y": 9,
      "z": 1,
      "name": "Rock_Shale"
    },
    {
      "x": 4,
      "y": 10,
      "z": 1,
      "name": "Rock_Shale"
    },
    {
      "x": 4,
      "y": 11,
      "z": 1,
      "name": "Rock_Shale"
    },
    {
      "x": 4,
      "y": 12,
      "z": 1,
      "name": "Soil_Dirt_Cold"
    },
    {
      "x": 4,
      "y": 13,
      "z": 1,
      "name": "Soil_Pebbles_Frozen"
    },
    {
      "x": 4,
      "y": 9,
      "z": 2,
      "name": "Rock_Shale"
    },
    {
      "x": 4,
      "y": 10,
      "z": 2,
      "name": "Rock_Shale"
    },
    {
      "x": 4,
      "y": 11,
      "z": 2,
      "name": "Soil_Dirt_Cold"
    },
    {
      "x": 4,
      "y": 12,
      "z": 2,
      "name": "Soil_Dirt_Cold"
    },
    {
      "x": 4,
      "y": 13,
      "z": 2,
      "name": "Soil_Pebbles_Frozen"
    },
    {
      "x": 4,
      "y": 14,
      "z": 2,
      "name": "Wood_Fir_Trunk",
      "rotation": 4
    },
    {
      "x": 4,
      "y": 15,
      "z": 2,
      "name": "Wood_Deadwood_Fence",
      "rotation": 3
    },
    {
      "x": 4,
      "y": 11,
      "z": 3,
      "name": "Soil_Dirt_Cold"
    },
    {
      "x": 4,
      "y": 12,
      "z": 3,
      "name": "Soil_Dirt_Cold"
    },
    {
      "x": 4,
      "y": 13,
      "z": 3,
      "name": "Soil_Dirt_Cold"
    },
    {
      "x": 4,
      "y": 14,
      "z": 3,
      "name": "Wood_Fir_Trunk",
      "rotation": 4
    },
    {
      "x": 4,
      "y": 15,
      "z": 3,
      "name": "Wood_Deadwood_Fence",
      "rotation": 3
    },
    {
      "x": 4,
      "y": 11,
      "z": 4,
      "name": "Soil_Dirt_Cold"
    },
    {
      "x": 4,
      "y": 12,
      "z": 4,
      "name": "Soil_Dirt_Cold"
    },
    {
      "x": 4,
      "y": 13,
      "z": 4,
      "name": "Soil_Dirt_Cold"
    },
    {
      "x": 4,
      "y": 14,
      "z": 4,
      "name": "Wood_Fir_Trunk",
      "rotation": 4
    },
    {
      "x": 4,
      "y": 15,
      "z": 4,
      "name": "Wood_Deadwood_Fence",
      "rotation": 3
    },
    {
      "x": 4,
      "y": 13,
      "z": 5,
      "name": "Soil_Dirt_Cold"
    },
    {
      "x": 4,
      "y": 14,
      "z": 5,
      "name": "Wood_Fir_Trunk",
      "rotation": 4
    },
    {
      "x": 4,
      "y": 15,
      "z": 5,
      "name": "*Wood_Deadwood_Fence_State_Definitions_Corner",
      "rotation": 3
    }
  ]
}
