{
  "version": 8,
  "blockIdVersion": 8,
  "anchorX": 0,
  "anchorY": 7,
  "anchorZ": -1,
  "blocks": [
    {
      "x": -12,
      "y": 0,
      "z": -9,
      "name": "Wood_Fir_Trunk",
      "support": 15
    },
    {
      "x": -12,
      "y": 1,
      "z": -9,
      "name": "Wood_Fir_Trunk",
      "support": 15
    },
    {
      "x": -12,
      "y": 2,
      "z": -9,
      "name": "Wood_Fir_Trunk",
      "support": 15
    },
    {
      "x": -12,
      "y": 3,
      "z": -9,
      "name": "Wood_Fir_Trunk",
      "support": 15
    },
    {
      "x": -12,
      "y": 4,
      "z": -9,
      "name": "Wood_Fir_Trunk",
      "support": 15
    },
    {
      "x": -12,
      "y": 5,
      "z": -9,
      "name": "Wood_Fir_Trunk",
      "support": 15
    },
    {
      "x": -12,
      "y": 6,
      "z": -9,
      "name": "Wood_Fir_Trunk",
      "support": 15
    },
    {
      "x": -12,
      "y": 7,
      "z": -9,
      "name": "Wood_Fir_Trunk",
      "support": 15
    },
    {
      "x": -12,
      "y": 8,
      "z": -9,
      "name": "Wood_Fir_Trunk",
      "support": 15
    },
    {
      "x": -12,
      "y": 9,
      "z": -9,
      "name": "Wood_Fir_Trunk",
      "support": 15
    },
    {
      "x": -12,
      "y": 10,
      "z": -9,
      "name": "Wood_Fir_Trunk",
      "support": 15
    },
    {
      "x": -12,
      "y": 11,
      "z": -9,
      "name": "Wood_Fir_Trunk",
      "support": 15
    },
    {
      "x": -12,
      "y": 12,
      "z": -9,
      "name": "Wood_Fir_Trunk",
      "support": 15
    },
    {
      "x": -12,
      "y": 13,
      "z": -9,
      "name": "Wood_Fir_Trunk",
      "support": 15
    },
    {
      "x": -12,
      "y": 14,
      "z": -9,
      "name": "Wood_Fir_Branch_Long",
      "support": 15
    },
    {
      "x": -12,
      "y": 0,
      "z": -8,
      "name": "Wood_Fir_Trunk",
      "support": 15
    },
    {
      "x": -12,
      "y": 1,
      "z": -8,
      "name": "Wood_Fir_Trunk",
      "support": 15
    },
    {
      "x": -12,
      "y": 2,
      "z": -8,
      "name": "Wood_Fir_Trunk",
      "support": 15
    },
    {
      "x": -12,
      "y": 3,
      "z": -8,
      "name": "Wood_Fir_Trunk",
      "support": 15
    },
    {
      "x": -12,
      "y": 4,
      "z": -8,
      "name": "Wood_Fir_Trunk",
      "support": 15
    },
    {
      "x": -12,
      "y": 5,
      "z": -8,
      "name": "Wood_Fir_Trunk",
      "support": 15
    },
    {
      "x": -12,
      "y": 6,
      "z": -8,
      "name": "Wood_Fir_Trunk",
      "support": 15
    },
    {
      "x": -12,
      "y": 7,
      "z": -8,
      "name": "Wood_Fir_Trunk",
      "support": 15
    },
    {
      "x": -12,
      "y": 8,
      "z": -8,
      "name": "Wood_Fir_Trunk",
      "support": 15
    },
    {
      "x": -12,
      "y": 9,
      "z": -8,
      "name": "Wood_Fir_Trunk",
      "support": 15
    },
    {
      "x": -12,
      "y": 10,
      "z": -8,
      "name": "Wood_Fir_Trunk",
      "support": 15
    },
    {
      "x": -12,
      "y": 11,
      "z": -8,
      "name": "Wood_Fir_Trunk",
      "support": 15
    },
    {
      "x": -12,
      "y": 12,
      "z": -8,
      "name": "Wood_Fir_Trunk",
      "support": 15
    },
    {
      "x": -12,
      "y": 0,
      "z": -7,
      "name": "Wood_Fir_Trunk",
      "support": 15
    },
    {
      "x": -12,
      "y": 1,
      "z": -7,
      "name": "Wood_Fir_Trunk",
      "support": 15
    },
    {
      "x": -12,
      "y": 2,
      "z": -7,
      "name": "Wood_Fir_Trunk",
      "support": 15
    },
    {
      "x": -12,
      "y": 3,
      "z": -7,
      "name": "Wood_Fir_Trunk",
      "support": 15
    },
    {
      "x": -12,
      "y": 4,
      "z": -7,
      "name": "Wood_Fir_Trunk",
      "support": 15
    },
    {
      "x": -12,
      "y": 5,
      "z": -7,
      "name": "Wood_Fir_Trunk",
      "support": 15
    },
    {
      "x": -12,
      "y": 6,
      "z": -7,
      "name": "Wood_Fir_Trunk",
      "support": 15
    },
    {
      "x": -12,
      "y": 7,
      "z": -7,
      "name": "Wood_Fir_Trunk",
      "support": 15
    },
    {
      "x": -12,
      "y": 8,
      "z": -7,
      "name": "Wood_Fir_Trunk",
      "support": 15
    },
    {
      "x": -12,
      "y": 9,
      "z": -7,
      "name": "Wood_Fir_Trunk",
      "support": 15
    },
    {
      "x": -12,
      "y": 10,
      "z": -7,
      "name": "Wood_Fir_Trunk",
      "support": 15
    },
    {
      "x": -12,
      "y": 11,
      "z": -7,
      "name": "Wood_Fir_Trunk",
      "support": 15
    },
    {
      "x": -12,
      "y": 12,
      "z": -7,
      "name": "Wood_Fir_Trunk",
      "support": 15
    },
    {
      "x": -12,
      "y": 13,
      "z": -7,
      "name": "Wood_Fir_Trunk",
      "support": 15
    },
    {
      "x": -12,
      "y": 14,
      "z": -7,
      "name": "Wood_Fir_Trunk",
      "support": 15
    },
    {
      "x": -12,
      "y": 15,
      "z": -7,
      "name": "Wood_Fir_Branch_Long",
      "support": 15
    },
    {
      "x": -12,
      "y": 16,
      "z": -7,
      "name": "Survival_Trap_Spike_Wood_Large"
    },
    {
      "x": -12,
      "y": 0,
      "z": -6,
      "name": "Wood_Fir_Trunk",
      "support": 15
    },
    {
      "x": -12,
      "y": 1,
      "z": -6,
      "name": "Wood_Fir_Trunk",
      "support": 15
    },
    {
      "x": -12,
      "y": 2,
      "z": -6,
      "name": "Wood_Fir_Trunk",
      "support": 15
    },
    {
      "x": -12,
      "y": 3,
      "z": -6,
      "name": "Wood_Fir_Trunk",
      "support": 15
    },
    {
      "x": -12,
      "y": 4,
      "z": -6,
      "name": "Wood_Fir_Trunk",
      "support": 15
    },
    {
      "x": -12,
      "y": 5,
      "z": -6,
      "name": "Wood_Fir_Trunk",
      "support": 15
    },
    {
      "x": -12,
      "y": 6,
      "z": -6,
      "name": "Wood_Fir_Trunk",
      "support": 15
    },
    {
      "x": -12,
      "y": 7,
      "z": -6,
      "name": "Wood_Fir_Trunk",
      "support": 15
    },
    {
      "x": -12,
      "y": 8,
      "z": -6,
      "name": "Wood_Fir_Trunk",
      "support": 15
    },
    {
      "x": -12,
      "y": 9,
      "z": -6,
      "name": "Wood_Fir_Trunk",
      "support": 15
    },
    {
      "x": -12,
      "y": 10,
      "z": -6,
      "name": "Wood_Fir_Trunk",
      "support": 15
    },
    {
      "x": -12,
      "y": 11,
      "z": -6,
      "name": "Wood_Fir_Trunk",
      "support": 15
    },
    {
      "x": -12,
      "y": 12,
      "z": -6,
      "name": "Wood_Fir_Trunk",
      "support": 15
    },
    {
      "x": -12,
      "y": 13,
      "z": -6,
      "name": "Wood_Fir_Trunk",
      "support": 15
    },
    {
      "x": -12,
      "y": 14,
      "z": -6,
      "name": "Survival_Trap_Spike_Wood_Large"
    },
    {
      "x": -12,
      "y": 0,
      "z": 7,
      "name": "Wood_Fir_Trunk",
      "support": 15
    },
    {
      "x": -12,
      "y": 1,
      "z": 7,
      "name": "Wood_Fir_Trunk",
      "support": 15
    },
    {
      "x": -12,
      "y": 2,
      "z": 7,
      "name": "Wood_Fir_Trunk",
      "support": 15
    },
    {
      "x": -12,
      "y": 3,
      "z": 7,
      "name": "Wood_Fir_Trunk",
      "support": 15
    },
    {
      "x": -12,
      "y": 4,
      "z": 7,
      "name": "Wood_Fir_Trunk",
      "support": 15
    },
    {
      "x": -12,
      "y": 5,
      "z": 7,
      "name": "Wood_Fir_Trunk",
      "support": 15
    },
    {
      "x": -12,
      "y": 6,
      "z": 7,
      "name": "Wood_Fir_Trunk",
      "support": 15
    },
    {
      "x": -12,
      "y": 7,
      "z": 7,
      "name": "Wood_Fir_Trunk",
      "support": 15
    },
    {
      "x": -12,
      "y": 8,
      "z": 7,
      "name": "Wood_Fir_Trunk",
      "support": 15
    },
    {
      "x": -12,
      "y": 9,
      "z": 7,
      "name": "Wood_Fir_Trunk",
      "support": 15
    },
    {
      "x": -12,
      "y": 10,
      "z": 7,
      "name": "Wood_Fir_Trunk",
      "support": 15
    },
    {
      "x": -12,
      "y": 11,
      "z": 7,
      "name": "Wood_Fir_Trunk",
      "support": 15
    },
    {
      "x": -12,
      "y": 12,
      "z": 7,
      "name": "Wood_Fir_Trunk",
      "support": 15
    },
    {
      "x": -12,
      "y": 13,
      "z": 7,
      "name": "Wood_Fir_Branch_Long",
      "support": 15
    },
    {
      "x": -12,
      "y": 14,
      "z": 7,
      "name": "Furniture_Crude_Torch"
    },
    {
      "x": -12,
      "y": 0,
      "z": 8,
      "name": "Wood_Fir_Trunk",
      "support": 15
    },
    {
      "x": -12,
      "y": 1,
      "z": 8,
      "name": "Wood_Fir_Trunk",
      "support": 15
    },
    {
      "x": -12,
      "y": 2,
      "z": 8,
      "name": "Wood_Fir_Trunk",
      "support": 15
    },
    {
      "x": -12,
      "y": 3,
      "z": 8,
      "name": "Wood_Fir_Trunk",
      "support": 15
    },
    {
      "x": -12,
      "y": 4,
      "z": 8,
      "name": "Wood_Fir_Trunk",
      "support": 15
    },
    {
      "x": -12,
      "y": 5,
      "z": 8,
      "name": "Wood_Fir_Trunk",
      "support": 15
    },
    {
      "x": -12,
      "y": 6,
      "z": 8,
      "name": "Wood_Fir_Trunk",
      "support": 15
    },
    {
      "x": -12,
      "y": 7,
      "z": 8,
      "name": "Wood_Fir_Trunk",
      "support": 15
    },
    {
      "x": -12,
      "y": 8,
      "z": 8,
      "name": "Wood_Fir_Trunk",
      "support": 15
    },
    {
      "x": -12,
      "y": 9,
      "z": 8,
      "name": "Wood_Fir_Trunk",
      "support": 15
    },
    {
      "x": -12,
      "y": 10,
      "z": 8,
      "name": "Wood_Fir_Trunk",
      "support": 15
    },
    {
      "x": -12,
      "y": 11,
      "z": 8,
      "name": "Wood_Fir_Trunk",
      "support": 15
    },
    {
      "x": -12,
      "y": 12,
      "z": 8,
      "name": "Wood_Fir_Trunk",
      "support": 15
    },
    {
      "x": -12,
      "y": 0,
      "z": 9,
      "name": "Wood_Fir_Trunk",
      "support": 15
    },
    {
      "x": -12,
      "y": 1,
      "z": 9,
      "name": "Wood_Fir_Trunk",
      "support": 15
    },
    {
      "x": -12,
      "y": 2,
      "z": 9,
      "name": "Wood_Fir_Trunk",
      "support": 15
    },
    {
      "x": -12,
      "y": 3,
      "z": 9,
      "name": "Wood_Fir_Trunk",
      "support": 15
    },
    {
      "x": -12,
      "y": 4,
      "z": 9,
      "name": "Wood_Fir_Trunk",
      "support": 15
    },
    {
      "x": -12,
      "y": 5,
      "z": 9,
      "name": "Wood_Fir_Trunk",
      "support": 15
    },
    {
      "x": -12,
      "y": 6,
      "z": 9,
      "name": "Wood_Fir_Trunk",
      "support": 15
    },
    {
      "x": -12,
      "y": 7,
      "z": 9,
      "name": "Wood_Fir_Trunk",
      "support": 15
    },
    {
      "x": -12,
      "y": 8,
      "z": 9,
      "name": "Wood_Fir_Trunk",
      "support": 15
    },
    {
      "x": -12,
      "y": 9,
      "z": 9,
      "name": "Wood_Fir_Trunk",
      "support": 15
    },
    {
      "x": -12,
      "y": 10,
      "z": 9,
      "name": "Wood_Fir_Trunk",
      "support": 15
    },
    {
      "x": -12,
      "y": 11,
      "z": 9,
      "name": "Wood_Fir_Trunk",
      "support": 15
    },
    {
      "x": -12,
      "y": 0,
      "z": 10,
      "name": "Wood_Fir_Trunk",
      "support": 15
    },
    {
      "x": -12,
      "y": 1,
      "z": 10,
      "name": "Wood_Fir_Trunk",
      "support": 15
    },
    {
      "x": -12,
      "y": 2,
      "z": 10,
      "name": "Wood_Fir_Trunk",
      "support": 15
    },
    {
      "x": -12,
      "y": 3,
      "z": 10,
      "name": "Wood_Fir_Trunk",
      "support": 15
    },
    {
      "x": -12,
      "y": 4,
      "z": 10,
      "name": "Wood_Fir_Trunk",
      "support": 15
    },
    {
      "x": -12,
      "y": 5,
      "z": 10,
      "name": "Wood_Fir_Trunk",
      "support": 15
    },
    {
      "x": -12,
      "y": 6,
      "z": 10,
      "name": "Wood_Fir_Trunk",
      "support": 15
    },
    {
      "x": -12,
      "y": 7,
      "z": 10,
      "name": "Wood_Fir_Trunk",
      "support": 15
    },
    {
      "x": -12,
      "y": 8,
      "z": 10,
      "name": "Wood_Fir_Trunk",
      "support": 15
    },
    {
      "x": -12,
      "y": 9,
      "z": 10,
      "name": "Wood_Fir_Trunk",
      "support": 15
    },
    {
      "x": -12,
      "y": 10,
      "z": 10,
      "name": "Wood_Fir_Trunk",
      "support": 15
    },
    {
      "x": -12,
      "y": 11,
      "z": 10,
      "name": "Wood_Fir_Trunk",
      "support": 15
    },
    {
      "x": -11,
      "y": 0,
      "z": -12,
      "name": "Wood_Fir_Trunk",
      "support": 15
    },
    {
      "x": -11,
      "y": 1,
      "z": -12,
      "name": "Wood_Fir_Trunk",
      "support": 15
    },
    {
      "x": -11,
      "y": 2,
      "z": -12,
      "name": "Wood_Fir_Trunk",
      "support": 15
    },
    {
      "x": -11,
      "y": 3,
      "z": -12,
      "name": "Wood_Fir_Trunk",
      "support": 15
    },
    {
      "x": -11,
      "y": 4,
      "z": -12,
      "name": "Wood_Fir_Trunk",
      "support": 15
    },
    {
      "x": -11,
      "y": 5,
      "z": -12,
      "name": "Wood_Fir_Trunk",
      "support": 15
    },
    {
      "x": -11,
      "y": 6,
      "z": -12,
      "name": "Wood_Fir_Trunk",
      "support": 15
    },
    {
      "x": -11,
      "y": 7,
      "z": -12,
      "name": "Wood_Fir_Trunk",
      "support": 15
    },
    {
      "x": -11,
      "y": 8,
      "z": -12,
      "name": "Wood_Fir_Trunk",
      "support": 15
    },
    {
      "x": -11,
      "y": 9,
      "z": -12,
      "name": "Wood_Fir_Trunk",
      "support": 15
    },
    {
      "x": -11,
      "y": 10,
      "z": -12,
      "name": "Wood_Fir_Trunk",
      "support": 15
    },
    {
      "x": -11,
      "y": 11,
      "z": -12,
      "name": "Wood_Fir_Trunk",
      "support": 15
    },
    {
      "x": -11,
      "y": 12,
      "z": -12,
      "name": "Wood_Fir_Trunk",
      "support": 15
    },
    {
      "x": -11,
      "y": 13,
      "z": -12,
      "name": "Wood_Fir_Trunk",
      "support": 15
    },
    {
      "x": -11,
      "y": 14,
      "z": -12,
      "name": "Survival_Trap_Spike_Wood_Large"
    },
    {
      "x": -11,
      "y": 0,
      "z": -11,
      "name": "Wood_Fir_Trunk",
      "support": 15
    },
    {
      "x": -11,
      "y": 1,
      "z": -11,
      "name": "Wood_Fir_Trunk",
      "support": 15
    },
    {
      "x": -11,
      "y": 2,
      "z": -11,
      "name": "Wood_Fir_Trunk",
      "support": 15
    },
    {
      "x": -11,
      "y": 3,
      "z": -11,
      "name": "Wood_Fir_Trunk",
      "support": 15
    },
    {
      "x": -11,
      "y": 4,
      "z": -11,
      "name": "Wood_Fir_Trunk",
      "support": 15
    },
    {
      "x": -11,
      "y": 5,
      "z": -11,
      "name": "Wood_Fir_Trunk",
      "support": 15
    },
    {
      "x": -11,
      "y": 6,
      "z": -11,
      "name": "Wood_Fir_Trunk",
      "support": 15
    },
    {
      "x": -11,
      "y": 7,
      "z": -11,
      "name": "Wood_Fir_Trunk",
      "support": 15
    },
    {
      "x": -11,
      "y": 8,
      "z": -11,
      "name": "Wood_Fir_Trunk",
      "support": 15
    },
    {
      "x": -11,
      "y": 9,
      "z": -11,
      "name": "Wood_Fir_Trunk",
      "support": 15
    },
    {
      "x": -11,
      "y": 10,
      "z": -11,
      "name": "Wood_Fir_Trunk",
      "support": 15
    },
    {
      "x": -11,
      "y": 11,
      "z": -11,
      "name": "Wood_Fir_Trunk",
      "support": 15
    },
    {
      "x": -11,
      "y": 12,
      "z": -11,
      "name": "Wood_Fir_Trunk",
      "support": 15
    },
    {
      "x": -11,
      "y": 0,
      "z": -10,
      "name": "Wood_Fir_Trunk",
      "support": 15
    },
    {
      "x": -11,
      "y": 1,
      "z": -10,
      "name": "Wood_Fir_Trunk",
      "support": 15
    },
    {
      "x": -11,
      "y": 2,
      "z": -10,
      "name": "Wood_Fir_Trunk",
      "support": 15
    },
    {
      "x": -11,
      "y": 3,
      "z": -10,
      "name": "Wood_Fir_Trunk",
      "support": 15
    },
    {
      "x": -11,
      "y": 4,
      "z": -10,
      "name": "Wood_Fir_Trunk",
      "support": 15
    },
    {
      "x": -11,
      "y": 5,
      "z": -10,
      "name": "Wood_Fir_Trunk",
      "support": 15
    },
    {
      "x": -11,
      "y": 6,
      "z": -10,
      "name": "Wood_Fir_Trunk",
      "support": 15
    },
    {
      "x": -11,
      "y": 7,
      "z": -10,
      "name": "Wood_Fir_Trunk",
      "support": 15
    },
    {
      "x": -11,
      "y": 8,
      "z": -10,
      "name": "Wood_Fir_Trunk",
      "support": 15
    },
    {
      "x": -11,
      "y": 9,
      "z": -10,
      "name": "Wood_Fir_Trunk",
      "support": 15
    },
    {
      "x": -11,
      "y": 10,
      "z": -10,
      "name": "Wood_Fir_Trunk",
      "support": 15
    },
    {
      "x": -11,
      "y": 11,
      "z": -10,
      "name": "Wood_Fir_Trunk",
      "support": 15
    },
    {
      "x": -11,
      "y": 12,
      "z": -10,
      "name": "Wood_Fir_Trunk",
      "support": 15
    },
    {
      "x": -11,
      "y": 13,
      "z": -10,
      "name": "Wood_Fir_Trunk",
      "support": 15
    },
    {
      "x": -11,
      "y": 14,
      "z": -10,
      "name": "Wood_Fir_Trunk",
      "support": 15
    },
    {
      "x": -11,
      "y": 15,
      "z": -10,
      "name": "Wood_Fir_Trunk",
      "support": 15
    },
    {
      "x": -11,
      "y": 16,
      "z": -10,
      "name": "Wood_Fir_Branch_Long",
      "support": 15
    },
    {
      "x": -11,
      "y": 17,
      "z": -10,
      "name": "Wood_Fir_Branch_Long",
      "support": 15
    },
    {
      "x": -11,
      "y": 18,
      "z": -10,
      "name": "Survival_Trap_Spike_Wood_Large"
    },
    {
      "x": -11,
      "y": 0,
      "z": -9,
      "name": "Soil_Dirt_Cold"
    },
    {
      "x": -11,
      "y": 1,
      "z": -9,
      "name": "Soil_Dirt_Cold"
    },
    {
      "x": -11,
      "y": 2,
      "z": -9,
      "name": "Soil_Dirt_Cold"
    },
    {
      "x": -11,
      "y": 3,
      "z": -9,
      "name": "Soil_Dirt_Cold"
    },
    {
      "x": -11,
      "y": 4,
      "z": -9,
      "name": "Soil_Dirt_Cold"
    },
    {
      "x": -11,
      "y": 5,
      "z": -9,
      "name": "Soil_Dirt_Cold"
    },
    {
      "x": -11,
      "y": 6,
      "z": -9,
      "name": "Soil_Dirt_Cold"
    },
    {
      "x": -11,
      "y": 7,
      "z": -9,
      "name": "Soil_Dirt_Cold"
    },
    {
      "x": -11,
      "y": 8,
      "z": -9,
      "name": "Soil_Dirt_Cold"
    },
    {
      "x": -11,
      "y": 9,
      "z": -9,
      "name": "Soil_Dirt_Cold"
    },
    {
      "x": -11,
      "y": 10,
      "z": -9,
      "name": "Soil_Dirt_Cold"
    },
    {
      "x": -11,
      "y": 11,
      "z": -9,
      "name": "Soil_Pebbles_Frozen"
    },
    {
      "x": -11,
      "y": 12,
      "z": -9,
      "name": "Furniture_Tavern_Barrel"
    },
    {
      "x": -11,
      "y": 0,
      "z": -8,
      "name": "Soil_Dirt_Cold"
    },
    {
      "x": -11,
      "y": 1,
      "z": -8,
      "name": "Soil_Dirt_Cold"
    },
    {
      "x": -11,
      "y": 2,
      "z": -8,
      "name": "Soil_Dirt_Cold"
    },
    {
      "x": -11,
      "y": 3,
      "z": -8,
      "name": "Soil_Dirt_Cold"
    },
    {
      "x": -11,
      "y": 4,
      "z": -8,
      "name": "Soil_Dirt_Cold"
    },
    {
      "x": -11,
      "y": 5,
      "z": -8,
      "name": "Soil_Dirt_Cold"
    },
    {
      "x": -11,
      "y": 6,
      "z": -8,
      "name": "Soil_Dirt_Cold"
    },
    {
      "x": -11,
      "y": 7,
      "z": -8,
      "name": "Soil_Dirt_Cold"
    },
    {
      "x": -11,
      "y": 8,
      "z": -8,
      "name": "Soil_Dirt_Cold"
    },
    {
      "x": -11,
      "y": 9,
      "z": -8,
      "name": "Soil_Dirt_Cold"
    },
    {
      "x": -11,
      "y": 10,
      "z": -8,
      "name": "Soil_Dirt_Cold"
    },
    {
      "x": -11,
      "y": 11,
      "z": -8,
      "name": "Soil_Pebbles_Frozen"
    },
    {
      "x": -11,
      "y": 12,
      "z": -8,
      "name": "Container_Bucket"
    },
    {
      "x": -11,
      "y": 0,
      "z": -7,
      "name": "Soil_Dirt_Cold"
    },
    {
      "x": -11,
      "y": 1,
      "z": -7,
      "name": "Soil_Dirt_Cold"
    },
    {
      "x": -11,
      "y": 2,
      "z": -7,
      "name": "Soil_Dirt_Cold"
    },
    {
      "x": -11,
      "y": 3,
      "z": -7,
      "name": "Soil_Dirt_Cold"
    },
    {
      "x": -11,
      "y": 4,
      "z": -7,
      "name": "Soil_Dirt_Cold"
    },
    {
      "x": -11,
      "y": 5,
      "z": -7,
      "name": "Soil_Dirt_Cold"
    },
    {
      "x": -11,
      "y": 6,
      "z": -7,
      "name": "Soil_Dirt_Cold"
    },
    {
      "x": -11,
      "y": 7,
      "z": -7,
      "name": "Soil_Dirt_Cold"
    },
    {
      "x": -11,
      "y": 8,
      "z": -7,
      "name": "Soil_Dirt_Cold"
    },
    {
      "x": -11,
      "y": 9,
      "z": -7,
      "name": "Soil_Dirt_Cold"
    },
    {
      "x": -11,
      "y": 10,
      "z": -7,
      "name": "Soil_Dirt_Cold"
    },
    {
      "x": -11,
      "y": 11,
      "z": -7,
      "name": "Soil_Pebbles_Frozen"
    },
    {
      "x": -11,
      "y": 0,
      "z": -6,
      "name": "Soil_Dirt_Cold"
    },
    {
      "x": -11,
      "y": 1,
      "z": -6,
      "name": "Soil_Dirt_Cold"
    },
    {
      "x": -11,
      "y": 2,
      "z": -6,
      "name": "Soil_Dirt_Cold"
    },
    {
      "x": -11,
      "y": 3,
      "z": -6,
      "name": "Soil_Dirt_Cold"
    },
    {
      "x": -11,
      "y": 4,
      "z": -6,
      "name": "Soil_Dirt_Cold"
    },
    {
      "x": -11,
      "y": 5,
      "z": -6,
      "name": "Soil_Dirt_Cold"
    },
    {
      "x": -11,
      "y": 6,
      "z": -6,
      "name": "Soil_Dirt_Cold"
    },
    {
      "x": -11,
      "y": 7,
      "z": -6,
      "name": "Soil_Dirt_Cold"
    },
    {
      "x": -11,
      "y": 8,
      "z": -6,
      "name": "Soil_Dirt_Cold"
    },
    {
      "x": -11,
      "y": 9,
      "z": -6,
      "name": "Soil_Dirt_Cold"
    },
    {
      "x": -11,
      "y": 10,
      "z": -6,
      "name": "Soil_Dirt_Cold"
    },
    {
      "x": -11,
      "y": 11,
      "z": -6,
      "name": "Soil_Pebbles_Frozen"
    },
    {
      "x": -11,
      "y": 0,
      "z": -5,
      "name": "Wood_Fir_Trunk",
      "support": 15
    },
    {
      "x": -11,
      "y": 1,
      "z": -5,
      "name": "Wood_Fir_Trunk",
      "support": 15
    },
    {
      "x": -11,
      "y": 2,
      "z": -5,
      "name": "Wood_Fir_Trunk",
      "support": 15
    },
    {
      "x": -11,
      "y": 3,
      "z": -5,
      "name": "Wood_Fir_Trunk",
      "support": 15
    },
    {
      "x": -11,
      "y": 4,
      "z": -5,
      "name": "Wood_Fir_Trunk",
      "support": 15
    },
    {
      "x": -11,
      "y": 5,
      "z": -5,
      "name": "Wood_Fir_Trunk",
      "support": 15
    },
    {
      "x": -11,
      "y": 6,
      "z": -5,
      "name": "Wood_Fir_Trunk",
      "support": 15
    },
    {
      "x": -11,
      "y": 7,
      "z": -5,
      "name": "Wood_Fir_Trunk",
      "support": 15
    },
    {
      "x": -11,
      "y": 8,
      "z": -5,
      "name": "Wood_Fir_Trunk",
      "support": 15
    },
    {
      "x": -11,
      "y": 9,
      "z": -5,
      "name": "Wood_Fir_Trunk",
      "support": 15
    },
    {
      "x": -11,
      "y": 10,
      "z": -5,
      "name": "Wood_Fir_Trunk",
      "support": 15
    },
    {
      "x": -11,
      "y": 11,
      "z": -5,
      "name": "Wood_Fir_Trunk",
      "support": 15
    },
    {
      "x": -11,
      "y": 12,
      "z": -5,
      "name": "Wood_Fir_Trunk",
      "support": 15
    },
    {
      "x": -11,
      "y": 0,
      "z": -4,
      "name": "Furniture_Tavern_Ladder",
      "rotation": 3
    },
    {
      "x": -11,
      "y": 1,
      "z": -4,
      "name": "Furniture_Tavern_Ladder",
      "rotation": 3
    },
    {
      "x": -11,
      "y": 2,
      "z": -4,
      "name": "Furniture_Tavern_Ladder",
      "rotation": 3
    },
    {
      "x": -11,
      "y": 3,
      "z": -4,
      "name": "Furniture_Tavern_Ladder",
      "rotation": 3
    },
    {
      "x": -11,
      "y": 4,
      "z": -4,
      "name": "Furniture_Tavern_Ladder",
      "rotation": 3
    },
    {
      "x": -11,
      "y": 5,
      "z": -4,
      "name": "Furniture_Tavern_Ladder",
      "rotation": 3
    },
    {
      "x": -11,
      "y": 6,
      "z": -4,
      "name": "Furniture_Tavern_Ladder",
      "rotation": 3
    },
    {
      "x": -11,
      "y": 7,
      "z": -4,
      "name": "Furniture_Tavern_Ladder",
      "rotation": 3
    },
    {
      "x": -11,
      "y": 8,
      "z": -4,
      "name": "Furniture_Tavern_Ladder",
      "rotation": 3
    },
    {
      "x": -11,
      "y": 9,
      "z": -4,
      "name": "Furniture_Tavern_Ladder",
      "rotation": 3
    },
    {
      "x": -11,
      "y": 10,
      "z": -4,
      "name": "Furniture_Tavern_Ladder",
      "rotation": 3
    },
    {
      "x": -11,
      "y": 11,
      "z": -4,
      "name": "Furniture_Tavern_Ladder",
      "rotation": 3
    },
    {
      "x": -11,
      "y": 0,
      "z": -3,
      "name": "Wood_Fir_Trunk",
      "support": 15
    },
    {
      "x": -11,
      "y": 1,
      "z": -3,
      "name": "Wood_Fir_Trunk",
      "support": 15
    },
    {
      "x": -11,
      "y": 2,
      "z": -3,
      "name": "Wood_Fir_Trunk",
      "support": 15
    },
    {
      "x": -11,
      "y": 3,
      "z": -3,
      "name": "Wood_Fir_Trunk",
      "support": 15
    },
    {
      "x": -11,
      "y": 4,
      "z": -3,
      "name": "Wood_Fir_Trunk",
      "support": 15
    },
    {
      "x": -11,
      "y": 5,
      "z": -3,
      "name": "Wood_Fir_Trunk",
      "support": 15
    },
    {
      "x": -11,
      "y": 6,
      "z": -3,
      "name": "Wood_Fir_Trunk",
      "support": 15
    },
    {
      "x": -11,
      "y": 7,
      "z": -3,
      "name": "Wood_Fir_Trunk",
      "support": 15
    },
    {
      "x": -11,
      "y": 8,
      "z": -3,
      "name": "Wood_Fir_Trunk",
      "support": 15
    },
    {
      "x": -11,
      "y": 9,
      "z": -3,
      "name": "Wood_Fir_Trunk",
      "support": 15
    },
    {
      "x": -11,
      "y": 10,
      "z": -3,
      "name": "Wood_Fir_Trunk",
      "support": 15
    },
    {
      "x": -11,
      "y": 11,
      "z": -3,
      "name": "Wood_Fir_Trunk",
      "support": 15
    },
    {
      "x": -11,
      "y": 12,
      "z": -3,
      "name": "Wood_Fir_Trunk",
      "support": 15
    },
    {
      "x": -11,
      "y": 0,
      "z": -2,
      "name": "Wood_Fir_Trunk",
      "support": 15
    },
    {
      "x": -11,
      "y": 1,
      "z": -2,
      "name": "Wood_Fir_Trunk",
      "support": 15
    },
    {
      "x": -11,
      "y": 2,
      "z": -2,
      "name": "Wood_Fir_Trunk",
      "support": 15
    },
    {
      "x": -11,
      "y": 3,
      "z": -2,
      "name": "Wood_Fir_Trunk",
      "support": 15
    },
    {
      "x": -11,
      "y": 4,
      "z": -2,
      "name": "Wood_Fir_Trunk",
      "support": 15
    },
    {
      "x": -11,
      "y": 5,
      "z": -2,
      "name": "Wood_Fir_Trunk",
      "support": 15
    },
    {
      "x": -11,
      "y": 6,
      "z": -2,
      "name": "Wood_Fir_Trunk",
      "support": 15
    },
    {
      "x": -11,
      "y": 7,
      "z": -2,
      "name": "Wood_Fir_Trunk",
      "support": 15
    },
    {
      "x": -11,
      "y": 8,
      "z": -2,
      "name": "Wood_Fir_Trunk",
      "support": 15
    },
    {
      "x": -11,
      "y": 9,
      "z": -2,
      "name": "Wood_Fir_Trunk",
      "support": 15
    },
    {
      "x": -11,
      "y": 10,
      "z": -2,
      "name": "Wood_Fir_Trunk",
      "support": 15
    },
    {
      "x": -11,
      "y": 11,
      "z": -2,
      "name": "Wood_Fir_Trunk",
      "support": 15
    },
    {
      "x": -11,
      "y": 12,
      "z": -2,
      "name": "Wood_Fir_Trunk",
      "support": 15
    },
    {
      "x": -11,
      "y": 13,
      "z": -2,
      "name": "Wood_Fir_Trunk",
      "support": 15
    },
    {
      "x": -11,
      "y": 14,
      "z": -2,
      "name": "Wood_Fir_Branch_Long",
      "support": 15
    },
    {
      "x": -11,
      "y": 15,
      "z": -2,
      "name": "Survival_Trap_Spike_Wood_Large"
    },
    {
      "x": -11,
      "y": 0,
      "z": -1,
      "name": "Wood_Fir_Trunk",
      "support": 15
    },
    {
      "x": -11,
      "y": 1,
      "z": -1,
      "name": "Wood_Fir_Trunk",
      "support": 15
    },
    {
      "x": -11,
      "y": 2,
      "z": -1,
      "name": "Wood_Fir_Trunk",
      "support": 15
    },
    {
      "x": -11,
      "y": 3,
      "z": -1,
      "name": "Wood_Fir_Trunk",
      "support": 15
    },
    {
      "x": -11,
      "y": 4,
      "z": -1,
      "name": "Wood_Fir_Trunk",
      "support": 15
    },
    {
      "x": -11,
      "y": 5,
      "z": -1,
      "name": "Wood_Fir_Trunk",
      "support": 15
    },
    {
      "x": -11,
      "y": 6,
      "z": -1,
      "name": "Wood_Fir_Trunk",
      "support": 15
    },
    {
      "x": -11,
      "y": 7,
      "z": -1,
      "name": "Wood_Fir_Trunk",
      "support": 15
    },
    {
      "x": -11,
      "y": 8,
      "z": -1,
      "name": "Wood_Fir_Trunk",
      "support": 15
    },
    {
      "x": -11,
      "y": 9,
      "z": -1,
      "name": "Wood_Fir_Trunk",
      "support": 15
    },
    {
      "x": -11,
      "y": 10,
      "z": -1,
      "name": "Wood_Fir_Trunk",
      "support": 15
    },
    {
      "x": -11,
      "y": 11,
      "z": -1,
      "name": "Wood_Fir_Trunk",
      "support": 15
    },
    {
      "x": -11,
      "y": 12,
      "z": -1,
      "name": "Wood_Fir_Trunk",
      "support": 15
    },
    {
      "x": -11,
      "y": 0,
      "z": 0,
      "name": "Wood_Fir_Trunk",
      "support": 15
    },
    {
      "x": -11,
      "y": 1,
      "z": 0,
      "name": "Wood_Fir_Trunk",
      "support": 15
    },
    {
      "x": -11,
      "y": 2,
      "z": 0,
      "name": "Wood_Fir_Trunk",
      "support": 15
    },
    {
      "x": -11,
      "y": 3,
      "z": 0,
      "name": "Wood_Fir_Trunk",
      "support": 15
    },
    {
      "x": -11,
      "y": 4,
      "z": 0,
      "name": "Wood_Fir_Trunk",
      "support": 15
    },
    {
      "x": -11,
      "y": 5,
      "z": 0,
      "name": "Wood_Fir_Trunk",
      "support": 15
    },
    {
      "x": -11,
      "y": 6,
      "z": 0,
      "name": "Wood_Fir_Trunk",
      "support": 15
    },
    {
      "x": -11,
      "y": 7,
      "z": 0,
      "name": "Wood_Fir_Trunk",
      "support": 15
    },
    {
      "x": -11,
      "y": 8,
      "z": 0,
      "name": "Wood_Fir_Trunk",
      "support": 15
    },
    {
      "x": -11,
      "y": 9,
      "z": 0,
      "name": "Wood_Fir_Trunk",
      "support": 15
    },
    {
      "x": -11,
      "y": 10,
      "z": 0,
      "name": "Wood_Fir_Trunk",
      "support": 15
    },
    {
      "x": -11,
      "y": 11,
      "z": 0,
      "name": "Wood_Fir_Trunk",
      "support": 15
    },
    {
      "x": -11,
      "y": 12,
      "z": 0,
      "name": "Wood_Fir_Trunk",
      "support": 15
    },
    {
      "x": -11,
      "y": 13,
      "z": 0,
      "name": "Wood_Fir_Trunk",
      "support": 15
    },
    {
      "x": -11,
      "y": 0,
      "z": 5,
      "name": "Wood_Fir_Trunk",
      "support": 15
    },
    {
      "x": -11,
      "y": 1,
      "z": 5,
      "name": "Wood_Fir_Trunk",
      "support": 15
    },
    {
      "x": -11,
      "y": 2,
      "z": 5,
      "name": "Wood_Fir_Trunk",
      "support": 15
    },
    {
      "x": -11,
      "y": 3,
      "z": 5,
      "name": "Wood_Fir_Trunk",
      "support": 15
    },
    {
      "x": -11,
      "y": 4,
      "z": 5,
      "name": "Wood_Fir_Trunk",
      "support": 15
    },
    {
      "x": -11,
      "y": 5,
      "z": 5,
      "name": "Wood_Fir_Trunk",
      "support": 15
    },
    {
      "x": -11,
      "y": 6,
      "z": 5,
      "name": "Wood_Fir_Trunk",
      "support": 15
    },
    {
      "x": -11,
      "y": 7,
      "z": 5,
      "name": "Wood_Fir_Trunk",
      "support": 15
    },
    {
      "x": -11,
      "y": 8,
      "z": 5,
      "name": "Wood_Fir_Trunk",
      "support": 15
    },
    {
      "x": -11,
      "y": 9,
      "z": 5,
      "name": "Wood_Fir_Trunk",
      "support": 15
    },
    {
      "x": -11,
      "y": 10,
      "z": 5,
      "name": "Wood_Fir_Trunk",
      "support": 15
    },
    {
      "x": -11,
      "y": 11,
      "z": 5,
      "name": "Wood_Fir_Trunk",
      "support": 15
    },
    {
      "x": -11,
      "y": 12,
      "z": 5,
      "name": "Wood_Fir_Trunk",
      "support": 15
    },
    {
      "x": -11,
      "y": 0,
      "z": 6,
      "name": "Wood_Fir_Trunk",
      "support": 15
    },
    {
      "x": -11,
      "y": 1,
      "z": 6,
      "name": "Wood_Fir_Trunk",
      "support": 15
    },
    {
      "x": -11,
      "y": 2,
      "z": 6,
      "name": "Wood_Fir_Trunk",
      "support": 15
    },
    {
      "x": -11,
      "y": 3,
      "z": 6,
      "name": "Wood_Fir_Trunk",
      "support": 15
    },
    {
      "x": -11,
      "y": 4,
      "z": 6,
      "name": "Wood_Fir_Trunk",
      "support": 15
    },
    {
      "x": -11,
      "y": 5,
      "z": 6,
      "name": "Wood_Fir_Trunk",
      "support": 15
    },
    {
      "x": -11,
      "y": 6,
      "z": 6,
      "name": "Wood_Fir_Trunk",
      "support": 15
    },
    {
      "x": -11,
      "y": 7,
      "z": 6,
      "name": "Wood_Fir_Trunk",
      "support": 15
    },
    {
      "x": -11,
      "y": 8,
      "z": 6,
      "name": "Wood_Fir_Trunk",
      "support": 15
    },
    {
      "x": -11,
      "y": 9,
      "z": 6,
      "name": "Wood_Fir_Trunk",
      "support": 15
    },
    {
      "x": -11,
      "y": 10,
      "z": 6,
      "name": "Wood_Fir_Trunk",
      "support": 15
    },
    {
      "x": -11,
      "y": 11,
      "z": 6,
      "name": "Wood_Fir_Trunk",
      "support": 15
    },
    {
      "x": -11,
      "y": 12,
      "z": 6,
      "name": "Wood_Fir_Trunk",
      "support": 15
    },
    {
      "x": -11,
      "y": 13,
      "z": 6,
      "name": "Wood_Fir_Trunk",
      "support": 15
    },
    {
      "x": -11,
      "y": 14,
      "z": 6,
      "name": "Survival_Trap_Spike_Wood_Large"
    },
    {
      "x": -11,
      "y": 0,
      "z": 7,
      "name": "Wood_Fir_Trunk",
      "support": 15
    },
    {
      "x": -11,
      "y": 1,
      "z": 7,
      "name": "Wood_Fir_Trunk",
      "support": 15
    },
    {
      "x": -11,
      "y": 2,
      "z": 7,
      "name": "Wood_Fir_Trunk",
      "support": 15
    },
    {
      "x": -11,
      "y": 3,
      "z": 7,
      "name": "Wood_Fir_Trunk",
      "support": 15
    },
    {
      "x": -11,
      "y": 4,
      "z": 7,
      "name": "Wood_Fir_Trunk",
      "support": 15
    },
    {
      "x": -11,
      "y": 5,
      "z": 7,
      "name": "Wood_Fir_Trunk",
      "support": 15
    },
    {
      "x": -11,
      "y": 6,
      "z": 7,
      "name": "Wood_Fir_Trunk",
      "support": 15
    },
    {
      "x": -11,
      "y": 7,
      "z": 7,
      "name": "Wood_Fir_Trunk",
      "support": 15
    },
    {
      "x": -11,
      "y": 8,
      "z": 7,
      "name": "Wood_Fir_Trunk",
      "support": 15
    },
    {
      "x": -11,
      "y": 9,
      "z": 7,
      "name": "Wood_Fir_Trunk",
      "support": 15
    },
    {
      "x": -11,
      "y": 10,
      "z": 7,
      "name": "Wood_Fir_Trunk",
      "support": 15
    },
    {
      "x": -11,
      "y": 11,
      "z": 7,
      "name": "Wood_Fir_Trunk",
      "support": 15
    },
    {
      "x": -11,
      "y": 12,
      "z": 7,
      "name": "Wood_Fir_Trunk",
      "support": 15
    },
    {
      "x": -11,
      "y": 0,
      "z": 8,
      "name": "Soil_Dirt_Cold"
    },
    {
      "x": -11,
      "y": 1,
      "z": 8,
      "name": "Soil_Dirt_Cold"
    },
    {
      "x": -11,
      "y": 2,
      "z": 8,
      "name": "Soil_Dirt_Cold"
    },
    {
      "x": -11,
      "y": 3,
      "z": 8,
      "name": "Soil_Dirt_Cold"
    },
    {
      "x": -11,
      "y": 4,
      "z": 8,
      "name": "Soil_Dirt_Cold"
    },
    {
      "x": -11,
      "y": 5,
      "z": 8,
      "name": "Soil_Dirt_Cold"
    },
    {
      "x": -11,
      "y": 6,
      "z": 8,
      "name": "Soil_Dirt_Cold"
    },
    {
      "x": -11,
      "y": 7,
      "z": 8,
      "name": "Soil_Dirt_Cold"
    },
    {
      "x": -11,
      "y": 8,
      "z": 8,
      "name": "Soil_Dirt_Cold"
    },
    {
      "x": -11,
      "y": 9,
      "z": 8,
      "name": "Soil_Dirt_Cold"
    },
    {
      "x": -11,
      "y": 10,
      "z": 8,
      "name": "Soil_Dirt_Cold"
    },
    {
      "x": -11,
      "y": 11,
      "z": 8,
      "name": "Soil_Dirt_Cold"
    },
    {
      "x": -11,
      "y": 0,
      "z": 9,
      "name": "Soil_Dirt_Cold"
    },
    {
      "x": -11,
      "y": 1,
      "z": 9,
      "name": "Soil_Dirt_Cold"
    },
    {
      "x": -11,
      "y": 2,
      "z": 9,
      "name": "Soil_Dirt_Cold"
    },
    {
      "x": -11,
      "y": 3,
      "z": 9,
      "name": "Soil_Dirt_Cold"
    },
    {
      "x": -11,
      "y": 4,
      "z": 9,
      "name": "Soil_Dirt_Cold"
    },
    {
      "x": -11,
      "y": 5,
      "z": 9,
      "name": "Soil_Dirt_Cold"
    },
    {
      "x": -11,
      "y": 6,
      "z": 9,
      "name": "Soil_Dirt_Cold"
    },
    {
      "x": -11,
      "y": 7,
      "z": 9,
      "name": "Soil_Dirt_Cold"
    },
    {
      "x": -11,
      "y": 8,
      "z": 9,
      "name": "Soil_Dirt_Cold"
    },
    {
      "x": -11,
      "y": 9,
      "z": 9,
      "name": "Soil_Dirt_Cold"
    },
    {
      "x": -11,
      "y": 10,
      "z": 9,
      "name": "Soil_Dirt_Cold"
    },
    {
      "x": -11,
      "y": 11,
      "z": 9,
      "name": "Soil_Dirt_Cold"
    },
    {
      "x": -11,
      "y": 0,
      "z": 10,
      "name": "Soil_Dirt_Cold"
    },
    {
      "x": -11,
      "y": 1,
      "z": 10,
      "name": "Soil_Dirt_Cold"
    },
    {
      "x": -11,
      "y": 2,
      "z": 10,
      "name": "Soil_Dirt_Cold"
    },
    {
      "x": -11,
      "y": 3,
      "z": 10,
      "name": "Soil_Dirt_Cold"
    },
    {
      "x": -11,
      "y": 4,
      "z": 10,
      "name": "Soil_Dirt_Cold"
    },
    {
      "x": -11,
      "y": 5,
      "z": 10,
      "name": "Soil_Dirt_Cold"
    },
    {
      "x": -11,
      "y": 6,
      "z": 10,
      "name": "Soil_Dirt_Cold"
    },
    {
      "x": -11,
      "y": 7,
      "z": 10,
      "name": "Soil_Dirt_Cold"
    },
    {
      "x": -11,
      "y": 8,
      "z": 10,
      "name": "Soil_Dirt_Cold"
    },
    {
      "x": -11,
      "y": 9,
      "z": 10,
      "name": "Soil_Dirt_Cold"
    },
    {
      "x": -11,
      "y": 10,
      "z": 10,
      "name": "Soil_Dirt_Cold"
    },
    {
      "x": -11,
      "y": 11,
      "z": 10,
      "name": "Soil_Dirt_Cold"
    },
    {
      "x": -11,
      "y": 0,
      "z": 11,
      "name": "Wood_Fir_Trunk",
      "support": 15
    },
    {
      "x": -11,
      "y": 1,
      "z": 11,
      "name": "Wood_Fir_Trunk",
      "support": 15
    },
    {
      "x": -11,
      "y": 2,
      "z": 11,
      "name": "Wood_Fir_Trunk",
      "support": 15
    },
    {
      "x": -11,
      "y": 3,
      "z": 11,
      "name": "Wood_Fir_Trunk",
      "support": 15
    },
    {
      "x": -11,
      "y": 4,
      "z": 11,
      "name": "Wood_Fir_Trunk",
      "support": 15
    },
    {
      "x": -11,
      "y": 5,
      "z": 11,
      "name": "Wood_Fir_Trunk",
      "support": 15
    },
    {
      "x": -11,
      "y": 6,
      "z": 11,
      "name": "Wood_Fir_Trunk",
      "support": 15
    },
    {
      "x": -11,
      "y": 7,
      "z": 11,
      "name": "Wood_Fir_Trunk",
      "support": 15
    },
    {
      "x": -11,
      "y": 8,
      "z": 11,
      "name": "Wood_Fir_Trunk",
      "support": 15
    },
    {
      "x": -11,
      "y": 9,
      "z": 11,
      "name": "Wood_Fir_Trunk",
      "support": 15
    },
    {
      "x": -11,
      "y": 10,
      "z": 11,
      "name": "Wood_Fir_Trunk",
      "support": 15
    },
    {
      "x": -11,
      "y": 11,
      "z": 11,
      "name": "Wood_Fir_Trunk",
      "support": 15
    },
    {
      "x": -10,
      "y": 0,
      "z": -13,
      "name": "Wood_Fir_Trunk",
      "support": 15
    },
    {
      "x": -10,
      "y": 1,
      "z": -13,
      "name": "Wood_Fir_Trunk",
      "support": 15
    },
    {
      "x": -10,
      "y": 2,
      "z": -13,
      "name": "Wood_Fir_Trunk",
      "support": 15
    },
    {
      "x": -10,
      "y": 3,
      "z": -13,
      "name": "Wood_Fir_Trunk",
      "support": 15
    },
    {
      "x": -10,
      "y": 4,
      "z": -13,
      "name": "Wood_Fir_Trunk",
      "support": 15
    },
    {
      "x": -10,
      "y": 5,
      "z": -13,
      "name": "Wood_Fir_Trunk",
      "support": 15
    },
    {
      "x": -10,
      "y": 6,
      "z": -13,
      "name": "Wood_Fir_Trunk",
      "support": 15
    },
    {
      "x": -10,
      "y": 7,
      "z": -13,
      "name": "Wood_Fir_Trunk",
      "support": 15
    },
    {
      "x": -10,
      "y": 8,
      "z": -13,
      "name": "Wood_Fir_Trunk",
      "support": 15
    },
    {
      "x": -10,
      "y": 9,
      "z": -13,
      "name": "Wood_Fir_Trunk",
      "support": 15
    },
    {
      "x": -10,
      "y": 10,
      "z": -13,
      "name": "Wood_Fir_Trunk",
      "support": 15
    },
    {
      "x": -10,
      "y": 11,
      "z": -13,
      "name": "Wood_Fir_Trunk",
      "support": 15
    },
    {
      "x": -10,
      "y": 12,
      "z": -13,
      "name": "Wood_Fir_Trunk",
      "support": 15
    },
    {
      "x": -10,
      "y": 13,
      "z": -13,
      "name": "Wood_Fir_Trunk",
      "support": 15
    },
    {
      "x": -10,
      "y": 14,
      "z": -13,
      "name": "Wood_Fir_Trunk",
      "support": 15
    },
    {
      "x": -10,
      "y": 15,
      "z": -13,
      "name": "Wood_Fir_Trunk",
      "support": 15
    },
    {
      "x": -10,
      "y": 16,
      "z": -13,
      "name": "Wood_Fir_Branch_Long",
      "support": 15
    },
    {
      "x": -10,
      "y": 17,
      "z": -13,
      "name": "Survival_Trap_Spike_Wood_Large"
    },
    {
      "x": -10,
      "y": 0,
      "z": -12,
      "name": "Soil_Dirt_Cold"
    },
    {
      "x": -10,
      "y": 1,
      "z": -12,
      "name": "Soil_Dirt_Cold"
    },
    {
      "x": -10,
      "y": 2,
      "z": -12,
      "name": "Soil_Dirt_Cold"
    },
    {
      "x": -10,
      "y": 3,
      "z": -12,
      "name": "Soil_Dirt_Cold"
    },
    {
      "x": -10,
      "y": 4,
      "z": -12,
      "name": "Soil_Dirt_Cold"
    },
    {
      "x": -10,
      "y": 5,
      "z": -12,
      "name": "Soil_Dirt_Cold"
    },
    {
      "x": -10,
      "y": 6,
      "z": -12,
      "name": "Soil_Dirt_Cold"
    },
    {
      "x": -10,
      "y": 7,
      "z": -12,
      "name": "Soil_Dirt_Cold"
    },
    {
      "x": -10,
      "y": 8,
      "z": -12,
      "name": "Soil_Dirt_Cold"
    },
    {
      "x": -10,
      "y": 9,
      "z": -12,
      "name": "Soil_Dirt_Cold"
    },
    {
      "x": -10,
      "y": 10,
      "z": -12,
      "name": "Soil_Dirt_Cold"
    },
    {
      "x": -10,
      "y": 11,
      "z": -12,
      "name": "Soil_Dirt_Cold"
    },
    {
      "x": -10,
      "y": 12,
      "z": -12,
      "name": "Wood_Fir_Trunk",
      "support": 15
    },
    {
      "x": -10,
      "y": 13,
      "z": -12,
      "name": "Wood_Fir_Trunk",
      "support": 15
    },
    {
      "x": -10,
      "y": 14,
      "z": -12,
      "name": "Wood_Fir_Trunk",
      "support": 15
    },
    {
      "x": -10,
      "y": 0,
      "z": -11,
      "name": "Soil_Dirt_Cold"
    },
    {
      "x": -10,
      "y": 1,
      "z": -11,
      "name": "Soil_Dirt_Cold"
    },
    {
      "x": -10,
      "y": 2,
      "z": -11,
      "name": "Soil_Dirt_Cold"
    },
    {
      "x": -10,
      "y": 3,
      "z": -11,
      "name": "Soil_Dirt_Cold"
    },
    {
      "x": -10,
      "y": 4,
      "z": -11,
      "name": "Soil_Dirt_Cold"
    },
    {
      "x": -10,
      "y": 5,
      "z": -11,
      "name": "Soil_Dirt_Cold"
    },
    {
      "x": -10,
      "y": 6,
      "z": -11,
      "name": "Soil_Dirt_Cold"
    },
    {
      "x": -10,
      "y": 7,
      "z": -11,
      "name": "Soil_Dirt_Cold"
    },
    {
      "x": -10,
      "y": 8,
      "z": -11,
      "name": "Soil_Dirt_Cold"
    },
    {
      "x": -10,
      "y": 9,
      "z": -11,
      "name": "Soil_Dirt_Cold"
    },
    {
      "x": -10,
      "y": 10,
      "z": -11,
      "name": "Soil_Dirt_Cold"
    },
    {
      "x": -10,
      "y": 11,
      "z": -11,
      "name": "Soil_Dirt_Cold"
    },
    {
      "x": -10,
      "y": 0,
      "z": -10,
      "name": "Soil_Dirt_Cold"
    },
    {
      "x": -10,
      "y": 1,
      "z": -10,
      "name": "Soil_Dirt_Cold"
    },
    {
      "x": -10,
      "y": 2,
      "z": -10,
      "name": "Soil_Dirt_Cold"
    },
    {
      "x": -10,
      "y": 3,
      "z": -10,
      "name": "Soil_Dirt_Cold"
    },
    {
      "x": -10,
      "y": 4,
      "z": -10,
      "name": "Soil_Dirt_Cold"
    },
    {
      "x": -10,
      "y": 5,
      "z": -10,
      "name": "Soil_Dirt_Cold"
    },
    {
      "x": -10,
      "y": 6,
      "z": -10,
      "name": "Soil_Dirt_Cold"
    },
    {
      "x": -10,
      "y": 7,
      "z": -10,
      "name": "Soil_Dirt_Cold"
    },
    {
      "x": -10,
      "y": 8,
      "z": -10,
      "name": "Soil_Dirt_Cold"
    },
    {
      "x": -10,
      "y": 9,
      "z": -10,
      "name": "Soil_Dirt_Cold"
    },
    {
      "x": -10,
      "y": 10,
      "z": -10,
      "name": "Soil_Dirt_Cold"
    },
    {
      "x": -10,
      "y": 11,
      "z": -10,
      "name": "Soil_Dirt_Cold"
    },
    {
      "x": -10,
      "y": 13,
      "z": -10,
      "name": "Wood_Torch_Wall",
      "rotation": 1
    },
    {
      "x": -10,
      "y": 0,
      "z": -9,
      "name": "Soil_Dirt_Cold"
    },
    {
      "x": -10,
      "y": 1,
      "z": -9,
      "name": "Soil_Dirt_Cold"
    },
    {
      "x": -10,
      "y": 2,
      "z": -9,
      "name": "Soil_Dirt_Cold"
    },
    {
      "x": -10,
      "y": 3,
      "z": -9,
      "name": "Soil_Dirt_Cold"
    },
    {
      "x": -10,
      "y": 4,
      "z": -9,
      "name": "Soil_Dirt_Cold"
    },
    {
      "x": -10,
      "y": 5,
      "z": -9,
      "name": "Soil_Dirt_Cold"
    },
    {
      "x": -10,
      "y": 6,
      "z": -9,
      "name": "Soil_Dirt_Cold"
    },
    {
      "x": -10,
      "y": 7,
      "z": -9,
      "name": "Soil_Dirt_Cold"
    },
    {
      "x": -10,
      "y": 8,
      "z": -9,
      "name": "Soil_Dirt_Cold"
    },
    {
      "x": -10,
      "y": 9,
      "z": -9,
      "name": "Soil_Dirt_Cold"
    },
    {
      "x": -10,
      "y": 10,
      "z": -9,
      "name": "Soil_Dirt_Cold"
    },
    {
      "x": -10,
      "y": 11,
      "z": -9,
      "name": "Soil_Dirt_Cold"
    },
    {
      "x": -10,
      "y": 0,
      "z": -8,
      "name": "Soil_Dirt_Cold"
    },
    {
      "x": -10,
      "y": 1,
      "z": -8,
      "name": "Soil_Dirt_Cold"
    },
    {
      "x": -10,
      "y": 2,
      "z": -8,
      "name": "Soil_Dirt_Cold"
    },
    {
      "x": -10,
      "y": 3,
      "z": -8,
      "name": "Soil_Dirt_Cold"
    },
    {
      "x": -10,
      "y": 4,
      "z": -8,
      "name": "Soil_Dirt_Cold"
    },
    {
      "x": -10,
      "y": 5,
      "z": -8,
      "name": "Soil_Dirt_Cold"
    },
    {
      "x": -10,
      "y": 6,
      "z": -8,
      "name": "Soil_Dirt_Cold"
    },
    {
      "x": -10,
      "y": 7,
      "z": -8,
      "name": "Soil_Dirt_Cold"
    },
    {
      "x": -10,
      "y": 8,
      "z": -8,
      "name": "Soil_Dirt_Cold"
    },
    {
      "x": -10,
      "y": 9,
      "z": -8,
      "name": "Soil_Dirt_Cold"
    },
    {
      "x": -10,
      "y": 10,
      "z": -8,
      "name": "Soil_Dirt_Cold"
    },
    {
      "x": -10,
      "y": 11,
      "z": -8,
      "name": "Soil_Pebbles_Frozen"
    },
    {
      "x": -10,
      "y": 0,
      "z": -7,
      "name": "Soil_Dirt_Cold"
    },
    {
      "x": -10,
      "y": 1,
      "z": -7,
      "name": "Soil_Dirt_Cold"
    },
    {
      "x": -10,
      "y": 2,
      "z": -7,
      "name": "Soil_Dirt_Cold"
    },
    {
      "x": -10,
      "y": 3,
      "z": -7,
      "name": "Soil_Dirt_Cold"
    },
    {
      "x": -10,
      "y": 4,
      "z": -7,
      "name": "Soil_Dirt_Cold"
    },
    {
      "x": -10,
      "y": 5,
      "z": -7,
      "name": "Soil_Dirt_Cold"
    },
    {
      "x": -10,
      "y": 6,
      "z": -7,
      "name": "Soil_Dirt_Cold"
    },
    {
      "x": -10,
      "y": 7,
      "z": -7,
      "name": "Soil_Dirt_Cold"
    },
    {
      "x": -10,
      "y": 8,
      "z": -7,
      "name": "Soil_Dirt_Cold"
    },
    {
      "x": -10,
      "y": 9,
      "z": -7,
      "name": "Soil_Dirt_Cold"
    },
    {
      "x": -10,
      "y": 10,
      "z": -7,
      "name": "Soil_Dirt_Cold"
    },
    {
      "x": -10,
      "y": 11,
      "z": -7,
      "name": "Soil_Dirt_Cold"
    },
    {
      "x": -10,
      "y": 0,
      "z": -6,
      "name": "Soil_Dirt_Cold"
    },
    {
      "x": -10,
      "y": 1,
      "z": -6,
      "name": "Soil_Dirt_Cold"
    },
    {
      "x": -10,
      "y": 2,
      "z": -6,
      "name": "Soil_Dirt_Cold"
    },
    {
      "x": -10,
      "y": 3,
      "z": -6,
      "name": "Soil_Dirt_Cold"
    },
    {
      "x": -10,
      "y": 4,
      "z": -6,
      "name": "Soil_Dirt_Cold"
    },
    {
      "x": -10,
      "y": 5,
      "z": -6,
      "name": "Soil_Dirt_Cold"
    },
    {
      "x": -10,
      "y": 6,
      "z": -6,
      "name": "Soil_Dirt_Cold"
    },
    {
      "x": -10,
      "y": 7,
      "z": -6,
      "name": "Soil_Dirt_Cold"
    },
    {
      "x": -10,
      "y": 8,
      "z": -6,
      "name": "Soil_Dirt_Cold"
    },
    {
      "x": -10,
      "y": 9,
      "z": -6,
      "name": "Soil_Dirt_Cold"
    },
    {
      "x": -10,
      "y": 10,
      "z": -6,
      "name": "Soil_Dirt_Cold"
    },
    {
      "x": -10,
      "y": 11,
      "z": -6,
      "name": "Soil_Pebbles_Frozen"
    },
    {
      "x": -10,
      "y": 0,
      "z": -5,
      "name": "Soil_Dirt_Cold"
    },
    {
      "x": -10,
      "y": 1,
      "z": -5,
      "name": "Soil_Dirt_Cold"
    },
    {
      "x": -10,
      "y": 2,
      "z": -5,
      "name": "Soil_Dirt_Cold"
    },
    {
      "x": -10,
      "y": 3,
      "z": -5,
      "name": "Soil_Dirt_Cold"
    },
    {
      "x": -10,
      "y": 4,
      "z": -5,
      "name": "Soil_Dirt_Cold"
    },
    {
      "x": -10,
      "y": 5,
      "z": -5,
      "name": "Soil_Dirt_Cold"
    },
    {
      "x": -10,
      "y": 6,
      "z": -5,
      "name": "Soil_Dirt_Cold"
    },
    {
      "x": -10,
      "y": 7,
      "z": -5,
      "name": "Soil_Dirt_Cold"
    },
    {
      "x": -10,
      "y": 8,
      "z": -5,
      "name": "Soil_Dirt_Cold"
    },
    {
      "x": -10,
      "y": 9,
      "z": -5,
      "name": "Soil_Dirt_Cold"
    },
    {
      "x": -10,
      "y": 10,
      "z": -5,
      "name": "Soil_Dirt_Cold"
    },
    {
      "x": -10,
      "y": 11,
      "z": -5,
      "name": "Wood_Fir_Trunk",
      "support": 15,
      "rotation": 4
    },
    {
      "x": -10,
      "y": 0,
      "z": -4,
      "name": "Soil_Dirt_Cold"
    },
    {
      "x": -10,
      "y": 1,
      "z": -4,
      "name": "Soil_Dirt_Cold"
    },
    {
      "x": -10,
      "y": 2,
      "z": -4,
      "name": "Soil_Dirt_Cold"
    },
    {
      "x": -10,
      "y": 3,
      "z": -4,
      "name": "Soil_Dirt_Cold"
    },
    {
      "x": -10,
      "y": 4,
      "z": -4,
      "name": "Soil_Dirt_Cold"
    },
    {
      "x": -10,
      "y": 5,
      "z": -4,
      "name": "Soil_Dirt_Cold"
    },
    {
      "x": -10,
      "y": 6,
      "z": -4,
      "name": "Soil_Dirt_Cold"
    },
    {
      "x": -10,
      "y": 7,
      "z": -4,
      "name": "Soil_Dirt_Cold"
    },
    {
      "x": -10,
      "y": 8,
      "z": -4,
      "name": "Soil_Dirt_Cold"
    },
    {
      "x": -10,
      "y": 9,
      "z": -4,
      "name": "Soil_Dirt_Cold"
    },
    {
      "x": -10,
      "y": 10,
      "z": -4,
      "name": "Soil_Dirt_Cold"
    },
    {
      "x": -10,
      "y": 11,
      "z": -4,
      "name": "Wood_Fir_Trunk",
      "support": 15,
      "rotation": 4
    },
    {
      "x": -10,
      "y": 0,
      "z": -3,
      "name": "Soil_Dirt_Cold"
    },
    {
      "x": -10,
      "y": 1,
      "z": -3,
      "name": "Soil_Dirt_Cold"
    },
    {
      "x": -10,
      "y": 2,
      "z": -3,
      "name": "Soil_Dirt_Cold"
    },
    {
      "x": -10,
      "y": 3,
      "z": -3,
      "name": "Soil_Dirt_Cold"
    },
    {
      "x": -10,
      "y": 4,
      "z": -3,
      "name": "Soil_Dirt_Cold"
    },
    {
      "x": -10,
      "y": 5,
      "z": -3,
      "name": "Soil_Dirt_Cold"
    },
    {
      "x": -10,
      "y": 6,
      "z": -3,
      "name": "Soil_Dirt_Cold"
    },
    {
      "x": -10,
      "y": 7,
      "z": -3,
      "name": "Soil_Dirt_Cold"
    },
    {
      "x": -10,
      "y": 8,
      "z": -3,
      "name": "Soil_Dirt_Cold"
    },
    {
      "x": -10,
      "y": 9,
      "z": -3,
      "name": "Soil_Dirt_Cold"
    },
    {
      "x": -10,
      "y": 10,
      "z": -3,
      "name": "Soil_Dirt_Cold"
    },
    {
      "x": -10,
      "y": 11,
      "z": -3,
      "name": "Wood_Fir_Trunk",
      "support": 15,
      "rotation": 4
    },
    {
      "x": -10,
      "y": 0,
      "z": -2,
      "name": "Soil_Dirt_Cold"
    },
    {
      "x": -10,
      "y": 1,
      "z": -2,
      "name": "Soil_Dirt_Cold"
    },
    {
      "x": -10,
      "y": 2,
      "z": -2,
      "name": "Soil_Dirt_Cold"
    },
    {
      "x": -10,
      "y": 3,
      "z": -2,
      "name": "Soil_Dirt_Cold"
    },
    {
      "x": -10,
      "y": 4,
      "z": -2,
      "name": "Soil_Dirt_Cold"
    },
    {
      "x": -10,
      "y": 5,
      "z": -2,
      "name": "Soil_Dirt_Cold"
    },
    {
      "x": -10,
      "y": 6,
      "z": -2,
      "name": "Soil_Dirt_Cold"
    },
    {
      "x": -10,
      "y": 7,
      "z": -2,
      "name": "Soil_Dirt_Cold"
    },
    {
      "x": -10,
      "y": 8,
      "z": -2,
      "name": "Soil_Dirt_Cold"
    },
    {
      "x": -10,
      "y": 9,
      "z": -2,
      "name": "Soil_Dirt_Cold"
    },
    {
      "x": -10,
      "y": 10,
      "z": -2,
      "name": "Soil_Dirt_Cold"
    },
    {
      "x": -10,
      "y": 11,
      "z": -2,
      "name": "Soil_Pebbles_Frozen"
    },
    {
      "x": -10,
      "y": 0,
      "z": -1,
      "name": "Soil_Dirt_Cold"
    },
    {
      "x": -10,
      "y": 1,
      "z": -1,
      "name": "Soil_Dirt_Cold"
    },
    {
      "x": -10,
      "y": 2,
      "z": -1,
      "name": "Soil_Dirt_Cold"
    },
    {
      "x": -10,
      "y": 3,
      "z": -1,
      "name": "Soil_Dirt_Cold"
    },
    {
      "x": -10,
      "y": 4,
      "z": -1,
      "name": "Soil_Dirt_Cold"
    },
    {
      "x": -10,
      "y": 5,
      "z": -1,
      "name": "Soil_Dirt_Cold"
    },
    {
      "x": -10,
      "y": 6,
      "z": -1,
      "name": "Soil_Dirt_Cold"
    },
    {
      "x": -10,
      "y": 7,
      "z": -1,
      "name": "Soil_Dirt_Cold"
    },
    {
      "x": -10,
      "y": 8,
      "z": -1,
      "name": "Soil_Dirt_Cold"
    },
    {
      "x": -10,
      "y": 9,
      "z": -1,
      "name": "Soil_Dirt_Cold"
    },
    {
      "x": -10,
      "y": 10,
      "z": -1,
      "name": "Soil_Dirt_Cold"
    },
    {
      "x": -10,
      "y": 11,
      "z": -1,
      "name": "Soil_Pebbles_Frozen"
    },
    {
      "x": -10,
      "y": 0,
      "z": 0,
      "name": "Soil_Dirt_Cold"
    },
    {
      "x": -10,
      "y": 1,
      "z": 0,
      "name": "Soil_Dirt_Cold"
    },
    {
      "x": -10,
      "y": 2,
      "z": 0,
      "name": "Soil_Dirt_Cold"
    },
    {
      "x": -10,
      "y": 3,
      "z": 0,
      "name": "Soil_Dirt_Cold"
    },
    {
      "x": -10,
      "y": 4,
      "z": 0,
      "name": "Soil_Dirt_Cold"
    },
    {
      "x": -10,
      "y": 5,
      "z": 0,
      "name": "Soil_Dirt_Cold"
    },
    {
      "x": -10,
      "y": 6,
      "z": 0,
      "name": "Soil_Dirt_Cold"
    },
    {
      "x": -10,
      "y": 7,
      "z": 0,
      "name": "Soil_Dirt_Cold"
    },
    {
      "x": -10,
      "y": 8,
      "z": 0,
      "name": "Soil_Dirt_Cold"
    },
    {
      "x": -10,
      "y": 9,
      "z": 0,
      "name": "Soil_Dirt_Cold"
    },
    {
      "x": -10,
      "y": 10,
      "z": 0,
      "name": "Soil_Dirt_Cold"
    },
    {
      "x": -10,
      "y": 11,
      "z": 0,
      "name": "Soil_Dirt_Cold"
    },
    {
      "x": -10,
      "y": 0,
      "z": 1,
      "name": "Wood_Fir_Trunk",
      "support": 15
    },
    {
      "x": -10,
      "y": 1,
      "z": 1,
      "name": "Wood_Fir_Trunk",
      "support": 15
    },
    {
      "x": -10,
      "y": 2,
      "z": 1,
      "name": "Wood_Fir_Trunk",
      "support": 15
    },
    {
      "x": -10,
      "y": 3,
      "z": 1,
      "name": "Wood_Fir_Trunk",
      "support": 15
    },
    {
      "x": -10,
      "y": 4,
      "z": 1,
      "name": "Wood_Fir_Trunk",
      "support": 15
    },
    {
      "x": -10,
      "y": 5,
      "z": 1,
      "name": "Wood_Fir_Trunk",
      "support": 15
    },
    {
      "x": -10,
      "y": 6,
      "z": 1,
      "name": "Wood_Fir_Trunk",
      "support": 15
    },
    {
      "x": -10,
      "y": 7,
      "z": 1,
      "name": "Wood_Fir_Trunk",
      "support": 15
    },
    {
      "x": -10,
      "y": 8,
      "z": 1,
      "name": "Wood_Fir_Trunk",
      "support": 15
    },
    {
      "x": -10,
      "y": 9,
      "z": 1,
      "name": "Wood_Fir_Trunk",
      "support": 15
    },
    {
      "x": -10,
      "y": 10,
      "z": 1,
      "name": "Wood_Fir_Trunk",
      "support": 15
    },
    {
      "x": -10,
      "y": 11,
      "z": 1,
      "name": "Wood_Fir_Trunk",
      "support": 15
    },
    {
      "x": -10,
      "y": 12,
      "z": 1,
      "name": "Wood_Fir_Trunk",
      "support": 15
    },
    {
      "x": -10,
      "y": 13,
      "z": 1,
      "name": "Wood_Fir_Branch_Long",
      "support": 15
    },
    {
      "x": -10,
      "y": 14,
      "z": 1,
      "name": "Survival_Trap_Spike_Wood_Large"
    },
    {
      "x": -10,
      "y": 0,
      "z": 2,
      "name": "Wood_Fir_Trunk",
      "support": 15
    },
    {
      "x": -10,
      "y": 1,
      "z": 2,
      "name": "Wood_Fir_Trunk",
      "support": 15
    },
    {
      "x": -10,
      "y": 2,
      "z": 2,
      "name": "Wood_Fir_Trunk",
      "support": 15
    },
    {
      "x": -10,
      "y": 3,
      "z": 2,
      "name": "Wood_Fir_Trunk",
      "support": 15
    },
    {
      "x": -10,
      "y": 4,
      "z": 2,
      "name": "Wood_Fir_Trunk",
      "support": 15
    },
    {
      "x": -10,
      "y": 5,
      "z": 2,
      "name": "Wood_Fir_Trunk",
      "support": 15
    },
    {
      "x": -10,
      "y": 6,
      "z": 2,
      "name": "Wood_Fir_Trunk",
      "support": 15
    },
    {
      "x": -10,
      "y": 7,
      "z": 2,
      "name": "Wood_Fir_Trunk",
      "support": 15
    },
    {
      "x": -10,
      "y": 8,
      "z": 2,
      "name": "Wood_Fir_Trunk",
      "support": 15
    },
    {
      "x": -10,
      "y": 9,
      "z": 2,
      "name": "Wood_Fir_Trunk",
      "support": 15
    },
    {
      "x": -10,
      "y": 10,
      "z": 2,
      "name": "Wood_Fir_Trunk",
      "support": 15
    },
    {
      "x": -10,
      "y": 11,
      "z": 2,
      "name": "Wood_Fir_Trunk",
      "support": 15
    },
    {
      "x": -10,
      "y": 0,
      "z": 3,
      "name": "Wood_Fir_Trunk",
      "support": 15
    },
    {
      "x": -10,
      "y": 1,
      "z": 3,
      "name": "Wood_Fir_Trunk",
      "support": 15
    },
    {
      "x": -10,
      "y": 2,
      "z": 3,
      "name": "Wood_Fir_Trunk",
      "support": 15
    },
    {
      "x": -10,
      "y": 3,
      "z": 3,
      "name": "Wood_Fir_Trunk",
      "support": 15
    },
    {
      "x": -10,
      "y": 4,
      "z": 3,
      "name": "Wood_Fir_Trunk",
      "support": 15
    },
    {
      "x": -10,
      "y": 5,
      "z": 3,
      "name": "Wood_Fir_Trunk",
      "support": 15
    },
    {
      "x": -10,
      "y": 6,
      "z": 3,
      "name": "Wood_Fir_Trunk",
      "support": 15
    },
    {
      "x": -10,
      "y": 7,
      "z": 3,
      "name": "Wood_Fir_Trunk",
      "support": 15
    },
    {
      "x": -10,
      "y": 8,
      "z": 3,
      "name": "Wood_Fir_Trunk",
      "support": 15
    },
    {
      "x": -10,
      "y": 9,
      "z": 3,
      "name": "Wood_Fir_Trunk",
      "support": 15
    },
    {
      "x": -10,
      "y": 10,
      "z": 3,
      "name": "Wood_Fir_Trunk",
      "support": 15
    },
    {
      "x": -10,
      "y": 11,
      "z": 3,
      "name": "Wood_Fir_Trunk",
      "support": 15
    },
    {
      "x": -10,
      "y": 12,
      "z": 3,
      "name": "Wood_Fir_Trunk",
      "support": 15
    },
    {
      "x": -10,
      "y": 13,
      "z": 3,
      "name": "Wood_Fir_Trunk",
      "support": 15
    },
    {
      "x": -10,
      "y": 0,
      "z": 4,
      "name": "Wood_Fir_Trunk",
      "support": 15
    },
    {
      "x": -10,
      "y": 1,
      "z": 4,
      "name": "Wood_Fir_Trunk",
      "support": 15
    },
    {
      "x": -10,
      "y": 2,
      "z": 4,
      "name": "Wood_Fir_Trunk",
      "support": 15
    },
    {
      "x": -10,
      "y": 3,
      "z": 4,
      "name": "Wood_Fir_Trunk",
      "support": 15
    },
    {
      "x": -10,
      "y": 4,
      "z": 4,
      "name": "Wood_Fir_Trunk",
      "support": 15
    },
    {
      "x": -10,
      "y": 5,
      "z": 4,
      "name": "Wood_Fir_Trunk",
      "support": 15
    },
    {
      "x": -10,
      "y": 6,
      "z": 4,
      "name": "Wood_Fir_Trunk",
      "support": 15
    },
    {
      "x": -10,
      "y": 7,
      "z": 4,
      "name": "Wood_Fir_Trunk",
      "support": 15
    },
    {
      "x": -10,
      "y": 8,
      "z": 4,
      "name": "Wood_Fir_Trunk",
      "support": 15
    },
    {
      "x": -10,
      "y": 9,
      "z": 4,
      "name": "Wood_Fir_Trunk",
      "support": 15
    },
    {
      "x": -10,
      "y": 10,
      "z": 4,
      "name": "Wood_Fir_Trunk",
      "support": 15
    },
    {
      "x": -10,
      "y": 11,
      "z": 4,
      "name": "Wood_Fir_Trunk",
      "support": 15
    },
    {
      "x": -10,
      "y": 12,
      "z": 4,
      "name": "Wood_Fir_Trunk",
      "support": 15
    },
    {
      "x": -10,
      "y": 13,
      "z": 4,
      "name": "Wood_Fir_Trunk",
      "support": 15
    },
    {
      "x": -10,
      "y": 14,
      "z": 4,
      "name": "Wood_Fir_Trunk",
      "support": 15
    },
    {
      "x": -10,
      "y": 15,
      "z": 4,
      "name": "Wood_Fir_Branch_Long",
      "support": 15
    },
    {
      "x": -10,
      "y": 16,
      "z": 4,
      "name": "Survival_Trap_Spike_Wood_Large"
    },
    {
      "x": -10,
      "y": 0,
      "z": 5,
      "name": "Soil_Dirt_Cold"
    },
    {
      "x": -10,
      "y": 1,
      "z": 5,
      "name": "Soil_Dirt_Cold"
    },
    {
      "x": -10,
      "y": 2,
      "z": 5,
      "name": "Soil_Dirt_Cold"
    },
    {
      "x": -10,
      "y": 3,
      "z": 5,
      "name": "Soil_Dirt_Cold"
    },
    {
      "x": -10,
      "y": 4,
      "z": 5,
      "name": "Soil_Dirt_Cold"
    },
    {
      "x": -10,
      "y": 5,
      "z": 5,
      "name": "Soil_Dirt_Cold"
    },
    {
      "x": -10,
      "y": 6,
      "z": 5,
      "name": "Soil_Dirt_Cold"
    },
    {
      "x": -10,
      "y": 7,
      "z": 5,
      "name": "Soil_Dirt_Cold"
    },
    {
      "x": -10,
      "y": 8,
      "z": 5,
      "name": "Soil_Dirt_Cold"
    },
    {
      "x": -10,
      "y": 9,
      "z": 5,
      "name": "Soil_Dirt_Cold"
    },
    {
      "x": -10,
      "y": 10,
      "z": 5,
      "name": "Soil_Dirt_Cold"
    },
    {
      "x": -10,
      "y": 11,
      "z": 5,
      "name": "Soil_Dirt_Cold"
    },
    {
      "x": -10,
      "y": 12,
      "z": 5,
      "name": "Rubble_Shale_Medium"
    },
    {
      "x": -10,
      "y": 0,
      "z": 6,
      "name": "Soil_Dirt_Cold"
    },
    {
      "x": -10,
      "y": 1,
      "z": 6,
      "name": "Soil_Dirt_Cold"
    },
    {
      "x": -10,
      "y": 2,
      "z": 6,
      "name": "Soil_Dirt_Cold"
    },
    {
      "x": -10,
      "y": 3,
      "z": 6,
      "name": "Soil_Dirt_Cold"
    },
    {
      "x": -10,
      "y": 4,
      "z": 6,
      "name": "Soil_Dirt_Cold"
    },
    {
      "x": -10,
      "y": 5,
      "z": 6,
      "name": "Soil_Dirt_Cold"
    },
    {
      "x": -10,
      "y": 6,
      "z": 6,
      "name": "Soil_Dirt_Cold"
    },
    {
      "x": -10,
      "y": 7,
      "z": 6,
      "name": "Soil_Dirt_Cold"
    },
    {
      "x": -10,
      "y": 8,
      "z": 6,
      "name": "Soil_Dirt_Cold"
    },
    {
      "x": -10,
      "y": 9,
      "z": 6,
      "name": "Soil_Dirt_Cold"
    },
    {
      "x": -10,
      "y": 10,
      "z": 6,
      "name": "Soil_Dirt_Cold"
    },
    {
      "x": -10,
      "y": 11,
      "z": 6,
      "name": "Soil_Dirt_Cold"
    },
    {
      "x": -10,
      "y": 12,
      "z": 6,
      "name": "Rubble_Shale"
    },
    {
      "x": -10,
      "y": 0,
      "z": 7,
      "name": "Soil_Dirt_Cold"
    },
    {
      "x": -10,
      "y": 1,
      "z": 7,
      "name": "Soil_Dirt_Cold"
    },
    {
      "x": -10,
      "y": 2,
      "z": 7,
      "name": "Soil_Dirt_Cold"
    },
    {
      "x": -10,
      "y": 3,
      "z": 7,
      "name": "Soil_Dirt_Cold"
    },
    {
      "x": -10,
      "y": 4,
      "z": 7,
      "name": "Soil_Dirt_Cold"
    },
    {
      "x": -10,
      "y": 5,
      "z": 7,
      "name": "Soil_Dirt_Cold"
    },
    {
      "x": -10,
      "y": 6,
      "z": 7,
      "name": "Soil_Dirt_Cold"
    },
    {
      "x": -10,
      "y": 7,
      "z": 7,
      "name": "Soil_Dirt_Cold"
    },
    {
      "x": -10,
      "y": 8,
      "z": 7,
      "name": "Soil_Dirt_Cold"
    },
    {
      "x": -10,
      "y": 9,
      "z": 7,
      "name": "Soil_Dirt_Cold"
    },
    {
      "x": -10,
      "y": 10,
      "z": 7,
      "name": "Soil_Dirt_Cold"
    },
    {
      "x": -10,
      "y": 11,
      "z": 7,
      "name": "Soil_Dirt_Cold"
    },
    {
      "x": -10,
      "y": 0,
      "z": 8,
      "name": "Soil_Dirt_Cold"
    },
    {
      "x": -10,
      "y": 1,
      "z": 8,
      "name": "Soil_Dirt_Cold"
    },
    {
      "x": -10,
      "y": 2,
      "z": 8,
      "name": "Soil_Dirt_Cold"
    },
    {
      "x": -10,
      "y": 3,
      "z": 8,
      "name": "Soil_Dirt_Cold"
    },
    {
      "x": -10,
      "y": 4,
      "z": 8,
      "name": "Soil_Dirt_Cold"
    },
    {
      "x": -10,
      "y": 5,
      "z": 8,
      "name": "Soil_Dirt_Cold"
    },
    {
      "x": -10,
      "y": 6,
      "z": 8,
      "name": "Soil_Dirt_Cold"
    },
    {
      "x": -10,
      "y": 7,
      "z": 8,
      "name": "Soil_Dirt_Cold"
    },
    {
      "x": -10,
      "y": 8,
      "z": 8,
      "name": "Soil_Dirt_Cold"
    },
    {
      "x": -10,
      "y": 9,
      "z": 8,
      "name": "Soil_Dirt_Cold"
    },
    {
      "x": -10,
      "y": 10,
      "z": 8,
      "name": "Soil_Dirt_Cold"
    },
    {
      "x": -10,
      "y": 11,
      "z": 8,
      "name": "Soil_Dirt_Cold"
    },
    {
      "x": -10,
      "y": 0,
      "z": 9,
      "name": "Soil_Dirt_Cold"
    },
    {
      "x": -10,
      "y": 1,
      "z": 9,
      "name": "Soil_Dirt_Cold"
    },
    {
      "x": -10,
      "y": 2,
      "z": 9,
      "name": "Soil_Dirt_Cold"
    },
    {
      "x": -10,
      "y": 3,
      "z": 9,
      "name": "Soil_Dirt_Cold"
    },
    {
      "x": -10,
      "y": 4,
      "z": 9,
      "name": "Soil_Dirt_Cold"
    },
    {
      "x": -10,
      "y": 5,
      "z": 9,
      "name": "Soil_Dirt_Cold"
    },
    {
      "x": -10,
      "y": 6,
      "z": 9,
      "name": "Soil_Dirt_Cold"
    },
    {
      "x": -10,
      "y": 7,
      "z": 9,
      "name": "Soil_Dirt_Cold"
    },
    {
      "x": -10,
      "y": 8,
      "z": 9,
      "name": "Soil_Dirt_Cold"
    },
    {
      "x": -10,
      "y": 9,
      "z": 9,
      "name": "Soil_Dirt_Cold"
    },
    {
      "x": -10,
      "y": 10,
      "z": 9,
      "name": "Soil_Dirt_Cold"
    },
    {
      "x": -10,
      "y": 11,
      "z": 9,
      "name": "Soil_Dirt_Cold"
    },
    {
      "x": -10,
      "y": 0,
      "z": 10,
      "name": "Soil_Dirt_Cold"
    },
    {
      "x": -10,
      "y": 1,
      "z": 10,
      "name": "Soil_Dirt_Cold"
    },
    {
      "x": -10,
      "y": 2,
      "z": 10,
      "name": "Soil_Dirt_Cold"
    },
    {
      "x": -10,
      "y": 3,
      "z": 10,
      "name": "Soil_Dirt_Cold"
    },
    {
      "x": -10,
      "y": 4,
      "z": 10,
      "name": "Soil_Dirt_Cold"
    },
    {
      "x": -10,
      "y": 5,
      "z": 10,
      "name": "Soil_Dirt_Cold"
    },
    {
      "x": -10,
      "y": 6,
      "z": 10,
      "name": "Soil_Dirt_Cold"
    },
    {
      "x": -10,
      "y": 7,
      "z": 10,
      "name": "Soil_Dirt_Cold"
    },
    {
      "x": -10,
      "y": 8,
      "z": 10,
      "name": "Soil_Dirt_Cold"
    },
    {
      "x": -10,
      "y": 9,
      "z": 10,
      "name": "Soil_Dirt_Cold"
    },
    {
      "x": -10,
      "y": 10,
      "z": 10,
      "name": "Soil_Dirt_Cold"
    },
    {
      "x": -10,
      "y": 11,
      "z": 10,
      "name": "Soil_Dirt_Cold"
    },
    {
      "x": -10,
      "y": 0,
      "z": 11,
      "name": "Wood_Fir_Trunk",
      "support": 15
    },
    {
      "x": -10,
      "y": 1,
      "z": 11,
      "name": "Wood_Fir_Trunk",
      "support": 15
    },
    {
      "x": -10,
      "y": 2,
      "z": 11,
      "name": "Wood_Fir_Trunk",
      "support": 15
    },
    {
      "x": -10,
      "y": 3,
      "z": 11,
      "name": "Wood_Fir_Trunk",
      "support": 15
    },
    {
      "x": -10,
      "y": 4,
      "z": 11,
      "name": "Wood_Fir_Trunk",
      "support": 15
    },
    {
      "x": -10,
      "y": 5,
      "z": 11,
      "name": "Wood_Fir_Trunk",
      "support": 15
    },
    {
      "x": -10,
      "y": 6,
      "z": 11,
      "name": "Wood_Fir_Trunk",
      "support": 15
    },
    {
      "x": -10,
      "y": 7,
      "z": 11,
      "name": "Wood_Fir_Trunk",
      "support": 15
    },
    {
      "x": -10,
      "y": 8,
      "z": 11,
      "name": "Wood_Fir_Trunk",
      "support": 15
    },
    {
      "x": -10,
      "y": 9,
      "z": 11,
      "name": "Wood_Fir_Trunk",
      "support": 15
    },
    {
      "x": -10,
      "y": 10,
      "z": 11,
      "name": "Wood_Fir_Trunk",
      "support": 15
    },
    {
      "x": -10,
      "y": 11,
      "z": 11,
      "name": "Wood_Fir_Trunk",
      "support": 15
    },
    {
      "x": -9,
      "y": 0,
      "z": -13,
      "name": "Wood_Fir_Trunk",
      "support": 15
    },
    {
      "x": -9,
      "y": 1,
      "z": -13,
      "name": "Wood_Fir_Trunk",
      "support": 15
    },
    {
      "x": -9,
      "y": 2,
      "z": -13,
      "name": "Wood_Fir_Trunk",
      "support": 15
    },
    {
      "x": -9,
      "y": 3,
      "z": -13,
      "name": "Wood_Fir_Trunk",
      "support": 15
    },
    {
      "x": -9,
      "y": 4,
      "z": -13,
      "name": "Wood_Fir_Trunk",
      "support": 15
    },
    {
      "x": -9,
      "y": 5,
      "z": -13,
      "name": "Wood_Fir_Trunk",
      "support": 15
    },
    {
      "x": -9,
      "y": 6,
      "z": -13,
      "name": "Wood_Fir_Trunk",
      "support": 15
    },
    {
      "x": -9,
      "y": 7,
      "z": -13,
      "name": "Wood_Fir_Trunk",
      "support": 15
    },
    {
      "x": -9,
      "y": 8,
      "z": -13,
      "name": "Wood_Fir_Trunk",
      "support": 15
    },
    {
      "x": -9,
      "y": 9,
      "z": -13,
      "name": "Wood_Fir_Trunk",
      "support": 15
    },
    {
      "x": -9,
      "y": 10,
      "z": -13,
      "name": "Wood_Fir_Trunk",
      "support": 15
    },
    {
      "x": -9,
      "y": 11,
      "z": -13,
      "name": "Wood_Fir_Trunk",
      "support": 15
    },
    {
      "x": -9,
      "y": 12,
      "z": -13,
      "name": "Wood_Fir_Trunk",
      "support": 15
    },
    {
      "x": -9,
      "y": 13,
      "z": -13,
      "name": "Wood_Fir_Trunk",
      "support": 15
    },
    {
      "x": -9,
      "y": 0,
      "z": -12,
      "name": "Soil_Dirt_Cold"
    },
    {
      "x": -9,
      "y": 1,
      "z": -12,
      "name": "Soil_Dirt_Cold"
    },
    {
      "x": -9,
      "y": 2,
      "z": -12,
      "name": "Soil_Dirt_Cold"
    },
    {
      "x": -9,
      "y": 3,
      "z": -12,
      "name": "Soil_Dirt_Cold"
    },
    {
      "x": -9,
      "y": 4,
      "z": -12,
      "name": "Soil_Dirt_Cold"
    },
    {
      "x": -9,
      "y": 5,
      "z": -12,
      "name": "Soil_Dirt_Cold"
    },
    {
      "x": -9,
      "y": 6,
      "z": -12,
      "name": "Soil_Dirt_Cold"
    },
    {
      "x": -9,
      "y": 7,
      "z": -12,
      "name": "Soil_Dirt_Cold"
    },
    {
      "x": -9,
      "y": 8,
      "z": -12,
      "name": "Soil_Dirt_Cold"
    },
    {
      "x": -9,
      "y": 9,
      "z": -12,
      "name": "Soil_Dirt_Cold"
    },
    {
      "x": -9,
      "y": 10,
      "z": -12,
      "name": "Soil_Dirt_Cold"
    },
    {
      "x": -9,
      "y": 11,
      "z": -12,
      "name": "Soil_Dirt_Cold"
    },
    {
      "x": -9,
      "y": 12,
      "z": -12,
      "name": "Furniture_Ancient_Barrel"
    },
    {
      "x": -9,
      "y": 0,
      "z": -11,
      "name": "Soil_Dirt_Cold"
    },
    {
      "x": -9,
      "y": 1,
      "z": -11,
      "name": "Soil_Dirt_Cold"
    },
    {
      "x": -9,
      "y": 2,
      "z": -11,
      "name": "Soil_Dirt_Cold"
    },
    {
      "x": -9,
      "y": 3,
      "z": -11,
      "name": "Soil_Dirt_Cold"
    },
    {
      "x": -9,
      "y": 4,
      "z": -11,
      "name": "Soil_Dirt_Cold"
    },
    {
      "x": -9,
      "y": 5,
      "z": -11,
      "name": "Soil_Dirt_Cold"
    },
    {
      "x": -9,
      "y": 6,
      "z": -11,
      "name": "Soil_Dirt_Cold"
    },
    {
      "x": -9,
      "y": 7,
      "z": -11,
      "name": "Soil_Dirt_Cold"
    },
    {
      "x": -9,
      "y": 8,
      "z": -11,
      "name": "Soil_Dirt_Cold"
    },
    {
      "x": -9,
      "y": 9,
      "z": -11,
      "name": "Soil_Dirt_Cold"
    },
    {
      "x": -9,
      "y": 10,
      "z": -11,
      "name": "Soil_Dirt_Cold"
    },
    {
      "x": -9,
      "y": 11,
      "z": -11,
      "name": "Soil_Dirt_Cold"
    },
    {
      "x": -9,
      "y": 0,
      "z": -10,
      "name": "Soil_Dirt_Cold"
    },
    {
      "x": -9,
      "y": 1,
      "z": -10,
      "name": "Soil_Dirt_Cold"
    },
    {
      "x": -9,
      "y": 2,
      "z": -10,
      "name": "Soil_Dirt_Cold"
    },
    {
      "x": -9,
      "y": 3,
      "z": -10,
      "name": "Soil_Dirt_Cold"
    },
    {
      "x": -9,
      "y": 4,
      "z": -10,
      "name": "Soil_Dirt_Cold"
    },
    {
      "x": -9,
      "y": 5,
      "z": -10,
      "name": "Soil_Dirt_Cold"
    },
    {
      "x": -9,
      "y": 6,
      "z": -10,
      "name": "Soil_Dirt_Cold"
    },
    {
      "x": -9,
      "y": 7,
      "z": -10,
      "name": "Soil_Dirt_Cold"
    },
    {
      "x": -9,
      "y": 8,
      "z": -10,
      "name": "Soil_Dirt_Cold"
    },
    {
      "x": -9,
      "y": 9,
      "z": -10,
      "name": "Soil_Dirt_Cold"
    },
    {
      "x": -9,
      "y": 10,
      "z": -10,
      "name": "Soil_Dirt_Cold"
    },
    {
      "x": -9,
      "y": 11,
      "z": -10,
      "name": "Soil_Dirt_Cold"
    },
    {
      "x": -9,
      "y": 0,
      "z": -9,
      "name": "Soil_Dirt_Cold"
    },
    {
      "x": -9,
      "y": 1,
      "z": -9,
      "name": "Soil_Dirt_Cold"
    },
    {
      "x": -9,
      "y": 2,
      "z": -9,
      "name": "Soil_Dirt_Cold"
    },
    {
      "x": -9,
      "y": 3,
      "z": -9,
      "name": "Soil_Dirt_Cold"
    },
    {
      "x": -9,
      "y": 4,
      "z": -9,
      "name": "Soil_Dirt_Cold"
    },
    {
      "x": -9,
      "y": 5,
      "z": -9,
      "name": "Soil_Dirt_Cold"
    },
    {
      "x": -9,
      "y": 6,
      "z": -9,
      "name": "Soil_Dirt_Cold"
    },
    {
      "x": -9,
      "y": 7,
      "z": -9,
      "name": "Soil_Dirt_Cold"
    },
    {
      "x": -9,
      "y": 8,
      "z": -9,
      "name": "Soil_Dirt_Cold"
    },
    {
      "x": -9,
      "y": 9,
      "z": -9,
      "name": "Soil_Dirt_Cold"
    },
    {
      "x": -9,
      "y": 10,
      "z": -9,
      "name": "Soil_Dirt_Cold"
    },
    {
      "x": -9,
      "y": 11,
      "z": -9,
      "name": "Soil_Dirt_Cold"
    },
    {
      "x": -9,
      "y": 0,
      "z": -8,
      "name": "Soil_Dirt_Cold"
    },
    {
      "x": -9,
      "y": 1,
      "z": -8,
      "name": "Soil_Dirt_Cold"
    },
    {
      "x": -9,
      "y": 2,
      "z": -8,
      "name": "Soil_Dirt_Cold"
    },
    {
      "x": -9,
      "y": 3,
      "z": -8,
      "name": "Soil_Dirt_Cold"
    },
    {
      "x": -9,
      "y": 4,
      "z": -8,
      "name": "Soil_Dirt_Cold"
    },
    {
      "x": -9,
      "y": 5,
      "z": -8,
      "name": "Soil_Dirt_Cold"
    },
    {
      "x": -9,
      "y": 6,
      "z": -8,
      "name": "Soil_Dirt_Cold"
    },
    {
      "x": -9,
      "y": 7,
      "z": -8,
      "name": "Soil_Dirt_Cold"
    },
    {
      "x": -9,
      "y": 8,
      "z": -8,
      "name": "Soil_Dirt_Cold"
    },
    {
      "x": -9,
      "y": 9,
      "z": -8,
      "name": "Soil_Dirt_Cold"
    },
    {
      "x": -9,
      "y": 10,
      "z": -8,
      "name": "Soil_Dirt_Cold"
    },
    {
      "x": -9,
      "y": 11,
      "z": -8,
      "name": "Soil_Dirt_Cold"
    },
    {
      "x": -9,
      "y": 0,
      "z": -7,
      "name": "Soil_Dirt_Cold"
    },
    {
      "x": -9,
      "y": 1,
      "z": -7,
      "name": "Soil_Dirt_Cold"
    },
    {
      "x": -9,
      "y": 2,
      "z": -7,
      "name": "Soil_Dirt_Cold"
    },
    {
      "x": -9,
      "y": 3,
      "z": -7,
      "name": "Soil_Dirt_Cold"
    },
    {
      "x": -9,
      "y": 4,
      "z": -7,
      "name": "Soil_Dirt_Cold"
    },
    {
      "x": -9,
      "y": 5,
      "z": -7,
      "name": "Soil_Dirt_Cold"
    },
    {
      "x": -9,
      "y": 6,
      "z": -7,
      "name": "Soil_Dirt_Cold"
    },
    {
      "x": -9,
      "y": 7,
      "z": -7,
      "name": "Soil_Dirt_Cold"
    },
    {
      "x": -9,
      "y": 8,
      "z": -7,
      "name": "Soil_Dirt_Cold"
    },
    {
      "x": -9,
      "y": 9,
      "z": -7,
      "name": "Soil_Dirt_Cold"
    },
    {
      "x": -9,
      "y": 10,
      "z": -7,
      "name": "Soil_Dirt_Cold"
    },
    {
      "x": -9,
      "y": 11,
      "z": -7,
      "name": "Soil_Dirt_Cold"
    },
    {
      "x": -9,
      "y": 0,
      "z": -6,
      "name": "Soil_Dirt_Cold"
    },
    {
      "x": -9,
      "y": 1,
      "z": -6,
      "name": "Soil_Dirt_Cold"
    },
    {
      "x": -9,
      "y": 2,
      "z": -6,
      "name": "Soil_Dirt_Cold"
    },
    {
      "x": -9,
      "y": 3,
      "z": -6,
      "name": "Soil_Dirt_Cold"
    },
    {
      "x": -9,
      "y": 4,
      "z": -6,
      "name": "Soil_Dirt_Cold"
    },
    {
      "x": -9,
      "y": 5,
      "z": -6,
      "name": "Soil_Dirt_Cold"
    },
    {
      "x": -9,
      "y": 6,
      "z": -6,
      "name": "Soil_Dirt_Cold"
    },
    {
      "x": -9,
      "y": 7,
      "z": -6,
      "name": "Soil_Dirt_Cold"
    },
    {
      "x": -9,
      "y": 8,
      "z": -6,
      "name": "Soil_Dirt_Cold"
    },
    {
      "x": -9,
      "y": 9,
      "z": -6,
      "name": "Soil_Dirt_Cold"
    },
    {
      "x": -9,
      "y": 10,
      "z": -6,
      "name": "Soil_Dirt_Cold"
    },
    {
      "x": -9,
      "y": 11,
      "z": -6,
      "name": "Soil_Pebbles_Frozen"
    },
    {
      "x": -9,
      "y": 0,
      "z": -5,
      "name": "Soil_Dirt_Cold"
    },
    {
      "x": -9,
      "y": 1,
      "z": -5,
      "name": "Soil_Dirt_Cold"
    },
    {
      "x": -9,
      "y": 2,
      "z": -5,
      "name": "Soil_Dirt_Cold"
    },
    {
      "x": -9,
      "y": 3,
      "z": -5,
      "name": "Soil_Dirt_Cold"
    },
    {
      "x": -9,
      "y": 4,
      "z": -5,
      "name": "Soil_Dirt_Cold"
    },
    {
      "x": -9,
      "y": 5,
      "z": -5,
      "name": "Soil_Dirt_Cold"
    },
    {
      "x": -9,
      "y": 6,
      "z": -5,
      "name": "Soil_Dirt_Cold"
    },
    {
      "x": -9,
      "y": 7,
      "z": -5,
      "name": "Soil_Dirt_Cold"
    },
    {
      "x": -9,
      "y": 8,
      "z": -5,
      "name": "Soil_Dirt_Cold"
    },
    {
      "x": -9,
      "y": 9,
      "z": -5,
      "name": "Soil_Dirt_Cold"
    },
    {
      "x": -9,
      "y": 10,
      "z": -5,
      "name": "Soil_Dirt_Cold"
    },
    {
      "x": -9,
      "y": 11,
      "z": -5,
      "name": "Soil_Pebbles_Frozen"
    },
    {
      "x": -9,
      "y": 0,
      "z": -4,
      "name": "Soil_Dirt_Cold"
    },
    {
      "x": -9,
      "y": 1,
      "z": -4,
      "name": "Soil_Dirt_Cold"
    },
    {
      "x": -9,
      "y": 2,
      "z": -4,
      "name": "Soil_Dirt_Cold"
    },
    {
      "x": -9,
      "y": 3,
      "z": -4,
      "name": "Soil_Dirt_Cold"
    },
    {
      "x": -9,
      "y": 4,
      "z": -4,
      "name": "Soil_Dirt_Cold"
    },
    {
      "x": -9,
      "y": 5,
      "z": -4,
      "name": "Soil_Dirt_Cold"
    },
    {
      "x": -9,
      "y": 6,
      "z": -4,
      "name": "Soil_Dirt_Cold"
    },
    {
      "x": -9,
      "y": 7,
      "z": -4,
      "name": "Soil_Dirt_Cold"
    },
    {
      "x": -9,
      "y": 8,
      "z": -4,
      "name": "Soil_Dirt_Cold"
    },
    {
      "x": -9,
      "y": 9,
      "z": -4,
      "name": "Soil_Dirt_Cold"
    },
    {
      "x": -9,
      "y": 10,
      "z": -4,
      "name": "Soil_Dirt_Cold"
    },
    {
      "x": -9,
      "y": 11,
      "z": -4,
      "name": "Soil_Pebbles_Frozen"
    },
    {
      "x": -9,
      "y": 0,
      "z": -3,
      "name": "Soil_Dirt_Cold"
    },
    {
      "x": -9,
      "y": 1,
      "z": -3,
      "name": "Soil_Dirt_Cold"
    },
    {
      "x": -9,
      "y": 2,
      "z": -3,
      "name": "Soil_Dirt_Cold"
    },
    {
      "x": -9,
      "y": 3,
      "z": -3,
      "name": "Soil_Dirt_Cold"
    },
    {
      "x": -9,
      "y": 4,
      "z": -3,
      "name": "Soil_Dirt_Cold"
    },
    {
      "x": -9,
      "y": 5,
      "z": -3,
      "name": "Soil_Dirt_Cold"
    },
    {
      "x": -9,
      "y": 6,
      "z": -3,
      "name": "Soil_Dirt_Cold"
    },
    {
      "x": -9,
      "y": 7,
      "z": -3,
      "name": "Soil_Dirt_Cold"
    },
    {
      "x": -9,
      "y": 8,
      "z": -3,
      "name": "Soil_Dirt_Cold"
    },
    {
      "x": -9,
      "y": 9,
      "z": -3,
      "name": "Soil_Dirt_Cold"
    },
    {
      "x": -9,
      "y": 10,
      "z": -3,
      "name": "Soil_Dirt_Cold"
    },
    {
      "x": -9,
      "y": 11,
      "z": -3,
      "name": "Soil_Pebbles_Frozen"
    },
    {
      "x": -9,
      "y": 0,
      "z": -2,
      "name": "Soil_Dirt_Cold"
    },
    {
      "x": -9,
      "y": 1,
      "z": -2,
      "name": "Soil_Dirt_Cold"
    },
    {
      "x": -9,
      "y": 2,
      "z": -2,
      "name": "Soil_Dirt_Cold"
    },
    {
      "x": -9,
      "y": 3,
      "z": -2,
      "name": "Soil_Dirt_Cold"
    },
    {
      "x": -9,
      "y": 4,
      "z": -2,
      "name": "Soil_Dirt_Cold"
    },
    {
      "x": -9,
      "y": 5,
      "z": -2,
      "name": "Soil_Dirt_Cold"
    },
    {
      "x": -9,
      "y": 6,
      "z": -2,
      "name": "Soil_Dirt_Cold"
    },
    {
      "x": -9,
      "y": 7,
      "z": -2,
      "name": "Soil_Dirt_Cold"
    },
    {
      "x": -9,
      "y": 8,
      "z": -2,
      "name": "Soil_Dirt_Cold"
    },
    {
      "x": -9,
      "y": 9,
      "z": -2,
      "name": "Soil_Dirt_Cold"
    },
    {
      "x": -9,
      "y": 10,
      "z": -2,
      "name": "Soil_Dirt_Cold"
    },
    {
      "x": -9,
      "y": 11,
      "z": -2,
      "name": "Soil_Pebbles_Frozen"
    },
    {
      "x": -9,
      "y": 0,
      "z": -1,
      "name": "Soil_Dirt_Cold"
    },
    {
      "x": -9,
      "y": 1,
      "z": -1,
      "name": "Soil_Dirt_Cold"
    },
    {
      "x": -9,
      "y": 2,
      "z": -1,
      "name": "Soil_Dirt_Cold"
    },
    {
      "x": -9,
      "y": 3,
      "z": -1,
      "name": "Soil_Dirt_Cold"
    },
    {
      "x": -9,
      "y": 4,
      "z": -1,
      "name": "Soil_Dirt_Cold"
    },
    {
      "x": -9,
      "y": 5,
      "z": -1,
      "name": "Soil_Dirt_Cold"
    },
    {
      "x": -9,
      "y": 6,
      "z": -1,
      "name": "Soil_Dirt_Cold"
    },
    {
      "x": -9,
      "y": 7,
      "z": -1,
      "name": "Soil_Dirt_Cold"
    },
    {
      "x": -9,
      "y": 8,
      "z": -1,
      "name": "Soil_Dirt_Cold"
    },
    {
      "x": -9,
      "y": 9,
      "z": -1,
      "name": "Soil_Dirt_Cold"
    },
    {
      "x": -9,
      "y": 10,
      "z": -1,
      "name": "Soil_Dirt_Cold"
    },
    {
      "x": -9,
      "y": 11,
      "z": -1,
      "name": "Soil_Dirt_Cold"
    },
    {
      "x": -9,
      "y": 0,
      "z": 0,
      "name": "Soil_Dirt_Cold"
    },
    {
      "x": -9,
      "y": 1,
      "z": 0,
      "name": "Soil_Dirt_Cold"
    },
    {
      "x": -9,
      "y": 2,
      "z": 0,
      "name": "Soil_Dirt_Cold"
    },
    {
      "x": -9,
      "y": 3,
      "z": 0,
      "name": "Soil_Dirt_Cold"
    },
    {
      "x": -9,
      "y": 4,
      "z": 0,
      "name": "Soil_Dirt_Cold"
    },
    {
      "x": -9,
      "y": 5,
      "z": 0,
      "name": "Soil_Dirt_Cold"
    },
    {
      "x": -9,
      "y": 6,
      "z": 0,
      "name": "Soil_Dirt_Cold"
    },
    {
      "x": -9,
      "y": 7,
      "z": 0,
      "name": "Soil_Dirt_Cold"
    },
    {
      "x": -9,
      "y": 8,
      "z": 0,
      "name": "Soil_Dirt_Cold"
    },
    {
      "x": -9,
      "y": 9,
      "z": 0,
      "name": "Soil_Dirt_Cold"
    },
    {
      "x": -9,
      "y": 10,
      "z": 0,
      "name": "Soil_Dirt_Cold"
    },
    {
      "x": -9,
      "y": 11,
      "z": 0,
      "name": "Soil_Dirt_Cold"
    },
    {
      "x": -9,
      "y": 0,
      "z": 1,
      "name": "Soil_Dirt_Cold"
    },
    {
      "x": -9,
      "y": 1,
      "z": 1,
      "name": "Soil_Dirt_Cold"
    },
    {
      "x": -9,
      "y": 2,
      "z": 1,
      "name": "Soil_Dirt_Cold"
    },
    {
      "x": -9,
      "y": 3,
      "z": 1,
      "name": "Soil_Dirt_Cold"
    },
    {
      "x": -9,
      "y": 4,
      "z": 1,
      "name": "Soil_Dirt_Cold"
    },
    {
      "x": -9,
      "y": 5,
      "z": 1,
      "name": "Soil_Dirt_Cold"
    },
    {
      "x": -9,
      "y": 6,
      "z": 1,
      "name": "Soil_Dirt_Cold"
    },
    {
      "x": -9,
      "y": 7,
      "z": 1,
      "name": "Soil_Dirt_Cold"
    },
    {
      "x": -9,
      "y": 8,
      "z": 1,
      "name": "Soil_Dirt_Cold"
    },
    {
      "x": -9,
      "y": 9,
      "z": 1,
      "name": "Soil_Dirt_Cold"
    },
    {
      "x": -9,
      "y": 10,
      "z": 1,
      "name": "Soil_Dirt_Cold"
    },
    {
      "x": -9,
      "y": 11,
      "z": 1,
      "name": "Soil_Dirt_Cold"
    },
    {
      "x": -9,
      "y": 0,
      "z": 2,
      "name": "Soil_Dirt_Cold"
    },
    {
      "x": -9,
      "y": 1,
      "z": 2,
      "name": "Soil_Dirt_Cold"
    },
    {
      "x": -9,
      "y": 2,
      "z": 2,
      "name": "Soil_Dirt_Cold"
    },
    {
      "x": -9,
      "y": 3,
      "z": 2,
      "name": "Soil_Dirt_Cold"
    },
    {
      "x": -9,
      "y": 4,
      "z": 2,
      "name": "Soil_Dirt_Cold"
    },
    {
      "x": -9,
      "y": 5,
      "z": 2,
      "name": "Soil_Dirt_Cold"
    },
    {
      "x": -9,
      "y": 6,
      "z": 2,
      "name": "Soil_Dirt_Cold"
    },
    {
      "x": -9,
      "y": 7,
      "z": 2,
      "name": "Soil_Dirt_Cold"
    },
    {
      "x": -9,
      "y": 8,
      "z": 2,
      "name": "Soil_Dirt_Cold"
    },
    {
      "x": -9,
      "y": 9,
      "z": 2,
      "name": "Soil_Dirt_Cold"
    },
    {
      "x": -9,
      "y": 10,
      "z": 2,
      "name": "Soil_Dirt_Cold"
    },
    {
      "x": -9,
      "y": 11,
      "z": 2,
      "name": "Soil_Dirt_Cold"
    },
    {
      "x": -9,
      "y": 0,
      "z": 3,
      "name": "Soil_Dirt_Cold"
    },
    {
      "x": -9,
      "y": 1,
      "z": 3,
      "name": "Soil_Dirt_Cold"
    },
    {
      "x": -9,
      "y": 2,
      "z": 3,
      "name": "Soil_Dirt_Cold"
    },
    {
      "x": -9,
      "y": 3,
      "z": 3,
      "name": "Soil_Dirt_Cold"
    },
    {
      "x": -9,
      "y": 4,
      "z": 3,
      "name": "Soil_Dirt_Cold"
    },
    {
      "x": -9,
      "y": 5,
      "z": 3,
      "name": "Soil_Dirt_Cold"
    },
    {
      "x": -9,
      "y": 6,
      "z": 3,
      "name": "Soil_Dirt_Cold"
    },
    {
      "x": -9,
      "y": 7,
      "z": 3,
      "name": "Soil_Dirt_Cold"
    },
    {
      "x": -9,
      "y": 8,
      "z": 3,
      "name": "Soil_Dirt_Cold"
    },
    {
      "x": -9,
      "y": 9,
      "z": 3,
      "name": "Soil_Dirt_Cold"
    },
    {
      "x": -9,
      "y": 10,
      "z": 3,
      "name": "Soil_Dirt_Cold"
    },
    {
      "x": -9,
      "y": 11,
      "z": 3,
      "name": "Soil_Dirt_Cold"
    },
    {
      "x": -9,
      "y": 0,
      "z": 4,
      "name": "Wood_Fir_Trunk",
      "support": 15
    },
    {
      "x": -9,
      "y": 1,
      "z": 4,
      "name": "Wood_Fir_Trunk",
      "support": 15
    },
    {
      "x": -9,
      "y": 2,
      "z": 4,
      "name": "Wood_Fir_Trunk",
      "support": 15
    },
    {
      "x": -9,
      "y": 3,
      "z": 4,
      "name": "Wood_Fir_Trunk",
      "support": 15
    },
    {
      "x": -9,
      "y": 4,
      "z": 4,
      "name": "Wood_Fir_Trunk",
      "support": 15
    },
    {
      "x": -9,
      "y": 5,
      "z": 4,
      "name": "Wood_Fir_Trunk",
      "support": 15
    },
    {
      "x": -9,
      "y": 6,
      "z": 4,
      "name": "Wood_Fir_Trunk",
      "support": 15
    },
    {
      "x": -9,
      "y": 7,
      "z": 4,
      "name": "Wood_Fir_Trunk",
      "support": 15
    },
    {
      "x": -9,
      "y": 8,
      "z": 4,
      "name": "Wood_Fir_Trunk",
      "support": 15
    },
    {
      "x": -9,
      "y": 9,
      "z": 4,
      "name": "Wood_Fir_Trunk",
      "support": 15
    },
    {
      "x": -9,
      "y": 10,
      "z": 4,
      "name": "Wood_Fir_Trunk",
      "support": 15
    },
    {
      "x": -9,
      "y": 11,
      "z": 4,
      "name": "Wood_Fir_Trunk",
      "support": 15
    },
    {
      "x": -9,
      "y": 12,
      "z": 4,
      "name": "Wood_Fir_Trunk",
      "support": 15
    },
    {
      "x": -9,
      "y": 0,
      "z": 5,
      "name": "Soil_Dirt_Cold"
    },
    {
      "x": -9,
      "y": 1,
      "z": 5,
      "name": "Soil_Dirt_Cold"
    },
    {
      "x": -9,
      "y": 2,
      "z": 5,
      "name": "Soil_Dirt_Cold"
    },
    {
      "x": -9,
      "y": 3,
      "z": 5,
      "name": "Soil_Dirt_Cold"
    },
    {
      "x": -9,
      "y": 4,
      "z": 5,
      "name": "Soil_Dirt_Cold"
    },
    {
      "x": -9,
      "y": 5,
      "z": 5,
      "name": "Soil_Dirt_Cold"
    },
    {
      "x": -9,
      "y": 6,
      "z": 5,
      "name": "Soil_Dirt_Cold"
    },
    {
      "x": -9,
      "y": 7,
      "z": 5,
      "name": "Soil_Dirt_Cold"
    },
    {
      "x": -9,
      "y": 8,
      "z": 5,
      "name": "Soil_Dirt_Cold"
    },
    {
      "x": -9,
      "y": 9,
      "z": 5,
      "name": "Soil_Dirt_Cold"
    },
    {
      "x": -9,
      "y": 10,
      "z": 5,
      "name": "Soil_Dirt_Cold"
    },
    {
      "x": -9,
      "y": 11,
      "z": 5,
      "name": "Soil_Dirt_Cold"
    },
    {
      "x": -9,
      "y": 12,
      "z": 5,
      "name": "Rubble_Shale"
    },
    {
      "x": -9,
      "y": 0,
      "z": 6,
      "name": "Soil_Dirt_Cold"
    },
    {
      "x": -9,
      "y": 1,
      "z": 6,
      "name": "Soil_Dirt_Cold"
    },
    {
      "x": -9,
      "y": 2,
      "z": 6,
      "name": "Soil_Dirt_Cold"
    },
    {
      "x": -9,
      "y": 3,
      "z": 6,
      "name": "Soil_Dirt_Cold"
    },
    {
      "x": -9,
      "y": 4,
      "z": 6,
      "name": "Soil_Dirt_Cold"
    },
    {
      "x": -9,
      "y": 5,
      "z": 6,
      "name": "Soil_Dirt_Cold"
    },
    {
      "x": -9,
      "y": 6,
      "z": 6,
      "name": "Soil_Dirt_Cold"
    },
    {
      "x": -9,
      "y": 7,
      "z": 6,
      "name": "Soil_Dirt_Cold"
    },
    {
      "x": -9,
      "y": 8,
      "z": 6,
      "name": "Soil_Dirt_Cold"
    },
    {
      "x": -9,
      "y": 9,
      "z": 6,
      "name": "Soil_Dirt_Cold"
    },
    {
      "x": -9,
      "y": 10,
      "z": 6,
      "name": "Soil_Dirt_Cold"
    },
    {
      "x": -9,
      "y": 11,
      "z": 6,
      "name": "Soil_Ash"
    },
    {
      "x": -9,
      "y": 12,
      "z": 6,
      "name": "Furniture_Crude_Brazier"
    },
    {
      "x": -9,
      "y": 0,
      "z": 7,
      "name": "Soil_Dirt_Cold"
    },
    {
      "x": -9,
      "y": 1,
      "z": 7,
      "name": "Soil_Dirt_Cold"
    },
    {
      "x": -9,
      "y": 2,
      "z": 7,
      "name": "Soil_Dirt_Cold"
    },
    {
      "x": -9,
      "y": 3,
      "z": 7,
      "name": "Soil_Dirt_Cold"
    },
    {
      "x": -9,
      "y": 4,
      "z": 7,
      "name": "Soil_Dirt_Cold"
    },
    {
      "x": -9,
      "y": 5,
      "z": 7,
      "name": "Soil_Dirt_Cold"
    },
    {
      "x": -9,
      "y": 6,
      "z": 7,
      "name": "Soil_Dirt_Cold"
    },
    {
      "x": -9,
      "y": 7,
      "z": 7,
      "name": "Soil_Dirt_Cold"
    },
    {
      "x": -9,
      "y": 8,
      "z": 7,
      "name": "Soil_Dirt_Cold"
    },
    {
      "x": -9,
      "y": 9,
      "z": 7,
      "name": "Soil_Dirt_Cold"
    },
    {
      "x": -9,
      "y": 10,
      "z": 7,
      "name": "Soil_Dirt_Cold"
    },
    {
      "x": -9,
      "y": 11,
      "z": 7,
      "name": "Soil_Dirt_Cold"
    },
    {
      "x": -9,
      "y": 0,
      "z": 8,
      "name": "Soil_Dirt_Cold"
    },
    {
      "x": -9,
      "y": 1,
      "z": 8,
      "name": "Soil_Dirt_Cold"
    },
    {
      "x": -9,
      "y": 2,
      "z": 8,
      "name": "Soil_Dirt_Cold"
    },
    {
      "x": -9,
      "y": 3,
      "z": 8,
      "name": "Soil_Dirt_Cold"
    },
    {
      "x": -9,
      "y": 4,
      "z": 8,
      "name": "Soil_Dirt_Cold"
    },
    {
      "x": -9,
      "y": 5,
      "z": 8,
      "name": "Soil_Dirt_Cold"
    },
    {
      "x": -9,
      "y": 6,
      "z": 8,
      "name": "Soil_Dirt_Cold"
    },
    {
      "x": -9,
      "y": 7,
      "z": 8,
      "name": "Soil_Dirt_Cold"
    },
    {
      "x": -9,
      "y": 8,
      "z": 8,
      "name": "Soil_Dirt_Cold"
    },
    {
      "x": -9,
      "y": 9,
      "z": 8,
      "name": "Soil_Dirt_Cold"
    },
    {
      "x": -9,
      "y": 10,
      "z": 8,
      "name": "Soil_Dirt_Cold"
    },
    {
      "x": -9,
      "y": 11,
      "z": 8,
      "name": "Soil_Dirt_Cold"
    },
    {
      "x": -9,
      "y": 0,
      "z": 9,
      "name": "Soil_Dirt_Cold"
    },
    {
      "x": -9,
      "y": 1,
      "z": 9,
      "name": "Soil_Dirt_Cold"
    },
    {
      "x": -9,
      "y": 2,
      "z": 9,
      "name": "Soil_Dirt_Cold"
    },
    {
      "x": -9,
      "y": 3,
      "z": 9,
      "name": "Soil_Dirt_Cold"
    },
    {
      "x": -9,
      "y": 4,
      "z": 9,
      "name": "Soil_Dirt_Cold"
    },
    {
      "x": -9,
      "y": 5,
      "z": 9,
      "name": "Soil_Dirt_Cold"
    },
    {
      "x": -9,
      "y": 6,
      "z": 9,
      "name": "Soil_Dirt_Cold"
    },
    {
      "x": -9,
      "y": 7,
      "z": 9,
      "name": "Soil_Dirt_Cold"
    },
    {
      "x": -9,
      "y": 8,
      "z": 9,
      "name": "Soil_Dirt_Cold"
    },
    {
      "x": -9,
      "y": 9,
      "z": 9,
      "name": "Soil_Dirt_Cold"
    },
    {
      "x": -9,
      "y": 10,
      "z": 9,
      "name": "Soil_Dirt_Cold"
    },
    {
      "x": -9,
      "y": 11,
      "z": 9,
      "name": "Soil_Dirt_Cold"
    },
    {
      "x": -9,
      "y": 0,
      "z": 10,
      "name": "Soil_Dirt_Cold"
    },
    {
      "x": -9,
      "y": 1,
      "z": 10,
      "name": "Soil_Dirt_Cold"
    },
    {
      "x": -9,
      "y": 2,
      "z": 10,
      "name": "Soil_Dirt_Cold"
    },
    {
      "x": -9,
      "y": 3,
      "z": 10,
      "name": "Soil_Dirt_Cold"
    },
    {
      "x": -9,
      "y": 4,
      "z": 10,
      "name": "Soil_Dirt_Cold"
    },
    {
      "x": -9,
      "y": 5,
      "z": 10,
      "name": "Soil_Dirt_Cold"
    },
    {
      "x": -9,
      "y": 6,
      "z": 10,
      "name": "Soil_Dirt_Cold"
    },
    {
      "x": -9,
      "y": 7,
      "z": 10,
      "name": "Soil_Dirt_Cold"
    },
    {
      "x": -9,
      "y": 8,
      "z": 10,
      "name": "Soil_Dirt_Cold"
    },
    {
      "x": -9,
      "y": 9,
      "z": 10,
      "name": "Soil_Dirt_Cold"
    },
    {
      "x": -9,
      "y": 10,
      "z": 10,
      "name": "Soil_Dirt_Cold"
    },
    {
      "x": -9,
      "y": 11,
      "z": 10,
      "name": "Soil_Dirt_Cold"
    },
    {
      "x": -9,
      "y": 0,
      "z": 11,
      "name": "Wood_Fir_Trunk",
      "support": 15
    },
    {
      "x": -9,
      "y": 1,
      "z": 11,
      "name": "Wood_Fir_Trunk",
      "support": 15
    },
    {
      "x": -9,
      "y": 2,
      "z": 11,
      "name": "Wood_Fir_Trunk",
      "support": 15
    },
    {
      "x": -9,
      "y": 3,
      "z": 11,
      "name": "Wood_Fir_Trunk",
      "support": 15
    },
    {
      "x": -9,
      "y": 4,
      "z": 11,
      "name": "Wood_Fir_Trunk",
      "support": 15
    },
    {
      "x": -9,
      "y": 5,
      "z": 11,
      "name": "Wood_Fir_Trunk",
      "support": 15
    },
    {
      "x": -9,
      "y": 6,
      "z": 11,
      "name": "Wood_Fir_Trunk",
      "support": 15
    },
    {
      "x": -9,
      "y": 7,
      "z": 11,
      "name": "Wood_Fir_Trunk",
      "support": 15
    },
    {
      "x": -9,
      "y": 8,
      "z": 11,
      "name": "Wood_Fir_Trunk",
      "support": 15
    },
    {
      "x": -9,
      "y": 9,
      "z": 11,
      "name": "Wood_Fir_Trunk",
      "support": 15
    },
    {
      "x": -9,
      "y": 10,
      "z": 11,
      "name": "Wood_Fir_Trunk",
      "support": 15
    },
    {
      "x": -9,
      "y": 11,
      "z": 11,
      "name": "Wood_Fir_Trunk",
      "support": 15
    },
    {
      "x": -9,
      "y": 12,
      "z": 11,
      "name": "Wood_Fir_Trunk",
      "support": 15
    },
    {
      "x": -9,
      "y": 13,
      "z": 11,
      "name": "Survival_Trap_Spike_Wood_Large"
    },
    {
      "x": -8,
      "y": 0,
      "z": -13,
      "name": "Wood_Fir_Trunk",
      "support": 15
    },
    {
      "x": -8,
      "y": 1,
      "z": -13,
      "name": "Wood_Fir_Trunk",
      "support": 15
    },
    {
      "x": -8,
      "y": 2,
      "z": -13,
      "name": "Wood_Fir_Trunk",
      "support": 15
    },
    {
      "x": -8,
      "y": 3,
      "z": -13,
      "name": "Wood_Fir_Trunk",
      "support": 15
    },
    {
      "x": -8,
      "y": 4,
      "z": -13,
      "name": "Wood_Fir_Trunk",
      "support": 15
    },
    {
      "x": -8,
      "y": 5,
      "z": -13,
      "name": "Wood_Fir_Trunk",
      "support": 15
    },
    {
      "x": -8,
      "y": 6,
      "z": -13,
      "name": "Wood_Fir_Trunk",
      "support": 15
    },
    {
      "x": -8,
      "y": 7,
      "z": -13,
      "name": "Wood_Fir_Trunk",
      "support": 15
    },
    {
      "x": -8,
      "y": 8,
      "z": -13,
      "name": "Wood_Fir_Trunk",
      "support": 15
    },
    {
      "x": -8,
      "y": 9,
      "z": -13,
      "name": "Wood_Fir_Trunk",
      "support": 15
    },
    {
      "x": -8,
