{
  "version": 8,
  "blockIdVersion": 10,
  "anchorX": 0,
  "anchorY": 3,
  "anchorZ": 0,
  "blocks": [
    {
      "x": -29,
      "y": 0,
      "z": 19,
      "name": "Rock_Sandstone_Cobble"
    },
    {
      "x": -29,
      "y": 1,
      "z": 19,
      "name": "Rock_Sandstone_Cobble"
    },
    {
      "x": -29,
      "y": 2,
      "z": 19,
      "name": "Rock_Sandstone_Cobble"
    },
    {
      "x": -28,
      "y": 0,
      "z": -28,
      "name": "Rock_Sandstone_Cobble"
    },
    {
      "x": -28,
      "y": 1,
      "z": -28,
      "name": "Rock_Sandstone_Cobble"
    },
    {
      "x": -28,
      "y": 2,
      "z": -28,
      "name": "Rock_Sandstone_Cobble"
    },
    {
      "x": -28,
      "y": 3,
      "z": -28,
      "name": "Rock_Sandstone_Cobble"
    },
    {
      "x": -21,
      "y": 3,
      "z": 5,
      "name": "Cloth_Block_Wool_Pink"
    },
    {
      "x": -21,
      "y": 3,
      "z": 6,
      "name": "Cloth_Block_Wool_Pink"
    },
    {
      "x": -21,
      "y": 3,
      "z": 7,
      "name": "Cloth_Block_Wool_Pink"
    },
    {
      "x": -20,
      "y": 3,
      "z": 5,
      "name": "Cloth_Block_Wool_Pink"
    },
    {
      "x": -20,
      "y": 3,
      "z": 6,
      "name": "Cloth_Block_Wool_Pink"
    },
    {
      "x": -20,
      "y": 4,
      "z": 6,
      "name": "Prefab_Spawner_Block",
      "rotation": 3
    },
    {
      "x": -20,
      "y": 3,
      "z": 7,
      "name": "Cloth_Block_Wool_Pink"
    },
    {
      "x": -19,
      "y": 3,
      "z": 5,
      "name": "Cloth_Block_Wool_Pink"
    },
    {
      "x": -19,
      "y": 3,
      "z": 6,
      "name": "Cloth_Block_Wool_Pink"
    },
    {
      "x": -19,
      "y": 3,
      "z": 7,
      "name": "Cloth_Block_Wool_Pink"
    },
    {
      "x": -10,
      "y": 7,
      "z": -23,
      "name": "Cloth_Block_Wool_Orange"
    },
    {
      "x": -10,
      "y": 7,
      "z": -22,
      "name": "Cloth_Block_Wool_Orange"
    },
    {
      "x": -10,
      "y": 7,
      "z": -21,
      "name": "Cloth_Block_Wool_Orange"
    },
    {
      "x": -9,
      "y": 7,
      "z": -23,
      "name": "Cloth_Block_Wool_Orange"
    },
    {
      "x": -9,
      "y": 0,
      "z": -22,
      "name": "Rock_Sandstone_Cobble"
    },
    {
      "x": -9,
      "y": 1,
      "z": -22,
      "name": "Rock_Sandstone_Cobble"
    },
    {
      "x": -9,
      "y": 2,
      "z": -22,
      "name": "Rock_Sandstone_Cobble"
    },
    {
      "x": -9,
      "y": 3,
      "z": -22,
      "name": "Rock_Sandstone_Cobble"
    },
    {
      "x": -9,
      "y": 4,
      "z": -22,
      "name": "Rock_Sandstone_Cobble"
    },
    {
      "x": -9,
      "y": 5,
      "z": -22,
      "name": "Rock_Sandstone_Cobble"
    },
    {
      "x": -9,
      "y": 6,
      "z": -22,
      "name": "Rock_Sandstone_Cobble"
    },
    {
      "x": -9,
      "y": 7,
      "z": -22,
      "name": "Cloth_Block_Wool_Orange"
    },
    {
      "x": -9,
      "y": 8,
      "z": -22,
      "name": "Prefab_Spawner_Block"
    },
    {
      "x": -9,
      "y": 7,
      "z": -21,
      "name": "Cloth_Block_Wool_Orange"
    },
    {
      "x": -8,
      "y": 7,
      "z": -23,
      "name": "Cloth_Block_Wool_Orange"
    },
    {
      "x": -8,
      "y": 7,
      "z": -22,
      "name": "Cloth_Block_Wool_Orange"
    },
    {
      "x": -8,
      "y": 7,
      "z": -21,
      "name": "Cloth_Block_Wool_Orange"
    },
    {
      "x": 0,
      "y": 2,
      "z": -7,
      "name": "Cloth_Block_Wool_Red"
    },
    {
      "x": 0,
      "y": 2,
      "z": -6,
      "name": "Cloth_Block_Wool_Red"
    },
    {
      "x": 0,
      "y": 2,
      "z": -5,
      "name": "Cloth_Block_Wool_Red"
    },
    {
      "x": 1,
      "y": 2,
      "z": -7,
      "name": "Cloth_Block_Wool_Red"
    },
    {
      "x": 1,
      "y": 0,
      "z": -6,
      "name": "Rock_Sandstone_Cobble"
    },
    {
      "x": 1,
      "y": 1,
      "z": -6,
      "name": "Rock_Sandstone_Cobble"
    },
    {
      "x": 1,
      "y": 2,
      "z": -6,
      "name": "Cloth_Block_Wool_Red"
    },
    {
      "x": 1,
      "y": 3,
      "z": -6,
      "name": "Prefab_Spawner_Block"
    },
    {
      "x": 1,
      "y": 2,
      "z": -5,
      "name": "Cloth_Block_Wool_Red"
    },
    {
      "x": 2,
      "y": 2,
      "z": -7,
      "name": "Cloth_Block_Wool_Red"
    },
    {
      "x": 2,
      "y": 2,
      "z": -6,
      "name": "Cloth_Block_Wool_Red"
    },
    {
      "x": 2,
      "y": 2,
      "z": -5,
      "name": "Cloth_Block_Wool_Red"
    },
    {
      "x": 11,
      "y": 7,
      "z": -26,
      "name": "Cloth_Block_Wool_Pink"
    },
    {
      "x": 11,
      "y": 7,
      "z": -25,
      "name": "Cloth_Block_Wool_Pink"
    },
    {
      "x": 11,
      "y": 7,
      "z": -24,
      "name": "Cloth_Block_Wool_Pink"
    },
    {
      "x": 12,
      "y": 7,
      "z": -26,
      "name": "Cloth_Block_Wool_Pink"
    },
    {
      "x": 12,
      "y": 0,
      "z": -25,
      "name": "Rock_Sandstone_Cobble"
    },
    {
      "x": 12,
      "y": 1,
      "z": -25,
      "name": "Rock_Sandstone_Cobble"
    },
    {
      "x": 12,
      "y": 2,
      "z": -25,
      "name": "Rock_Sandstone_Cobble"
    },
    {
      "x": 12,
      "y": 3,
      "z": -25,
      "name": "Rock_Sandstone_Cobble"
    },
    {
      "x": 12,
      "y": 4,
      "z": -25,
      "name": "Rock_Sandstone_Cobble"
    },
    {
      "x": 12,
      "y": 5,
      "z": -25,
      "name": "Rock_Sandstone_Cobble"
    },
    {
      "x": 12,
      "y": 6,
      "z": -25,
      "name": "Rock_Sandstone_Cobble"
    },
    {
      "x": 12,
      "y": 7,
      "z": -25,
      "name": "Cloth_Block_Wool_Pink"
    },
    {
      "x": 12,
      "y": 8,
      "z": -25,
      "name": "Prefab_Spawner_Block",
      "rotation": 2
    },
    {
      "x": 12,
      "y": 7,
      "z": -24,
      "name": "Cloth_Block_Wool_Pink"
    },
    {
      "x": 13,
      "y": 7,
      "z": -26,
      "name": "Cloth_Block_Wool_Pink"
    },
    {
      "x": 13,
      "y": 7,
      "z": -25,
      "name": "Cloth_Block_Wool_Pink"
    },
    {
      "x": 13,
      "y": 7,
      "z": -24,
      "name": "Cloth_Block_Wool_Pink"
    },
    {
      "x": 21,
      "y": 3,
      "z": -12,
      "name": "Cloth_Block_Wool_Pink"
    },
    {
      "x": 21,
      "y": 3,
      "z": -11,
      "name": "Cloth_Block_Wool_Pink"
    },
    {
      "x": 21,
      "y": 3,
      "z": -10,
      "name": "Cloth_Block_Wool_Pink"
    },
    {
      "x": 21,
      "y": 3,
      "z": 5,
      "name": "Cloth_Block_Wool_Pink"
    },
    {
      "x": 21,
      "y": 3,
      "z": 6,
      "name": "Cloth_Block_Wool_Pink"
    },
    {
      "x": 21,
      "y": 3,
      "z": 7,
      "name": "Cloth_Block_Wool_Pink"
    },
    {
      "x": 22,
      "y": 3,
      "z": -12,
      "name": "Cloth_Block_Wool_Pink"
    },
    {
      "x": 22,
      "y": 0,
      "z": -11,
      "name": "Rock_Sandstone_Cobble"
    },
    {
      "x": 22,
      "y": 1,
      "z": -11,
      "name": "Rock_Sandstone_Cobble"
    },
    {
      "x": 22,
      "y": 2,
      "z": -11,
      "name": "Rock_Sandstone_Cobble"
    },
    {
      "x": 22,
      "y": 3,
      "z": -11,
      "name": "Cloth_Block_Wool_Pink"
    },
    {
      "x": 22,
      "y": 4,
      "z": -11,
      "name": "Prefab_Spawner_Block",
      "rotation": 1
    },
    {
      "x": 22,
      "y": 3,
      "z": -10,
      "name": "Cloth_Block_Wool_Pink"
    },
    {
      "x": 22,
      "y": 3,
      "z": 5,
      "name": "Cloth_Block_Wool_Pink"
    },
    {
      "x": 22,
      "y": 0,
      "z": 6,
      "name": "Rock_Sandstone_Cobble"
    },
    {
      "x": 22,
      "y": 1,
      "z": 6,
      "name": "Rock_Sandstone_Cobble"
    },
    {
      "x": 22,
      "y": 2,
      "z": 6,
      "name": "Rock_Sandstone_Cobble"
    },
    {
      "x": 22,
      "y": 3,
      "z": 6,
      "name": "Cloth_Block_Wool_Pink"
    },
    {
      "x": 22,
      "y": 4,
      "z": 6,
      "name": "Prefab_Spawner_Block",
      "rotation": 1
    },
    {
      "x": 22,
      "y": 3,
      "z": 7,
      "name": "Cloth_Block_Wool_Pink"
    },
    {
      "x": 23,
      "y": 3,
      "z": -12,
      "name": "Cloth_Block_Wool_Pink"
    },
    {
      "x": 23,
      "y": 3,
      "z": -11,
      "name": "Cloth_Block_Wool_Pink"
    },
    {
      "x": 23,
      "y": 3,
      "z": -10,
      "name": "Cloth_Block_Wool_Pink"
    },
    {
      "x": 23,
      "y": 3,
      "z": 5,
      "name": "Cloth_Block_Wool_Pink"
    },
    {
      "x": 23,
      "y": 3,
      "z": 6,
      "name": "Cloth_Block_Wool_Pink"
    },
    {
      "x": 23,
      "y": 3,
      "z": 7,
      "name": "Cloth_Block_Wool_Pink"
    },
    {
      "x": 30,
      "y": 0,
      "z": -27,
      "name": "Rock_Sandstone_Cobble"
    },
    {
      "x": 30,
      "y": 1,
      "z": -27,
      "name": "Rock_Sandstone_Cobble"
    },
    {
      "x": 30,
      "y": 2,
      "z": -27,
      "name": "Rock_Sandstone_Cobble"
    },
    {
      "x": 31,
      "y": 0,
      "z": 16,
      "name": "Rock_Sandstone_Cobble"
    },
    {
      "x": 31,
      "y": 1,
      "z": 16,
      "name": "Rock_Sandstone_Cobble"
    },
    {
      "x": 31,
      "y": 2,
      "z": 16,
      "name": "Rock_Sandstone_Cobble"
    }
  ]
}